Fri, 26 Apr 2019 14:25:33 log.py[line:17] DEBUG 执行过程中出错
Fri, 26 Apr 2019 14:25:33 log.py[line:20] ERROR (1054, "Unknown column 'from_no_in' in 'field list'")
Traceback (most recent call last):
  File "C:\Users\ipharmacare\newreport\GetSQLvalue\itemZoneValue.py", line 315, in getSqlValue_zone
    sqlValue = self.getValueInZone(itemname, zoneid, startT, endT)
  File "C:\Users\ipharmacare\newreport\GetSQLvalue\itemZoneValue.py", line 43, in getValueInZone
    sqlValue = self.conndb.executeSQL_zoneid_one(self.cur, self.sql, zoneid, startT, endT)
  File "C:\Users\ipharmacare\newreport\common\connectDB.py", line 49, in executeSQL_zoneid_one
    cur.execute(sql, (zoneid, startT, endT))
  File "C:\Users\ipharmacare\python27\lib\site-packages\MySQLdb\cursors.py", line 205, in execute
    self.errorhandler(self, exc, value)
  File "C:\Users\ipharmacare\python27\lib\site-packages\MySQLdb\connections.py", line 36, in defaulterrorhandler
    raise errorclass, errorvalue
OperationalError: (1054, "Unknown column 'from_no_in' in 'field list'")
Fri, 26 Apr 2019 14:25:33 log.py[line:17] DEBUG 执行过程中出错
Fri, 26 Apr 2019 14:25:33 log.py[line:20] ERROR (1054, "Unknown column 'from_no_in' in 'field list'")
Traceback (most recent call last):
  File "C:\Users\ipharmacare\newreport\GetSQLvalue\itemZoneValue.py", line 315, in getSqlValue_zone
    sqlValue = self.getValueInZone(itemname, zoneid, startT, endT)
  File "C:\Users\ipharmacare\newreport\GetSQLvalue\itemZoneValue.py", line 43, in getValueInZone
    sqlValue = self.conndb.executeSQL_zoneid_one(self.cur, self.sql, zoneid, startT, endT)
  File "C:\Users\ipharmacare\newreport\common\connectDB.py", line 49, in executeSQL_zoneid_one
    cur.execute(sql, (zoneid, startT, endT))
  File "C:\Users\ipharmacare\python27\lib\site-packages\MySQLdb\cursors.py", line 205, in execute
    self.errorhandler(self, exc, value)
  File "C:\Users\ipharmacare\python27\lib\site-packages\MySQLdb\connections.py", line 36, in defaulterrorhandler
    raise errorclass, errorvalue
OperationalError: (1054, "Unknown column 'from_no_in' in 'field list'")
Fri, 26 Apr 2019 14:25:33 log.py[line:17] DEBUG 该指标在指标库中不存在,门诊输液药物输液总量
Fri, 26 Apr 2019 14:25:33 log.py[line:17] DEBUG 读取配置项发生了错误,zone,门诊输液药物输液总量
Fri, 26 Apr 2019 14:25:33 log.py[line:20] ERROR No option '\xe9\x97\xa8\xe8\xaf\x8a\xe8\xbe\x93\xe6\xb6\xb2\xe8\x8d\xaf\xe7\x89\xa9\xe8\xbe\x93\xe6\xb6\xb2\xe6\x80\xbb\xe9\x87\x8f' in section: 'zone'
Traceback (most recent call last):
  File "C:\Users\ipharmacare\newreport\common\configReader.py", line 27, in get
    return self.conf.get(field,key)
  File "C:\Users\ipharmacare\python27\lib\ConfigParser.py", line 618, in get
    raise NoOptionError(option, section)
NoOptionError: No option '\xe9\x97\xa8\xe8\xaf\x8a\xe8\xbe\x93\xe6\xb6\xb2\xe8\x8d\xaf\xe7\x89\xa9\xe8\xbe\x93\xe6\xb6\xb2\xe6\x80\xbb\xe9\x87\x8f' in section: 'zone'
Fri, 26 Apr 2019 14:25:33 log.py[line:17] DEBUG 执行过程中出错
Fri, 26 Apr 2019 14:25:33 log.py[line:20] ERROR unsupported operand type(s) for %: 'NoneType' and 'tuple'
Traceback (most recent call last):
  File "C:\Users\ipharmacare\newreport\GetSQLvalue\itemZoneValue.py", line 325, in getSqlValue_zone
    sqlValue = self.getValueInCalc(itemname, zoneid, startT, endT, self.optcalcminus)
  File "C:\Users\ipharmacare\newreport\GetSQLvalue\itemZoneValue.py", line 114, in getValueInCalc
    self.itemvalue_one = self.getCalc_Numerator_zone(self.itemnameOne, zoneid, startT, endT, optcalcminus)
  File "C:\Users\ipharmacare\newreport\GetSQLvalue\itemZoneValue.py", line 219, in getCalc_Numerator_zone
    self.itemvalue_one = self.conndb.executeSQL_zoneid_one(self.cur, self.itemOneSql, zoneid, startT, endT)
  File "C:\Users\ipharmacare\newreport\common\connectDB.py", line 49, in executeSQL_zoneid_one
    cur.execute(sql, (zoneid, startT, endT))
  File "C:\Users\ipharmacare\python27\lib\site-packages\MySQLdb\cursors.py", line 187, in execute
    query = query % tuple([db.literal(item) for item in args])
TypeError: unsupported operand type(s) for %: 'NoneType' and 'tuple'
Fri, 26 Apr 2019 14:25:33 log.py[line:17] DEBUG 该指标在指标库中不存在,住院输液药物输液总量
Fri, 26 Apr 2019 14:25:33 log.py[line:17] DEBUG 读取配置项发生了错误,zone,住院输液药物输液总量
Fri, 26 Apr 2019 14:25:33 log.py[line:20] ERROR No option '\xe4\xbd\x8f\xe9\x99\xa2\xe8\xbe\x93\xe6\xb6\xb2\xe8\x8d\xaf\xe7\x89\xa9\xe8\xbe\x93\xe6\xb6\xb2\xe6\x80\xbb\xe9\x87\x8f' in section: 'zone'
Traceback (most recent call last):
  File "C:\Users\ipharmacare\newreport\common\configReader.py", line 27, in get
    return self.conf.get(field,key)
  File "C:\Users\ipharmacare\python27\lib\ConfigParser.py", line 618, in get
    raise NoOptionError(option, section)
NoOptionError: No option '\xe4\xbd\x8f\xe9\x99\xa2\xe8\xbe\x93\xe6\xb6\xb2\xe8\x8d\xaf\xe7\x89\xa9\xe8\xbe\x93\xe6\xb6\xb2\xe6\x80\xbb\xe9\x87\x8f' in section: 'zone'
Fri, 26 Apr 2019 14:25:33 log.py[line:17] DEBUG 执行过程中出错
Fri, 26 Apr 2019 14:25:33 log.py[line:20] ERROR unsupported operand type(s) for %: 'NoneType' and 'tuple'
Traceback (most recent call last):
  File "C:\Users\ipharmacare\newreport\GetSQLvalue\itemZoneValue.py", line 325, in getSqlValue_zone
    sqlValue = self.getValueInCalc(itemname, zoneid, startT, endT, self.optcalcminus)
  File "C:\Users\ipharmacare\newreport\GetSQLvalue\itemZoneValue.py", line 114, in getValueInCalc
    self.itemvalue_one = self.getCalc_Numerator_zone(self.itemnameOne, zoneid, startT, endT, optcalcminus)
  File "C:\Users\ipharmacare\newreport\GetSQLvalue\itemZoneValue.py", line 219, in getCalc_Numerator_zone
    self.itemvalue_one = self.conndb.executeSQL_zoneid_one(self.cur, self.itemOneSql, zoneid, startT, endT)
  File "C:\Users\ipharmacare\newreport\common\connectDB.py", line 49, in executeSQL_zoneid_one
    cur.execute(sql, (zoneid, startT, endT))
  File "C:\Users\ipharmacare\python27\lib\site-packages\MySQLdb\cursors.py", line 187, in execute
    query = query % tuple([db.literal(item) for item in args])
TypeError: unsupported operand type(s) for %: 'NoneType' and 'tuple'
Fri, 26 Apr 2019 14:25:38 log.py[line:17] DEBUG 执行过程中出错
Fri, 26 Apr 2019 14:25:38 log.py[line:20] ERROR (1054, "Unknown column 'Herb_Packet_Count' in 'field list'")
Traceback (most recent call last):
  File "C:\Users\ipharmacare\newreport\GetSQLvalue\itemZoneValue.py", line 325, in getSqlValue_zone
    sqlValue = self.getValueInCalc(itemname, zoneid, startT, endT, self.optcalcminus)
  File "C:\Users\ipharmacare\newreport\GetSQLvalue\itemZoneValue.py", line 114, in getValueInCalc
    self.itemvalue_one = self.getCalc_Numerator_zone(self.itemnameOne, zoneid, startT, endT, optcalcminus)
  File "C:\Users\ipharmacare\newreport\GetSQLvalue\itemZoneValue.py", line 219, in getCalc_Numerator_zone
    self.itemvalue_one = self.conndb.executeSQL_zoneid_one(self.cur, self.itemOneSql, zoneid, startT, endT)
  File "C:\Users\ipharmacare\newreport\common\connectDB.py", line 49, in executeSQL_zoneid_one
    cur.execute(sql, (zoneid, startT, endT))
  File "C:\Users\ipharmacare\python27\lib\site-packages\MySQLdb\cursors.py", line 205, in execute
    self.errorhandler(self, exc, value)
  File "C:\Users\ipharmacare\python27\lib\site-packages\MySQLdb\connections.py", line 36, in defaulterrorhandler
    raise errorclass, errorvalue
OperationalError: (1054, "Unknown column 'Herb_Packet_Count' in 'field list'")
Fri, 26 Apr 2019 14:25:42 log.py[line:17] DEBUG 该指标在指标库中不存在,出院患者中抗菌药物治疗使用前病原学检查送检人次
Fri, 26 Apr 2019 14:28:43 log.py[line:17] DEBUG 指标计算时出错
Fri, 26 Apr 2019 14:28:43 log.py[line:20] ERROR (1054, "Unknown column 'Herb_Packet_Count' in 'field list'")
Traceback (most recent call last):
  File "C:\Users\ipharmacare\newreport\GetSQLvalue\itemZoneValue.py", line 95, in getValueInCalcminus
    endT)
  File "C:\Users\ipharmacare\newreport\common\connectDB.py", line 49, in executeSQL_zoneid_one
    cur.execute(sql, (zoneid, startT, endT))
  File "C:\Users\ipharmacare\python27\lib\site-packages\MySQLdb\cursors.py", line 205, in execute
    self.errorhandler(self, exc, value)
  File "C:\Users\ipharmacare\python27\lib\site-packages\MySQLdb\connections.py", line 36, in defaulterrorhandler
    raise errorclass, errorvalue
OperationalError: (1054, "Unknown column 'Herb_Packet_Count' in 'field list'")
Fri, 26 Apr 2019 14:28:43 log.py[line:17] DEBUG 计算指标不成功，有指标值为空
Fri, 26 Apr 2019 14:28:43 log.py[line:17] DEBUG 指标计算时出错
Fri, 26 Apr 2019 14:28:43 log.py[line:20] ERROR (1054, "Unknown column 'Herb_Packet_Count' in 'field list'")
Traceback (most recent call last):
  File "C:\Users\ipharmacare\newreport\GetSQLvalue\itemZoneValue.py", line 95, in getValueInCalcminus
    endT)
  File "C:\Users\ipharmacare\newreport\common\connectDB.py", line 49, in executeSQL_zoneid_one
    cur.execute(sql, (zoneid, startT, endT))
  File "C:\Users\ipharmacare\python27\lib\site-packages\MySQLdb\cursors.py", line 205, in execute
    self.errorhandler(self, exc, value)
  File "C:\Users\ipharmacare\python27\lib\site-packages\MySQLdb\connections.py", line 36, in defaulterrorhandler
    raise errorclass, errorvalue
OperationalError: (1054, "Unknown column 'Herb_Packet_Count' in 'field list'")
Fri, 26 Apr 2019 14:28:43 log.py[line:17] DEBUG 计算指标不成功，有指标值为空
Fri, 26 Apr 2019 14:37:25 log.py[line:17] DEBUG 执行过程中出错
Fri, 26 Apr 2019 14:37:25 log.py[line:20] ERROR unsupported format character ''' (0x27) at index 455
Traceback (most recent call last):
  File "C:\Users\ipharmacare\newreport\GetSQLvalue\itemZoneValue.py", line 320, in getSqlValue_zone
    sqlValue = self.getValueInHospital(itemname, zoneid, startT, endT)
  File "C:\Users\ipharmacare\newreport\GetSQLvalue\itemZoneValue.py", line 73, in getValueInHospital
    sqlValue = self.conndb.executeSQL_zoneid_two(self.cur, self.sql, zoneid, startT, endT)
  File "C:\Users\ipharmacare\newreport\common\connectDB.py", line 54, in executeSQL_zoneid_two
    cur.execute(sql,(zoneid, startT, endT,zoneid, startT, endT))
  File "C:\Users\ipharmacare\python27\lib\site-packages\MySQLdb\cursors.py", line 187, in execute
    query = query % tuple([db.literal(item) for item in args])
ValueError: unsupported format character ''' (0x27) at index 455
Fri, 26 Apr 2019 14:38:45 connectionpool.py[line:205] DEBUG Starting new HTTP connection (1): 192.168.1.209:9999
Fri, 26 Apr 2019 14:38:46 log.py[line:20] ERROR HTTPConnectionPool(host='192.168.1.209', port=9999): Max retries exceeded with url: /syscenter/api/v1/currentUser (Caused by NewConnectionError('<urllib3.connection.HTTPConnection object at 0x0000000004F786D8>: Failed to establish a new connection: [Errno 10061] ',))
Traceback (most recent call last):
  File "C:\Users\ipharmacare\newreport\GetSQLvalue\itemZoneValue.py", line 352, in getSqlValue_zone
    sqlValue = self.getValueInddds(itemname,zoneid,startT,endT)[0]
  File "C:\Users\ipharmacare\newreport\GetSQLvalue\itemZoneValue.py", line 53, in getValueInddds
    qtyvalue=self.configValue.getvalue('qty')
  File "C:\Users\ipharmacare\newreport\configvalue\getconfigvalue.py", line 36, in getvalue
    self.login()
  File "C:\Users\ipharmacare\newreport\configvalue\getconfigvalue.py", line 31, in login
    self.session.post(self.addr, data=json.dumps(self.params), headers=self.headers)
  File "C:\Users\ipharmacare\python27\lib\site-packages\requests\sessions.py", line 581, in post
    return self.request('POST', url, data=data, json=json, **kwargs)
  File "C:\Users\ipharmacare\python27\lib\site-packages\requests\sessions.py", line 533, in request
    resp = self.send(prep, **send_kwargs)
  File "C:\Users\ipharmacare\python27\lib\site-packages\requests\sessions.py", line 646, in send
    r = adapter.send(request, **kwargs)
  File "C:\Users\ipharmacare\python27\lib\site-packages\requests\adapters.py", line 516, in send
    raise ConnectionError(e, request=request)
ConnectionError: HTTPConnectionPool(host='192.168.1.209', port=9999): Max retries exceeded with url: /syscenter/api/v1/currentUser (Caused by NewConnectionError('<urllib3.connection.HTTPConnection object at 0x0000000004F786D8>: Failed to establish a new connection: [Errno 10061] ',))
Fri, 26 Apr 2019 14:38:46 connectionpool.py[line:205] DEBUG Starting new HTTP connection (1): 192.168.1.209:9999
Fri, 26 Apr 2019 14:38:47 log.py[line:20] ERROR HTTPConnectionPool(host='192.168.1.209', port=9999): Max retries exceeded with url: /syscenter/api/v1/currentUser (Caused by NewConnectionError('<urllib3.connection.HTTPConnection object at 0x0000000004F3EF60>: Failed to establish a new connection: [Errno 10061] ',))
Traceback (most recent call last):
  File "C:\Users\ipharmacare\newreport\GetSQLvalue\itemZoneValue.py", line 352, in getSqlValue_zone
    sqlValue = self.getValueInddds(itemname,zoneid,startT,endT)[0]
  File "C:\Users\ipharmacare\newreport\GetSQLvalue\itemZoneValue.py", line 53, in getValueInddds
    qtyvalue=self.configValue.getvalue('qty')
  File "C:\Users\ipharmacare\newreport\configvalue\getconfigvalue.py", line 36, in getvalue
    self.login()
  File "C:\Users\ipharmacare\newreport\configvalue\getconfigvalue.py", line 31, in login
    self.session.post(self.addr, data=json.dumps(self.params), headers=self.headers)
  File "C:\Users\ipharmacare\python27\lib\site-packages\requests\sessions.py", line 581, in post
    return self.request('POST', url, data=data, json=json, **kwargs)
  File "C:\Users\ipharmacare\python27\lib\site-packages\requests\sessions.py", line 533, in request
    resp = self.send(prep, **send_kwargs)
  File "C:\Users\ipharmacare\python27\lib\site-packages\requests\sessions.py", line 646, in send
    r = adapter.send(request, **kwargs)
  File "C:\Users\ipharmacare\python27\lib\site-packages\requests\adapters.py", line 516, in send
    raise ConnectionError(e, request=request)
ConnectionError: HTTPConnectionPool(host='192.168.1.209', port=9999): Max retries exceeded with url: /syscenter/api/v1/currentUser (Caused by NewConnectionError('<urllib3.connection.HTTPConnection object at 0x0000000004F3EF60>: Failed to establish a new connection: [Errno 10061] ',))
Fri, 26 Apr 2019 14:38:47 connectionpool.py[line:205] DEBUG Starting new HTTP connection (1): 192.168.1.209:9999
Fri, 26 Apr 2019 14:38:48 log.py[line:20] ERROR HTTPConnectionPool(host='192.168.1.209', port=9999): Max retries exceeded with url: /syscenter/api/v1/currentUser (Caused by NewConnectionError('<urllib3.connection.HTTPConnection object at 0x0000000004F3E080>: Failed to establish a new connection: [Errno 10061] ',))
Traceback (most recent call last):
  File "C:\Users\ipharmacare\newreport\GetSQLvalue\itemZoneValue.py", line 352, in getSqlValue_zone
    sqlValue = self.getValueInddds(itemname,zoneid,startT,endT)[0]
  File "C:\Users\ipharmacare\newreport\GetSQLvalue\itemZoneValue.py", line 53, in getValueInddds
    qtyvalue=self.configValue.getvalue('qty')
  File "C:\Users\ipharmacare\newreport\configvalue\getconfigvalue.py", line 36, in getvalue
    self.login()
  File "C:\Users\ipharmacare\newreport\configvalue\getconfigvalue.py", line 31, in login
    self.session.post(self.addr, data=json.dumps(self.params), headers=self.headers)
  File "C:\Users\ipharmacare\python27\lib\site-packages\requests\sessions.py", line 581, in post
    return self.request('POST', url, data=data, json=json, **kwargs)
  File "C:\Users\ipharmacare\python27\lib\site-packages\requests\sessions.py", line 533, in request
    resp = self.send(prep, **send_kwargs)
  File "C:\Users\ipharmacare\python27\lib\site-packages\requests\sessions.py", line 646, in send
    r = adapter.send(request, **kwargs)
  File "C:\Users\ipharmacare\python27\lib\site-packages\requests\adapters.py", line 516, in send
    raise ConnectionError(e, request=request)
ConnectionError: HTTPConnectionPool(host='192.168.1.209', port=9999): Max retries exceeded with url: /syscenter/api/v1/currentUser (Caused by NewConnectionError('<urllib3.connection.HTTPConnection object at 0x0000000004F3E080>: Failed to establish a new connection: [Errno 10061] ',))
Fri, 26 Apr 2019 14:38:48 connectionpool.py[line:205] DEBUG Starting new HTTP connection (1): 192.168.1.209:9999
Fri, 26 Apr 2019 14:38:49 log.py[line:20] ERROR HTTPConnectionPool(host='192.168.1.209', port=9999): Max retries exceeded with url: /syscenter/api/v1/currentUser (Caused by NewConnectionError('<urllib3.connection.HTTPConnection object at 0x0000000004F786A0>: Failed to establish a new connection: [Errno 10061] ',))
Traceback (most recent call last):
  File "C:\Users\ipharmacare\newreport\GetSQLvalue\itemZoneValue.py", line 352, in getSqlValue_zone
    sqlValue = self.getValueInddds(itemname,zoneid,startT,endT)[0]
  File "C:\Users\ipharmacare\newreport\GetSQLvalue\itemZoneValue.py", line 53, in getValueInddds
    qtyvalue=self.configValue.getvalue('qty')
  File "C:\Users\ipharmacare\newreport\configvalue\getconfigvalue.py", line 36, in getvalue
    self.login()
  File "C:\Users\ipharmacare\newreport\configvalue\getconfigvalue.py", line 31, in login
    self.session.post(self.addr, data=json.dumps(self.params), headers=self.headers)
  File "C:\Users\ipharmacare\python27\lib\site-packages\requests\sessions.py", line 581, in post
    return self.request('POST', url, data=data, json=json, **kwargs)
  File "C:\Users\ipharmacare\python27\lib\site-packages\requests\sessions.py", line 533, in request
    resp = self.send(prep, **send_kwargs)
  File "C:\Users\ipharmacare\python27\lib\site-packages\requests\sessions.py", line 646, in send
    r = adapter.send(request, **kwargs)
  File "C:\Users\ipharmacare\python27\lib\site-packages\requests\adapters.py", line 516, in send
    raise ConnectionError(e, request=request)
ConnectionError: HTTPConnectionPool(host='192.168.1.209', port=9999): Max retries exceeded with url: /syscenter/api/v1/currentUser (Caused by NewConnectionError('<urllib3.connection.HTTPConnection object at 0x0000000004F786A0>: Failed to establish a new connection: [Errno 10061] ',))
Fri, 26 Apr 2019 14:38:53 log.py[line:17] DEBUG 计算指标不成功，有指标值为空
Fri, 26 Apr 2019 14:38:54 log.py[line:17] DEBUG 计算指标不成功，有指标值为空
Fri, 26 Apr 2019 14:38:55 log.py[line:17] DEBUG 计算指标不成功，有指标值为空
Fri, 26 Apr 2019 14:38:58 log.py[line:17] DEBUG 执行过程中出错
Fri, 26 Apr 2019 14:38:58 log.py[line:20] ERROR unsupported format character ''' (0x27) at index 309
Traceback (most recent call last):
  File "C:\Users\ipharmacare\newreport\GetSQLvalue\itemZoneValue.py", line 320, in getSqlValue_zone
    sqlValue = self.getValueInHospital(itemname, zoneid, startT, endT)
  File "C:\Users\ipharmacare\newreport\GetSQLvalue\itemZoneValue.py", line 73, in getValueInHospital
    sqlValue = self.conndb.executeSQL_zoneid_two(self.cur, self.sql, zoneid, startT, endT)
  File "C:\Users\ipharmacare\newreport\common\connectDB.py", line 54, in executeSQL_zoneid_two
    cur.execute(sql,(zoneid, startT, endT,zoneid, startT, endT))
  File "C:\Users\ipharmacare\python27\lib\site-packages\MySQLdb\cursors.py", line 187, in execute
    query = query % tuple([db.literal(item) for item in args])
ValueError: unsupported format character ''' (0x27) at index 309
Fri, 26 Apr 2019 14:39:02 log.py[line:17] DEBUG 指标计算时出错
Fri, 26 Apr 2019 14:39:02 log.py[line:20] ERROR (1054, "Unknown column 'Herb_Packet_Count' in 'field list'")
Traceback (most recent call last):
  File "C:\Users\ipharmacare\newreport\GetSQLvalue\itemZoneValue.py", line 95, in getValueInCalcminus
    endT)
  File "C:\Users\ipharmacare\newreport\common\connectDB.py", line 49, in executeSQL_zoneid_one
    cur.execute(sql, (zoneid, startT, endT))
  File "C:\Users\ipharmacare\python27\lib\site-packages\MySQLdb\cursors.py", line 205, in execute
    self.errorhandler(self, exc, value)
  File "C:\Users\ipharmacare\python27\lib\site-packages\MySQLdb\connections.py", line 36, in defaulterrorhandler
    raise errorclass, errorvalue
OperationalError: (1054, "Unknown column 'Herb_Packet_Count' in 'field list'")
Fri, 26 Apr 2019 14:39:02 log.py[line:17] DEBUG 计算指标不成功，有指标值为空
Fri, 26 Apr 2019 14:42:50 log.py[line:17] DEBUG 指标计算时出错
Fri, 26 Apr 2019 14:42:50 log.py[line:20] ERROR (1054, "Unknown column 'Herb_Packet_Count' in 'field list'")
Traceback (most recent call last):
  File "C:\Users\ipharmacare\newreport\GetSQLvalue\itemZoneValue.py", line 95, in getValueInCalcminus
    endT)
  File "C:\Users\ipharmacare\newreport\common\connectDB.py", line 49, in executeSQL_zoneid_one
    cur.execute(sql, (zoneid, startT, endT))
  File "C:\Users\ipharmacare\python27\lib\site-packages\MySQLdb\cursors.py", line 205, in execute
    self.errorhandler(self, exc, value)
  File "C:\Users\ipharmacare\python27\lib\site-packages\MySQLdb\connections.py", line 36, in defaulterrorhandler
    raise errorclass, errorvalue
OperationalError: (1054, "Unknown column 'Herb_Packet_Count' in 'field list'")
Fri, 26 Apr 2019 14:42:50 log.py[line:17] DEBUG 计算指标不成功，有指标值为空
Fri, 26 Apr 2019 14:42:50 log.py[line:17] DEBUG 指标计算时出错
Fri, 26 Apr 2019 14:42:50 log.py[line:20] ERROR (1054, "Unknown column 'Herb_Packet_Count' in 'field list'")
Traceback (most recent call last):
  File "C:\Users\ipharmacare\newreport\GetSQLvalue\itemZoneValue.py", line 95, in getValueInCalcminus
    endT)
  File "C:\Users\ipharmacare\newreport\common\connectDB.py", line 49, in executeSQL_zoneid_one
    cur.execute(sql, (zoneid, startT, endT))
  File "C:\Users\ipharmacare\python27\lib\site-packages\MySQLdb\cursors.py", line 205, in execute
    self.errorhandler(self, exc, value)
  File "C:\Users\ipharmacare\python27\lib\site-packages\MySQLdb\connections.py", line 36, in defaulterrorhandler
    raise errorclass, errorvalue
OperationalError: (1054, "Unknown column 'Herb_Packet_Count' in 'field list'")
Fri, 26 Apr 2019 14:42:51 log.py[line:17] DEBUG 计算指标不成功，有指标值为空
Fri, 26 Apr 2019 14:43:15 log.py[line:17] DEBUG 指标计算时出错
Fri, 26 Apr 2019 14:43:15 log.py[line:20] ERROR (1054, "Unknown column 'Herb_Packet_Count' in 'field list'")
Traceback (most recent call last):
  File "C:\Users\ipharmacare\newreport\GetSQLvalue\itemZoneValue.py", line 95, in getValueInCalcminus
    endT)
  File "C:\Users\ipharmacare\newreport\common\connectDB.py", line 49, in executeSQL_zoneid_one
    cur.execute(sql, (zoneid, startT, endT))
  File "C:\Users\ipharmacare\python27\lib\site-packages\MySQLdb\cursors.py", line 205, in execute
    self.errorhandler(self, exc, value)
  File "C:\Users\ipharmacare\python27\lib\site-packages\MySQLdb\connections.py", line 36, in defaulterrorhandler
    raise errorclass, errorvalue
OperationalError: (1054, "Unknown column 'Herb_Packet_Count' in 'field list'")
Fri, 26 Apr 2019 14:43:15 log.py[line:17] DEBUG 计算指标不成功，有指标值为空
Fri, 26 Apr 2019 14:43:19 log.py[line:17] DEBUG 执行过程中出错
Fri, 26 Apr 2019 14:43:19 log.py[line:20] ERROR 'NoneType' object has no attribute '__getitem__'
Traceback (most recent call last):
  File "C:\Users\ipharmacare\newreport\GetSQLvalue\itemZoneValue.py", line 335, in getSqlValue_zone
    sqlValue = self.getValueInCalc100(itemname, zoneid, startT, endT)
  File "C:\Users\ipharmacare\newreport\GetSQLvalue\itemZoneValue.py", line 138, in getValueInCalc100
    self.itemvalue_one = self.calcddds.calcddds_1('zone_ddds', self.itemnameOne, zoneid, startT, endT)[0]
TypeError: 'NoneType' object has no attribute '__getitem__'
Fri, 26 Apr 2019 14:43:19 log.py[line:17] DEBUG 计算指标不成功，有指标值为空
Fri, 26 Apr 2019 14:44:20 log.py[line:17] DEBUG 读取配置项发生了错误,zone,出院患者中抗菌药物治疗使用前病原学检查送检人次
Fri, 26 Apr 2019 14:44:20 log.py[line:20] ERROR No option '\xe5\x87\xba\xe9\x99\xa2\xe6\x82\xa3\xe8\x80\x85\xe4\xb8\xad\xe6\x8a\x97\xe8\x8f\x8c\xe8\x8d\xaf\xe7\x89\xa9\xe6\xb2\xbb\xe7\x96\x97\xe4\xbd\xbf\xe7\x94\xa8\xe5\x89\x8d\xe7\x97\x85\xe5\x8e\x9f\xe5\xad\xa6\xe6\xa3\x80\xe6\x9f\xa5\xe9\x80\x81\xe6\xa3\x80\xe4\xba\xba\xe6\xac\xa1' in section: 'zone'
Traceback (most recent call last):
  File "C:\Users\ipharmacare\newreport\common\configReader.py", line 27, in get
    return self.conf.get(field,key)
  File "C:\Users\ipharmacare\python27\lib\ConfigParser.py", line 618, in get
    raise NoOptionError(option, section)
NoOptionError: No option '\xe5\x87\xba\xe9\x99\xa2\xe6\x82\xa3\xe8\x80\x85\xe4\xb8\xad\xe6\x8a\x97\xe8\x8f\x8c\xe8\x8d\xaf\xe7\x89\xa9\xe6\xb2\xbb\xe7\x96\x97\xe4\xbd\xbf\xe7\x94\xa8\xe5\x89\x8d\xe7\x97\x85\xe5\x8e\x9f\xe5\xad\xa6\xe6\xa3\x80\xe6\x9f\xa5\xe9\x80\x81\xe6\xa3\x80\xe4\xba\xba\xe6\xac\xa1' in section: 'zone'
Fri, 26 Apr 2019 14:44:20 log.py[line:17] DEBUG 执行过程中出错
Fri, 26 Apr 2019 14:44:20 log.py[line:20] ERROR unsupported operand type(s) for %: 'NoneType' and 'tuple'
Traceback (most recent call last):
  File "C:\Users\ipharmacare\newreport\GetSQLvalue\itemZoneValue.py", line 325, in getSqlValue_zone
    sqlValue = self.getValueInCalc(itemname, zoneid, startT, endT, self.optcalcminus)
  File "C:\Users\ipharmacare\newreport\GetSQLvalue\itemZoneValue.py", line 114, in getValueInCalc
    self.itemvalue_one = self.getCalc_Numerator_zone(self.itemnameOne, zoneid, startT, endT, optcalcminus)
  File "C:\Users\ipharmacare\newreport\GetSQLvalue\itemZoneValue.py", line 219, in getCalc_Numerator_zone
    self.itemvalue_one = self.conndb.executeSQL_zoneid_one(self.cur, self.itemOneSql, zoneid, startT, endT)
  File "C:\Users\ipharmacare\newreport\common\connectDB.py", line 49, in executeSQL_zoneid_one
    cur.execute(sql, (zoneid, startT, endT))
  File "C:\Users\ipharmacare\python27\lib\site-packages\MySQLdb\cursors.py", line 187, in execute
    query = query % tuple([db.literal(item) for item in args])
TypeError: unsupported operand type(s) for %: 'NoneType' and 'tuple'
Fri, 26 Apr 2019 14:46:22 log.py[line:17] DEBUG 执行过程中出错
Fri, 26 Apr 2019 14:46:22 log.py[line:20] ERROR 'NoneType' object has no attribute '__getitem__'
Traceback (most recent call last):
  File "C:\Users\ipharmacare\newreport\GetSQLvalue\itemZoneValue.py", line 335, in getSqlValue_zone
    sqlValue = self.getValueInCalc100(itemname, zoneid, startT, endT)
  File "C:\Users\ipharmacare\newreport\GetSQLvalue\itemZoneValue.py", line 138, in getValueInCalc100
    self.itemvalue_one = self.calcddds.calcddds_1('zone_ddds', self.itemnameOne, zoneid, startT, endT)[0]
TypeError: 'NoneType' object has no attribute '__getitem__'
Fri, 26 Apr 2019 14:48:19 connectionpool.py[line:205] DEBUG Starting new HTTP connection (1): 192.168.1.209:9999
Fri, 26 Apr 2019 14:48:20 log.py[line:20] ERROR HTTPConnectionPool(host='192.168.1.209', port=9999): Max retries exceeded with url: /syscenter/api/v1/currentUser (Caused by NewConnectionError('<urllib3.connection.HTTPConnection object at 0x0000000004537BA8>: Failed to establish a new connection: [Errno 10061] ',))
Traceback (most recent call last):
  File "C:\Users\ipharmacare\newreport\GetSQLvalue\itemZoneValue.py", line 352, in getSqlValue_zone
    sqlValue = self.getValueInddds(itemname,zoneid,startT,endT)[0]
  File "C:\Users\ipharmacare\newreport\GetSQLvalue\itemZoneValue.py", line 53, in getValueInddds
    qtyvalue=self.configValue.getvalue('qty')
  File "C:\Users\ipharmacare\newreport\configvalue\getconfigvalue.py", line 36, in getvalue
    self.login()
  File "C:\Users\ipharmacare\newreport\configvalue\getconfigvalue.py", line 31, in login
    self.session.post(self.addr, data=json.dumps(self.params), headers=self.headers)
  File "C:\Users\ipharmacare\python27\lib\site-packages\requests\sessions.py", line 581, in post
    return self.request('POST', url, data=data, json=json, **kwargs)
  File "C:\Users\ipharmacare\python27\lib\site-packages\requests\sessions.py", line 533, in request
    resp = self.send(prep, **send_kwargs)
  File "C:\Users\ipharmacare\python27\lib\site-packages\requests\sessions.py", line 646, in send
    r = adapter.send(request, **kwargs)
  File "C:\Users\ipharmacare\python27\lib\site-packages\requests\adapters.py", line 516, in send
    raise ConnectionError(e, request=request)
ConnectionError: HTTPConnectionPool(host='192.168.1.209', port=9999): Max retries exceeded with url: /syscenter/api/v1/currentUser (Caused by NewConnectionError('<urllib3.connection.HTTPConnection object at 0x0000000004537BA8>: Failed to establish a new connection: [Errno 10061] ',))
Fri, 26 Apr 2019 14:48:25 log.py[line:17] DEBUG 执行过程中出错
Fri, 26 Apr 2019 14:48:25 log.py[line:20] ERROR 'NoneType' object has no attribute '__getitem__'
Traceback (most recent call last):
  File "C:\Users\ipharmacare\newreport\GetSQLvalue\itemZoneValue.py", line 335, in getSqlValue_zone
    sqlValue = self.getValueInCalc100(itemname, zoneid, startT, endT)
  File "C:\Users\ipharmacare\newreport\GetSQLvalue\itemZoneValue.py", line 138, in getValueInCalc100
    self.itemvalue_one = self.calcddds.calcddds_1('zone_ddds', self.itemnameOne, zoneid, startT, endT)[0]
TypeError: 'NoneType' object has no attribute '__getitem__'
Fri, 26 Apr 2019 14:48:25 connectionpool.py[line:205] DEBUG Starting new HTTP connection (1): 192.168.1.209:9999
Fri, 26 Apr 2019 14:48:26 log.py[line:20] ERROR HTTPConnectionPool(host='192.168.1.209', port=9999): Max retries exceeded with url: /syscenter/api/v1/currentUser (Caused by NewConnectionError('<urllib3.connection.HTTPConnection object at 0x0000000004537400>: Failed to establish a new connection: [Errno 10061] ',))
Traceback (most recent call last):
  File "C:\Users\ipharmacare\newreport\GetSQLvalue\itemZoneValue.py", line 352, in getSqlValue_zone
    sqlValue = self.getValueInddds(itemname,zoneid,startT,endT)[0]
  File "C:\Users\ipharmacare\newreport\GetSQLvalue\itemZoneValue.py", line 53, in getValueInddds
    qtyvalue=self.configValue.getvalue('qty')
  File "C:\Users\ipharmacare\newreport\configvalue\getconfigvalue.py", line 36, in getvalue
    self.login()
  File "C:\Users\ipharmacare\newreport\configvalue\getconfigvalue.py", line 31, in login
    self.session.post(self.addr, data=json.dumps(self.params), headers=self.headers)
  File "C:\Users\ipharmacare\python27\lib\site-packages\requests\sessions.py", line 581, in post
    return self.request('POST', url, data=data, json=json, **kwargs)
  File "C:\Users\ipharmacare\python27\lib\site-packages\requests\sessions.py", line 533, in request
    resp = self.send(prep, **send_kwargs)
  File "C:\Users\ipharmacare\python27\lib\site-packages\requests\sessions.py", line 646, in send
    r = adapter.send(request, **kwargs)
  File "C:\Users\ipharmacare\python27\lib\site-packages\requests\adapters.py", line 516, in send
    raise ConnectionError(e, request=request)
ConnectionError: HTTPConnectionPool(host='192.168.1.209', port=9999): Max retries exceeded with url: /syscenter/api/v1/currentUser (Caused by NewConnectionError('<urllib3.connection.HTTPConnection object at 0x0000000004537400>: Failed to establish a new connection: [Errno 10061] ',))
Fri, 26 Apr 2019 14:48:32 log.py[line:17] DEBUG 执行过程中出错
Fri, 26 Apr 2019 14:48:32 log.py[line:20] ERROR 'NoneType' object has no attribute '__getitem__'
Traceback (most recent call last):
  File "C:\Users\ipharmacare\newreport\GetSQLvalue\itemZoneValue.py", line 335, in getSqlValue_zone
    sqlValue = self.getValueInCalc100(itemname, zoneid, startT, endT)
  File "C:\Users\ipharmacare\newreport\GetSQLvalue\itemZoneValue.py", line 138, in getValueInCalc100
    self.itemvalue_one = self.calcddds.calcddds_1('zone_ddds', self.itemnameOne, zoneid, startT, endT)[0]
TypeError: 'NoneType' object has no attribute '__getitem__'
Fri, 26 Apr 2019 14:48:32 connectionpool.py[line:205] DEBUG Starting new HTTP connection (1): 192.168.1.209:9999
Fri, 26 Apr 2019 14:48:33 log.py[line:20] ERROR HTTPConnectionPool(host='192.168.1.209', port=9999): Max retries exceeded with url: /syscenter/api/v1/currentUser (Caused by NewConnectionError('<urllib3.connection.HTTPConnection object at 0x0000000004F3EEF0>: Failed to establish a new connection: [Errno 10061] ',))
Traceback (most recent call last):
  File "C:\Users\ipharmacare\newreport\GetSQLvalue\itemZoneValue.py", line 352, in getSqlValue_zone
    sqlValue = self.getValueInddds(itemname,zoneid,startT,endT)[0]
  File "C:\Users\ipharmacare\newreport\GetSQLvalue\itemZoneValue.py", line 53, in getValueInddds
    qtyvalue=self.configValue.getvalue('qty')
  File "C:\Users\ipharmacare\newreport\configvalue\getconfigvalue.py", line 36, in getvalue
    self.login()
  File "C:\Users\ipharmacare\newreport\configvalue\getconfigvalue.py", line 31, in login
    self.session.post(self.addr, data=json.dumps(self.params), headers=self.headers)
  File "C:\Users\ipharmacare\python27\lib\site-packages\requests\sessions.py", line 581, in post
    return self.request('POST', url, data=data, json=json, **kwargs)
  File "C:\Users\ipharmacare\python27\lib\site-packages\requests\sessions.py", line 533, in request
    resp = self.send(prep, **send_kwargs)
  File "C:\Users\ipharmacare\python27\lib\site-packages\requests\sessions.py", line 646, in send
    r = adapter.send(request, **kwargs)
  File "C:\Users\ipharmacare\python27\lib\site-packages\requests\adapters.py", line 516, in send
    raise ConnectionError(e, request=request)
ConnectionError: HTTPConnectionPool(host='192.168.1.209', port=9999): Max retries exceeded with url: /syscenter/api/v1/currentUser (Caused by NewConnectionError('<urllib3.connection.HTTPConnection object at 0x0000000004F3EEF0>: Failed to establish a new connection: [Errno 10061] ',))
Fri, 26 Apr 2019 14:48:57 log.py[line:17] DEBUG 执行过程中出错
Fri, 26 Apr 2019 14:48:57 log.py[line:20] ERROR 'NoneType' object has no attribute '__getitem__'
Traceback (most recent call last):
  File "C:\Users\ipharmacare\newreport\GetSQLvalue\itemZoneValue.py", line 335, in getSqlValue_zone
    sqlValue = self.getValueInCalc100(itemname, zoneid, startT, endT)
  File "C:\Users\ipharmacare\newreport\GetSQLvalue\itemZoneValue.py", line 138, in getValueInCalc100
    self.itemvalue_one = self.calcddds.calcddds_1('zone_ddds', self.itemnameOne, zoneid, startT, endT)[0]
TypeError: 'NoneType' object has no attribute '__getitem__'
Fri, 26 Apr 2019 14:48:57 connectionpool.py[line:205] DEBUG Starting new HTTP connection (1): 192.168.1.209:9999
Fri, 26 Apr 2019 14:48:58 log.py[line:20] ERROR HTTPConnectionPool(host='192.168.1.209', port=9999): Max retries exceeded with url: /syscenter/api/v1/currentUser (Caused by NewConnectionError('<urllib3.connection.HTTPConnection object at 0x0000000004537B38>: Failed to establish a new connection: [Errno 10061] ',))
Traceback (most recent call last):
  File "C:\Users\ipharmacare\newreport\GetSQLvalue\itemZoneValue.py", line 352, in getSqlValue_zone
    sqlValue = self.getValueInddds(itemname,zoneid,startT,endT)[0]
  File "C:\Users\ipharmacare\newreport\GetSQLvalue\itemZoneValue.py", line 53, in getValueInddds
    qtyvalue=self.configValue.getvalue('qty')
  File "C:\Users\ipharmacare\newreport\configvalue\getconfigvalue.py", line 36, in getvalue
    self.login()
  File "C:\Users\ipharmacare\newreport\configvalue\getconfigvalue.py", line 31, in login
    self.session.post(self.addr, data=json.dumps(self.params), headers=self.headers)
  File "C:\Users\ipharmacare\python27\lib\site-packages\requests\sessions.py", line 581, in post
    return self.request('POST', url, data=data, json=json, **kwargs)
  File "C:\Users\ipharmacare\python27\lib\site-packages\requests\sessions.py", line 533, in request
    resp = self.send(prep, **send_kwargs)
  File "C:\Users\ipharmacare\python27\lib\site-packages\requests\sessions.py", line 646, in send
    r = adapter.send(request, **kwargs)
  File "C:\Users\ipharmacare\python27\lib\site-packages\requests\adapters.py", line 516, in send
    raise ConnectionError(e, request=request)
ConnectionError: HTTPConnectionPool(host='192.168.1.209', port=9999): Max retries exceeded with url: /syscenter/api/v1/currentUser (Caused by NewConnectionError('<urllib3.connection.HTTPConnection object at 0x0000000004537B38>: Failed to establish a new connection: [Errno 10061] ',))
Fri, 26 Apr 2019 14:48:58 connectionpool.py[line:205] DEBUG Starting new HTTP connection (1): 192.168.1.209:9999
Fri, 26 Apr 2019 14:48:59 log.py[line:20] ERROR HTTPConnectionPool(host='192.168.1.209', port=9999): Max retries exceeded with url: /syscenter/api/v1/currentUser (Caused by NewConnectionError('<urllib3.connection.HTTPConnection object at 0x0000000004537908>: Failed to establish a new connection: [Errno 10061] ',))
Traceback (most recent call last):
  File "C:\Users\ipharmacare\newreport\GetSQLvalue\itemZoneValue.py", line 210, in getCalc_Numerator_zone
    self.itemvalue_one = self.getValueInddds(self.itemnameOne, zoneid, startT, endT)[0]
  File "C:\Users\ipharmacare\newreport\GetSQLvalue\itemZoneValue.py", line 53, in getValueInddds
    qtyvalue=self.configValue.getvalue('qty')
  File "C:\Users\ipharmacare\newreport\configvalue\getconfigvalue.py", line 36, in getvalue
    self.login()
  File "C:\Users\ipharmacare\newreport\configvalue\getconfigvalue.py", line 31, in login
    self.session.post(self.addr, data=json.dumps(self.params), headers=self.headers)
  File "C:\Users\ipharmacare\python27\lib\site-packages\requests\sessions.py", line 581, in post
    return self.request('POST', url, data=data, json=json, **kwargs)
  File "C:\Users\ipharmacare\python27\lib\site-packages\requests\sessions.py", line 533, in request
    resp = self.send(prep, **send_kwargs)
  File "C:\Users\ipharmacare\python27\lib\site-packages\requests\sessions.py", line 646, in send
    r = adapter.send(request, **kwargs)
  File "C:\Users\ipharmacare\python27\lib\site-packages\requests\adapters.py", line 516, in send
    raise ConnectionError(e, request=request)
ConnectionError: HTTPConnectionPool(host='192.168.1.209', port=9999): Max retries exceeded with url: /syscenter/api/v1/currentUser (Caused by NewConnectionError('<urllib3.connection.HTTPConnection object at 0x0000000004537908>: Failed to establish a new connection: [Errno 10061] ',))
Fri, 26 Apr 2019 14:48:59 connectionpool.py[line:205] DEBUG Starting new HTTP connection (1): 192.168.1.209:9999
Fri, 26 Apr 2019 14:49:00 log.py[line:20] ERROR HTTPConnectionPool(host='192.168.1.209', port=9999): Max retries exceeded with url: /syscenter/api/v1/currentUser (Caused by NewConnectionError('<urllib3.connection.HTTPConnection object at 0x0000000004537C88>: Failed to establish a new connection: [Errno 10061] ',))
Traceback (most recent call last):
  File "C:\Users\ipharmacare\newreport\GetSQLvalue\itemZoneValue.py", line 243, in getCalc_denominator_zone
    self.itemvalue_two = self.getValueInddds(self.itemnameOne, zoneid, startT, endT)[0]
  File "C:\Users\ipharmacare\newreport\GetSQLvalue\itemZoneValue.py", line 53, in getValueInddds
    qtyvalue=self.configValue.getvalue('qty')
  File "C:\Users\ipharmacare\newreport\configvalue\getconfigvalue.py", line 36, in getvalue
    self.login()
  File "C:\Users\ipharmacare\newreport\configvalue\getconfigvalue.py", line 31, in login
    self.session.post(self.addr, data=json.dumps(self.params), headers=self.headers)
  File "C:\Users\ipharmacare\python27\lib\site-packages\requests\sessions.py", line 581, in post
    return self.request('POST', url, data=data, json=json, **kwargs)
  File "C:\Users\ipharmacare\python27\lib\site-packages\requests\sessions.py", line 533, in request
    resp = self.send(prep, **send_kwargs)
  File "C:\Users\ipharmacare\python27\lib\site-packages\requests\sessions.py", line 646, in send
    r = adapter.send(request, **kwargs)
  File "C:\Users\ipharmacare\python27\lib\site-packages\requests\adapters.py", line 516, in send
    raise ConnectionError(e, request=request)
ConnectionError: HTTPConnectionPool(host='192.168.1.209', port=9999): Max retries exceeded with url: /syscenter/api/v1/currentUser (Caused by NewConnectionError('<urllib3.connection.HTTPConnection object at 0x0000000004537C88>: Failed to establish a new connection: [Errno 10061] ',))
Fri, 26 Apr 2019 14:49:00 log.py[line:17] DEBUG 计算指标不成功，有指标值为空
Fri, 26 Apr 2019 14:49:00 log.py[line:17] DEBUG 该指标在指标库中不存在,出院患者I类切口手术例次
Fri, 26 Apr 2019 14:49:00 connectionpool.py[line:205] DEBUG Starting new HTTP connection (1): 192.168.1.209:9999
Fri, 26 Apr 2019 14:49:01 log.py[line:17] DEBUG 执行过程中出错
Fri, 26 Apr 2019 14:49:01 log.py[line:20] ERROR HTTPConnectionPool(host='192.168.1.209', port=9999): Max retries exceeded with url: /syscenter/api/v1/currentUser (Caused by NewConnectionError('<urllib3.connection.HTTPConnection object at 0x0000000004537DD8>: Failed to establish a new connection: [Errno 10061] ',))
Traceback (most recent call last):
  File "C:\Users\ipharmacare\newreport\GetSQLvalue\itemZoneValue.py", line 339, in getSqlValue_zone
    configValue = self.configValue.getvalue(itemname)
  File "C:\Users\ipharmacare\newreport\configvalue\getconfigvalue.py", line 36, in getvalue
    self.login()
  File "C:\Users\ipharmacare\newreport\configvalue\getconfigvalue.py", line 31, in login
    self.session.post(self.addr, data=json.dumps(self.params), headers=self.headers)
  File "C:\Users\ipharmacare\python27\lib\site-packages\requests\sessions.py", line 581, in post
    return self.request('POST', url, data=data, json=json, **kwargs)
  File "C:\Users\ipharmacare\python27\lib\site-packages\requests\sessions.py", line 533, in request
    resp = self.send(prep, **send_kwargs)
  File "C:\Users\ipharmacare\python27\lib\site-packages\requests\sessions.py", line 646, in send
    r = adapter.send(request, **kwargs)
  File "C:\Users\ipharmacare\python27\lib\site-packages\requests\adapters.py", line 516, in send
    raise ConnectionError(e, request=request)
ConnectionError: HTTPConnectionPool(host='192.168.1.209', port=9999): Max retries exceeded with url: /syscenter/api/v1/currentUser (Caused by NewConnectionError('<urllib3.connection.HTTPConnection object at 0x0000000004537DD8>: Failed to establish a new connection: [Errno 10061] ',))
Fri, 26 Apr 2019 14:49:01 connectionpool.py[line:205] DEBUG Starting new HTTP connection (1): 192.168.1.209:9999
Fri, 26 Apr 2019 14:49:02 log.py[line:17] DEBUG 执行过程中出错
Fri, 26 Apr 2019 14:49:02 log.py[line:20] ERROR HTTPConnectionPool(host='192.168.1.209', port=9999): Max retries exceeded with url: /syscenter/api/v1/currentUser (Caused by NewConnectionError('<urllib3.connection.HTTPConnection object at 0x0000000004537748>: Failed to establish a new connection: [Errno 10061] ',))
Traceback (most recent call last):
  File "C:\Users\ipharmacare\newreport\GetSQLvalue\itemZoneValue.py", line 345, in getSqlValue_zone
    drugcodes = self.configValue.getDrugCode(itemname)
  File "C:\Users\ipharmacare\newreport\configvalue\getconfigvalue.py", line 50, in getDrugCode
    self.configValue=self.getvalue(itemname)
  File "C:\Users\ipharmacare\newreport\configvalue\getconfigvalue.py", line 36, in getvalue
    self.login()
  File "C:\Users\ipharmacare\newreport\configvalue\getconfigvalue.py", line 31, in login
    self.session.post(self.addr, data=json.dumps(self.params), headers=self.headers)
  File "C:\Users\ipharmacare\python27\lib\site-packages\requests\sessions.py", line 581, in post
    return self.request('POST', url, data=data, json=json, **kwargs)
  File "C:\Users\ipharmacare\python27\lib\site-packages\requests\sessions.py", line 533, in request
    resp = self.send(prep, **send_kwargs)
  File "C:\Users\ipharmacare\python27\lib\site-packages\requests\sessions.py", line 646, in send
    r = adapter.send(request, **kwargs)
  File "C:\Users\ipharmacare\python27\lib\site-packages\requests\adapters.py", line 516, in send
    raise ConnectionError(e, request=request)
ConnectionError: HTTPConnectionPool(host='192.168.1.209', port=9999): Max retries exceeded with url: /syscenter/api/v1/currentUser (Caused by NewConnectionError('<urllib3.connection.HTTPConnection object at 0x0000000004537748>: Failed to establish a new connection: [Errno 10061] ',))
Fri, 26 Apr 2019 14:49:02 log.py[line:17] DEBUG 该指标在指标库中不存在,I类切口手术预防使用抗菌药物品种选择合理例次
Fri, 26 Apr 2019 14:49:02 connectionpool.py[line:205] DEBUG Starting new HTTP connection (1): 192.168.1.209:9999
Fri, 26 Apr 2019 14:49:03 log.py[line:17] DEBUG 执行过程中出错
Fri, 26 Apr 2019 14:49:03 log.py[line:20] ERROR HTTPConnectionPool(host='192.168.1.209', port=9999): Max retries exceeded with url: /syscenter/api/v1/currentUser (Caused by NewConnectionError('<urllib3.connection.HTTPConnection object at 0x00000000045379E8>: Failed to establish a new connection: [Errno 10061] ',))
Traceback (most recent call last):
  File "C:\Users\ipharmacare\newreport\GetSQLvalue\itemZoneValue.py", line 325, in getSqlValue_zone
    sqlValue = self.getValueInCalc(itemname, zoneid, startT, endT, self.optcalcminus)
  File "C:\Users\ipharmacare\newreport\GetSQLvalue\itemZoneValue.py", line 114, in getValueInCalc
    self.itemvalue_one = self.getCalc_Numerator_zone(self.itemnameOne, zoneid, startT, endT, optcalcminus)
  File "C:\Users\ipharmacare\newreport\GetSQLvalue\itemZoneValue.py", line 202, in getCalc_Numerator_zone
    drugcodes = self.configValue.getDrugCode(self.itemnameOne)
  File "C:\Users\ipharmacare\newreport\configvalue\getconfigvalue.py", line 50, in getDrugCode
    self.configValue=self.getvalue(itemname)
  File "C:\Users\ipharmacare\newreport\configvalue\getconfigvalue.py", line 36, in getvalue
    self.login()
  File "C:\Users\ipharmacare\newreport\configvalue\getconfigvalue.py", line 31, in login
    self.session.post(self.addr, data=json.dumps(self.params), headers=self.headers)
  File "C:\Users\ipharmacare\python27\lib\site-packages\requests\sessions.py", line 581, in post
    return self.request('POST', url, data=data, json=json, **kwargs)
  File "C:\Users\ipharmacare\python27\lib\site-packages\requests\sessions.py", line 533, in request
    resp = self.send(prep, **send_kwargs)
  File "C:\Users\ipharmacare\python27\lib\site-packages\requests\sessions.py", line 646, in send
    r = adapter.send(request, **kwargs)
  File "C:\Users\ipharmacare\python27\lib\site-packages\requests\adapters.py", line 516, in send
    raise ConnectionError(e, request=request)
ConnectionError: HTTPConnectionPool(host='192.168.1.209', port=9999): Max retries exceeded with url: /syscenter/api/v1/currentUser (Caused by NewConnectionError('<urllib3.connection.HTTPConnection object at 0x00000000045379E8>: Failed to establish a new connection: [Errno 10061] ',))
Fri, 26 Apr 2019 14:49:03 log.py[line:17] DEBUG 读取配置项发生了错误,zone,I类切口手术预防使用抗菌药物品种选择合理例次
Fri, 26 Apr 2019 14:49:03 log.py[line:20] ERROR No option 'i\xe7\xb1\xbb\xe5\x88\x87\xe5\x8f\xa3\xe6\x89\x8b\xe6\x9c\xaf\xe9\xa2\x84\xe9\x98\xb2\xe4\xbd\xbf\xe7\x94\xa8\xe6\x8a\x97\xe8\x8f\x8c\xe8\x8d\xaf\xe7\x89\xa9\xe5\x93\x81\xe7\xa7\x8d\xe9\x80\x89\xe6\x8b\xa9\xe5\x90\x88\xe7\x90\x86\xe4\xbe\x8b\xe6\xac\xa1' in section: 'zone'
Traceback (most recent call last):
  File "C:\Users\ipharmacare\newreport\common\configReader.py", line 27, in get
    return self.conf.get(field,key)
  File "C:\Users\ipharmacare\python27\lib\ConfigParser.py", line 618, in get
    raise NoOptionError(option, section)
NoOptionError: No option 'i\xe7\xb1\xbb\xe5\x88\x87\xe5\x8f\xa3\xe6\x89\x8b\xe6\x9c\xaf\xe9\xa2\x84\xe9\x98\xb2\xe4\xbd\xbf\xe7\x94\xa8\xe6\x8a\x97\xe8\x8f\x8c\xe8\x8d\xaf\xe7\x89\xa9\xe5\x93\x81\xe7\xa7\x8d\xe9\x80\x89\xe6\x8b\xa9\xe5\x90\x88\xe7\x90\x86\xe4\xbe\x8b\xe6\xac\xa1' in section: 'zone'
Fri, 26 Apr 2019 14:49:03 log.py[line:17] DEBUG 执行过程中出错
Fri, 26 Apr 2019 14:49:03 log.py[line:20] ERROR unsupported operand type(s) for %: 'NoneType' and 'tuple'
Traceback (most recent call last):
  File "C:\Users\ipharmacare\newreport\GetSQLvalue\itemZoneValue.py", line 325, in getSqlValue_zone
    sqlValue = self.getValueInCalc(itemname, zoneid, startT, endT, self.optcalcminus)
  File "C:\Users\ipharmacare\newreport\GetSQLvalue\itemZoneValue.py", line 114, in getValueInCalc
    self.itemvalue_one = self.getCalc_Numerator_zone(self.itemnameOne, zoneid, startT, endT, optcalcminus)
  File "C:\Users\ipharmacare\newreport\GetSQLvalue\itemZoneValue.py", line 219, in getCalc_Numerator_zone
    self.itemvalue_one = self.conndb.executeSQL_zoneid_one(self.cur, self.itemOneSql, zoneid, startT, endT)
  File "C:\Users\ipharmacare\newreport\common\connectDB.py", line 49, in executeSQL_zoneid_one
    cur.execute(sql, (zoneid, startT, endT))
  File "C:\Users\ipharmacare\python27\lib\site-packages\MySQLdb\cursors.py", line 187, in execute
    query = query % tuple([db.literal(item) for item in args])
TypeError: unsupported operand type(s) for %: 'NoneType' and 'tuple'
Fri, 26 Apr 2019 14:49:03 log.py[line:17] DEBUG 该指标在指标库中不存在,I类切口手术前0.5-1.0小时内给药例次
Fri, 26 Apr 2019 14:49:03 connectionpool.py[line:205] DEBUG Starting new HTTP connection (1): 192.168.1.209:9999
Fri, 26 Apr 2019 14:49:04 log.py[line:20] ERROR HTTPConnectionPool(host='192.168.1.209', port=9999): Max retries exceeded with url: /syscenter/api/v1/currentUser (Caused by NewConnectionError('<urllib3.connection.HTTPConnection object at 0x0000000004537F60>: Failed to establish a new connection: [Errno 10061] ',))
Traceback (most recent call last):
  File "C:\Users\ipharmacare\newreport\GetSQLvalue\itemZoneValue.py", line 352, in getSqlValue_zone
    sqlValue = self.getValueInddds(itemname,zoneid,startT,endT)[0]
  File "C:\Users\ipharmacare\newreport\GetSQLvalue\itemZoneValue.py", line 53, in getValueInddds
    qtyvalue=self.configValue.getvalue('qty')
  File "C:\Users\ipharmacare\newreport\configvalue\getconfigvalue.py", line 36, in getvalue
    self.login()
  File "C:\Users\ipharmacare\newreport\configvalue\getconfigvalue.py", line 31, in login
    self.session.post(self.addr, data=json.dumps(self.params), headers=self.headers)
  File "C:\Users\ipharmacare\python27\lib\site-packages\requests\sessions.py", line 581, in post
    return self.request('POST', url, data=data, json=json, **kwargs)
  File "C:\Users\ipharmacare\python27\lib\site-packages\requests\sessions.py", line 533, in request
    resp = self.send(prep, **send_kwargs)
  File "C:\Users\ipharmacare\python27\lib\site-packages\requests\sessions.py", line 646, in send
    r = adapter.send(request, **kwargs)
  File "C:\Users\ipharmacare\python27\lib\site-packages\requests\adapters.py", line 516, in send
    raise ConnectionError(e, request=request)
ConnectionError: HTTPConnectionPool(host='192.168.1.209', port=9999): Max retries exceeded with url: /syscenter/api/v1/currentUser (Caused by NewConnectionError('<urllib3.connection.HTTPConnection object at 0x0000000004537F60>: Failed to establish a new connection: [Errno 10061] ',))
Fri, 26 Apr 2019 14:49:04 connectionpool.py[line:205] DEBUG Starting new HTTP connection (1): 192.168.1.209:9999
Fri, 26 Apr 2019 14:49:05 log.py[line:20] ERROR HTTPConnectionPool(host='192.168.1.209', port=9999): Max retries exceeded with url: /syscenter/api/v1/currentUser (Caused by NewConnectionError('<urllib3.connection.HTTPConnection object at 0x0000000004537B70>: Failed to establish a new connection: [Errno 10061] ',))
Traceback (most recent call last):
  File "C:\Users\ipharmacare\newreport\GetSQLvalue\itemZoneValue.py", line 352, in getSqlValue_zone
    sqlValue = self.getValueInddds(itemname,zoneid,startT,endT)[0]
  File "C:\Users\ipharmacare\newreport\GetSQLvalue\itemZoneValue.py", line 53, in getValueInddds
    qtyvalue=self.configValue.getvalue('qty')
  File "C:\Users\ipharmacare\newreport\configvalue\getconfigvalue.py", line 36, in getvalue
    self.login()
  File "C:\Users\ipharmacare\newreport\configvalue\getconfigvalue.py", line 31, in login
    self.session.post(self.addr, data=json.dumps(self.params), headers=self.headers)
  File "C:\Users\ipharmacare\python27\lib\site-packages\requests\sessions.py", line 581, in post
    return self.request('POST', url, data=data, json=json, **kwargs)
  File "C:\Users\ipharmacare\python27\lib\site-packages\requests\sessions.py", line 533, in request
    resp = self.send(prep, **send_kwargs)
  File "C:\Users\ipharmacare\python27\lib\site-packages\requests\sessions.py", line 646, in send
    r = adapter.send(request, **kwargs)
  File "C:\Users\ipharmacare\python27\lib\site-packages\requests\adapters.py", line 516, in send
    raise ConnectionError(e, request=request)
ConnectionError: HTTPConnectionPool(host='192.168.1.209', port=9999): Max retries exceeded with url: /syscenter/api/v1/currentUser (Caused by NewConnectionError('<urllib3.connection.HTTPConnection object at 0x0000000004537B70>: Failed to establish a new connection: [Errno 10061] ',))
Fri, 26 Apr 2019 14:49:14 connectionpool.py[line:205] DEBUG Starting new HTTP connection (1): 192.168.1.209:9999
Fri, 26 Apr 2019 14:49:15 log.py[line:20] ERROR HTTPConnectionPool(host='192.168.1.209', port=9999): Max retries exceeded with url: /syscenter/api/v1/currentUser (Caused by NewConnectionError('<urllib3.connection.HTTPConnection object at 0x0000000004537F98>: Failed to establish a new connection: [Errno 10061] ',))
Traceback (most recent call last):
  File "C:\Users\ipharmacare\newreport\GetSQLvalue\itemZoneValue.py", line 352, in getSqlValue_zone
    sqlValue = self.getValueInddds(itemname,zoneid,startT,endT)[0]
  File "C:\Users\ipharmacare\newreport\GetSQLvalue\itemZoneValue.py", line 53, in getValueInddds
    qtyvalue=self.configValue.getvalue('qty')
  File "C:\Users\ipharmacare\newreport\configvalue\getconfigvalue.py", line 36, in getvalue
    self.login()
  File "C:\Users\ipharmacare\newreport\configvalue\getconfigvalue.py", line 31, in login
    self.session.post(self.addr, data=json.dumps(self.params), headers=self.headers)
  File "C:\Users\ipharmacare\python27\lib\site-packages\requests\sessions.py", line 581, in post
    return self.request('POST', url, data=data, json=json, **kwargs)
  File "C:\Users\ipharmacare\python27\lib\site-packages\requests\sessions.py", line 533, in request
    resp = self.send(prep, **send_kwargs)
  File "C:\Users\ipharmacare\python27\lib\site-packages\requests\sessions.py", line 646, in send
    r = adapter.send(request, **kwargs)
  File "C:\Users\ipharmacare\python27\lib\site-packages\requests\adapters.py", line 516, in send
    raise ConnectionError(e, request=request)
ConnectionError: HTTPConnectionPool(host='192.168.1.209', port=9999): Max retries exceeded with url: /syscenter/api/v1/currentUser (Caused by NewConnectionError('<urllib3.connection.HTTPConnection object at 0x0000000004537F98>: Failed to establish a new connection: [Errno 10061] ',))
Fri, 26 Apr 2019 14:49:19 log.py[line:17] DEBUG 执行过程中出错
Fri, 26 Apr 2019 14:49:19 log.py[line:20] ERROR 'NoneType' object has no attribute '__getitem__'
Traceback (most recent call last):
  File "C:\Users\ipharmacare\newreport\GetSQLvalue\itemZoneValue.py", line 335, in getSqlValue_zone
    sqlValue = self.getValueInCalc100(itemname, zoneid, startT, endT)
  File "C:\Users\ipharmacare\newreport\GetSQLvalue\itemZoneValue.py", line 138, in getValueInCalc100
    self.itemvalue_one = self.calcddds.calcddds_1('zone_ddds', self.itemnameOne, zoneid, startT, endT)[0]
TypeError: 'NoneType' object has no attribute '__getitem__'
Fri, 26 Apr 2019 14:49:20 connectionpool.py[line:205] DEBUG Starting new HTTP connection (1): 192.168.1.209:9999
Fri, 26 Apr 2019 14:49:21 log.py[line:20] ERROR HTTPConnectionPool(host='192.168.1.209', port=9999): Max retries exceeded with url: /syscenter/api/v1/currentUser (Caused by NewConnectionError('<urllib3.connection.HTTPConnection object at 0x0000000004537FD0>: Failed to establish a new connection: [Errno 10061] ',))
Traceback (most recent call last):
  File "C:\Users\ipharmacare\newreport\GetSQLvalue\itemZoneValue.py", line 352, in getSqlValue_zone
    sqlValue = self.getValueInddds(itemname,zoneid,startT,endT)[0]
  File "C:\Users\ipharmacare\newreport\GetSQLvalue\itemZoneValue.py", line 53, in getValueInddds
    qtyvalue=self.configValue.getvalue('qty')
  File "C:\Users\ipharmacare\newreport\configvalue\getconfigvalue.py", line 36, in getvalue
    self.login()
  File "C:\Users\ipharmacare\newreport\configvalue\getconfigvalue.py", line 31, in login
    self.session.post(self.addr, data=json.dumps(self.params), headers=self.headers)
  File "C:\Users\ipharmacare\python27\lib\site-packages\requests\sessions.py", line 581, in post
    return self.request('POST', url, data=data, json=json, **kwargs)
  File "C:\Users\ipharmacare\python27\lib\site-packages\requests\sessions.py", line 533, in request
    resp = self.send(prep, **send_kwargs)
  File "C:\Users\ipharmacare\python27\lib\site-packages\requests\sessions.py", line 646, in send
    r = adapter.send(request, **kwargs)
  File "C:\Users\ipharmacare\python27\lib\site-packages\requests\adapters.py", line 516, in send
    raise ConnectionError(e, request=request)
ConnectionError: HTTPConnectionPool(host='192.168.1.209', port=9999): Max retries exceeded with url: /syscenter/api/v1/currentUser (Caused by NewConnectionError('<urllib3.connection.HTTPConnection object at 0x0000000004537FD0>: Failed to establish a new connection: [Errno 10061] ',))
Fri, 26 Apr 2019 14:49:21 connectionpool.py[line:205] DEBUG Starting new HTTP connection (1): 192.168.1.209:9999
Fri, 26 Apr 2019 14:49:22 log.py[line:20] ERROR HTTPConnectionPool(host='192.168.1.209', port=9999): Max retries exceeded with url: /syscenter/api/v1/currentUser (Caused by NewConnectionError('<urllib3.connection.HTTPConnection object at 0x0000000004537898>: Failed to establish a new connection: [Errno 10061] ',))
Traceback (most recent call last):
  File "C:\Users\ipharmacare\newreport\GetSQLvalue\itemZoneValue.py", line 210, in getCalc_Numerator_zone
    self.itemvalue_one = self.getValueInddds(self.itemnameOne, zoneid, startT, endT)[0]
  File "C:\Users\ipharmacare\newreport\GetSQLvalue\itemZoneValue.py", line 53, in getValueInddds
    qtyvalue=self.configValue.getvalue('qty')
  File "C:\Users\ipharmacare\newreport\configvalue\getconfigvalue.py", line 36, in getvalue
    self.login()
  File "C:\Users\ipharmacare\newreport\configvalue\getconfigvalue.py", line 31, in login
    self.session.post(self.addr, data=json.dumps(self.params), headers=self.headers)
  File "C:\Users\ipharmacare\python27\lib\site-packages\requests\sessions.py", line 581, in post
    return self.request('POST', url, data=data, json=json, **kwargs)
  File "C:\Users\ipharmacare\python27\lib\site-packages\requests\sessions.py", line 533, in request
    resp = self.send(prep, **send_kwargs)
  File "C:\Users\ipharmacare\python27\lib\site-packages\requests\sessions.py", line 646, in send
    r = adapter.send(request, **kwargs)
  File "C:\Users\ipharmacare\python27\lib\site-packages\requests\adapters.py", line 516, in send
    raise ConnectionError(e, request=request)
ConnectionError: HTTPConnectionPool(host='192.168.1.209', port=9999): Max retries exceeded with url: /syscenter/api/v1/currentUser (Caused by NewConnectionError('<urllib3.connection.HTTPConnection object at 0x0000000004537898>: Failed to establish a new connection: [Errno 10061] ',))
Fri, 26 Apr 2019 14:49:22 connectionpool.py[line:205] DEBUG Starting new HTTP connection (1): 192.168.1.209:9999
Fri, 26 Apr 2019 14:49:23 log.py[line:20] ERROR HTTPConnectionPool(host='192.168.1.209', port=9999): Max retries exceeded with url: /syscenter/api/v1/currentUser (Caused by NewConnectionError('<urllib3.connection.HTTPConnection object at 0x0000000004537E80>: Failed to establish a new connection: [Errno 10061] ',))
Traceback (most recent call last):
  File "C:\Users\ipharmacare\newreport\GetSQLvalue\itemZoneValue.py", line 243, in getCalc_denominator_zone
    self.itemvalue_two = self.getValueInddds(self.itemnameOne, zoneid, startT, endT)[0]
  File "C:\Users\ipharmacare\newreport\GetSQLvalue\itemZoneValue.py", line 53, in getValueInddds
    qtyvalue=self.configValue.getvalue('qty')
  File "C:\Users\ipharmacare\newreport\configvalue\getconfigvalue.py", line 36, in getvalue
    self.login()
  File "C:\Users\ipharmacare\newreport\configvalue\getconfigvalue.py", line 31, in login
    self.session.post(self.addr, data=json.dumps(self.params), headers=self.headers)
  File "C:\Users\ipharmacare\python27\lib\site-packages\requests\sessions.py", line 581, in post
    return self.request('POST', url, data=data, json=json, **kwargs)
  File "C:\Users\ipharmacare\python27\lib\site-packages\requests\sessions.py", line 533, in request
    resp = self.send(prep, **send_kwargs)
  File "C:\Users\ipharmacare\python27\lib\site-packages\requests\sessions.py", line 646, in send
    r = adapter.send(request, **kwargs)
  File "C:\Users\ipharmacare\python27\lib\site-packages\requests\adapters.py", line 516, in send
    raise ConnectionError(e, request=request)
ConnectionError: HTTPConnectionPool(host='192.168.1.209', port=9999): Max retries exceeded with url: /syscenter/api/v1/currentUser (Caused by NewConnectionError('<urllib3.connection.HTTPConnection object at 0x0000000004537E80>: Failed to establish a new connection: [Errno 10061] ',))
Fri, 26 Apr 2019 14:49:23 log.py[line:17] DEBUG 计算指标不成功，有指标值为空
Fri, 26 Apr 2019 14:53:37 log.py[line:17] DEBUG 该指标在指标库中不存在,使用抗菌药物出院患者中病原学检查送检人次
Fri, 26 Apr 2019 14:53:37 log.py[line:17] DEBUG 读取配置项发生了错误,zone,使用抗菌药物出院患者中病原学检查送检人次
Fri, 26 Apr 2019 14:53:37 log.py[line:20] ERROR No option '\xe4\xbd\xbf\xe7\x94\xa8\xe6\x8a\x97\xe8\x8f\x8c\xe8\x8d\xaf\xe7\x89\xa9\xe5\x87\xba\xe9\x99\xa2\xe6\x82\xa3\xe8\x80\x85\xe4\xb8\xad\xe7\x97\x85\xe5\x8e\x9f\xe5\xad\xa6\xe6\xa3\x80\xe6\x9f\xa5\xe9\x80\x81\xe6\xa3\x80\xe4\xba\xba\xe6\xac\xa1' in section: 'zone'
Traceback (most recent call last):
  File "C:\Users\ipharmacare\newreport\common\configReader.py", line 27, in get
    return self.conf.get(field,key)
  File "C:\Users\ipharmacare\python27\lib\ConfigParser.py", line 618, in get
    raise NoOptionError(option, section)
NoOptionError: No option '\xe4\xbd\xbf\xe7\x94\xa8\xe6\x8a\x97\xe8\x8f\x8c\xe8\x8d\xaf\xe7\x89\xa9\xe5\x87\xba\xe9\x99\xa2\xe6\x82\xa3\xe8\x80\x85\xe4\xb8\xad\xe7\x97\x85\xe5\x8e\x9f\xe5\xad\xa6\xe6\xa3\x80\xe6\x9f\xa5\xe9\x80\x81\xe6\xa3\x80\xe4\xba\xba\xe6\xac\xa1' in section: 'zone'
Fri, 26 Apr 2019 14:53:37 log.py[line:17] DEBUG 执行过程中出错
Fri, 26 Apr 2019 14:53:37 log.py[line:20] ERROR unsupported operand type(s) for %: 'NoneType' and 'tuple'
Traceback (most recent call last):
  File "C:\Users\ipharmacare\newreport\GetSQLvalue\itemZoneValue.py", line 325, in getSqlValue_zone
    sqlValue = self.getValueInCalc(itemname, zoneid, startT, endT, self.optcalcminus)
  File "C:\Users\ipharmacare\newreport\GetSQLvalue\itemZoneValue.py", line 114, in getValueInCalc
    self.itemvalue_one = self.getCalc_Numerator_zone(self.itemnameOne, zoneid, startT, endT, optcalcminus)
  File "C:\Users\ipharmacare\newreport\GetSQLvalue\itemZoneValue.py", line 219, in getCalc_Numerator_zone
    self.itemvalue_one = self.conndb.executeSQL_zoneid_one(self.cur, self.itemOneSql, zoneid, startT, endT)
  File "C:\Users\ipharmacare\newreport\common\connectDB.py", line 49, in executeSQL_zoneid_one
    cur.execute(sql, (zoneid, startT, endT))
  File "C:\Users\ipharmacare\python27\lib\site-packages\MySQLdb\cursors.py", line 187, in execute
    query = query % tuple([db.literal(item) for item in args])
TypeError: unsupported operand type(s) for %: 'NoneType' and 'tuple'
Fri, 26 Apr 2019 14:53:37 log.py[line:17] DEBUG 执行过程中出错
Fri, 26 Apr 2019 14:53:37 log.py[line:20] ERROR unsupported format character ''' (0x27) at index 615
Traceback (most recent call last):
  File "C:\Users\ipharmacare\newreport\GetSQLvalue\itemZoneValue.py", line 320, in getSqlValue_zone
    sqlValue = self.getValueInHospital(itemname, zoneid, startT, endT)
  File "C:\Users\ipharmacare\newreport\GetSQLvalue\itemZoneValue.py", line 73, in getValueInHospital
    sqlValue = self.conndb.executeSQL_zoneid_two(self.cur, self.sql, zoneid, startT, endT)
  File "C:\Users\ipharmacare\newreport\common\connectDB.py", line 54, in executeSQL_zoneid_two
    cur.execute(sql,(zoneid, startT, endT,zoneid, startT, endT))
  File "C:\Users\ipharmacare\python27\lib\site-packages\MySQLdb\cursors.py", line 187, in execute
    query = query % tuple([db.literal(item) for item in args])
ValueError: unsupported format character ''' (0x27) at index 615
Fri, 26 Apr 2019 14:53:37 log.py[line:17] DEBUG 执行过程中出错
Fri, 26 Apr 2019 14:53:37 log.py[line:20] ERROR unsupported format character ''' (0x27) at index 615
Traceback (most recent call last):
  File "C:\Users\ipharmacare\newreport\GetSQLvalue\itemZoneValue.py", line 320, in getSqlValue_zone
    sqlValue = self.getValueInHospital(itemname, zoneid, startT, endT)
  File "C:\Users\ipharmacare\newreport\GetSQLvalue\itemZoneValue.py", line 73, in getValueInHospital
    sqlValue = self.conndb.executeSQL_zoneid_two(self.cur, self.sql, zoneid, startT, endT)
  File "C:\Users\ipharmacare\newreport\common\connectDB.py", line 54, in executeSQL_zoneid_two
    cur.execute(sql,(zoneid, startT, endT,zoneid, startT, endT))
  File "C:\Users\ipharmacare\python27\lib\site-packages\MySQLdb\cursors.py", line 187, in execute
    query = query % tuple([db.literal(item) for item in args])
ValueError: unsupported format character ''' (0x27) at index 615
Fri, 26 Apr 2019 14:53:38 log.py[line:17] DEBUG 执行过程中出错
Fri, 26 Apr 2019 14:53:38 log.py[line:20] ERROR unsupported format character ''' (0x27) at index 618
Traceback (most recent call last):
  File "C:\Users\ipharmacare\newreport\GetSQLvalue\itemZoneValue.py", line 320, in getSqlValue_zone
    sqlValue = self.getValueInHospital(itemname, zoneid, startT, endT)
  File "C:\Users\ipharmacare\newreport\GetSQLvalue\itemZoneValue.py", line 73, in getValueInHospital
    sqlValue = self.conndb.executeSQL_zoneid_two(self.cur, self.sql, zoneid, startT, endT)
  File "C:\Users\ipharmacare\newreport\common\connectDB.py", line 54, in executeSQL_zoneid_two
    cur.execute(sql,(zoneid, startT, endT,zoneid, startT, endT))
  File "C:\Users\ipharmacare\python27\lib\site-packages\MySQLdb\cursors.py", line 187, in execute
    query = query % tuple([db.literal(item) for item in args])
ValueError: unsupported format character ''' (0x27) at index 618
Fri, 26 Apr 2019 14:53:38 log.py[line:17] DEBUG 执行过程中出错
Fri, 26 Apr 2019 14:53:38 log.py[line:20] ERROR unsupported format character ''' (0x27) at index 618
Traceback (most recent call last):
  File "C:\Users\ipharmacare\newreport\GetSQLvalue\itemZoneValue.py", line 320, in getSqlValue_zone
    sqlValue = self.getValueInHospital(itemname, zoneid, startT, endT)
  File "C:\Users\ipharmacare\newreport\GetSQLvalue\itemZoneValue.py", line 73, in getValueInHospital
    sqlValue = self.conndb.executeSQL_zoneid_two(self.cur, self.sql, zoneid, startT, endT)
  File "C:\Users\ipharmacare\newreport\common\connectDB.py", line 54, in executeSQL_zoneid_two
    cur.execute(sql,(zoneid, startT, endT,zoneid, startT, endT))
  File "C:\Users\ipharmacare\python27\lib\site-packages\MySQLdb\cursors.py", line 187, in execute
    query = query % tuple([db.literal(item) for item in args])
ValueError: unsupported format character ''' (0x27) at index 618
Fri, 26 Apr 2019 14:53:39 log.py[line:17] DEBUG 执行过程中出错
Fri, 26 Apr 2019 14:53:39 log.py[line:20] ERROR (1054, "Unknown column 'Herb_Packet_Count' in 'field list'")
Traceback (most recent call last):
  File "C:\Users\ipharmacare\newreport\GetSQLvalue\itemZoneValue.py", line 315, in getSqlValue_zone
    sqlValue = self.getValueInZone(itemname, zoneid, startT, endT)
  File "C:\Users\ipharmacare\newreport\GetSQLvalue\itemZoneValue.py", line 43, in getValueInZone
    sqlValue = self.conndb.executeSQL_zoneid_one(self.cur, self.sql, zoneid, startT, endT)
  File "C:\Users\ipharmacare\newreport\common\connectDB.py", line 49, in executeSQL_zoneid_one
    cur.execute(sql, (zoneid, startT, endT))
  File "C:\Users\ipharmacare\python27\lib\site-packages\MySQLdb\cursors.py", line 205, in execute
    self.errorhandler(self, exc, value)
  File "C:\Users\ipharmacare\python27\lib\site-packages\MySQLdb\connections.py", line 36, in defaulterrorhandler
    raise errorclass, errorvalue
OperationalError: (1054, "Unknown column 'Herb_Packet_Count' in 'field list'")
Fri, 26 Apr 2019 14:53:40 log.py[line:17] DEBUG 指标计算时出错
Fri, 26 Apr 2019 14:53:40 log.py[line:20] ERROR (1054, "Unknown column 'Herb_Packet_Count' in 'field list'")
Traceback (most recent call last):
  File "C:\Users\ipharmacare\newreport\GetSQLvalue\itemZoneValue.py", line 95, in getValueInCalcminus
    endT)
  File "C:\Users\ipharmacare\newreport\common\connectDB.py", line 49, in executeSQL_zoneid_one
    cur.execute(sql, (zoneid, startT, endT))
  File "C:\Users\ipharmacare\python27\lib\site-packages\MySQLdb\cursors.py", line 205, in execute
    self.errorhandler(self, exc, value)
  File "C:\Users\ipharmacare\python27\lib\site-packages\MySQLdb\connections.py", line 36, in defaulterrorhandler
    raise errorclass, errorvalue
OperationalError: (1054, "Unknown column 'Herb_Packet_Count' in 'field list'")
Fri, 26 Apr 2019 14:53:41 log.py[line:17] DEBUG 执行过程中出错
Fri, 26 Apr 2019 14:53:41 log.py[line:20] ERROR (1054, "Unknown column 'Herb_Packet_Count' in 'field list'")
Traceback (most recent call last):
  File "C:\Users\ipharmacare\newreport\GetSQLvalue\itemZoneValue.py", line 315, in getSqlValue_zone
    sqlValue = self.getValueInZone(itemname, zoneid, startT, endT)
  File "C:\Users\ipharmacare\newreport\GetSQLvalue\itemZoneValue.py", line 43, in getValueInZone
    sqlValue = self.conndb.executeSQL_zoneid_one(self.cur, self.sql, zoneid, startT, endT)
  File "C:\Users\ipharmacare\newreport\common\connectDB.py", line 49, in executeSQL_zoneid_one
    cur.execute(sql, (zoneid, startT, endT))
  File "C:\Users\ipharmacare\python27\lib\site-packages\MySQLdb\cursors.py", line 205, in execute
    self.errorhandler(self, exc, value)
  File "C:\Users\ipharmacare\python27\lib\site-packages\MySQLdb\connections.py", line 36, in defaulterrorhandler
    raise errorclass, errorvalue
OperationalError: (1054, "Unknown column 'Herb_Packet_Count' in 'field list'")
Fri, 26 Apr 2019 14:53:41 log.py[line:17] DEBUG 指标计算时出错
Fri, 26 Apr 2019 14:53:41 log.py[line:20] ERROR (1054, "Unknown column 'Herb_Packet_Count' in 'field list'")
Traceback (most recent call last):
  File "C:\Users\ipharmacare\newreport\GetSQLvalue\itemZoneValue.py", line 95, in getValueInCalcminus
    endT)
  File "C:\Users\ipharmacare\newreport\common\connectDB.py", line 49, in executeSQL_zoneid_one
    cur.execute(sql, (zoneid, startT, endT))
  File "C:\Users\ipharmacare\python27\lib\site-packages\MySQLdb\cursors.py", line 205, in execute
    self.errorhandler(self, exc, value)
  File "C:\Users\ipharmacare\python27\lib\site-packages\MySQLdb\connections.py", line 36, in defaulterrorhandler
    raise errorclass, errorvalue
OperationalError: (1054, "Unknown column 'Herb_Packet_Count' in 'field list'")
