Wed, 03 Jul 2019 15:49:02 log.py[line:17] DEBUG 读取配置项发生了错误,hospital_doc
Wed, 03 Jul 2019 15:49:02 log.py[line:20] ERROR No section: 'hospital_doc'
Traceback (most recent call last):
  File "C:\Users\ipharmacare\newreport\common\configReader.py", line 50, in getitems
    result=self.conf.items(field)
  File "C:\Users\ipharmacare\python27\lib\ConfigParser.py", line 642, in items
    raise NoSectionError(section)
NoSectionError: No section: 'hospital_doc'
Wed, 03 Jul 2019 15:49:02 log.py[line:17] DEBUG 读取配置项发生了错误,default_doc
Wed, 03 Jul 2019 15:49:02 log.py[line:20] ERROR No section: 'default_doc'
Traceback (most recent call last):
  File "C:\Users\ipharmacare\newreport\common\configReader.py", line 50, in getitems
    result=self.conf.items(field)
  File "C:\Users\ipharmacare\python27\lib\ConfigParser.py", line 642, in items
    raise NoSectionError(section)
NoSectionError: No section: 'default_doc'
Wed, 03 Jul 2019 15:49:02 log.py[line:17] DEBUG 读取配置项发生了错误,ConfigurationItem_doc
Wed, 03 Jul 2019 15:49:02 log.py[line:20] ERROR No section: 'ConfigurationItem_doc'
Traceback (most recent call last):
  File "C:\Users\ipharmacare\newreport\common\configReader.py", line 50, in getitems
    result=self.conf.items(field)
  File "C:\Users\ipharmacare\python27\lib\ConfigParser.py", line 642, in items
    raise NoSectionError(section)
NoSectionError: No section: 'ConfigurationItem_doc'
Wed, 03 Jul 2019 15:49:02 log.py[line:17] DEBUG 读取配置项发生了错误,doc_ddds
Wed, 03 Jul 2019 15:49:02 log.py[line:20] ERROR No section: 'doc_ddds'
Traceback (most recent call last):
  File "C:\Users\ipharmacare\newreport\common\configReader.py", line 50, in getitems
    result=self.conf.items(field)
  File "C:\Users\ipharmacare\python27\lib\ConfigParser.py", line 642, in items
    raise NoSectionError(section)
NoSectionError: No section: 'doc_ddds'
Wed, 03 Jul 2019 15:49:02 log.py[line:17] DEBUG 读取配置项发生了错误,hospitalDoc_ddds
Wed, 03 Jul 2019 15:49:02 log.py[line:20] ERROR No section: 'hospitalDoc_ddds'
Traceback (most recent call last):
  File "C:\Users\ipharmacare\newreport\common\configReader.py", line 50, in getitems
    result=self.conf.items(field)
  File "C:\Users\ipharmacare\python27\lib\ConfigParser.py", line 642, in items
    raise NoSectionError(section)
NoSectionError: No section: 'hospitalDoc_ddds'
Wed, 03 Jul 2019 15:49:02 log.py[line:17] DEBUG 读取配置项发生了错误,hospital_dept
Wed, 03 Jul 2019 15:49:02 log.py[line:20] ERROR No section: 'hospital_dept'
Traceback (most recent call last):
  File "C:\Users\ipharmacare\newreport\common\configReader.py", line 50, in getitems
    result=self.conf.items(field)
  File "C:\Users\ipharmacare\python27\lib\ConfigParser.py", line 642, in items
    raise NoSectionError(section)
NoSectionError: No section: 'hospital_dept'
Wed, 03 Jul 2019 15:49:02 log.py[line:17] DEBUG 读取配置项发生了错误,default_dept
Wed, 03 Jul 2019 15:49:02 log.py[line:20] ERROR No section: 'default_dept'
Traceback (most recent call last):
  File "C:\Users\ipharmacare\newreport\common\configReader.py", line 50, in getitems
    result=self.conf.items(field)
  File "C:\Users\ipharmacare\python27\lib\ConfigParser.py", line 642, in items
    raise NoSectionError(section)
NoSectionError: No section: 'default_dept'
Wed, 03 Jul 2019 15:49:02 log.py[line:17] DEBUG 读取配置项发生了错误,ConfigurationItem_dept
Wed, 03 Jul 2019 15:49:02 log.py[line:20] ERROR No section: 'ConfigurationItem_dept'
Traceback (most recent call last):
  File "C:\Users\ipharmacare\newreport\common\configReader.py", line 50, in getitems
    result=self.conf.items(field)
  File "C:\Users\ipharmacare\python27\lib\ConfigParser.py", line 642, in items
    raise NoSectionError(section)
NoSectionError: No section: 'ConfigurationItem_dept'
Wed, 03 Jul 2019 15:49:02 log.py[line:17] DEBUG 读取配置项发生了错误,dept_ddds
Wed, 03 Jul 2019 15:49:02 log.py[line:20] ERROR No section: 'dept_ddds'
Traceback (most recent call last):
  File "C:\Users\ipharmacare\newreport\common\configReader.py", line 50, in getitems
    result=self.conf.items(field)
  File "C:\Users\ipharmacare\python27\lib\ConfigParser.py", line 642, in items
    raise NoSectionError(section)
NoSectionError: No section: 'dept_ddds'
Wed, 03 Jul 2019 15:49:02 log.py[line:17] DEBUG 读取配置项发生了错误,hospitalDept_ddds
Wed, 03 Jul 2019 15:49:02 log.py[line:20] ERROR No section: 'hospitalDept_ddds'
Traceback (most recent call last):
  File "C:\Users\ipharmacare\newreport\common\configReader.py", line 50, in getitems
    result=self.conf.items(field)
  File "C:\Users\ipharmacare\python27\lib\ConfigParser.py", line 642, in items
    raise NoSectionError(section)
NoSectionError: No section: 'hospitalDept_ddds'
Wed, 03 Jul 2019 15:49:02 log.py[line:17] DEBUG 读取配置项发生了错误,default_group
Wed, 03 Jul 2019 15:49:02 log.py[line:20] ERROR No section: 'default_group'
Traceback (most recent call last):
  File "C:\Users\ipharmacare\newreport\common\configReader.py", line 50, in getitems
    result=self.conf.items(field)
  File "C:\Users\ipharmacare\python27\lib\ConfigParser.py", line 642, in items
    raise NoSectionError(section)
NoSectionError: No section: 'default_group'
Wed, 03 Jul 2019 15:49:03 log.py[line:17] DEBUG 计算指标不成功，有指标值为空
Wed, 03 Jul 2019 15:49:03 log.py[line:17] DEBUG 计算指标不成功，有指标值为空
Wed, 03 Jul 2019 15:49:03 log.py[line:17] DEBUG 计算指标不成功，有指标值为空
Wed, 03 Jul 2019 15:49:03 log.py[line:17] DEBUG 计算指标不成功，有指标值为空
Wed, 03 Jul 2019 15:49:19 log.py[line:17] DEBUG 计算指标不成功，有指标值为空
Wed, 03 Jul 2019 15:49:19 log.py[line:17] DEBUG 计算指标不成功，有指标值为空
Wed, 03 Jul 2019 15:49:19 log.py[line:17] DEBUG 执行过程中出错
Wed, 03 Jul 2019 15:49:19 log.py[line:20] ERROR (1064, "You have an error in your SQL syntax; check the manual that corresponds to your MySQL server version for the right syntax to use near '\xe9\x97\xa8\xe8\xaf\x8a\xe9\x9d\x99\xe8\x84\x89\xe8\xbe\x93\xe6\xb6\xb2\xe5\xa4\x84\xe6\x96\xb9\xe6\x95\xb0:SELECT  COUNT(DISTINCT (recipe_id)) FROM  ipharmacar' at line 1")
Traceback (most recent call last):
  File "C:\Users\ipharmacare\newreport\GetSQLvalue\itemZoneValue.py", line 324, in getSqlValue_zone
    sqlValue = self.getValueInCalc(itemname, zoneid, startT, endT, self.optcalcminus)
  File "C:\Users\ipharmacare\newreport\GetSQLvalue\itemZoneValue.py", line 114, in getValueInCalc
    self.itemvalue_one = self.getCalc_Numerator_zone(self.itemnameOne, zoneid, startT, endT, optcalcminus)
  File "C:\Users\ipharmacare\newreport\GetSQLvalue\itemZoneValue.py", line 218, in getCalc_Numerator_zone
    self.itemvalue_one = self.conndb.executeSQL_zoneid_one(self.cur, self.itemOneSql, zoneid, startT, endT)
  File "C:\Users\ipharmacare\newreport\common\connectDB.py", line 49, in executeSQL_zoneid_one
    cur.execute(sql, (zoneid, startT, endT))
  File "C:\Users\ipharmacare\python27\lib\site-packages\MySQLdb\cursors.py", line 205, in execute
    self.errorhandler(self, exc, value)
  File "C:\Users\ipharmacare\python27\lib\site-packages\MySQLdb\connections.py", line 36, in defaulterrorhandler
    raise errorclass, errorvalue
ProgrammingError: (1064, "You have an error in your SQL syntax; check the manual that corresponds to your MySQL server version for the right syntax to use near '\xe9\x97\xa8\xe8\xaf\x8a\xe9\x9d\x99\xe8\x84\x89\xe8\xbe\x93\xe6\xb6\xb2\xe5\xa4\x84\xe6\x96\xb9\xe6\x95\xb0:SELECT  COUNT(DISTINCT (recipe_id)) FROM  ipharmacar' at line 1")
Wed, 03 Jul 2019 15:49:19 log.py[line:17] DEBUG 计算指标不成功，有指标值为空
Wed, 03 Jul 2019 15:49:19 log.py[line:17] DEBUG 计算指标不成功，有指标值为空
Wed, 03 Jul 2019 15:49:19 log.py[line:17] DEBUG 读取配置项发生了错误,zone,门诊处方总数（排除中药饮片）
Wed, 03 Jul 2019 15:49:19 log.py[line:20] ERROR No option '\xe9\x97\xa8\xe8\xaf\x8a\xe5\xa4\x84\xe6\x96\xb9\xe6\x80\xbb\xe6\x95\xb0\xef\xbc\x88\xe6\x8e\x92\xe9\x99\xa4\xe4\xb8\xad\xe8\x8d\xaf\xe9\xa5\xae\xe7\x89\x87\xef\xbc\x89' in section: 'zone'
Traceback (most recent call last):
  File "C:\Users\ipharmacare\newreport\common\configReader.py", line 27, in get
    return self.conf.get(field,key)
  File "C:\Users\ipharmacare\python27\lib\ConfigParser.py", line 618, in get
    raise NoOptionError(option, section)
NoOptionError: No option '\xe9\x97\xa8\xe8\xaf\x8a\xe5\xa4\x84\xe6\x96\xb9\xe6\x80\xbb\xe6\x95\xb0\xef\xbc\x88\xe6\x8e\x92\xe9\x99\xa4\xe4\xb8\xad\xe8\x8d\xaf\xe9\xa5\xae\xe7\x89\x87\xef\xbc\x89' in section: 'zone'
Wed, 03 Jul 2019 15:49:19 log.py[line:17] DEBUG 执行过程中出错
Wed, 03 Jul 2019 15:49:19 log.py[line:20] ERROR unsupported operand type(s) for %: 'NoneType' and 'tuple'
Traceback (most recent call last):
  File "C:\Users\ipharmacare\newreport\GetSQLvalue\itemZoneValue.py", line 324, in getSqlValue_zone
    sqlValue = self.getValueInCalc(itemname, zoneid, startT, endT, self.optcalcminus)
  File "C:\Users\ipharmacare\newreport\GetSQLvalue\itemZoneValue.py", line 115, in getValueInCalc
    self.itemvalue_two = self.getCalc_denominator_zone(self.itemnameTwo, zoneid, startT, endT, optcalcminus)
  File "C:\Users\ipharmacare\newreport\GetSQLvalue\itemZoneValue.py", line 249, in getCalc_denominator_zone
    self.itemvalue_two = self.conndb.executeSQL_zoneid_one(self.cur, self.itemTwoSql, zoneid, startT, endT)
  File "C:\Users\ipharmacare\newreport\common\connectDB.py", line 49, in executeSQL_zoneid_one
    cur.execute(sql, (zoneid, startT, endT))
  File "C:\Users\ipharmacare\python27\lib\site-packages\MySQLdb\cursors.py", line 187, in execute
    query = query % tuple([db.literal(item) for item in args])
TypeError: unsupported operand type(s) for %: 'NoneType' and 'tuple'
Wed, 03 Jul 2019 15:49:19 log.py[line:17] DEBUG 读取配置项发生了错误,zone,门诊处方总数（排除中药饮片）
Wed, 03 Jul 2019 15:49:19 log.py[line:20] ERROR No option '\xe9\x97\xa8\xe8\xaf\x8a\xe5\xa4\x84\xe6\x96\xb9\xe6\x80\xbb\xe6\x95\xb0\xef\xbc\x88\xe6\x8e\x92\xe9\x99\xa4\xe4\xb8\xad\xe8\x8d\xaf\xe9\xa5\xae\xe7\x89\x87\xef\xbc\x89' in section: 'zone'
Traceback (most recent call last):
  File "C:\Users\ipharmacare\newreport\common\configReader.py", line 27, in get
    return self.conf.get(field,key)
  File "C:\Users\ipharmacare\python27\lib\ConfigParser.py", line 618, in get
    raise NoOptionError(option, section)
NoOptionError: No option '\xe9\x97\xa8\xe8\xaf\x8a\xe5\xa4\x84\xe6\x96\xb9\xe6\x80\xbb\xe6\x95\xb0\xef\xbc\x88\xe6\x8e\x92\xe9\x99\xa4\xe4\xb8\xad\xe8\x8d\xaf\xe9\xa5\xae\xe7\x89\x87\xef\xbc\x89' in section: 'zone'
Wed, 03 Jul 2019 15:49:19 log.py[line:17] DEBUG 执行过程中出错
Wed, 03 Jul 2019 15:49:19 log.py[line:20] ERROR unsupported operand type(s) for %: 'NoneType' and 'tuple'
Traceback (most recent call last):
  File "C:\Users\ipharmacare\newreport\GetSQLvalue\itemZoneValue.py", line 324, in getSqlValue_zone
    sqlValue = self.getValueInCalc(itemname, zoneid, startT, endT, self.optcalcminus)
  File "C:\Users\ipharmacare\newreport\GetSQLvalue\itemZoneValue.py", line 115, in getValueInCalc
    self.itemvalue_two = self.getCalc_denominator_zone(self.itemnameTwo, zoneid, startT, endT, optcalcminus)
  File "C:\Users\ipharmacare\newreport\GetSQLvalue\itemZoneValue.py", line 249, in getCalc_denominator_zone
    self.itemvalue_two = self.conndb.executeSQL_zoneid_one(self.cur, self.itemTwoSql, zoneid, startT, endT)
  File "C:\Users\ipharmacare\newreport\common\connectDB.py", line 49, in executeSQL_zoneid_one
    cur.execute(sql, (zoneid, startT, endT))
  File "C:\Users\ipharmacare\python27\lib\site-packages\MySQLdb\cursors.py", line 187, in execute
    query = query % tuple([db.literal(item) for item in args])
TypeError: unsupported operand type(s) for %: 'NoneType' and 'tuple'
Wed, 03 Jul 2019 15:49:19 log.py[line:17] DEBUG 读取配置项发生了错误,zone,门诊处方总数（排除中药饮片）
Wed, 03 Jul 2019 15:49:19 log.py[line:20] ERROR No option '\xe9\x97\xa8\xe8\xaf\x8a\xe5\xa4\x84\xe6\x96\xb9\xe6\x80\xbb\xe6\x95\xb0\xef\xbc\x88\xe6\x8e\x92\xe9\x99\xa4\xe4\xb8\xad\xe8\x8d\xaf\xe9\xa5\xae\xe7\x89\x87\xef\xbc\x89' in section: 'zone'
Traceback (most recent call last):
  File "C:\Users\ipharmacare\newreport\common\configReader.py", line 27, in get
    return self.conf.get(field,key)
  File "C:\Users\ipharmacare\python27\lib\ConfigParser.py", line 618, in get
    raise NoOptionError(option, section)
NoOptionError: No option '\xe9\x97\xa8\xe8\xaf\x8a\xe5\xa4\x84\xe6\x96\xb9\xe6\x80\xbb\xe6\x95\xb0\xef\xbc\x88\xe6\x8e\x92\xe9\x99\xa4\xe4\xb8\xad\xe8\x8d\xaf\xe9\xa5\xae\xe7\x89\x87\xef\xbc\x89' in section: 'zone'
Wed, 03 Jul 2019 15:49:19 log.py[line:17] DEBUG 执行过程中出错
Wed, 03 Jul 2019 15:49:19 log.py[line:20] ERROR unsupported operand type(s) for %: 'NoneType' and 'tuple'
Traceback (most recent call last):
  File "C:\Users\ipharmacare\newreport\GetSQLvalue\itemZoneValue.py", line 324, in getSqlValue_zone
    sqlValue = self.getValueInCalc(itemname, zoneid, startT, endT, self.optcalcminus)
  File "C:\Users\ipharmacare\newreport\GetSQLvalue\itemZoneValue.py", line 115, in getValueInCalc
    self.itemvalue_two = self.getCalc_denominator_zone(self.itemnameTwo, zoneid, startT, endT, optcalcminus)
  File "C:\Users\ipharmacare\newreport\GetSQLvalue\itemZoneValue.py", line 249, in getCalc_denominator_zone
    self.itemvalue_two = self.conndb.executeSQL_zoneid_one(self.cur, self.itemTwoSql, zoneid, startT, endT)
  File "C:\Users\ipharmacare\newreport\common\connectDB.py", line 49, in executeSQL_zoneid_one
    cur.execute(sql, (zoneid, startT, endT))
  File "C:\Users\ipharmacare\python27\lib\site-packages\MySQLdb\cursors.py", line 187, in execute
    query = query % tuple([db.literal(item) for item in args])
TypeError: unsupported operand type(s) for %: 'NoneType' and 'tuple'
Wed, 03 Jul 2019 15:49:19 log.py[line:17] DEBUG 计算指标不成功，有指标值为空
Wed, 03 Jul 2019 15:49:19 log.py[line:17] DEBUG 计算指标不成功，有指标值为空
Wed, 03 Jul 2019 15:56:28 log.py[line:17] DEBUG 读取配置项发生了错误,hospital_doc
Wed, 03 Jul 2019 15:56:28 log.py[line:20] ERROR No section: 'hospital_doc'
Traceback (most recent call last):
  File "C:/Users/ipharmacare/newreport\common\configReader.py", line 50, in getitems
    result=self.conf.items(field)
  File "C:\Users\ipharmacare\python27\lib\ConfigParser.py", line 642, in items
    raise NoSectionError(section)
NoSectionError: No section: 'hospital_doc'
Wed, 03 Jul 2019 15:56:28 log.py[line:17] DEBUG 读取配置项发生了错误,default_doc
Wed, 03 Jul 2019 15:56:28 log.py[line:20] ERROR No section: 'default_doc'
Traceback (most recent call last):
  File "C:/Users/ipharmacare/newreport\common\configReader.py", line 50, in getitems
    result=self.conf.items(field)
  File "C:\Users\ipharmacare\python27\lib\ConfigParser.py", line 642, in items
    raise NoSectionError(section)
NoSectionError: No section: 'default_doc'
Wed, 03 Jul 2019 15:56:28 log.py[line:17] DEBUG 读取配置项发生了错误,ConfigurationItem_doc
Wed, 03 Jul 2019 15:56:28 log.py[line:20] ERROR No section: 'ConfigurationItem_doc'
Traceback (most recent call last):
  File "C:/Users/ipharmacare/newreport\common\configReader.py", line 50, in getitems
    result=self.conf.items(field)
  File "C:\Users\ipharmacare\python27\lib\ConfigParser.py", line 642, in items
    raise NoSectionError(section)
NoSectionError: No section: 'ConfigurationItem_doc'
Wed, 03 Jul 2019 15:56:28 log.py[line:17] DEBUG 读取配置项发生了错误,doc_ddds
Wed, 03 Jul 2019 15:56:28 log.py[line:20] ERROR No section: 'doc_ddds'
Traceback (most recent call last):
  File "C:/Users/ipharmacare/newreport\common\configReader.py", line 50, in getitems
    result=self.conf.items(field)
  File "C:\Users\ipharmacare\python27\lib\ConfigParser.py", line 642, in items
    raise NoSectionError(section)
NoSectionError: No section: 'doc_ddds'
Wed, 03 Jul 2019 15:56:28 log.py[line:17] DEBUG 读取配置项发生了错误,hospitalDoc_ddds
Wed, 03 Jul 2019 15:56:28 log.py[line:20] ERROR No section: 'hospitalDoc_ddds'
Traceback (most recent call last):
  File "C:/Users/ipharmacare/newreport\common\configReader.py", line 50, in getitems
    result=self.conf.items(field)
  File "C:\Users\ipharmacare\python27\lib\ConfigParser.py", line 642, in items
    raise NoSectionError(section)
NoSectionError: No section: 'hospitalDoc_ddds'
Wed, 03 Jul 2019 15:56:29 log.py[line:17] DEBUG 读取配置项发生了错误,hospital_dept
Wed, 03 Jul 2019 15:56:29 log.py[line:20] ERROR No section: 'hospital_dept'
Traceback (most recent call last):
  File "C:/Users/ipharmacare/newreport\common\configReader.py", line 50, in getitems
    result=self.conf.items(field)
  File "C:\Users\ipharmacare\python27\lib\ConfigParser.py", line 642, in items
    raise NoSectionError(section)
NoSectionError: No section: 'hospital_dept'
Wed, 03 Jul 2019 15:56:29 log.py[line:17] DEBUG 读取配置项发生了错误,default_dept
Wed, 03 Jul 2019 15:56:29 log.py[line:20] ERROR No section: 'default_dept'
Traceback (most recent call last):
  File "C:/Users/ipharmacare/newreport\common\configReader.py", line 50, in getitems
    result=self.conf.items(field)
  File "C:\Users\ipharmacare\python27\lib\ConfigParser.py", line 642, in items
    raise NoSectionError(section)
NoSectionError: No section: 'default_dept'
Wed, 03 Jul 2019 15:56:29 log.py[line:17] DEBUG 读取配置项发生了错误,ConfigurationItem_dept
Wed, 03 Jul 2019 15:56:29 log.py[line:20] ERROR No section: 'ConfigurationItem_dept'
Traceback (most recent call last):
  File "C:/Users/ipharmacare/newreport\common\configReader.py", line 50, in getitems
    result=self.conf.items(field)
  File "C:\Users\ipharmacare\python27\lib\ConfigParser.py", line 642, in items
    raise NoSectionError(section)
NoSectionError: No section: 'ConfigurationItem_dept'
Wed, 03 Jul 2019 15:56:29 log.py[line:17] DEBUG 读取配置项发生了错误,dept_ddds
Wed, 03 Jul 2019 15:56:29 log.py[line:20] ERROR No section: 'dept_ddds'
Traceback (most recent call last):
  File "C:/Users/ipharmacare/newreport\common\configReader.py", line 50, in getitems
    result=self.conf.items(field)
  File "C:\Users\ipharmacare\python27\lib\ConfigParser.py", line 642, in items
    raise NoSectionError(section)
NoSectionError: No section: 'dept_ddds'
Wed, 03 Jul 2019 15:56:29 log.py[line:17] DEBUG 读取配置项发生了错误,hospitalDept_ddds
Wed, 03 Jul 2019 15:56:29 log.py[line:20] ERROR No section: 'hospitalDept_ddds'
Traceback (most recent call last):
  File "C:/Users/ipharmacare/newreport\common\configReader.py", line 50, in getitems
    result=self.conf.items(field)
  File "C:\Users\ipharmacare\python27\lib\ConfigParser.py", line 642, in items
    raise NoSectionError(section)
NoSectionError: No section: 'hospitalDept_ddds'
Wed, 03 Jul 2019 15:56:29 log.py[line:17] DEBUG 读取配置项发生了错误,default_group
Wed, 03 Jul 2019 15:56:29 log.py[line:20] ERROR No section: 'default_group'
Traceback (most recent call last):
  File "C:/Users/ipharmacare/newreport\common\configReader.py", line 50, in getitems
    result=self.conf.items(field)
  File "C:\Users\ipharmacare\python27\lib\ConfigParser.py", line 642, in items
    raise NoSectionError(section)
NoSectionError: No section: 'default_group'
Wed, 03 Jul 2019 16:03:34 log.py[line:17] DEBUG 计算指标不成功，有指标值为空
Wed, 03 Jul 2019 16:03:44 log.py[line:17] DEBUG 计算指标不成功，有指标值为空
Wed, 03 Jul 2019 16:03:49 log.py[line:17] DEBUG 计算指标不成功，有指标值为空
Wed, 03 Jul 2019 16:25:07 log.py[line:17] DEBUG 读取配置项发生了错误,hospital_doc
Wed, 03 Jul 2019 16:25:07 log.py[line:20] ERROR No section: 'hospital_doc'
Traceback (most recent call last):
  File "C:\Users\ipharmacare\newreport\common\configReader.py", line 50, in getitems
    result=self.conf.items(field)
  File "C:\Users\ipharmacare\python27\lib\ConfigParser.py", line 642, in items
    raise NoSectionError(section)
NoSectionError: No section: 'hospital_doc'
Wed, 03 Jul 2019 16:25:07 log.py[line:17] DEBUG 读取配置项发生了错误,default_doc
Wed, 03 Jul 2019 16:25:07 log.py[line:20] ERROR No section: 'default_doc'
Traceback (most recent call last):
  File "C:\Users\ipharmacare\newreport\common\configReader.py", line 50, in getitems
    result=self.conf.items(field)
  File "C:\Users\ipharmacare\python27\lib\ConfigParser.py", line 642, in items
    raise NoSectionError(section)
NoSectionError: No section: 'default_doc'
Wed, 03 Jul 2019 16:25:07 log.py[line:17] DEBUG 读取配置项发生了错误,ConfigurationItem_doc
Wed, 03 Jul 2019 16:25:07 log.py[line:20] ERROR No section: 'ConfigurationItem_doc'
Traceback (most recent call last):
  File "C:\Users\ipharmacare\newreport\common\configReader.py", line 50, in getitems
    result=self.conf.items(field)
  File "C:\Users\ipharmacare\python27\lib\ConfigParser.py", line 642, in items
    raise NoSectionError(section)
NoSectionError: No section: 'ConfigurationItem_doc'
Wed, 03 Jul 2019 16:25:07 log.py[line:17] DEBUG 读取配置项发生了错误,doc_ddds
Wed, 03 Jul 2019 16:25:07 log.py[line:20] ERROR No section: 'doc_ddds'
Traceback (most recent call last):
  File "C:\Users\ipharmacare\newreport\common\configReader.py", line 50, in getitems
    result=self.conf.items(field)
  File "C:\Users\ipharmacare\python27\lib\ConfigParser.py", line 642, in items
    raise NoSectionError(section)
NoSectionError: No section: 'doc_ddds'
Wed, 03 Jul 2019 16:25:07 log.py[line:17] DEBUG 读取配置项发生了错误,hospitalDoc_ddds
Wed, 03 Jul 2019 16:25:07 log.py[line:20] ERROR No section: 'hospitalDoc_ddds'
Traceback (most recent call last):
  File "C:\Users\ipharmacare\newreport\common\configReader.py", line 50, in getitems
    result=self.conf.items(field)
  File "C:\Users\ipharmacare\python27\lib\ConfigParser.py", line 642, in items
    raise NoSectionError(section)
NoSectionError: No section: 'hospitalDoc_ddds'
Wed, 03 Jul 2019 16:25:07 log.py[line:17] DEBUG 读取配置项发生了错误,hospital_dept
Wed, 03 Jul 2019 16:25:07 log.py[line:20] ERROR No section: 'hospital_dept'
Traceback (most recent call last):
  File "C:\Users\ipharmacare\newreport\common\configReader.py", line 50, in getitems
    result=self.conf.items(field)
  File "C:\Users\ipharmacare\python27\lib\ConfigParser.py", line 642, in items
    raise NoSectionError(section)
NoSectionError: No section: 'hospital_dept'
Wed, 03 Jul 2019 16:25:07 log.py[line:17] DEBUG 读取配置项发生了错误,default_dept
Wed, 03 Jul 2019 16:25:07 log.py[line:20] ERROR No section: 'default_dept'
Traceback (most recent call last):
  File "C:\Users\ipharmacare\newreport\common\configReader.py", line 50, in getitems
    result=self.conf.items(field)
  File "C:\Users\ipharmacare\python27\lib\ConfigParser.py", line 642, in items
    raise NoSectionError(section)
NoSectionError: No section: 'default_dept'
Wed, 03 Jul 2019 16:25:07 log.py[line:17] DEBUG 读取配置项发生了错误,ConfigurationItem_dept
Wed, 03 Jul 2019 16:25:07 log.py[line:20] ERROR No section: 'ConfigurationItem_dept'
Traceback (most recent call last):
  File "C:\Users\ipharmacare\newreport\common\configReader.py", line 50, in getitems
    result=self.conf.items(field)
  File "C:\Users\ipharmacare\python27\lib\ConfigParser.py", line 642, in items
    raise NoSectionError(section)
NoSectionError: No section: 'ConfigurationItem_dept'
Wed, 03 Jul 2019 16:25:07 log.py[line:17] DEBUG 读取配置项发生了错误,dept_ddds
Wed, 03 Jul 2019 16:25:07 log.py[line:20] ERROR No section: 'dept_ddds'
Traceback (most recent call last):
  File "C:\Users\ipharmacare\newreport\common\configReader.py", line 50, in getitems
    result=self.conf.items(field)
  File "C:\Users\ipharmacare\python27\lib\ConfigParser.py", line 642, in items
    raise NoSectionError(section)
NoSectionError: No section: 'dept_ddds'
Wed, 03 Jul 2019 16:25:07 log.py[line:17] DEBUG 读取配置项发生了错误,hospitalDept_ddds
Wed, 03 Jul 2019 16:25:07 log.py[line:20] ERROR No section: 'hospitalDept_ddds'
Traceback (most recent call last):
  File "C:\Users\ipharmacare\newreport\common\configReader.py", line 50, in getitems
    result=self.conf.items(field)
  File "C:\Users\ipharmacare\python27\lib\ConfigParser.py", line 642, in items
    raise NoSectionError(section)
NoSectionError: No section: 'hospitalDept_ddds'
Wed, 03 Jul 2019 16:25:07 log.py[line:17] DEBUG 读取配置项发生了错误,default_group
Wed, 03 Jul 2019 16:25:07 log.py[line:20] ERROR No section: 'default_group'
Traceback (most recent call last):
  File "C:\Users\ipharmacare\newreport\common\configReader.py", line 50, in getitems
    result=self.conf.items(field)
  File "C:\Users\ipharmacare\python27\lib\ConfigParser.py", line 642, in items
    raise NoSectionError(section)
NoSectionError: No section: 'default_group'
Wed, 03 Jul 2019 16:25:39 log.py[line:17] DEBUG 读取配置项发生了错误,hospital_doc
Wed, 03 Jul 2019 16:25:39 log.py[line:20] ERROR No section: 'hospital_doc'
Traceback (most recent call last):
  File "C:\Users\ipharmacare\newreport\common\configReader.py", line 50, in getitems
    result=self.conf.items(field)
  File "C:\Users\ipharmacare\python27\lib\ConfigParser.py", line 642, in items
    raise NoSectionError(section)
NoSectionError: No section: 'hospital_doc'
Wed, 03 Jul 2019 16:25:39 log.py[line:17] DEBUG 读取配置项发生了错误,default_doc
Wed, 03 Jul 2019 16:25:39 log.py[line:20] ERROR No section: 'default_doc'
Traceback (most recent call last):
  File "C:\Users\ipharmacare\newreport\common\configReader.py", line 50, in getitems
    result=self.conf.items(field)
  File "C:\Users\ipharmacare\python27\lib\ConfigParser.py", line 642, in items
    raise NoSectionError(section)
NoSectionError: No section: 'default_doc'
Wed, 03 Jul 2019 16:25:39 log.py[line:17] DEBUG 读取配置项发生了错误,ConfigurationItem_doc
Wed, 03 Jul 2019 16:25:39 log.py[line:20] ERROR No section: 'ConfigurationItem_doc'
Traceback (most recent call last):
  File "C:\Users\ipharmacare\newreport\common\configReader.py", line 50, in getitems
    result=self.conf.items(field)
  File "C:\Users\ipharmacare\python27\lib\ConfigParser.py", line 642, in items
    raise NoSectionError(section)
NoSectionError: No section: 'ConfigurationItem_doc'
Wed, 03 Jul 2019 16:25:39 log.py[line:17] DEBUG 读取配置项发生了错误,doc_ddds
Wed, 03 Jul 2019 16:25:39 log.py[line:20] ERROR No section: 'doc_ddds'
Traceback (most recent call last):
  File "C:\Users\ipharmacare\newreport\common\configReader.py", line 50, in getitems
    result=self.conf.items(field)
  File "C:\Users\ipharmacare\python27\lib\ConfigParser.py", line 642, in items
    raise NoSectionError(section)
NoSectionError: No section: 'doc_ddds'
Wed, 03 Jul 2019 16:25:39 log.py[line:17] DEBUG 读取配置项发生了错误,hospitalDoc_ddds
Wed, 03 Jul 2019 16:25:39 log.py[line:20] ERROR No section: 'hospitalDoc_ddds'
Traceback (most recent call last):
  File "C:\Users\ipharmacare\newreport\common\configReader.py", line 50, in getitems
    result=self.conf.items(field)
  File "C:\Users\ipharmacare\python27\lib\ConfigParser.py", line 642, in items
    raise NoSectionError(section)
NoSectionError: No section: 'hospitalDoc_ddds'
Wed, 03 Jul 2019 16:25:39 log.py[line:17] DEBUG 读取配置项发生了错误,hospital_dept
Wed, 03 Jul 2019 16:25:39 log.py[line:20] ERROR No section: 'hospital_dept'
Traceback (most recent call last):
  File "C:\Users\ipharmacare\newreport\common\configReader.py", line 50, in getitems
    result=self.conf.items(field)
  File "C:\Users\ipharmacare\python27\lib\ConfigParser.py", line 642, in items
    raise NoSectionError(section)
NoSectionError: No section: 'hospital_dept'
Wed, 03 Jul 2019 16:25:39 log.py[line:17] DEBUG 读取配置项发生了错误,default_dept
Wed, 03 Jul 2019 16:25:39 log.py[line:20] ERROR No section: 'default_dept'
Traceback (most recent call last):
  File "C:\Users\ipharmacare\newreport\common\configReader.py", line 50, in getitems
    result=self.conf.items(field)
  File "C:\Users\ipharmacare\python27\lib\ConfigParser.py", line 642, in items
    raise NoSectionError(section)
NoSectionError: No section: 'default_dept'
Wed, 03 Jul 2019 16:25:39 log.py[line:17] DEBUG 读取配置项发生了错误,ConfigurationItem_dept
Wed, 03 Jul 2019 16:25:39 log.py[line:20] ERROR No section: 'ConfigurationItem_dept'
Traceback (most recent call last):
  File "C:\Users\ipharmacare\newreport\common\configReader.py", line 50, in getitems
    result=self.conf.items(field)
  File "C:\Users\ipharmacare\python27\lib\ConfigParser.py", line 642, in items
    raise NoSectionError(section)
NoSectionError: No section: 'ConfigurationItem_dept'
Wed, 03 Jul 2019 16:25:39 log.py[line:17] DEBUG 读取配置项发生了错误,dept_ddds
Wed, 03 Jul 2019 16:25:39 log.py[line:20] ERROR No section: 'dept_ddds'
Traceback (most recent call last):
  File "C:\Users\ipharmacare\newreport\common\configReader.py", line 50, in getitems
    result=self.conf.items(field)
  File "C:\Users\ipharmacare\python27\lib\ConfigParser.py", line 642, in items
    raise NoSectionError(section)
NoSectionError: No section: 'dept_ddds'
Wed, 03 Jul 2019 16:25:39 log.py[line:17] DEBUG 读取配置项发生了错误,hospitalDept_ddds
Wed, 03 Jul 2019 16:25:39 log.py[line:20] ERROR No section: 'hospitalDept_ddds'
Traceback (most recent call last):
  File "C:\Users\ipharmacare\newreport\common\configReader.py", line 50, in getitems
    result=self.conf.items(field)
  File "C:\Users\ipharmacare\python27\lib\ConfigParser.py", line 642, in items
    raise NoSectionError(section)
NoSectionError: No section: 'hospitalDept_ddds'
Wed, 03 Jul 2019 16:25:39 log.py[line:17] DEBUG 读取配置项发生了错误,default_group
Wed, 03 Jul 2019 16:25:39 log.py[line:20] ERROR No section: 'default_group'
Traceback (most recent call last):
  File "C:\Users\ipharmacare\newreport\common\configReader.py", line 50, in getitems
    result=self.conf.items(field)
  File "C:\Users\ipharmacare\python27\lib\ConfigParser.py", line 642, in items
    raise NoSectionError(section)
NoSectionError: No section: 'default_group'
Wed, 03 Jul 2019 16:26:20 log.py[line:17] DEBUG 计算指标不成功，有指标值为空
Wed, 03 Jul 2019 16:33:07 log.py[line:17] DEBUG 执行过程中出错
Wed, 03 Jul 2019 16:33:07 log.py[line:20] ERROR (1064, "You have an error in your SQL syntax; check the manual that corresponds to your MySQL server version for the right syntax to use near '\xe9\x97\xa8\xe8\xaf\x8a\xe9\x9d\x99\xe8\x84\x89\xe8\xbe\x93\xe6\xb6\xb2\xe5\xa4\x84\xe6\x96\xb9\xe6\x95\xb0:SELECT  COUNT(DISTINCT (recipe_id)) FROM  ipharmacar' at line 1")
Traceback (most recent call last):
  File "C:\Users\ipharmacare\newreport\GetSQLvalue\itemZoneValue.py", line 324, in getSqlValue_zone
    sqlValue = self.getValueInCalc(itemname, zoneid, startT, endT, self.optcalcminus)
  File "C:\Users\ipharmacare\newreport\GetSQLvalue\itemZoneValue.py", line 114, in getValueInCalc
    self.itemvalue_one = self.getCalc_Numerator_zone(self.itemnameOne, zoneid, startT, endT, optcalcminus)
  File "C:\Users\ipharmacare\newreport\GetSQLvalue\itemZoneValue.py", line 218, in getCalc_Numerator_zone
    self.itemvalue_one = self.conndb.executeSQL_zoneid_one(self.cur, self.itemOneSql, zoneid, startT, endT)
  File "C:\Users\ipharmacare\newreport\common\connectDB.py", line 49, in executeSQL_zoneid_one
    cur.execute(sql, (zoneid, startT, endT))
  File "C:\Users\ipharmacare\python27\lib\site-packages\MySQLdb\cursors.py", line 205, in execute
    self.errorhandler(self, exc, value)
  File "C:\Users\ipharmacare\python27\lib\site-packages\MySQLdb\connections.py", line 36, in defaulterrorhandler
    raise errorclass, errorvalue
ProgrammingError: (1064, "You have an error in your SQL syntax; check the manual that corresponds to your MySQL server version for the right syntax to use near '\xe9\x97\xa8\xe8\xaf\x8a\xe9\x9d\x99\xe8\x84\x89\xe8\xbe\x93\xe6\xb6\xb2\xe5\xa4\x84\xe6\x96\xb9\xe6\x95\xb0:SELECT  COUNT(DISTINCT (recipe_id)) FROM  ipharmacar' at line 1")
Wed, 03 Jul 2019 16:33:59 log.py[line:17] DEBUG 读取配置项发生了错误,zone,门诊处方总数（排除中药饮片）
Wed, 03 Jul 2019 16:33:59 log.py[line:20] ERROR No option '\xe9\x97\xa8\xe8\xaf\x8a\xe5\xa4\x84\xe6\x96\xb9\xe6\x80\xbb\xe6\x95\xb0\xef\xbc\x88\xe6\x8e\x92\xe9\x99\xa4\xe4\xb8\xad\xe8\x8d\xaf\xe9\xa5\xae\xe7\x89\x87\xef\xbc\x89' in section: 'zone'
Traceback (most recent call last):
  File "C:\Users\ipharmacare\newreport\common\configReader.py", line 27, in get
    return self.conf.get(field,key)
  File "C:\Users\ipharmacare\python27\lib\ConfigParser.py", line 618, in get
    raise NoOptionError(option, section)
NoOptionError: No option '\xe9\x97\xa8\xe8\xaf\x8a\xe5\xa4\x84\xe6\x96\xb9\xe6\x80\xbb\xe6\x95\xb0\xef\xbc\x88\xe6\x8e\x92\xe9\x99\xa4\xe4\xb8\xad\xe8\x8d\xaf\xe9\xa5\xae\xe7\x89\x87\xef\xbc\x89' in section: 'zone'
Wed, 03 Jul 2019 16:33:59 log.py[line:17] DEBUG 执行过程中出错
Wed, 03 Jul 2019 16:33:59 log.py[line:20] ERROR unsupported operand type(s) for %: 'NoneType' and 'tuple'
Traceback (most recent call last):
  File "C:\Users\ipharmacare\newreport\GetSQLvalue\itemZoneValue.py", line 324, in getSqlValue_zone
    sqlValue = self.getValueInCalc(itemname, zoneid, startT, endT, self.optcalcminus)
  File "C:\Users\ipharmacare\newreport\GetSQLvalue\itemZoneValue.py", line 115, in getValueInCalc
    self.itemvalue_two = self.getCalc_denominator_zone(self.itemnameTwo, zoneid, startT, endT, optcalcminus)
  File "C:\Users\ipharmacare\newreport\GetSQLvalue\itemZoneValue.py", line 249, in getCalc_denominator_zone
    self.itemvalue_two = self.conndb.executeSQL_zoneid_one(self.cur, self.itemTwoSql, zoneid, startT, endT)
  File "C:\Users\ipharmacare\newreport\common\connectDB.py", line 49, in executeSQL_zoneid_one
    cur.execute(sql, (zoneid, startT, endT))
  File "C:\Users\ipharmacare\python27\lib\site-packages\MySQLdb\cursors.py", line 187, in execute
    query = query % tuple([db.literal(item) for item in args])
TypeError: unsupported operand type(s) for %: 'NoneType' and 'tuple'
Wed, 03 Jul 2019 16:34:00 log.py[line:17] DEBUG 读取配置项发生了错误,zone,门诊处方总数（排除中药饮片）
Wed, 03 Jul 2019 16:34:00 log.py[line:20] ERROR No option '\xe9\x97\xa8\xe8\xaf\x8a\xe5\xa4\x84\xe6\x96\xb9\xe6\x80\xbb\xe6\x95\xb0\xef\xbc\x88\xe6\x8e\x92\xe9\x99\xa4\xe4\xb8\xad\xe8\x8d\xaf\xe9\xa5\xae\xe7\x89\x87\xef\xbc\x89' in section: 'zone'
Traceback (most recent call last):
  File "C:\Users\ipharmacare\newreport\common\configReader.py", line 27, in get
    return self.conf.get(field,key)
  File "C:\Users\ipharmacare\python27\lib\ConfigParser.py", line 618, in get
    raise NoOptionError(option, section)
NoOptionError: No option '\xe9\x97\xa8\xe8\xaf\x8a\xe5\xa4\x84\xe6\x96\xb9\xe6\x80\xbb\xe6\x95\xb0\xef\xbc\x88\xe6\x8e\x92\xe9\x99\xa4\xe4\xb8\xad\xe8\x8d\xaf\xe9\xa5\xae\xe7\x89\x87\xef\xbc\x89' in section: 'zone'
Wed, 03 Jul 2019 16:34:00 log.py[line:17] DEBUG 执行过程中出错
Wed, 03 Jul 2019 16:34:00 log.py[line:20] ERROR unsupported operand type(s) for %: 'NoneType' and 'tuple'
Traceback (most recent call last):
  File "C:\Users\ipharmacare\newreport\GetSQLvalue\itemZoneValue.py", line 324, in getSqlValue_zone
    sqlValue = self.getValueInCalc(itemname, zoneid, startT, endT, self.optcalcminus)
  File "C:\Users\ipharmacare\newreport\GetSQLvalue\itemZoneValue.py", line 115, in getValueInCalc
    self.itemvalue_two = self.getCalc_denominator_zone(self.itemnameTwo, zoneid, startT, endT, optcalcminus)
  File "C:\Users\ipharmacare\newreport\GetSQLvalue\itemZoneValue.py", line 249, in getCalc_denominator_zone
    self.itemvalue_two = self.conndb.executeSQL_zoneid_one(self.cur, self.itemTwoSql, zoneid, startT, endT)
  File "C:\Users\ipharmacare\newreport\common\connectDB.py", line 49, in executeSQL_zoneid_one
    cur.execute(sql, (zoneid, startT, endT))
  File "C:\Users\ipharmacare\python27\lib\site-packages\MySQLdb\cursors.py", line 187, in execute
    query = query % tuple([db.literal(item) for item in args])
TypeError: unsupported operand type(s) for %: 'NoneType' and 'tuple'
Wed, 03 Jul 2019 16:34:01 log.py[line:17] DEBUG 读取配置项发生了错误,zone,门诊处方总数（排除中药饮片）
Wed, 03 Jul 2019 16:34:01 log.py[line:20] ERROR No option '\xe9\x97\xa8\xe8\xaf\x8a\xe5\xa4\x84\xe6\x96\xb9\xe6\x80\xbb\xe6\x95\xb0\xef\xbc\x88\xe6\x8e\x92\xe9\x99\xa4\xe4\xb8\xad\xe8\x8d\xaf\xe9\xa5\xae\xe7\x89\x87\xef\xbc\x89' in section: 'zone'
Traceback (most recent call last):
  File "C:\Users\ipharmacare\newreport\common\configReader.py", line 27, in get
    return self.conf.get(field,key)
  File "C:\Users\ipharmacare\python27\lib\ConfigParser.py", line 618, in get
    raise NoOptionError(option, section)
NoOptionError: No option '\xe9\x97\xa8\xe8\xaf\x8a\xe5\xa4\x84\xe6\x96\xb9\xe6\x80\xbb\xe6\x95\xb0\xef\xbc\x88\xe6\x8e\x92\xe9\x99\xa4\xe4\xb8\xad\xe8\x8d\xaf\xe9\xa5\xae\xe7\x89\x87\xef\xbc\x89' in section: 'zone'
Wed, 03 Jul 2019 16:34:01 log.py[line:17] DEBUG 执行过程中出错
Wed, 03 Jul 2019 16:34:01 log.py[line:20] ERROR unsupported operand type(s) for %: 'NoneType' and 'tuple'
Traceback (most recent call last):
  File "C:\Users\ipharmacare\newreport\GetSQLvalue\itemZoneValue.py", line 324, in getSqlValue_zone
    sqlValue = self.getValueInCalc(itemname, zoneid, startT, endT, self.optcalcminus)
  File "C:\Users\ipharmacare\newreport\GetSQLvalue\itemZoneValue.py", line 115, in getValueInCalc
    self.itemvalue_two = self.getCalc_denominator_zone(self.itemnameTwo, zoneid, startT, endT, optcalcminus)
  File "C:\Users\ipharmacare\newreport\GetSQLvalue\itemZoneValue.py", line 249, in getCalc_denominator_zone
    self.itemvalue_two = self.conndb.executeSQL_zoneid_one(self.cur, self.itemTwoSql, zoneid, startT, endT)
  File "C:\Users\ipharmacare\newreport\common\connectDB.py", line 49, in executeSQL_zoneid_one
    cur.execute(sql, (zoneid, startT, endT))
  File "C:\Users\ipharmacare\python27\lib\site-packages\MySQLdb\cursors.py", line 187, in execute
    query = query % tuple([db.literal(item) for item in args])
TypeError: unsupported operand type(s) for %: 'NoneType' and 'tuple'
Wed, 03 Jul 2019 16:43:53 log.py[line:17] DEBUG 读取配置项发生了错误,hospital_doc
Wed, 03 Jul 2019 16:43:53 log.py[line:20] ERROR No section: 'hospital_doc'
Traceback (most recent call last):
  File "C:\Users\ipharmacare\newreport\common\configReader.py", line 50, in getitems
    result=self.conf.items(field)
  File "C:\Users\ipharmacare\python27\lib\ConfigParser.py", line 642, in items
    raise NoSectionError(section)
NoSectionError: No section: 'hospital_doc'
Wed, 03 Jul 2019 16:43:53 log.py[line:17] DEBUG 读取配置项发生了错误,default_doc
Wed, 03 Jul 2019 16:43:53 log.py[line:20] ERROR No section: 'default_doc'
Traceback (most recent call last):
  File "C:\Users\ipharmacare\newreport\common\configReader.py", line 50, in getitems
    result=self.conf.items(field)
  File "C:\Users\ipharmacare\python27\lib\ConfigParser.py", line 642, in items
    raise NoSectionError(section)
NoSectionError: No section: 'default_doc'
Wed, 03 Jul 2019 16:43:53 log.py[line:17] DEBUG 读取配置项发生了错误,ConfigurationItem_doc
Wed, 03 Jul 2019 16:43:53 log.py[line:20] ERROR No section: 'ConfigurationItem_doc'
Traceback (most recent call last):
  File "C:\Users\ipharmacare\newreport\common\configReader.py", line 50, in getitems
    result=self.conf.items(field)
  File "C:\Users\ipharmacare\python27\lib\ConfigParser.py", line 642, in items
    raise NoSectionError(section)
NoSectionError: No section: 'ConfigurationItem_doc'
Wed, 03 Jul 2019 16:43:53 log.py[line:17] DEBUG 读取配置项发生了错误,doc_ddds
Wed, 03 Jul 2019 16:43:53 log.py[line:20] ERROR No section: 'doc_ddds'
Traceback (most recent call last):
  File "C:\Users\ipharmacare\newreport\common\configReader.py", line 50, in getitems
    result=self.conf.items(field)
  File "C:\Users\ipharmacare\python27\lib\ConfigParser.py", line 642, in items
    raise NoSectionError(section)
NoSectionError: No section: 'doc_ddds'
Wed, 03 Jul 2019 16:43:53 log.py[line:17] DEBUG 读取配置项发生了错误,hospitalDoc_ddds
Wed, 03 Jul 2019 16:43:53 log.py[line:20] ERROR No section: 'hospitalDoc_ddds'
Traceback (most recent call last):
  File "C:\Users\ipharmacare\newreport\common\configReader.py", line 50, in getitems
    result=self.conf.items(field)
  File "C:\Users\ipharmacare\python27\lib\ConfigParser.py", line 642, in items
    raise NoSectionError(section)
NoSectionError: No section: 'hospitalDoc_ddds'
Wed, 03 Jul 2019 16:43:53 log.py[line:17] DEBUG 读取配置项发生了错误,hospital_dept
Wed, 03 Jul 2019 16:43:53 log.py[line:20] ERROR No section: 'hospital_dept'
Traceback (most recent call last):
  File "C:\Users\ipharmacare\newreport\common\configReader.py", line 50, in getitems
    result=self.conf.items(field)
  File "C:\Users\ipharmacare\python27\lib\ConfigParser.py", line 642, in items
    raise NoSectionError(section)
NoSectionError: No section: 'hospital_dept'
Wed, 03 Jul 2019 16:43:53 log.py[line:17] DEBUG 读取配置项发生了错误,default_dept
Wed, 03 Jul 2019 16:43:53 log.py[line:20] ERROR No section: 'default_dept'
Traceback (most recent call last):
  File "C:\Users\ipharmacare\newreport\common\configReader.py", line 50, in getitems
    result=self.conf.items(field)
  File "C:\Users\ipharmacare\python27\lib\ConfigParser.py", line 642, in items
    raise NoSectionError(section)
NoSectionError: No section: 'default_dept'
Wed, 03 Jul 2019 16:43:53 log.py[line:17] DEBUG 读取配置项发生了错误,ConfigurationItem_dept
Wed, 03 Jul 2019 16:43:53 log.py[line:20] ERROR No section: 'ConfigurationItem_dept'
Traceback (most recent call last):
  File "C:\Users\ipharmacare\newreport\common\configReader.py", line 50, in getitems
    result=self.conf.items(field)
  File "C:\Users\ipharmacare\python27\lib\ConfigParser.py", line 642, in items
    raise NoSectionError(section)
NoSectionError: No section: 'ConfigurationItem_dept'
Wed, 03 Jul 2019 16:43:53 log.py[line:17] DEBUG 读取配置项发生了错误,dept_ddds
Wed, 03 Jul 2019 16:43:53 log.py[line:20] ERROR No section: 'dept_ddds'
Traceback (most recent call last):
  File "C:\Users\ipharmacare\newreport\common\configReader.py", line 50, in getitems
    result=self.conf.items(field)
  File "C:\Users\ipharmacare\python27\lib\ConfigParser.py", line 642, in items
    raise NoSectionError(section)
NoSectionError: No section: 'dept_ddds'
Wed, 03 Jul 2019 16:43:53 log.py[line:17] DEBUG 读取配置项发生了错误,hospitalDept_ddds
Wed, 03 Jul 2019 16:43:53 log.py[line:20] ERROR No section: 'hospitalDept_ddds'
Traceback (most recent call last):
  File "C:\Users\ipharmacare\newreport\common\configReader.py", line 50, in getitems
    result=self.conf.items(field)
  File "C:\Users\ipharmacare\python27\lib\ConfigParser.py", line 642, in items
    raise NoSectionError(section)
NoSectionError: No section: 'hospitalDept_ddds'
Wed, 03 Jul 2019 16:43:53 log.py[line:17] DEBUG 读取配置项发生了错误,default_group
Wed, 03 Jul 2019 16:43:53 log.py[line:20] ERROR No section: 'default_group'
Traceback (most recent call last):
  File "C:\Users\ipharmacare\newreport\common\configReader.py", line 50, in getitems
    result=self.conf.items(field)
  File "C:\Users\ipharmacare\python27\lib\ConfigParser.py", line 642, in items
    raise NoSectionError(section)
NoSectionError: No section: 'default_group'
Wed, 03 Jul 2019 16:49:55 connectionpool.py[line:205] DEBUG Starting new HTTP connection (1): 10.1.1.89:9999
Wed, 03 Jul 2019 16:49:55 connectionpool.py[line:393] DEBUG http://10.1.1.89:9999 "POST /syscenter/api/v1/currentUser HTTP/1.1" 200 None
Wed, 03 Jul 2019 16:49:55 connectionpool.py[line:393] DEBUG http://10.1.1.89:9999 "GET /syscenter/api/v1/config/selectSysConfig?showName=qty%E8%AE%A1%E7%AE%97%E6%96%B9%E6%B3%95 HTTP/1.1" 200 None
Wed, 03 Jul 2019 16:49:55 log.py[line:17] DEBUG 配置项错误
Wed, 03 Jul 2019 16:49:55 log.py[line:20] ERROR getZoneSQLvalue instance has no attribute 'sqlValue'
Traceback (most recent call last):
  File "C:\Users\ipharmacare\newreport\GetSQLvalue\itemZoneValue.py", line 351, in getSqlValue_zone
    sqlValue = self.getValueInddds(itemname,zoneid,startT,endT)[0]
  File "C:\Users\ipharmacare\newreport\GetSQLvalue\itemZoneValue.py", line 63, in getValueInddds
    return self.sqlValue
AttributeError: getZoneSQLvalue instance has no attribute 'sqlValue'
Wed, 03 Jul 2019 16:49:55 connectionpool.py[line:205] DEBUG Starting new HTTP connection (1): 10.1.1.89:9999
Wed, 03 Jul 2019 16:49:55 connectionpool.py[line:393] DEBUG http://10.1.1.89:9999 "POST /syscenter/api/v1/currentUser HTTP/1.1" 200 None
Wed, 03 Jul 2019 16:49:55 connectionpool.py[line:393] DEBUG http://10.1.1.89:9999 "GET /syscenter/api/v1/config/selectSysConfig?showName=qty%E8%AE%A1%E7%AE%97%E6%96%B9%E6%B3%95 HTTP/1.1" 200 None
Wed, 03 Jul 2019 16:49:55 log.py[line:17] DEBUG 配置项错误
Wed, 03 Jul 2019 16:49:55 log.py[line:20] ERROR getZoneSQLvalue instance has no attribute 'sqlValue'
Traceback (most recent call last):
  File "C:\Users\ipharmacare\newreport\GetSQLvalue\itemZoneValue.py", line 351, in getSqlValue_zone
    sqlValue = self.getValueInddds(itemname,zoneid,startT,endT)[0]
  File "C:\Users\ipharmacare\newreport\GetSQLvalue\itemZoneValue.py", line 63, in getValueInddds
    return self.sqlValue
AttributeError: getZoneSQLvalue instance has no attribute 'sqlValue'
Wed, 03 Jul 2019 19:40:23 log.py[line:17] DEBUG 读取配置项发生了错误,hospital_doc
Wed, 03 Jul 2019 19:40:23 log.py[line:20] ERROR No section: 'hospital_doc'
Traceback (most recent call last):
  File "C:\Users\ipharmacare\newreport\common\configReader.py", line 50, in getitems
    result=self.conf.items(field)
  File "C:\Users\ipharmacare\python27\lib\ConfigParser.py", line 642, in items
    raise NoSectionError(section)
NoSectionError: No section: 'hospital_doc'
Wed, 03 Jul 2019 19:40:23 log.py[line:17] DEBUG 读取配置项发生了错误,default_doc
Wed, 03 Jul 2019 19:40:23 log.py[line:20] ERROR No section: 'default_doc'
Traceback (most recent call last):
  File "C:\Users\ipharmacare\newreport\common\configReader.py", line 50, in getitems
    result=self.conf.items(field)
  File "C:\Users\ipharmacare\python27\lib\ConfigParser.py", line 642, in items
    raise NoSectionError(section)
NoSectionError: No section: 'default_doc'
Wed, 03 Jul 2019 19:40:23 log.py[line:17] DEBUG 读取配置项发生了错误,ConfigurationItem_doc
Wed, 03 Jul 2019 19:40:23 log.py[line:20] ERROR No section: 'ConfigurationItem_doc'
Traceback (most recent call last):
  File "C:\Users\ipharmacare\newreport\common\configReader.py", line 50, in getitems
    result=self.conf.items(field)
  File "C:\Users\ipharmacare\python27\lib\ConfigParser.py", line 642, in items
    raise NoSectionError(section)
NoSectionError: No section: 'ConfigurationItem_doc'
Wed, 03 Jul 2019 19:40:23 log.py[line:17] DEBUG 读取配置项发生了错误,doc_ddds
Wed, 03 Jul 2019 19:40:23 log.py[line:20] ERROR No section: 'doc_ddds'
Traceback (most recent call last):
  File "C:\Users\ipharmacare\newreport\common\configReader.py", line 50, in getitems
    result=self.conf.items(field)
  File "C:\Users\ipharmacare\python27\lib\ConfigParser.py", line 642, in items
    raise NoSectionError(section)
NoSectionError: No section: 'doc_ddds'
Wed, 03 Jul 2019 19:40:23 log.py[line:17] DEBUG 读取配置项发生了错误,hospitalDoc_ddds
Wed, 03 Jul 2019 19:40:23 log.py[line:20] ERROR No section: 'hospitalDoc_ddds'
Traceback (most recent call last):
  File "C:\Users\ipharmacare\newreport\common\configReader.py", line 50, in getitems
    result=self.conf.items(field)
  File "C:\Users\ipharmacare\python27\lib\ConfigParser.py", line 642, in items
    raise NoSectionError(section)
NoSectionError: No section: 'hospitalDoc_ddds'
Wed, 03 Jul 2019 19:40:23 log.py[line:17] DEBUG 读取配置项发生了错误,hospital_dept
Wed, 03 Jul 2019 19:40:23 log.py[line:20] ERROR No section: 'hospital_dept'
Traceback (most recent call last):
  File "C:\Users\ipharmacare\newreport\common\configReader.py", line 50, in getitems
    result=self.conf.items(field)
  File "C:\Users\ipharmacare\python27\lib\ConfigParser.py", line 642, in items
    raise NoSectionError(section)
NoSectionError: No section: 'hospital_dept'
Wed, 03 Jul 2019 19:40:23 log.py[line:17] DEBUG 读取配置项发生了错误,default_dept
Wed, 03 Jul 2019 19:40:23 log.py[line:20] ERROR No section: 'default_dept'
Traceback (most recent call last):
  File "C:\Users\ipharmacare\newreport\common\configReader.py", line 50, in getitems
    result=self.conf.items(field)
  File "C:\Users\ipharmacare\python27\lib\ConfigParser.py", line 642, in items
    raise NoSectionError(section)
NoSectionError: No section: 'default_dept'
Wed, 03 Jul 2019 19:40:23 log.py[line:17] DEBUG 读取配置项发生了错误,ConfigurationItem_dept
Wed, 03 Jul 2019 19:40:23 log.py[line:20] ERROR No section: 'ConfigurationItem_dept'
Traceback (most recent call last):
  File "C:\Users\ipharmacare\newreport\common\configReader.py", line 50, in getitems
    result=self.conf.items(field)
  File "C:\Users\ipharmacare\python27\lib\ConfigParser.py", line 642, in items
    raise NoSectionError(section)
NoSectionError: No section: 'ConfigurationItem_dept'
Wed, 03 Jul 2019 19:40:23 log.py[line:17] DEBUG 读取配置项发生了错误,dept_ddds
Wed, 03 Jul 2019 19:40:23 log.py[line:20] ERROR No section: 'dept_ddds'
Traceback (most recent call last):
  File "C:\Users\ipharmacare\newreport\common\configReader.py", line 50, in getitems
    result=self.conf.items(field)
  File "C:\Users\ipharmacare\python27\lib\ConfigParser.py", line 642, in items
    raise NoSectionError(section)
NoSectionError: No section: 'dept_ddds'
Wed, 03 Jul 2019 19:40:23 log.py[line:17] DEBUG 读取配置项发生了错误,hospitalDept_ddds
Wed, 03 Jul 2019 19:40:23 log.py[line:20] ERROR No section: 'hospitalDept_ddds'
Traceback (most recent call last):
  File "C:\Users\ipharmacare\newreport\common\configReader.py", line 50, in getitems
    result=self.conf.items(field)
  File "C:\Users\ipharmacare\python27\lib\ConfigParser.py", line 642, in items
    raise NoSectionError(section)
NoSectionError: No section: 'hospitalDept_ddds'
Wed, 03 Jul 2019 19:40:23 log.py[line:17] DEBUG 读取配置项发生了错误,default_group
Wed, 03 Jul 2019 19:40:23 log.py[line:20] ERROR No section: 'default_group'
Traceback (most recent call last):
  File "C:\Users\ipharmacare\newreport\common\configReader.py", line 50, in getitems
    result=self.conf.items(field)
  File "C:\Users\ipharmacare\python27\lib\ConfigParser.py", line 642, in items
    raise NoSectionError(section)
NoSectionError: No section: 'default_group'
Wed, 03 Jul 2019 19:40:32 log.py[line:17] DEBUG 该指标在指标库中不存在,住院平均床日输液量
