Wed, 14 Aug 2019 15:02:33 log.py[line:17] DEBUG 读取配置项发生了错误,hospital_doc
Wed, 14 Aug 2019 15:02:33 log.py[line:20] ERROR No section: 'hospital_doc'
Traceback (most recent call last):
  File "C:\Users\ipharmacare\newreport\common\configReader.py", line 50, in getitems
    result=self.conf.items(field)
  File "C:\Users\ipharmacare\python27\lib\ConfigParser.py", line 642, in items
    raise NoSectionError(section)
NoSectionError: No section: 'hospital_doc'
Wed, 14 Aug 2019 15:02:33 log.py[line:17] DEBUG 读取配置项发生了错误,default_doc
Wed, 14 Aug 2019 15:02:33 log.py[line:20] ERROR No section: 'default_doc'
Traceback (most recent call last):
  File "C:\Users\ipharmacare\newreport\common\configReader.py", line 50, in getitems
    result=self.conf.items(field)
  File "C:\Users\ipharmacare\python27\lib\ConfigParser.py", line 642, in items
    raise NoSectionError(section)
NoSectionError: No section: 'default_doc'
Wed, 14 Aug 2019 15:02:33 log.py[line:17] DEBUG 读取配置项发生了错误,ConfigurationItem_doc
Wed, 14 Aug 2019 15:02:33 log.py[line:20] ERROR No section: 'ConfigurationItem_doc'
Traceback (most recent call last):
  File "C:\Users\ipharmacare\newreport\common\configReader.py", line 50, in getitems
    result=self.conf.items(field)
  File "C:\Users\ipharmacare\python27\lib\ConfigParser.py", line 642, in items
    raise NoSectionError(section)
NoSectionError: No section: 'ConfigurationItem_doc'
Wed, 14 Aug 2019 15:02:34 log.py[line:17] DEBUG 读取配置项发生了错误,doc_ddds
Wed, 14 Aug 2019 15:02:34 log.py[line:20] ERROR No section: 'doc_ddds'
Traceback (most recent call last):
  File "C:\Users\ipharmacare\newreport\common\configReader.py", line 50, in getitems
    result=self.conf.items(field)
  File "C:\Users\ipharmacare\python27\lib\ConfigParser.py", line 642, in items
    raise NoSectionError(section)
NoSectionError: No section: 'doc_ddds'
Wed, 14 Aug 2019 15:02:34 log.py[line:17] DEBUG 读取配置项发生了错误,hospitalDoc_ddds
Wed, 14 Aug 2019 15:02:34 log.py[line:20] ERROR No section: 'hospitalDoc_ddds'
Traceback (most recent call last):
  File "C:\Users\ipharmacare\newreport\common\configReader.py", line 50, in getitems
    result=self.conf.items(field)
  File "C:\Users\ipharmacare\python27\lib\ConfigParser.py", line 642, in items
    raise NoSectionError(section)
NoSectionError: No section: 'hospitalDoc_ddds'
Wed, 14 Aug 2019 15:02:34 log.py[line:17] DEBUG 读取配置项发生了错误,hospital_dept
Wed, 14 Aug 2019 15:02:34 log.py[line:20] ERROR No section: 'hospital_dept'
Traceback (most recent call last):
  File "C:\Users\ipharmacare\newreport\common\configReader.py", line 50, in getitems
    result=self.conf.items(field)
  File "C:\Users\ipharmacare\python27\lib\ConfigParser.py", line 642, in items
    raise NoSectionError(section)
NoSectionError: No section: 'hospital_dept'
Wed, 14 Aug 2019 15:02:34 log.py[line:17] DEBUG 读取配置项发生了错误,default_dept
Wed, 14 Aug 2019 15:02:34 log.py[line:20] ERROR No section: 'default_dept'
Traceback (most recent call last):
  File "C:\Users\ipharmacare\newreport\common\configReader.py", line 50, in getitems
    result=self.conf.items(field)
  File "C:\Users\ipharmacare\python27\lib\ConfigParser.py", line 642, in items
    raise NoSectionError(section)
NoSectionError: No section: 'default_dept'
Wed, 14 Aug 2019 15:02:34 log.py[line:17] DEBUG 读取配置项发生了错误,ConfigurationItem_dept
Wed, 14 Aug 2019 15:02:34 log.py[line:20] ERROR No section: 'ConfigurationItem_dept'
Traceback (most recent call last):
  File "C:\Users\ipharmacare\newreport\common\configReader.py", line 50, in getitems
    result=self.conf.items(field)
  File "C:\Users\ipharmacare\python27\lib\ConfigParser.py", line 642, in items
    raise NoSectionError(section)
NoSectionError: No section: 'ConfigurationItem_dept'
Wed, 14 Aug 2019 15:02:34 log.py[line:17] DEBUG 读取配置项发生了错误,dept_ddds
Wed, 14 Aug 2019 15:02:34 log.py[line:20] ERROR No section: 'dept_ddds'
Traceback (most recent call last):
  File "C:\Users\ipharmacare\newreport\common\configReader.py", line 50, in getitems
    result=self.conf.items(field)
  File "C:\Users\ipharmacare\python27\lib\ConfigParser.py", line 642, in items
    raise NoSectionError(section)
NoSectionError: No section: 'dept_ddds'
Wed, 14 Aug 2019 15:02:34 log.py[line:17] DEBUG 读取配置项发生了错误,hospitalDept_ddds
Wed, 14 Aug 2019 15:02:34 log.py[line:20] ERROR No section: 'hospitalDept_ddds'
Traceback (most recent call last):
  File "C:\Users\ipharmacare\newreport\common\configReader.py", line 50, in getitems
    result=self.conf.items(field)
  File "C:\Users\ipharmacare\python27\lib\ConfigParser.py", line 642, in items
    raise NoSectionError(section)
NoSectionError: No section: 'hospitalDept_ddds'
Wed, 14 Aug 2019 15:02:34 log.py[line:17] DEBUG 读取配置项发生了错误,default_group
Wed, 14 Aug 2019 15:02:34 log.py[line:20] ERROR No section: 'default_group'
Traceback (most recent call last):
  File "C:\Users\ipharmacare\newreport\common\configReader.py", line 50, in getitems
    result=self.conf.items(field)
  File "C:\Users\ipharmacare\python27\lib\ConfigParser.py", line 642, in items
    raise NoSectionError(section)
NoSectionError: No section: 'default_group'
Wed, 14 Aug 2019 15:02:34 connectionpool.py[line:205] DEBUG Starting new HTTP connection (1): 10.1.1.89:9999
Wed, 14 Aug 2019 15:02:34 connectionpool.py[line:393] DEBUG http://10.1.1.89:9999 "POST /syscenter/api/v1/currentUser HTTP/1.1" 200 None
Wed, 14 Aug 2019 15:02:34 connectionpool.py[line:393] DEBUG http://10.1.1.89:9999 "GET /syscenter/api/v1/config/selectSysConfig?showName=%E6%8A%97%E8%8F%8C%E8%8D%AF%E7%89%A9%E9%80%81%E6%A3%80%E6%A0%87%E8%AF%86 HTTP/1.1" 200 None
Wed, 14 Aug 2019 15:02:35 connectionpool.py[line:205] DEBUG Starting new HTTP connection (1): 10.1.1.89:9999
Wed, 14 Aug 2019 15:02:35 connectionpool.py[line:393] DEBUG http://10.1.1.89:9999 "POST /syscenter/api/v1/currentUser HTTP/1.1" 200 None
Wed, 14 Aug 2019 15:02:35 connectionpool.py[line:393] DEBUG http://10.1.1.89:9999 "GET /syscenter/api/v1/config/selectSysConfig?showName=%E6%8A%97%E8%8F%8C%E8%8D%AF%E7%89%A9%E9%80%81%E6%A3%80%E6%A0%87%E8%AF%86 HTTP/1.1" 200 None
Wed, 14 Aug 2019 15:02:35 log.py[line:17] DEBUG 该指标在指标库中不存在,去年同期出院患者总人次
Wed, 14 Aug 2019 15:02:35 log.py[line:17] DEBUG 该指标在指标库中不存在,使用非限制级抗菌药物出院患者中病原学检查送检人次
Wed, 14 Aug 2019 15:02:35 log.py[line:17] DEBUG 该指标在指标库中不存在,使用限制级抗菌药物出院患者中病原学检查送检人次
Wed, 14 Aug 2019 15:02:35 log.py[line:17] DEBUG 该指标在指标库中不存在,使用特殊级抗菌药物出院患者中病原学检查送检人次
Wed, 14 Aug 2019 15:02:35 log.py[line:17] DEBUG 该指标在指标库中不存在,出院患者静脉输液总人次
Wed, 14 Aug 2019 15:02:35 log.py[line:17] DEBUG 该指标在指标库中不存在,出院患者总人次（排除中药饮片）
Wed, 14 Aug 2019 15:02:35 log.py[line:17] DEBUG 该指标在指标库中不存在,住院省基药使用金额
Wed, 14 Aug 2019 15:02:35 log.py[line:17] DEBUG 该指标在指标库中不存在,门诊省基药使用金额
Wed, 14 Aug 2019 15:02:35 log.py[line:17] DEBUG 该指标在指标库中不存在,急诊省基药使用金额
Wed, 14 Aug 2019 15:05:44 log.py[line:17] DEBUG 读取配置项发生了错误,hospital_doc
Wed, 14 Aug 2019 15:05:44 log.py[line:20] ERROR No section: 'hospital_doc'
Traceback (most recent call last):
  File "C:\Users\ipharmacare\newreport\common\configReader.py", line 50, in getitems
    result=self.conf.items(field)
  File "C:\Users\ipharmacare\python27\lib\ConfigParser.py", line 642, in items
    raise NoSectionError(section)
NoSectionError: No section: 'hospital_doc'
Wed, 14 Aug 2019 15:05:44 log.py[line:17] DEBUG 读取配置项发生了错误,default_doc
Wed, 14 Aug 2019 15:05:44 log.py[line:20] ERROR No section: 'default_doc'
Traceback (most recent call last):
  File "C:\Users\ipharmacare\newreport\common\configReader.py", line 50, in getitems
    result=self.conf.items(field)
  File "C:\Users\ipharmacare\python27\lib\ConfigParser.py", line 642, in items
    raise NoSectionError(section)
NoSectionError: No section: 'default_doc'
Wed, 14 Aug 2019 15:05:44 log.py[line:17] DEBUG 读取配置项发生了错误,ConfigurationItem_doc
Wed, 14 Aug 2019 15:05:44 log.py[line:20] ERROR No section: 'ConfigurationItem_doc'
Traceback (most recent call last):
  File "C:\Users\ipharmacare\newreport\common\configReader.py", line 50, in getitems
    result=self.conf.items(field)
  File "C:\Users\ipharmacare\python27\lib\ConfigParser.py", line 642, in items
    raise NoSectionError(section)
NoSectionError: No section: 'ConfigurationItem_doc'
Wed, 14 Aug 2019 15:05:44 log.py[line:17] DEBUG 读取配置项发生了错误,doc_ddds
Wed, 14 Aug 2019 15:05:44 log.py[line:20] ERROR No section: 'doc_ddds'
Traceback (most recent call last):
  File "C:\Users\ipharmacare\newreport\common\configReader.py", line 50, in getitems
    result=self.conf.items(field)
  File "C:\Users\ipharmacare\python27\lib\ConfigParser.py", line 642, in items
    raise NoSectionError(section)
NoSectionError: No section: 'doc_ddds'
Wed, 14 Aug 2019 15:05:44 log.py[line:17] DEBUG 读取配置项发生了错误,hospitalDoc_ddds
Wed, 14 Aug 2019 15:05:44 log.py[line:20] ERROR No section: 'hospitalDoc_ddds'
Traceback (most recent call last):
  File "C:\Users\ipharmacare\newreport\common\configReader.py", line 50, in getitems
    result=self.conf.items(field)
  File "C:\Users\ipharmacare\python27\lib\ConfigParser.py", line 642, in items
    raise NoSectionError(section)
NoSectionError: No section: 'hospitalDoc_ddds'
Wed, 14 Aug 2019 15:05:44 log.py[line:17] DEBUG 读取配置项发生了错误,hospital_dept
Wed, 14 Aug 2019 15:05:44 log.py[line:20] ERROR No section: 'hospital_dept'
Traceback (most recent call last):
  File "C:\Users\ipharmacare\newreport\common\configReader.py", line 50, in getitems
    result=self.conf.items(field)
  File "C:\Users\ipharmacare\python27\lib\ConfigParser.py", line 642, in items
    raise NoSectionError(section)
NoSectionError: No section: 'hospital_dept'
Wed, 14 Aug 2019 15:05:44 log.py[line:17] DEBUG 读取配置项发生了错误,default_dept
Wed, 14 Aug 2019 15:05:44 log.py[line:20] ERROR No section: 'default_dept'
Traceback (most recent call last):
  File "C:\Users\ipharmacare\newreport\common\configReader.py", line 50, in getitems
    result=self.conf.items(field)
  File "C:\Users\ipharmacare\python27\lib\ConfigParser.py", line 642, in items
    raise NoSectionError(section)
NoSectionError: No section: 'default_dept'
Wed, 14 Aug 2019 15:05:44 log.py[line:17] DEBUG 读取配置项发生了错误,ConfigurationItem_dept
Wed, 14 Aug 2019 15:05:44 log.py[line:20] ERROR No section: 'ConfigurationItem_dept'
Traceback (most recent call last):
  File "C:\Users\ipharmacare\newreport\common\configReader.py", line 50, in getitems
    result=self.conf.items(field)
  File "C:\Users\ipharmacare\python27\lib\ConfigParser.py", line 642, in items
    raise NoSectionError(section)
NoSectionError: No section: 'ConfigurationItem_dept'
Wed, 14 Aug 2019 15:05:44 log.py[line:17] DEBUG 读取配置项发生了错误,dept_ddds
Wed, 14 Aug 2019 15:05:44 log.py[line:20] ERROR No section: 'dept_ddds'
Traceback (most recent call last):
  File "C:\Users\ipharmacare\newreport\common\configReader.py", line 50, in getitems
    result=self.conf.items(field)
  File "C:\Users\ipharmacare\python27\lib\ConfigParser.py", line 642, in items
    raise NoSectionError(section)
NoSectionError: No section: 'dept_ddds'
Wed, 14 Aug 2019 15:05:44 log.py[line:17] DEBUG 读取配置项发生了错误,hospitalDept_ddds
Wed, 14 Aug 2019 15:05:44 log.py[line:20] ERROR No section: 'hospitalDept_ddds'
Traceback (most recent call last):
  File "C:\Users\ipharmacare\newreport\common\configReader.py", line 50, in getitems
    result=self.conf.items(field)
  File "C:\Users\ipharmacare\python27\lib\ConfigParser.py", line 642, in items
    raise NoSectionError(section)
NoSectionError: No section: 'hospitalDept_ddds'
Wed, 14 Aug 2019 15:05:44 log.py[line:17] DEBUG 读取配置项发生了错误,default_group
Wed, 14 Aug 2019 15:05:44 log.py[line:20] ERROR No section: 'default_group'
Traceback (most recent call last):
  File "C:\Users\ipharmacare\newreport\common\configReader.py", line 50, in getitems
    result=self.conf.items(field)
  File "C:\Users\ipharmacare\python27\lib\ConfigParser.py", line 642, in items
    raise NoSectionError(section)
NoSectionError: No section: 'default_group'
Wed, 14 Aug 2019 15:05:44 connectionpool.py[line:205] DEBUG Starting new HTTP connection (1): 10.1.1.89:9999
Wed, 14 Aug 2019 15:05:44 connectionpool.py[line:393] DEBUG http://10.1.1.89:9999 "POST /syscenter/api/v1/currentUser HTTP/1.1" 200 None
Wed, 14 Aug 2019 15:05:44 connectionpool.py[line:393] DEBUG http://10.1.1.89:9999 "GET /syscenter/api/v1/config/selectSysConfig?showName=%E6%8A%97%E8%8F%8C%E8%8D%AF%E7%89%A9%E9%80%81%E6%A3%80%E6%A0%87%E8%AF%86 HTTP/1.1" 200 None
Wed, 14 Aug 2019 15:05:44 connectionpool.py[line:205] DEBUG Starting new HTTP connection (1): 10.1.1.89:9999
Wed, 14 Aug 2019 15:05:44 connectionpool.py[line:393] DEBUG http://10.1.1.89:9999 "POST /syscenter/api/v1/currentUser HTTP/1.1" 200 None
Wed, 14 Aug 2019 15:05:44 connectionpool.py[line:393] DEBUG http://10.1.1.89:9999 "GET /syscenter/api/v1/config/selectSysConfig?showName=%E6%8A%97%E8%8F%8C%E8%8D%AF%E7%89%A9%E9%80%81%E6%A3%80%E6%A0%87%E8%AF%86 HTTP/1.1" 200 None
Wed, 14 Aug 2019 15:05:44 log.py[line:17] DEBUG 该指标在指标库中不存在,去年同期出院患者总人次
Wed, 14 Aug 2019 15:05:44 log.py[line:17] DEBUG 该指标在指标库中不存在,使用非限制级抗菌药物出院患者中病原学检查送检人次
Wed, 14 Aug 2019 15:05:44 log.py[line:17] DEBUG 该指标在指标库中不存在,使用限制级抗菌药物出院患者中病原学检查送检人次
Wed, 14 Aug 2019 15:05:44 log.py[line:17] DEBUG 该指标在指标库中不存在,使用特殊级抗菌药物出院患者中病原学检查送检人次
Wed, 14 Aug 2019 15:05:44 log.py[line:17] DEBUG 该指标在指标库中不存在,出院患者静脉输液总人次
Wed, 14 Aug 2019 15:05:44 log.py[line:17] DEBUG 该指标在指标库中不存在,出院患者总人次（排除中药饮片）
Wed, 14 Aug 2019 15:05:45 log.py[line:17] DEBUG 该指标在指标库中不存在,住院省基药使用金额
Wed, 14 Aug 2019 15:05:45 log.py[line:17] DEBUG 该指标在指标库中不存在,门诊省基药使用金额
Wed, 14 Aug 2019 15:05:45 log.py[line:17] DEBUG 该指标在指标库中不存在,急诊省基药使用金额
Wed, 14 Aug 2019 15:11:36 log.py[line:17] DEBUG 读取配置项发生了错误,hospital_doc
Wed, 14 Aug 2019 15:11:36 log.py[line:20] ERROR No section: 'hospital_doc'
Traceback (most recent call last):
  File "C:/Users/ipharmacare/newreport\common\configReader.py", line 50, in getitems
    result=self.conf.items(field)
  File "C:\Users\ipharmacare\python27\lib\ConfigParser.py", line 642, in items
    raise NoSectionError(section)
NoSectionError: No section: 'hospital_doc'
Wed, 14 Aug 2019 15:11:36 log.py[line:17] DEBUG 读取配置项发生了错误,default_doc
Wed, 14 Aug 2019 15:11:36 log.py[line:20] ERROR No section: 'default_doc'
Traceback (most recent call last):
  File "C:/Users/ipharmacare/newreport\common\configReader.py", line 50, in getitems
    result=self.conf.items(field)
  File "C:\Users\ipharmacare\python27\lib\ConfigParser.py", line 642, in items
    raise NoSectionError(section)
NoSectionError: No section: 'default_doc'
Wed, 14 Aug 2019 15:11:36 log.py[line:17] DEBUG 读取配置项发生了错误,ConfigurationItem_doc
Wed, 14 Aug 2019 15:11:36 log.py[line:20] ERROR No section: 'ConfigurationItem_doc'
Traceback (most recent call last):
  File "C:/Users/ipharmacare/newreport\common\configReader.py", line 50, in getitems
    result=self.conf.items(field)
  File "C:\Users\ipharmacare\python27\lib\ConfigParser.py", line 642, in items
    raise NoSectionError(section)
NoSectionError: No section: 'ConfigurationItem_doc'
Wed, 14 Aug 2019 15:11:36 log.py[line:17] DEBUG 读取配置项发生了错误,doc_ddds
Wed, 14 Aug 2019 15:11:36 log.py[line:20] ERROR No section: 'doc_ddds'
Traceback (most recent call last):
  File "C:/Users/ipharmacare/newreport\common\configReader.py", line 50, in getitems
    result=self.conf.items(field)
  File "C:\Users\ipharmacare\python27\lib\ConfigParser.py", line 642, in items
    raise NoSectionError(section)
NoSectionError: No section: 'doc_ddds'
Wed, 14 Aug 2019 15:11:36 log.py[line:17] DEBUG 读取配置项发生了错误,hospitalDoc_ddds
Wed, 14 Aug 2019 15:11:36 log.py[line:20] ERROR No section: 'hospitalDoc_ddds'
Traceback (most recent call last):
  File "C:/Users/ipharmacare/newreport\common\configReader.py", line 50, in getitems
    result=self.conf.items(field)
  File "C:\Users\ipharmacare\python27\lib\ConfigParser.py", line 642, in items
    raise NoSectionError(section)
NoSectionError: No section: 'hospitalDoc_ddds'
Wed, 14 Aug 2019 15:11:36 log.py[line:17] DEBUG 读取配置项发生了错误,hospital_dept
Wed, 14 Aug 2019 15:11:36 log.py[line:20] ERROR No section: 'hospital_dept'
Traceback (most recent call last):
  File "C:/Users/ipharmacare/newreport\common\configReader.py", line 50, in getitems
    result=self.conf.items(field)
  File "C:\Users\ipharmacare\python27\lib\ConfigParser.py", line 642, in items
    raise NoSectionError(section)
NoSectionError: No section: 'hospital_dept'
Wed, 14 Aug 2019 15:11:36 log.py[line:17] DEBUG 读取配置项发生了错误,default_dept
Wed, 14 Aug 2019 15:11:36 log.py[line:20] ERROR No section: 'default_dept'
Traceback (most recent call last):
  File "C:/Users/ipharmacare/newreport\common\configReader.py", line 50, in getitems
    result=self.conf.items(field)
  File "C:\Users\ipharmacare\python27\lib\ConfigParser.py", line 642, in items
    raise NoSectionError(section)
NoSectionError: No section: 'default_dept'
Wed, 14 Aug 2019 15:11:36 log.py[line:17] DEBUG 读取配置项发生了错误,ConfigurationItem_dept
Wed, 14 Aug 2019 15:11:36 log.py[line:20] ERROR No section: 'ConfigurationItem_dept'
Traceback (most recent call last):
  File "C:/Users/ipharmacare/newreport\common\configReader.py", line 50, in getitems
    result=self.conf.items(field)
  File "C:\Users\ipharmacare\python27\lib\ConfigParser.py", line 642, in items
    raise NoSectionError(section)
NoSectionError: No section: 'ConfigurationItem_dept'
Wed, 14 Aug 2019 15:11:36 log.py[line:17] DEBUG 读取配置项发生了错误,dept_ddds
Wed, 14 Aug 2019 15:11:36 log.py[line:20] ERROR No section: 'dept_ddds'
Traceback (most recent call last):
  File "C:/Users/ipharmacare/newreport\common\configReader.py", line 50, in getitems
    result=self.conf.items(field)
  File "C:\Users\ipharmacare\python27\lib\ConfigParser.py", line 642, in items
    raise NoSectionError(section)
NoSectionError: No section: 'dept_ddds'
Wed, 14 Aug 2019 15:11:36 log.py[line:17] DEBUG 读取配置项发生了错误,hospitalDept_ddds
Wed, 14 Aug 2019 15:11:36 log.py[line:20] ERROR No section: 'hospitalDept_ddds'
Traceback (most recent call last):
  File "C:/Users/ipharmacare/newreport\common\configReader.py", line 50, in getitems
    result=self.conf.items(field)
  File "C:\Users\ipharmacare\python27\lib\ConfigParser.py", line 642, in items
    raise NoSectionError(section)
NoSectionError: No section: 'hospitalDept_ddds'
Wed, 14 Aug 2019 15:11:36 log.py[line:17] DEBUG 读取配置项发生了错误,default_group
Wed, 14 Aug 2019 15:11:36 log.py[line:20] ERROR No section: 'default_group'
Traceback (most recent call last):
  File "C:/Users/ipharmacare/newreport\common\configReader.py", line 50, in getitems
    result=self.conf.items(field)
  File "C:\Users\ipharmacare\python27\lib\ConfigParser.py", line 642, in items
    raise NoSectionError(section)
NoSectionError: No section: 'default_group'
Wed, 14 Aug 2019 17:35:00 log.py[line:17] DEBUG 读取配置项发生了错误,hospital_doc
Wed, 14 Aug 2019 17:35:00 log.py[line:20] ERROR No section: 'hospital_doc'
Traceback (most recent call last):
  File "C:\Users\ipharmacare\newreport\common\configReader.py", line 50, in getitems
    result=self.conf.items(field)
  File "C:\Users\ipharmacare\python27\lib\ConfigParser.py", line 642, in items
    raise NoSectionError(section)
NoSectionError: No section: 'hospital_doc'
Wed, 14 Aug 2019 17:35:00 log.py[line:17] DEBUG 读取配置项发生了错误,default_doc
Wed, 14 Aug 2019 17:35:00 log.py[line:20] ERROR No section: 'default_doc'
Traceback (most recent call last):
  File "C:\Users\ipharmacare\newreport\common\configReader.py", line 50, in getitems
    result=self.conf.items(field)
  File "C:\Users\ipharmacare\python27\lib\ConfigParser.py", line 642, in items
    raise NoSectionError(section)
NoSectionError: No section: 'default_doc'
Wed, 14 Aug 2019 17:35:00 log.py[line:17] DEBUG 读取配置项发生了错误,ConfigurationItem_doc
Wed, 14 Aug 2019 17:35:00 log.py[line:20] ERROR No section: 'ConfigurationItem_doc'
Traceback (most recent call last):
  File "C:\Users\ipharmacare\newreport\common\configReader.py", line 50, in getitems
    result=self.conf.items(field)
  File "C:\Users\ipharmacare\python27\lib\ConfigParser.py", line 642, in items
    raise NoSectionError(section)
NoSectionError: No section: 'ConfigurationItem_doc'
Wed, 14 Aug 2019 17:35:00 log.py[line:17] DEBUG 读取配置项发生了错误,doc_ddds
Wed, 14 Aug 2019 17:35:00 log.py[line:20] ERROR No section: 'doc_ddds'
Traceback (most recent call last):
  File "C:\Users\ipharmacare\newreport\common\configReader.py", line 50, in getitems
    result=self.conf.items(field)
  File "C:\Users\ipharmacare\python27\lib\ConfigParser.py", line 642, in items
    raise NoSectionError(section)
NoSectionError: No section: 'doc_ddds'
Wed, 14 Aug 2019 17:35:00 log.py[line:17] DEBUG 读取配置项发生了错误,hospitalDoc_ddds
Wed, 14 Aug 2019 17:35:00 log.py[line:20] ERROR No section: 'hospitalDoc_ddds'
Traceback (most recent call last):
  File "C:\Users\ipharmacare\newreport\common\configReader.py", line 50, in getitems
    result=self.conf.items(field)
  File "C:\Users\ipharmacare\python27\lib\ConfigParser.py", line 642, in items
    raise NoSectionError(section)
NoSectionError: No section: 'hospitalDoc_ddds'
Wed, 14 Aug 2019 17:35:00 log.py[line:17] DEBUG 读取配置项发生了错误,hospital_dept
Wed, 14 Aug 2019 17:35:00 log.py[line:20] ERROR No section: 'hospital_dept'
Traceback (most recent call last):
  File "C:\Users\ipharmacare\newreport\common\configReader.py", line 50, in getitems
    result=self.conf.items(field)
  File "C:\Users\ipharmacare\python27\lib\ConfigParser.py", line 642, in items
    raise NoSectionError(section)
NoSectionError: No section: 'hospital_dept'
Wed, 14 Aug 2019 17:35:00 log.py[line:17] DEBUG 读取配置项发生了错误,default_dept
Wed, 14 Aug 2019 17:35:00 log.py[line:20] ERROR No section: 'default_dept'
Traceback (most recent call last):
  File "C:\Users\ipharmacare\newreport\common\configReader.py", line 50, in getitems
    result=self.conf.items(field)
  File "C:\Users\ipharmacare\python27\lib\ConfigParser.py", line 642, in items
    raise NoSectionError(section)
NoSectionError: No section: 'default_dept'
Wed, 14 Aug 2019 17:35:00 log.py[line:17] DEBUG 读取配置项发生了错误,ConfigurationItem_dept
Wed, 14 Aug 2019 17:35:00 log.py[line:20] ERROR No section: 'ConfigurationItem_dept'
Traceback (most recent call last):
  File "C:\Users\ipharmacare\newreport\common\configReader.py", line 50, in getitems
    result=self.conf.items(field)
  File "C:\Users\ipharmacare\python27\lib\ConfigParser.py", line 642, in items
    raise NoSectionError(section)
NoSectionError: No section: 'ConfigurationItem_dept'
Wed, 14 Aug 2019 17:35:00 log.py[line:17] DEBUG 读取配置项发生了错误,dept_ddds
Wed, 14 Aug 2019 17:35:00 log.py[line:20] ERROR No section: 'dept_ddds'
Traceback (most recent call last):
  File "C:\Users\ipharmacare\newreport\common\configReader.py", line 50, in getitems
    result=self.conf.items(field)
  File "C:\Users\ipharmacare\python27\lib\ConfigParser.py", line 642, in items
    raise NoSectionError(section)
NoSectionError: No section: 'dept_ddds'
Wed, 14 Aug 2019 17:35:00 log.py[line:17] DEBUG 读取配置项发生了错误,hospitalDept_ddds
Wed, 14 Aug 2019 17:35:00 log.py[line:20] ERROR No section: 'hospitalDept_ddds'
Traceback (most recent call last):
  File "C:\Users\ipharmacare\newreport\common\configReader.py", line 50, in getitems
    result=self.conf.items(field)
  File "C:\Users\ipharmacare\python27\lib\ConfigParser.py", line 642, in items
    raise NoSectionError(section)
NoSectionError: No section: 'hospitalDept_ddds'
Wed, 14 Aug 2019 17:35:00 log.py[line:17] DEBUG 读取配置项发生了错误,default_group
Wed, 14 Aug 2019 17:35:00 log.py[line:20] ERROR No section: 'default_group'
Traceback (most recent call last):
  File "C:\Users\ipharmacare\newreport\common\configReader.py", line 50, in getitems
    result=self.conf.items(field)
  File "C:\Users\ipharmacare\python27\lib\ConfigParser.py", line 642, in items
    raise NoSectionError(section)
NoSectionError: No section: 'default_group'
Wed, 14 Aug 2019 17:35:00 log.py[line:17] DEBUG 该指标在指标库中不存在,使用抗菌药物出院患者中病原学检查送检人次占比(%)
Wed, 14 Aug 2019 17:35:00 connectionpool.py[line:205] DEBUG Starting new HTTP connection (1): 10.1.1.89:9999
Wed, 14 Aug 2019 17:35:00 connectionpool.py[line:393] DEBUG http://10.1.1.89:9999 "POST /syscenter/api/v1/currentUser HTTP/1.1" 200 None
Wed, 14 Aug 2019 17:35:01 connectionpool.py[line:393] DEBUG http://10.1.1.89:9999 "GET /syscenter/api/v1/config/selectSysConfig?showName=%E6%8A%97%E8%8F%8C%E8%8D%AF%E7%89%A9%E9%80%81%E6%A3%80%E6%A0%87%E8%AF%86 HTTP/1.1" 200 None
Wed, 14 Aug 2019 17:36:26 log.py[line:17] DEBUG 该指标在指标库中不存在,出院患者中抗菌药物治疗使用前病原学检查送检人次占比(%)
Wed, 14 Aug 2019 17:36:26 log.py[line:17] DEBUG 该指标在指标库中不存在,使用非限制级抗菌药物出院患者中病原学检查送检人次
Wed, 14 Aug 2019 17:36:26 log.py[line:17] DEBUG 该指标在指标库中不存在,使用非限制级抗菌药物出院患者中病原学检查送检人次占比(%)
Wed, 14 Aug 2019 17:36:26 log.py[line:17] DEBUG 该指标在指标库中不存在,使用限制级抗菌药物出院患者中病原学检查送检人次
Wed, 14 Aug 2019 17:36:26 log.py[line:17] DEBUG 该指标在指标库中不存在,使用限制级抗菌药物出院患者中病原学检查送检人次占比(%)
Wed, 14 Aug 2019 17:36:26 log.py[line:17] DEBUG 该指标在指标库中不存在,使用特殊级抗菌药物出院患者中病原学检查送检人次
Wed, 14 Aug 2019 17:36:26 log.py[line:17] DEBUG 该指标在指标库中不存在,使用特殊级抗菌药物出院患者中病原学检查送检人次占比(%)
Wed, 14 Aug 2019 17:44:20 log.py[line:17] DEBUG 该指标在指标库中不存在,门诊患者国家基药品种数占比(%)
Wed, 14 Aug 2019 17:48:54 log.py[line:17] DEBUG 该指标在指标库中不存在,门诊患者国家基药总金额占比(%)
Wed, 14 Aug 2019 17:49:08 log.py[line:17] DEBUG 该指标在指标库中不存在,门诊患者使用国家基药人次占比(%)
Wed, 14 Aug 2019 17:49:10 log.py[line:17] DEBUG 该指标在指标库中不存在,出院患者国家基药品种数占比(%)
Wed, 14 Aug 2019 17:49:20 log.py[line:17] DEBUG 该指标在指标库中不存在,出院患者国家基药总金额占比(%)
Wed, 14 Aug 2019 17:49:20 log.py[line:17] DEBUG 该指标在指标库中不存在,出院患者使用药物总金额
Wed, 14 Aug 2019 17:49:26 log.py[line:17] DEBUG 该指标在指标库中不存在,出院患者使用国家基药总人次占比(%)
Wed, 14 Aug 2019 17:49:26 log.py[line:17] DEBUG 该指标在指标库中不存在,门诊患者静脉输液使用量（瓶/袋）（≥14岁）
Wed, 14 Aug 2019 17:49:26 log.py[line:17] DEBUG 该指标在指标库中不存在,门诊患者静脉输液使用量（瓶/袋）（＜14岁）
Wed, 14 Aug 2019 17:49:26 log.py[line:17] DEBUG 该指标在指标库中不存在,门诊输液总人次
Wed, 14 Aug 2019 17:49:42 log.py[line:17] DEBUG 该指标在指标库中不存在,门诊输液人次占比(%)
Wed, 14 Aug 2019 17:49:42 log.py[line:17] DEBUG 该指标在指标库中不存在,门诊输液人次（≥14岁）占比(%)
Wed, 14 Aug 2019 17:49:42 log.py[line:17] DEBUG 该指标在指标库中不存在,门诊输液人次（＜14岁）占比(%)
Wed, 14 Aug 2019 17:49:42 log.py[line:17] DEBUG 该指标在指标库中不存在,出院患者静脉输液使用量（瓶/袋）（≥14岁）
Wed, 14 Aug 2019 17:49:42 log.py[line:17] DEBUG 该指标在指标库中不存在,出院患者静脉输液使用量（瓶/袋）（＜14岁）
Wed, 14 Aug 2019 19:28:08 log.py[line:17] DEBUG 读取配置项发生了错误,hospital_doc
Wed, 14 Aug 2019 19:28:08 log.py[line:20] ERROR No section: 'hospital_doc'
Traceback (most recent call last):
  File "C:\Users\ipharmacare\newreport\common\configReader.py", line 50, in getitems
    result=self.conf.items(field)
  File "C:\Users\ipharmacare\python27\lib\ConfigParser.py", line 642, in items
    raise NoSectionError(section)
NoSectionError: No section: 'hospital_doc'
Wed, 14 Aug 2019 19:28:08 log.py[line:17] DEBUG 读取配置项发生了错误,default_doc
Wed, 14 Aug 2019 19:28:08 log.py[line:20] ERROR No section: 'default_doc'
Traceback (most recent call last):
  File "C:\Users\ipharmacare\newreport\common\configReader.py", line 50, in getitems
    result=self.conf.items(field)
  File "C:\Users\ipharmacare\python27\lib\ConfigParser.py", line 642, in items
    raise NoSectionError(section)
NoSectionError: No section: 'default_doc'
Wed, 14 Aug 2019 19:28:08 log.py[line:17] DEBUG 读取配置项发生了错误,ConfigurationItem_doc
Wed, 14 Aug 2019 19:28:08 log.py[line:20] ERROR No section: 'ConfigurationItem_doc'
Traceback (most recent call last):
  File "C:\Users\ipharmacare\newreport\common\configReader.py", line 50, in getitems
    result=self.conf.items(field)
  File "C:\Users\ipharmacare\python27\lib\ConfigParser.py", line 642, in items
    raise NoSectionError(section)
NoSectionError: No section: 'ConfigurationItem_doc'
Wed, 14 Aug 2019 19:28:08 log.py[line:17] DEBUG 读取配置项发生了错误,doc_ddds
Wed, 14 Aug 2019 19:28:08 log.py[line:20] ERROR No section: 'doc_ddds'
Traceback (most recent call last):
  File "C:\Users\ipharmacare\newreport\common\configReader.py", line 50, in getitems
    result=self.conf.items(field)
  File "C:\Users\ipharmacare\python27\lib\ConfigParser.py", line 642, in items
    raise NoSectionError(section)
NoSectionError: No section: 'doc_ddds'
Wed, 14 Aug 2019 19:28:08 log.py[line:17] DEBUG 读取配置项发生了错误,hospitalDoc_ddds
Wed, 14 Aug 2019 19:28:08 log.py[line:20] ERROR No section: 'hospitalDoc_ddds'
Traceback (most recent call last):
  File "C:\Users\ipharmacare\newreport\common\configReader.py", line 50, in getitems
    result=self.conf.items(field)
  File "C:\Users\ipharmacare\python27\lib\ConfigParser.py", line 642, in items
    raise NoSectionError(section)
NoSectionError: No section: 'hospitalDoc_ddds'
Wed, 14 Aug 2019 19:28:08 log.py[line:17] DEBUG 读取配置项发生了错误,hospital_dept
Wed, 14 Aug 2019 19:28:08 log.py[line:20] ERROR No section: 'hospital_dept'
Traceback (most recent call last):
  File "C:\Users\ipharmacare\newreport\common\configReader.py", line 50, in getitems
    result=self.conf.items(field)
  File "C:\Users\ipharmacare\python27\lib\ConfigParser.py", line 642, in items
    raise NoSectionError(section)
NoSectionError: No section: 'hospital_dept'
Wed, 14 Aug 2019 19:28:08 log.py[line:17] DEBUG 读取配置项发生了错误,default_dept
Wed, 14 Aug 2019 19:28:08 log.py[line:20] ERROR No section: 'default_dept'
Traceback (most recent call last):
  File "C:\Users\ipharmacare\newreport\common\configReader.py", line 50, in getitems
    result=self.conf.items(field)
  File "C:\Users\ipharmacare\python27\lib\ConfigParser.py", line 642, in items
    raise NoSectionError(section)
NoSectionError: No section: 'default_dept'
Wed, 14 Aug 2019 19:28:08 log.py[line:17] DEBUG 读取配置项发生了错误,ConfigurationItem_dept
Wed, 14 Aug 2019 19:28:08 log.py[line:20] ERROR No section: 'ConfigurationItem_dept'
Traceback (most recent call last):
  File "C:\Users\ipharmacare\newreport\common\configReader.py", line 50, in getitems
    result=self.conf.items(field)
  File "C:\Users\ipharmacare\python27\lib\ConfigParser.py", line 642, in items
    raise NoSectionError(section)
NoSectionError: No section: 'ConfigurationItem_dept'
Wed, 14 Aug 2019 19:28:08 log.py[line:17] DEBUG 读取配置项发生了错误,dept_ddds
Wed, 14 Aug 2019 19:28:08 log.py[line:20] ERROR No section: 'dept_ddds'
Traceback (most recent call last):
  File "C:\Users\ipharmacare\newreport\common\configReader.py", line 50, in getitems
    result=self.conf.items(field)
  File "C:\Users\ipharmacare\python27\lib\ConfigParser.py", line 642, in items
    raise NoSectionError(section)
NoSectionError: No section: 'dept_ddds'
Wed, 14 Aug 2019 19:28:08 log.py[line:17] DEBUG 读取配置项发生了错误,hospitalDept_ddds
Wed, 14 Aug 2019 19:28:08 log.py[line:20] ERROR No section: 'hospitalDept_ddds'
Traceback (most recent call last):
  File "C:\Users\ipharmacare\newreport\common\configReader.py", line 50, in getitems
    result=self.conf.items(field)
  File "C:\Users\ipharmacare\python27\lib\ConfigParser.py", line 642, in items
    raise NoSectionError(section)
NoSectionError: No section: 'hospitalDept_ddds'
Wed, 14 Aug 2019 19:28:08 log.py[line:17] DEBUG 读取配置项发生了错误,default_group
Wed, 14 Aug 2019 19:28:08 log.py[line:20] ERROR No section: 'default_group'
Traceback (most recent call last):
  File "C:\Users\ipharmacare\newreport\common\configReader.py", line 50, in getitems
    result=self.conf.items(field)
  File "C:\Users\ipharmacare\python27\lib\ConfigParser.py", line 642, in items
    raise NoSectionError(section)
NoSectionError: No section: 'default_group'
Wed, 14 Aug 2019 19:28:08 log.py[line:17] DEBUG 该指标在指标库中不存在,使用抗菌药物出院患者中病原学检查送检人次占比(%)
Wed, 14 Aug 2019 19:28:08 connectionpool.py[line:205] DEBUG Starting new HTTP connection (1): 10.1.1.89:9999
Wed, 14 Aug 2019 19:28:08 connectionpool.py[line:393] DEBUG http://10.1.1.89:9999 "POST /syscenter/api/v1/currentUser HTTP/1.1" 200 None
Wed, 14 Aug 2019 19:28:08 connectionpool.py[line:393] DEBUG http://10.1.1.89:9999 "GET /syscenter/api/v1/config/selectSysConfig?showName=%E6%8A%97%E8%8F%8C%E8%8D%AF%E7%89%A9%E9%80%81%E6%A3%80%E6%A0%87%E8%AF%86 HTTP/1.1" 200 None
Wed, 14 Aug 2019 19:28:14 log.py[line:17] DEBUG 该指标在指标库中不存在,出院患者中抗菌药物治疗使用前病原学检查送检人次占比(%)
Wed, 14 Aug 2019 19:28:14 log.py[line:17] DEBUG 该指标在指标库中不存在,使用非限制级抗菌药物出院患者中病原学检查送检人次
Wed, 14 Aug 2019 19:28:14 log.py[line:17] DEBUG 该指标在指标库中不存在,使用非限制级抗菌药物出院患者中病原学检查送检人次占比(%)
Wed, 14 Aug 2019 19:28:14 log.py[line:17] DEBUG 该指标在指标库中不存在,使用限制级抗菌药物出院患者中病原学检查送检人次
Wed, 14 Aug 2019 19:28:14 log.py[line:17] DEBUG 该指标在指标库中不存在,使用限制级抗菌药物出院患者中病原学检查送检人次占比(%)
Wed, 14 Aug 2019 19:28:14 log.py[line:17] DEBUG 该指标在指标库中不存在,使用特殊级抗菌药物出院患者中病原学检查送检人次
Wed, 14 Aug 2019 19:28:14 log.py[line:17] DEBUG 该指标在指标库中不存在,使用特殊级抗菌药物出院患者中病原学检查送检人次占比(%)
Wed, 14 Aug 2019 19:34:46 log.py[line:17] DEBUG 该指标在指标库中不存在,门诊患者国家基药品种数占比(%)
Wed, 14 Aug 2019 19:39:08 log.py[line:17] DEBUG 该指标在指标库中不存在,门诊患者国家基药总金额占比(%)
Wed, 14 Aug 2019 19:39:08 log.py[line:17] DEBUG 该指标在指标库中不存在,门诊患者使用国家基药人次占比(%)
Wed, 14 Aug 2019 19:39:08 log.py[line:17] DEBUG 该指标在指标库中不存在,出院患者国家基药品种数占比(%)
Wed, 14 Aug 2019 19:39:08 log.py[line:17] DEBUG 该指标在指标库中不存在,出院患者国家基药总金额占比(%)
Wed, 14 Aug 2019 19:39:08 log.py[line:17] DEBUG 该指标在指标库中不存在,出院患者使用药物总金额
Wed, 14 Aug 2019 19:39:09 log.py[line:17] DEBUG 该指标在指标库中不存在,出院患者使用国家基药总人次占比(%)
Wed, 14 Aug 2019 19:39:09 log.py[line:17] DEBUG 该指标在指标库中不存在,门诊患者静脉输液使用量（瓶/袋）（≥14岁）
Wed, 14 Aug 2019 19:39:09 log.py[line:17] DEBUG 该指标在指标库中不存在,门诊患者静脉输液使用量（瓶/袋）（＜14岁）
Wed, 14 Aug 2019 19:39:09 log.py[line:17] DEBUG 该指标在指标库中不存在,门诊输液总人次
Wed, 14 Aug 2019 19:39:17 log.py[line:17] DEBUG 该指标在指标库中不存在,门诊输液人次占比(%)
Wed, 14 Aug 2019 19:39:17 log.py[line:17] DEBUG 该指标在指标库中不存在,门诊输液人次（≥14岁）占比(%)
Wed, 14 Aug 2019 19:39:17 log.py[line:17] DEBUG 该指标在指标库中不存在,门诊输液人次（＜14岁）占比(%)
Wed, 14 Aug 2019 19:39:17 log.py[line:17] DEBUG 该指标在指标库中不存在,出院患者静脉输液使用量（瓶/袋）（≥14岁）
Wed, 14 Aug 2019 19:39:17 log.py[line:17] DEBUG 该指标在指标库中不存在,出院患者静脉输液使用量（瓶/袋）（＜14岁）
Wed, 14 Aug 2019 20:37:53 log.py[line:17] DEBUG 该指标在指标库中不存在,出院患者抗菌药物输液总人次占比(%)
Thu, 15 Aug 2019 09:34:25 log.py[line:17] DEBUG 执行过程中出错
Thu, 15 Aug 2019 09:34:25 log.py[line:17] DEBUG 执行过程中出错
Thu, 15 Aug 2019 09:34:27 log.py[line:20] ERROR (2013, 'Lost connection to MySQL server during query')
Traceback (most recent call last):
  File "C:\Users\ipharmacare\newreport\GetSQLvalue\itemZoneValue.py", line 314, in getSqlValue_zone
    sqlValue = self.getValueInZone(itemname, zoneid, startT, endT)
  File "C:\Users\ipharmacare\newreport\GetSQLvalue\itemZoneValue.py", line 43, in getValueInZone
    sqlValue = self.conndb.executeSQL_zoneid_one(self.cur, self.sql, zoneid, startT, endT)
  File "C:\Users\ipharmacare\newreport\common\connectDB.py", line 49, in executeSQL_zoneid_one
    cur.execute(sql, (zoneid, startT, endT))
  File "C:\Users\ipharmacare\python27\lib\site-packages\MySQLdb\cursors.py", line 205, in execute
    self.errorhandler(self, exc, value)
  File "C:\Users\ipharmacare\python27\lib\site-packages\MySQLdb\connections.py", line 36, in defaulterrorhandler
    raise errorclass, errorvalue
OperationalError: (2013, 'Lost connection to MySQL server during query')
Thu, 15 Aug 2019 09:34:27 log.py[line:20] ERROR (2013, 'Lost connection to MySQL server during query')
Traceback (most recent call last):
  File "C:\Users\ipharmacare\newreport\GetSQLvalue\itemZoneValue.py", line 314, in getSqlValue_zone
    sqlValue = self.getValueInZone(itemname, zoneid, startT, endT)
  File "C:\Users\ipharmacare\newreport\GetSQLvalue\itemZoneValue.py", line 43, in getValueInZone
    sqlValue = self.conndb.executeSQL_zoneid_one(self.cur, self.sql, zoneid, startT, endT)
  File "C:\Users\ipharmacare\newreport\common\connectDB.py", line 49, in executeSQL_zoneid_one
    cur.execute(sql, (zoneid, startT, endT))
  File "C:\Users\ipharmacare\python27\lib\site-packages\MySQLdb\cursors.py", line 205, in execute
    self.errorhandler(self, exc, value)
  File "C:\Users\ipharmacare\python27\lib\site-packages\MySQLdb\connections.py", line 36, in defaulterrorhandler
    raise errorclass, errorvalue
OperationalError: (2013, 'Lost connection to MySQL server during query')
Thu, 15 Aug 2019 09:34:28 log.py[line:17] DEBUG 该指标在指标库中不存在,出院患者使用抗菌药物输液金额占比(%)
Thu, 15 Aug 2019 09:34:28 log.py[line:17] DEBUG 该指标在指标库中不存在,出院患者抗菌药物静脉输液使用量（瓶/袋）
Thu, 15 Aug 2019 09:34:28 log.py[line:17] DEBUG 该指标在指标库中不存在,出院患者抗菌药物静脉输液使用量（瓶/袋）占比(%)
Thu, 15 Aug 2019 09:34:28 log.py[line:17] DEBUG 执行过程中出错
Thu, 15 Aug 2019 09:34:28 log.py[line:17] DEBUG 该指标在指标库中不存在,出院患者静脉输液抗菌药物使用量（累计DDD数）
Thu, 15 Aug 2019 09:34:28 log.py[line:17] DEBUG 该指标在指标库中不存在,出院患者静脉输液总人次
Thu, 15 Aug 2019 09:34:28 log.py[line:20] ERROR (2006, 'MySQL server has gone away')
Traceback (most recent call last):
  File "C:\Users\ipharmacare\newreport\GetSQLvalue\itemZoneValue.py", line 314, in getSqlValue_zone
    sqlValue = self.getValueInZone(itemname, zoneid, startT, endT)
  File "C:\Users\ipharmacare\newreport\GetSQLvalue\itemZoneValue.py", line 43, in getValueInZone
    sqlValue = self.conndb.executeSQL_zoneid_one(self.cur, self.sql, zoneid, startT, endT)
  File "C:\Users\ipharmacare\newreport\common\connectDB.py", line 49, in executeSQL_zoneid_one
    cur.execute(sql, (zoneid, startT, endT))
  File "C:\Users\ipharmacare\python27\lib\site-packages\MySQLdb\cursors.py", line 205, in execute
    self.errorhandler(self, exc, value)
  File "C:\Users\ipharmacare\python27\lib\site-packages\MySQLdb\connections.py", line 36, in defaulterrorhandler
    raise errorclass, errorvalue
OperationalError: (2006, 'MySQL server has gone away')
Thu, 15 Aug 2019 09:34:28 log.py[line:17] DEBUG 该指标在指标库中不存在,出院患者抗菌药物输液总人次占比(%)
Thu, 15 Aug 2019 09:34:28 log.py[line:17] DEBUG 执行过程中出错
Thu, 15 Aug 2019 09:34:28 log.py[line:20] ERROR (2006, 'MySQL server has gone away')
Traceback (most recent call last):
  File "C:\Users\ipharmacare\newreport\GetSQLvalue\itemZoneValue.py", line 314, in getSqlValue_zone
    sqlValue = self.getValueInZone(itemname, zoneid, startT, endT)
  File "C:\Users\ipharmacare\newreport\GetSQLvalue\itemZoneValue.py", line 43, in getValueInZone
    sqlValue = self.conndb.executeSQL_zoneid_one(self.cur, self.sql, zoneid, startT, endT)
  File "C:\Users\ipharmacare\newreport\common\connectDB.py", line 49, in executeSQL_zoneid_one
    cur.execute(sql, (zoneid, startT, endT))
  File "C:\Users\ipharmacare\python27\lib\site-packages\MySQLdb\cursors.py", line 205, in execute
    self.errorhandler(self, exc, value)
  File "C:\Users\ipharmacare\python27\lib\site-packages\MySQLdb\connections.py", line 36, in defaulterrorhandler
    raise errorclass, errorvalue
OperationalError: (2006, 'MySQL server has gone away')
Thu, 15 Aug 2019 09:34:28 log.py[line:17] DEBUG 该指标在指标库中不存在,出院患者使用抗菌药物输液金额占比(%)
Thu, 15 Aug 2019 09:34:28 log.py[line:17] DEBUG 该指标在指标库中不存在,出院患者抗菌药物静脉输液使用量（瓶/袋）
Thu, 15 Aug 2019 09:34:28 log.py[line:17] DEBUG 该指标在指标库中不存在,出院患者抗菌药物静脉输液使用量（瓶/袋）占比(%)
Thu, 15 Aug 2019 09:34:28 log.py[line:17] DEBUG 该指标在指标库中不存在,出院患者静脉输液抗菌药物使用量（累计DDD数）
Thu, 15 Aug 2019 09:34:28 log.py[line:17] DEBUG 该指标在指标库中不存在,出院患者静脉输液总人次
Thu, 15 Aug 2019 09:34:28 log.py[line:17] DEBUG 该指标在指标库中不存在,出院患者使用特殊级抗菌药物输液金额
Thu, 15 Aug 2019 09:34:28 log.py[line:17] DEBUG 该指标在指标库中不存在,出院患者使用特殊级抗菌药物输液金额占比(%)
Thu, 15 Aug 2019 09:34:28 log.py[line:17] DEBUG 该指标在指标库中不存在,出院患者使用特殊级抗菌药物静脉输液使用量（瓶/袋)
Thu, 15 Aug 2019 09:34:28 log.py[line:17] DEBUG 该指标在指标库中不存在,出院患者使用特殊级抗菌药物静脉输液使用量（瓶/袋)占比(%)
Thu, 15 Aug 2019 09:34:28 log.py[line:17] DEBUG 该指标在指标库中不存在,出院患者静脉输液特殊级抗菌药物使用量（累计DDD数）
Thu, 15 Aug 2019 09:34:28 log.py[line:17] DEBUG 该指标在指标库中不存在,出院患者使用特殊级抗菌药物输液金额
Thu, 15 Aug 2019 09:34:28 log.py[line:17] DEBUG 该指标在指标库中不存在,出院患者使用特殊级抗菌药物输液金额占比(%)
Thu, 15 Aug 2019 09:34:28 log.py[line:17] DEBUG 该指标在指标库中不存在,出院患者使用特殊级抗菌药物静脉输液使用量（瓶/袋)
Thu, 15 Aug 2019 09:34:28 log.py[line:17] DEBUG 该指标在指标库中不存在,出院患者使用特殊级抗菌药物静脉输液使用量（瓶/袋)占比(%)
Thu, 15 Aug 2019 09:34:28 log.py[line:17] DEBUG 该指标在指标库中不存在,出院患者静脉输液特殊级抗菌药物使用量（累计DDD数）
Thu, 15 Aug 2019 09:34:28 log.py[line:17] DEBUG 执行过程中出错
Thu, 15 Aug 2019 09:34:28 log.py[line:17] DEBUG 执行过程中出错
Thu, 15 Aug 2019 09:34:28 log.py[line:20] ERROR (2006, 'MySQL server has gone away')
Traceback (most recent call last):
  File "C:\Users\ipharmacare\newreport\GetSQLvalue\itemZoneValue.py", line 324, in getSqlValue_zone
    sqlValue = self.getValueInCalc(itemname, zoneid, startT, endT, self.optcalcminus)
  File "C:\Users\ipharmacare\newreport\GetSQLvalue\itemZoneValue.py", line 114, in getValueInCalc
    self.itemvalue_one = self.getCalc_Numerator_zone(self.itemnameOne, zoneid, startT, endT, optcalcminus)
  File "C:\Users\ipharmacare\newreport\GetSQLvalue\itemZoneValue.py", line 218, in getCalc_Numerator_zone
    self.itemvalue_one = self.conndb.executeSQL_zoneid_one(self.cur, self.itemOneSql, zoneid, startT, endT)
  File "C:\Users\ipharmacare\newreport\common\connectDB.py", line 49, in executeSQL_zoneid_one
    cur.execute(sql, (zoneid, startT, endT))
  File "C:\Users\ipharmacare\python27\lib\site-packages\MySQLdb\cursors.py", line 205, in execute
    self.errorhandler(self, exc, value)
  File "C:\Users\ipharmacare\python27\lib\site-packages\MySQLdb\connections.py", line 36, in defaulterrorhandler
    raise errorclass, errorvalue
OperationalError: (2006, 'MySQL server has gone away')
Thu, 15 Aug 2019 09:34:28 log.py[line:17] DEBUG 执行过程中出错
Thu, 15 Aug 2019 09:34:28 log.py[line:20] ERROR (2006, 'MySQL server has gone away')
Traceback (most recent call last):
  File "C:\Users\ipharmacare\newreport\GetSQLvalue\itemZoneValue.py", line 324, in getSqlValue_zone
    sqlValue = self.getValueInCalc(itemname, zoneid, startT, endT, self.optcalcminus)
  File "C:\Users\ipharmacare\newreport\GetSQLvalue\itemZoneValue.py", line 114, in getValueInCalc
    self.itemvalue_one = self.getCalc_Numerator_zone(self.itemnameOne, zoneid, startT, endT, optcalcminus)
  File "C:\Users\ipharmacare\newreport\GetSQLvalue\itemZoneValue.py", line 218, in getCalc_Numerator_zone
    self.itemvalue_one = self.conndb.executeSQL_zoneid_one(self.cur, self.itemOneSql, zoneid, startT, endT)
  File "C:\Users\ipharmacare\newreport\common\connectDB.py", line 49, in executeSQL_zoneid_one
    cur.execute(sql, (zoneid, startT, endT))
  File "C:\Users\ipharmacare\python27\lib\site-packages\MySQLdb\cursors.py", line 205, in execute
    self.errorhandler(self, exc, value)
  File "C:\Users\ipharmacare\python27\lib\site-packages\MySQLdb\connections.py", line 36, in defaulterrorhandler
    raise errorclass, errorvalue
OperationalError: (2006, 'MySQL server has gone away')
Thu, 15 Aug 2019 09:34:28 log.py[line:17] DEBUG 读取配置项发生了错误,zone,门诊处方药品总金额
Thu, 15 Aug 2019 09:34:28 log.py[line:20] ERROR No option '\xe9\x97\xa8\xe8\xaf\x8a\xe5\xa4\x84\xe6\x96\xb9\xe8\x8d\xaf\xe5\x93\x81\xe6\x80\xbb\xe9\x87\x91\xe9\xa2\x9d' in section: 'zone'
Traceback (most recent call last):
  File "C:\Users\ipharmacare\newreport\common\configReader.py", line 27, in get
    return self.conf.get(field,key)
  File "C:\Users\ipharmacare\python27\lib\ConfigParser.py", line 618, in get
    raise NoOptionError(option, section)
NoOptionError: No option '\xe9\x97\xa8\xe8\xaf\x8a\xe5\xa4\x84\xe6\x96\xb9\xe8\x8d\xaf\xe5\x93\x81\xe6\x80\xbb\xe9\x87\x91\xe9\xa2\x9d' in section: 'zone'
Thu, 15 Aug 2019 09:34:28 log.py[line:17] DEBUG 执行过程中出错
Thu, 15 Aug 2019 09:34:28 log.py[line:20] ERROR unsupported operand type(s) for %: 'NoneType' and 'tuple'
Traceback (most recent call last):
  File "C:\Users\ipharmacare\newreport\GetSQLvalue\itemZoneValue.py", line 324, in getSqlValue_zone
    sqlValue = self.getValueInCalc(itemname, zoneid, startT, endT, self.optcalcminus)
  File "C:\Users\ipharmacare\newreport\GetSQLvalue\itemZoneValue.py", line 114, in getValueInCalc
    self.itemvalue_one = self.getCalc_Numerator_zone(self.itemnameOne, zoneid, startT, endT, optcalcminus)
  File "C:\Users\ipharmacare\newreport\GetSQLvalue\itemZoneValue.py", line 218, in getCalc_Numerator_zone
    self.itemvalue_one = self.conndb.executeSQL_zoneid_one(self.cur, self.itemOneSql, zoneid, startT, endT)
  File "C:\Users\ipharmacare\newreport\common\connectDB.py", line 49, in executeSQL_zoneid_one
    cur.execute(sql, (zoneid, startT, endT))
  File "C:\Users\ipharmacare\python27\lib\site-packages\MySQLdb\cursors.py", line 187, in execute
    query = query % tuple([db.literal(item) for item in args])
TypeError: unsupported operand type(s) for %: 'NoneType' and 'tuple'
Thu, 15 Aug 2019 09:34:28 log.py[line:17] DEBUG 读取配置项发生了错误,zone,(门诊处方药品总金额
Thu, 15 Aug 2019 09:34:28 log.py[line:20] ERROR No option '(\xe9\x97\xa8\xe8\xaf\x8a\xe5\xa4\x84\xe6\x96\xb9\xe8\x8d\xaf\xe5\x93\x81\xe6\x80\xbb\xe9\x87\x91\xe9\xa2\x9d' in section: 'zone'
Traceback (most recent call last):
  File "C:\Users\ipharmacare\newreport\common\configReader.py", line 27, in get
    return self.conf.get(field,key)
  File "C:\Users\ipharmacare\python27\lib\ConfigParser.py", line 618, in get
    raise NoOptionError(option, section)
NoOptionError: No option '(\xe9\x97\xa8\xe8\xaf\x8a\xe5\xa4\x84\xe6\x96\xb9\xe8\x8d\xaf\xe5\x93\x81\xe6\x80\xbb\xe9\x87\x91\xe9\xa2\x9d' in section: 'zone'
Thu, 15 Aug 2019 09:34:28 log.py[line:17] DEBUG 读取配置项发生了错误,zone,门诊患者使用中药饮片总金额)/(门诊处方总数
Thu, 15 Aug 2019 09:34:28 log.py[line:20] ERROR No option '\xe9\x97\xa8\xe8\xaf\x8a\xe6\x82\xa3\xe8\x80\x85\xe4\xbd\xbf\xe7\x94\xa8\xe4\xb8\xad\xe8\x8d\xaf\xe9\xa5\xae\xe7\x89\x87\xe6\x80\xbb\xe9\x87\x91\xe9\xa2\x9d)/(\xe9\x97\xa8\xe8\xaf\x8a\xe5\xa4\x84\xe6\x96\xb9\xe6\x80\xbb\xe6\x95\xb0' in section: 'zone'
Traceback (most recent call last):
  File "C:\Users\ipharmacare\newreport\common\configReader.py", line 27, in get
    return self.conf.get(field,key)
  File "C:\Users\ipharmacare\python27\lib\ConfigParser.py", line 618, in get
    raise NoOptionError(option, section)
NoOptionError: No option '\xe9\x97\xa8\xe8\xaf\x8a\xe6\x82\xa3\xe8\x80\x85\xe4\xbd\xbf\xe7\x94\xa8\xe4\xb8\xad\xe8\x8d\xaf\xe9\xa5\xae\xe7\x89\x87\xe6\x80\xbb\xe9\x87\x91\xe9\xa2\x9d)/(\xe9\x97\xa8\xe8\xaf\x8a\xe5\xa4\x84\xe6\x96\xb9\xe6\x80\xbb\xe6\x95\xb0' in section: 'zone'
Thu, 15 Aug 2019 09:34:28 log.py[line:17] DEBUG 指标计算时出错
Thu, 15 Aug 2019 09:34:28 log.py[line:20] ERROR unsupported operand type(s) for %: 'NoneType' and 'tuple'
Traceback (most recent call last):
  File "C:\Users\ipharmacare\newreport\GetSQLvalue\itemZoneValue.py", line 93, in getValueInCalcminus
    endT)
  File "C:\Users\ipharmacare\newreport\common\connectDB.py", line 49, in executeSQL_zoneid_one
    cur.execute(sql, (zoneid, startT, endT))
  File "C:\Users\ipharmacare\python27\lib\site-packages\MySQLdb\cursors.py", line 187, in execute
    query = query % tuple([db.literal(item) for item in args])
TypeError: unsupported operand type(s) for %: 'NoneType' and 'tuple'
Thu, 15 Aug 2019 09:34:28 log.py[line:17] DEBUG 读取配置项发生了错误,zone,门诊处方药品总金额
Thu, 15 Aug 2019 09:34:28 log.py[line:20] ERROR No option '\xe9\x97\xa8\xe8\xaf\x8a\xe5\xa4\x84\xe6\x96\xb9\xe8\x8d\xaf\xe5\x93\x81\xe6\x80\xbb\xe9\x87\x91\xe9\xa2\x9d' in section: 'zone'
Traceback (most recent call last):
  File "C:\Users\ipharmacare\newreport\common\configReader.py", line 27, in get
    return self.conf.get(field,key)
  File "C:\Users\ipharmacare\python27\lib\ConfigParser.py", line 618, in get
    raise NoOptionError(option, section)
NoOptionError: No option '\xe9\x97\xa8\xe8\xaf\x8a\xe5\xa4\x84\xe6\x96\xb9\xe8\x8d\xaf\xe5\x93\x81\xe6\x80\xbb\xe9\x87\x91\xe9\xa2\x9d' in section: 'zone'
Thu, 15 Aug 2019 09:34:28 log.py[line:17] DEBUG 执行过程中出错
Thu, 15 Aug 2019 09:34:28 log.py[line:20] ERROR unsupported operand type(s) for %: 'NoneType' and 'tuple'
Traceback (most recent call last):
  File "C:\Users\ipharmacare\newreport\GetSQLvalue\itemZoneValue.py", line 324, in getSqlValue_zone
    sqlValue = self.getValueInCalc(itemname, zoneid, startT, endT, self.optcalcminus)
  File "C:\Users\ipharmacare\newreport\GetSQLvalue\itemZoneValue.py", line 114, in getValueInCalc
    self.itemvalue_one = self.getCalc_Numerator_zone(self.itemnameOne, zoneid, startT, endT, optcalcminus)
  File "C:\Users\ipharmacare\newreport\GetSQLvalue\itemZoneValue.py", line 218, in getCalc_Numerator_zone
    self.itemvalue_one = self.conndb.executeSQL_zoneid_one(self.cur, self.itemOneSql, zoneid, startT, endT)
  File "C:\Users\ipharmacare\newreport\common\connectDB.py", line 49, in executeSQL_zoneid_one
    cur.execute(sql, (zoneid, startT, endT))
  File "C:\Users\ipharmacare\python27\lib\site-packages\MySQLdb\cursors.py", line 187, in execute
    query = query % tuple([db.literal(item) for item in args])
TypeError: unsupported operand type(s) for %: 'NoneType' and 'tuple'
Thu, 15 Aug 2019 09:34:28 log.py[line:20] ERROR (2006, 'MySQL server has gone away')
Traceback (most recent call last):
  File "C:\Users\ipharmacare\newreport\GetSQLvalue\itemZoneValue.py", line 324, in getSqlValue_zone
    sqlValue = self.getValueInCalc(itemname, zoneid, startT, endT, self.optcalcminus)
  File "C:\Users\ipharmacare\newreport\GetSQLvalue\itemZoneValue.py", line 114, in getValueInCalc
    self.itemvalue_one = self.getCalc_Numerator_zone(self.itemnameOne, zoneid, startT, endT, optcalcminus)
  File "C:\Users\ipharmacare\newreport\GetSQLvalue\itemZoneValue.py", line 218, in getCalc_Numerator_zone
    self.itemvalue_one = self.conndb.executeSQL_zoneid_one(self.cur, self.itemOneSql, zoneid, startT, endT)
  File "C:\Users\ipharmacare\newreport\common\connectDB.py", line 49, in executeSQL_zoneid_one
    cur.execute(sql, (zoneid, startT, endT))
  File "C:\Users\ipharmacare\python27\lib\site-packages\MySQLdb\cursors.py", line 205, in execute
    self.errorhandler(self, exc, value)
  File "C:\Users\ipharmacare\python27\lib\site-packages\MySQLdb\connections.py", line 36, in defaulterrorhandler
    raise errorclass, errorvalue
OperationalError: (2006, 'MySQL server has gone away')
Thu, 15 Aug 2019 09:34:28 log.py[line:17] DEBUG 执行过程中出错
Thu, 15 Aug 2019 09:34:28 log.py[line:20] ERROR (2006, 'MySQL server has gone away')
Traceback (most recent call last):
  File "C:\Users\ipharmacare\newreport\GetSQLvalue\itemZoneValue.py", line 324, in getSqlValue_zone
    sqlValue = self.getValueInCalc(itemname, zoneid, startT, endT, self.optcalcminus)
  File "C:\Users\ipharmacare\newreport\GetSQLvalue\itemZoneValue.py", line 114, in getValueInCalc
    self.itemvalue_one = self.getCalc_Numerator_zone(self.itemnameOne, zoneid, startT, endT, optcalcminus)
  File "C:\Users\ipharmacare\newreport\GetSQLvalue\itemZoneValue.py", line 218, in getCalc_Numerator_zone
    self.itemvalue_one = self.conndb.executeSQL_zoneid_one(self.cur, self.itemOneSql, zoneid, startT, endT)
  File "C:\Users\ipharmacare\newreport\common\connectDB.py", line 49, in executeSQL_zoneid_one
    cur.execute(sql, (zoneid, startT, endT))
  File "C:\Users\ipharmacare\python27\lib\site-packages\MySQLdb\cursors.py", line 205, in execute
    self.errorhandler(self, exc, value)
  File "C:\Users\ipharmacare\python27\lib\site-packages\MySQLdb\connections.py", line 36, in defaulterrorhandler
    raise errorclass, errorvalue
OperationalError: (2006, 'MySQL server has gone away')
Thu, 15 Aug 2019 09:34:28 log.py[line:17] DEBUG 读取配置项发生了错误,zone,门诊处方药品总金额
Thu, 15 Aug 2019 09:34:28 log.py[line:17] DEBUG 该指标在指标库中不存在,门诊处方总数（排除中药饮片）
Thu, 15 Aug 2019 09:34:28 log.py[line:17] DEBUG 该指标在指标库中不存在,门诊处方人次（排除中药饮片）
Thu, 15 Aug 2019 09:34:28 log.py[line:17] DEBUG 该指标在指标库中不存在,门诊处方人次
Thu, 15 Aug 2019 09:34:28 log.py[line:17] DEBUG 执行过程中出错
Thu, 15 Aug 2019 09:34:28 log.py[line:20] ERROR (2006, 'MySQL server has gone away')
Traceback (most recent call last):
  File "C:\Users\ipharmacare\newreport\GetSQLvalue\itemZoneValue.py", line 314, in getSqlValue_zone
    sqlValue = self.getValueInZone(itemname, zoneid, startT, endT)
  File "C:\Users\ipharmacare\newreport\GetSQLvalue\itemZoneValue.py", line 43, in getValueInZone
    sqlValue = self.conndb.executeSQL_zoneid_one(self.cur, self.sql, zoneid, startT, endT)
  File "C:\Users\ipharmacare\newreport\common\connectDB.py", line 49, in executeSQL_zoneid_one
    cur.execute(sql, (zoneid, startT, endT))
  File "C:\Users\ipharmacare\python27\lib\site-packages\MySQLdb\cursors.py", line 205, in execute
    self.errorhandler(self, exc, value)
  File "C:\Users\ipharmacare\python27\lib\site-packages\MySQLdb\connections.py", line 36, in defaulterrorhandler
    raise errorclass, errorvalue
OperationalError: (2006, 'MySQL server has gone away')
Thu, 15 Aug 2019 09:34:28 log.py[line:17] DEBUG 该指标在指标库中不存在,门诊中药饮片处方人次
Thu, 15 Aug 2019 09:34:28 log.py[line:17] DEBUG 执行过程中出错
Thu, 15 Aug 2019 09:34:28 log.py[line:20] ERROR (2006, 'MySQL server has gone away')
Traceback (most recent call last):
  File "C:\Users\ipharmacare\newreport\GetSQLvalue\itemZoneValue.py", line 324, in getSqlValue_zone
    sqlValue = self.getValueInCalc(itemname, zoneid, startT, endT, self.optcalcminus)
  File "C:\Users\ipharmacare\newreport\GetSQLvalue\itemZoneValue.py", line 114, in getValueInCalc
    self.itemvalue_one = self.getCalc_Numerator_zone(self.itemnameOne, zoneid, startT, endT, optcalcminus)
  File "C:\Users\ipharmacare\newreport\GetSQLvalue\itemZoneValue.py", line 218, in getCalc_Numerator_zone
    self.itemvalue_one = self.conndb.executeSQL_zoneid_one(self.cur, self.itemOneSql, zoneid, startT, endT)
  File "C:\Users\ipharmacare\newreport\common\connectDB.py", line 49, in executeSQL_zoneid_one
    cur.execute(sql, (zoneid, startT, endT))
  File "C:\Users\ipharmacare\python27\lib\site-packages\MySQLdb\cursors.py", line 205, in execute
    self.errorhandler(self, exc, value)
  File "C:\Users\ipharmacare\python27\lib\site-packages\MySQLdb\connections.py", line 36, in defaulterrorhandler
    raise errorclass, errorvalue
OperationalError: (2006, 'MySQL server has gone away')
Thu, 15 Aug 2019 09:34:28 log.py[line:17] DEBUG 读取配置项发生了错误,zone,(门诊处方药品总金额
Thu, 15 Aug 2019 09:34:28 log.py[line:20] ERROR No option '(\xe9\x97\xa8\xe8\xaf\x8a\xe5\xa4\x84\xe6\x96\xb9\xe8\x8d\xaf\xe5\x93\x81\xe6\x80\xbb\xe9\x87\x91\xe9\xa2\x9d' in section: 'zone'
Traceback (most recent call last):
  File "C:\Users\ipharmacare\newreport\common\configReader.py", line 27, in get
    return self.conf.get(field,key)
  File "C:\Users\ipharmacare\python27\lib\ConfigParser.py", line 618, in get
    raise NoOptionError(option, section)
NoOptionError: No option '(\xe9\x97\xa8\xe8\xaf\x8a\xe5\xa4\x84\xe6\x96\xb9\xe8\x8d\xaf\xe5\x93\x81\xe6\x80\xbb\xe9\x87\x91\xe9\xa2\x9d' in section: 'zone'
Thu, 15 Aug 2019 09:34:28 log.py[line:17] DEBUG 读取配置项发生了错误,zone,门诊患者使用中药饮片总金额)/门诊处方人次（排除中药饮片）
Thu, 15 Aug 2019 09:34:28 log.py[line:20] ERROR No option '\xe9\x97\xa8\xe8\xaf\x8a\xe6\x82\xa3\xe8\x80\x85\xe4\xbd\xbf\xe7\x94\xa8\xe4\xb8\xad\xe8\x8d\xaf\xe9\xa5\xae\xe7\x89\x87\xe6\x80\xbb\xe9\x87\x91\xe9\xa2\x9d)/\xe9\x97\xa8\xe8\xaf\x8a\xe5\xa4\x84\xe6\x96\xb9\xe4\xba\xba\xe6\xac\xa1\xef\xbc\x88\xe6\x8e\x92\xe9\x99\xa4\xe4\xb8\xad\xe8\x8d\xaf\xe9\xa5\xae\xe7\x89\x87\xef\xbc\x89' in section: 'zone'
Traceback (most recent call last):
  File "C:\Users\ipharmacare\newreport\common\configReader.py", line 27, in get
    return self.conf.get(field,key)
  File "C:\Users\ipharmacare\python27\lib\ConfigParser.py", line 618, in get
    raise NoOptionError(option, section)
NoOptionError: No option '\xe9\x97\xa8\xe8\xaf\x8a\xe6\x82\xa3\xe8\x80\x85\xe4\xbd\xbf\xe7\x94\xa8\xe4\xb8\xad\xe8\x8d\xaf\xe9\xa5\xae\xe7\x89\x87\xe6\x80\xbb\xe9\x87\x91\xe9\xa2\x9d)/\xe9\x97\xa8\xe8\xaf\x8a\xe5\xa4\x84\xe6\x96\xb9\xe4\xba\xba\xe6\xac\xa1\xef\xbc\x88\xe6\x8e\x92\xe9\x99\xa4\xe4\xb8\xad\xe8\x8d\xaf\xe9\xa5\xae\xe7\x89\x87\xef\xbc\x89' in section: 'zone'
Thu, 15 Aug 2019 09:34:28 log.py[line:17] DEBUG 指标计算时出错
Thu, 15 Aug 2019 09:34:28 log.py[line:20] ERROR unsupported operand type(s) for %: 'NoneType' and 'tuple'
Traceback (most recent call last):
  File "C:\Users\ipharmacare\newreport\GetSQLvalue\itemZoneValue.py", line 93, in getValueInCalcminus
    endT)
  File "C:\Users\ipharmacare\newreport\common\connectDB.py", line 49, in executeSQL_zoneid_one
    cur.execute(sql, (zoneid, startT, endT))
  File "C:\Users\ipharmacare\python27\lib\site-packages\MySQLdb\cursors.py", line 187, in execute
    query = query % tuple([db.literal(item) for item in args])
TypeError: unsupported operand type(s) for %: 'NoneType' and 'tuple'
Thu, 15 Aug 2019 09:34:28 log.py[line:17] DEBUG 执行过程中出错
Thu, 15 Aug 2019 09:34:28 log.py[line:20] ERROR (2006, 'MySQL server has gone away')
Traceback (most recent call last):
  File "C:\Users\ipharmacare\newreport\GetSQLvalue\itemZoneValue.py", line 324, in getSqlValue_zone
    sqlValue = self.getValueInCalc(itemname, zoneid, startT, endT, self.optcalcminus)
  File "C:\Users\ipharmacare\newreport\GetSQLvalue\itemZoneValue.py", line 114, in getValueInCalc
    self.itemvalue_one = self.getCalc_Numerator_zone(self.itemnameOne, zoneid, startT, endT, optcalcminus)
  File "C:\Users\ipharmacare\newreport\GetSQLvalue\itemZoneValue.py", line 218, in getCalc_Numerator_zone
    self.itemvalue_one = self.conndb.executeSQL_zoneid_one(self.cur, self.itemOneSql, zoneid, startT, endT)
  File "C:\Users\ipharmacare\newreport\common\connectDB.py", line 49, in executeSQL_zoneid_one
    cur.execute(sql, (zoneid, startT, endT))
  File "C:\Users\ipharmacare\python27\lib\site-packages\MySQLdb\cursors.py", line 205, in execute
    self.errorhandler(self, exc, value)
  File "C:\Users\ipharmacare\python27\lib\site-packages\MySQLdb\connections.py", line 36, in defaulterrorhandler
    raise errorclass, errorvalue
OperationalError: (2006, 'MySQL server has gone away')
Thu, 15 Aug 2019 09:34:28 log.py[line:17] DEBUG 执行过程中出错
Thu, 15 Aug 2019 09:34:28 log.py[line:20] ERROR (2006, 'MySQL server has gone away')
Traceback (most recent call last):
  File "C:\Users\ipharmacare\newreport\GetSQLvalue\itemZoneValue.py", line 314, in getSqlValue_zone
    sqlValue = self.getValueInZone(itemname, zoneid, startT, endT)
  File "C:\Users\ipharmacare\newreport\GetSQLvalue\itemZoneValue.py", line 43, in getValueInZone
    sqlValue = self.conndb.executeSQL_zoneid_one(self.cur, self.sql, zoneid, startT, endT)
  File "C:\Users\ipharmacare\newreport\common\connectDB.py", line 49, in executeSQL_zoneid_one
    cur.execute(sql, (zoneid, startT, endT))
  File "C:\Users\ipharmacare\python27\lib\site-packages\MySQLdb\cursors.py", line 205, in execute
    self.errorhandler(self, exc, value)
  File "C:\Users\ipharmacare\python27\lib\site-packages\MySQLdb\connections.py", line 36, in defaulterrorhandler
    raise errorclass, errorvalue
OperationalError: (2006, 'MySQL server has gone away')
Thu, 15 Aug 2019 09:34:28 log.py[line:17] DEBUG 执行过程中出错
Thu, 15 Aug 2019 09:34:28 log.py[line:20] ERROR No option '\xe9\x97\xa8\xe8\xaf\x8a\xe5\xa4\x84\xe6\x96\xb9\xe8\x8d\xaf\xe5\x93\x81\xe6\x80\xbb\xe9\x87\x91\xe9\xa2\x9d' in section: 'zone'
Traceback (most recent call last):
  File "C:\Users\ipharmacare\newreport\common\configReader.py", line 27, in get
    return self.conf.get(field,key)
  File "C:\Users\ipharmacare\python27\lib\ConfigParser.py", line 618, in get
    raise NoOptionError(option, section)
NoOptionError: No option '\xe9\x97\xa8\xe8\xaf\x8a\xe5\xa4\x84\xe6\x96\xb9\xe8\x8d\xaf\xe5\x93\x81\xe6\x80\xbb\xe9\x87\x91\xe9\xa2\x9d' in section: 'zone'
Thu, 15 Aug 2019 09:34:28 log.py[line:17] DEBUG 执行过程中出错
Thu, 15 Aug 2019 09:34:28 log.py[line:20] ERROR unsupported operand type(s) for %: 'NoneType' and 'tuple'
Traceback (most recent call last):
  File "C:\Users\ipharmacare\newreport\GetSQLvalue\itemZoneValue.py", line 324, in getSqlValue_zone
    sqlValue = self.getValueInCalc(itemname, zoneid, startT, endT, self.optcalcminus)
  File "C:\Users\ipharmacare\newreport\GetSQLvalue\itemZoneValue.py", line 114, in getValueInCalc
    self.itemvalue_one = self.getCalc_Numerator_zone(self.itemnameOne, zoneid, startT, endT, optcalcminus)
  File "C:\Users\ipharmacare\newreport\GetSQLvalue\itemZoneValue.py", line 218, in getCalc_Numerator_zone
    self.itemvalue_one = self.conndb.executeSQL_zoneid_one(self.cur, self.itemOneSql, zoneid, startT, endT)
  File "C:\Users\ipharmacare\newreport\common\connectDB.py", line 49, in executeSQL_zoneid_one
    cur.execute(sql, (zoneid, startT, endT))
  File "C:\Users\ipharmacare\python27\lib\site-packages\MySQLdb\cursors.py", line 187, in execute
    query = query % tuple([db.literal(item) for item in args])
TypeError: unsupported operand type(s) for %: 'NoneType' and 'tuple'
Thu, 15 Aug 2019 09:34:29 log.py[line:17] DEBUG 读取配置项发生了错误,zone,(门诊处方药品总金额
Thu, 15 Aug 2019 09:34:29 log.py[line:20] ERROR No option '(\xe9\x97\xa8\xe8\xaf\x8a\xe5\xa4\x84\xe6\x96\xb9\xe8\x8d\xaf\xe5\x93\x81\xe6\x80\xbb\xe9\x87\x91\xe9\xa2\x9d' in section: 'zone'
Traceback (most recent call last):
  File "C:\Users\ipharmacare\newreport\common\configReader.py", line 27, in get
    return self.conf.get(field,key)
  File "C:\Users\ipharmacare\python27\lib\ConfigParser.py", line 618, in get
    raise NoOptionError(option, section)
NoOptionError: No option '(\xe9\x97\xa8\xe8\xaf\x8a\xe5\xa4\x84\xe6\x96\xb9\xe8\x8d\xaf\xe5\x93\x81\xe6\x80\xbb\xe9\x87\x91\xe9\xa2\x9d' in section: 'zone'
Thu, 15 Aug 2019 09:34:29 log.py[line:17] DEBUG 读取配置项发生了错误,zone,门诊患者使用中药饮片总金额)/(门诊处方总数
Thu, 15 Aug 2019 09:34:29 log.py[line:20] ERROR No option '\xe9\x97\xa8\xe8\xaf\x8a\xe6\x82\xa3\xe8\x80\x85\xe4\xbd\xbf\xe7\x94\xa8\xe4\xb8\xad\xe8\x8d\xaf\xe9\xa5\xae\xe7\x89\x87\xe6\x80\xbb\xe9\x87\x91\xe9\xa2\x9d)/(\xe9\x97\xa8\xe8\xaf\x8a\xe5\xa4\x84\xe6\x96\xb9\xe6\x80\xbb\xe6\x95\xb0' in section: 'zone'
Traceback (most recent call last):
  File "C:\Users\ipharmacare\newreport\common\configReader.py", line 27, in get
    return self.conf.get(field,key)
  File "C:\Users\ipharmacare\python27\lib\ConfigParser.py", line 618, in get
    raise NoOptionError(option, section)
NoOptionError: No option '\xe9\x97\xa8\xe8\xaf\x8a\xe6\x82\xa3\xe8\x80\x85\xe4\xbd\xbf\xe7\x94\xa8\xe4\xb8\xad\xe8\x8d\xaf\xe9\xa5\xae\xe7\x89\x87\xe6\x80\xbb\xe9\x87\x91\xe9\xa2\x9d)/(\xe9\x97\xa8\xe8\xaf\x8a\xe5\xa4\x84\xe6\x96\xb9\xe6\x80\xbb\xe6\x95\xb0' in section: 'zone'
Thu, 15 Aug 2019 09:34:29 log.py[line:17] DEBUG 指标计算时出错
Thu, 15 Aug 2019 09:34:29 log.py[line:20] ERROR unsupported operand type(s) for %: 'NoneType' and 'tuple'
Traceback (most recent call last):
  File "C:\Users\ipharmacare\newreport\GetSQLvalue\itemZoneValue.py", line 93, in getValueInCalcminus
    endT)
  File "C:\Users\ipharmacare\newreport\common\connectDB.py", line 49, in executeSQL_zoneid_one
    cur.execute(sql, (zoneid, startT, endT))
  File "C:\Users\ipharmacare\python27\lib\site-packages\MySQLdb\cursors.py", line 187, in execute
    query = query % tuple([db.literal(item) for item in args])
TypeError: unsupported operand type(s) for %: 'NoneType' and 'tuple'
Thu, 15 Aug 2019 09:34:29 log.py[line:17] DEBUG 读取配置项发生了错误,zone,门诊处方药品总金额
Thu, 15 Aug 2019 09:34:29 log.py[line:20] ERROR No option '\xe9\x97\xa8\xe8\xaf\x8a\xe5\xa4\x84\xe6\x96\xb9\xe8\x8d\xaf\xe5\x93\x81\xe6\x80\xbb\xe9\x87\x91\xe9\xa2\x9d' in section: 'zone'
Traceback (most recent call last):
  File "C:\Users\ipharmacare\newreport\common\configReader.py", line 27, in get
    return self.conf.get(field,key)
  File "C:\Users\ipharmacare\python27\lib\ConfigParser.py", line 618, in get
    raise NoOptionError(option, section)
NoOptionError: No option '\xe9\x97\xa8\xe8\xaf\x8a\xe5\xa4\x84\xe6\x96\xb9\xe8\x8d\xaf\xe5\x93\x81\xe6\x80\xbb\xe9\x87\x91\xe9\xa2\x9d' in section: 'zone'
Thu, 15 Aug 2019 09:34:29 log.py[line:17] DEBUG 执行过程中出错
Thu, 15 Aug 2019 09:34:28 log.py[line:20] ERROR (2006, 'MySQL server has gone away')
Traceback (most recent call last):
  File "C:\Users\ipharmacare\newreport\GetSQLvalue\itemZoneValue.py", line 314, in getSqlValue_zone
    sqlValue = self.getValueInZone(itemname, zoneid, startT, endT)
  File "C:\Users\ipharmacare\newreport\GetSQLvalue\itemZoneValue.py", line 43, in getValueInZone
    sqlValue = self.conndb.executeSQL_zoneid_one(self.cur, self.sql, zoneid, startT, endT)
  File "C:\Users\ipharmacare\newreport\common\connectDB.py", line 49, in executeSQL_zoneid_one
    cur.execute(sql, (zoneid, startT, endT))
  File "C:\Users\ipharmacare\python27\lib\site-packages\MySQLdb\cursors.py", line 205, in execute
    self.errorhandler(self, exc, value)
  File "C:\Users\ipharmacare\python27\lib\site-packages\MySQLdb\connections.py", line 36, in defaulterrorhandler
    raise errorclass, errorvalue
OperationalError: (2006, 'MySQL server has gone away')
Thu, 15 Aug 2019 09:34:29 log.py[line:17] DEBUG 执行过程中出错
Thu, 15 Aug 2019 09:34:29 log.py[line:20] ERROR (2006, 'MySQL server has gone away')
Traceback (most recent call last):
  File "C:\Users\ipharmacare\newreport\GetSQLvalue\itemZoneValue.py", line 324, in getSqlValue_zone
    sqlValue = self.getValueInCalc(itemname, zoneid, startT, endT, self.optcalcminus)
  File "C:\Users\ipharmacare\newreport\GetSQLvalue\itemZoneValue.py", line 114, in getValueInCalc
    self.itemvalue_one = self.getCalc_Numerator_zone(self.itemnameOne, zoneid, startT, endT, optcalcminus)
  File "C:\Users\ipharmacare\newreport\GetSQLvalue\itemZoneValue.py", line 218, in getCalc_Numerator_zone
    self.itemvalue_one = self.conndb.executeSQL_zoneid_one(self.cur, self.itemOneSql, zoneid, startT, endT)
  File "C:\Users\ipharmacare\newreport\common\connectDB.py", line 49, in executeSQL_zoneid_one
    cur.execute(sql, (zoneid, startT, endT))
  File "C:\Users\ipharmacare\python27\lib\site-packages\MySQLdb\cursors.py", line 205, in execute
    self.errorhandler(self, exc, value)
  File "C:\Users\ipharmacare\python27\lib\site-packages\MySQLdb\connections.py", line 36, in defaulterrorhandler
    raise errorclass, errorvalue
OperationalError: (2006, 'MySQL server has gone away')
Thu, 15 Aug 2019 09:34:29 log.py[line:17] DEBUG 执行过程中出错
Thu, 15 Aug 2019 09:34:29 log.py[line:20] ERROR (2006, 'MySQL server has gone away')
Traceback (most recent call last):
  File "C:\Users\ipharmacare\newreport\GetSQLvalue\itemZoneValue.py", line 324, in getSqlValue_zone
    sqlValue = self.getValueInCalc(itemname, zoneid, startT, endT, self.optcalcminus)
  File "C:\Users\ipharmacare\newreport\GetSQLvalue\itemZoneValue.py", line 114, in getValueInCalc
    self.itemvalue_one = self.getCalc_Numerator_zone(self.itemnameOne, zoneid, startT, endT, optcalcminus)
  File "C:\Users\ipharmacare\newreport\GetSQLvalue\itemZoneValue.py", line 218, in getCalc_Numerator_zone
    self.itemvalue_one = self.conndb.executeSQL_zoneid_one(self.cur, self.itemOneSql, zoneid, startT, endT)
  File "C:\Users\ipharmacare\newreport\common\connectDB.py", line 49, in executeSQL_zoneid_one
    cur.execute(sql, (zoneid, startT, endT))
  File "C:\Users\ipharmacare\python27\lib\site-packages\MySQLdb\cursors.py", line 205, in execute
    self.errorhandler(self, exc, value)
  File "C:\Users\ipharmacare\python27\lib\site-packages\MySQLdb\connections.py", line 36, in defaulterrorhandler
    raise errorclass, errorvalue
OperationalError: (2006, 'MySQL server has gone away')
Thu, 15 Aug 2019 09:34:29 log.py[line:17] DEBUG 该指标在指标库中不存在,出院患者使用中药饮片人次数占比(%)
Thu, 15 Aug 2019 09:34:29 log.py[line:17] DEBUG 该指标在指标库中不存在,出院患者使用中药饮片总金额占比(%)
Thu, 15 Aug 2019 09:34:29 log.py[line:17] DEBUG 该指标在指标库中不存在,出院患者总人次（排除中药饮片）
Thu, 15 Aug 2019 09:34:29 log.py[line:17] DEBUG 该指标在指标库中不存在,出院患者用药总金额（排除中药饮片）
Thu, 15 Aug 2019 09:34:29 log.py[line:17] DEBUG 该指标在指标库中不存在,门急诊处方人次
Thu, 15 Aug 2019 09:34:29 log.py[line:17] DEBUG 执行过程中出错
Thu, 15 Aug 2019 09:34:29 log.py[line:20] ERROR (2006, 'MySQL server has gone away')
Traceback (most recent call last):
  File "C:\Users\ipharmacare\newreport\GetSQLvalue\itemZoneValue.py", line 314, in getSqlValue_zone
    sqlValue = self.getValueInZone(itemname, zoneid, startT, endT)
  File "C:\Users\ipharmacare\newreport\GetSQLvalue\itemZoneValue.py", line 43, in getValueInZone
    sqlValue = self.conndb.executeSQL_zoneid_one(self.cur, self.sql, zoneid, startT, endT)
  File "C:\Users\ipharmacare\newreport\common\connectDB.py", line 49, in executeSQL_zoneid_one
    cur.execute(sql, (zoneid, startT, endT))
  File "C:\Users\ipharmacare\python27\lib\site-packages\MySQLdb\cursors.py", line 205, in execute
    self.errorhandler(self, exc, value)
  File "C:\Users\ipharmacare\python27\lib\site-packages\MySQLdb\connections.py", line 36, in defaulterrorhandler
    raise errorclass, errorvalue
OperationalError: (2006, 'MySQL server has gone away')
Thu, 15 Aug 2019 09:34:29 log.py[line:17] DEBUG 执行过程中出错
Thu, 15 Aug 2019 09:34:29 log.py[line:20] ERROR (2006, 'MySQL server has gone away')
Traceback (most recent call last):
  File "C:\Users\ipharmacare\newreport\GetSQLvalue\itemZoneValue.py", line 314, in getSqlValue_zone
    sqlValue = self.getValueInZone(itemname, zoneid, startT, endT)
  File "C:\Users\ipharmacare\newreport\GetSQLvalue\itemZoneValue.py", line 43, in getValueInZone
    sqlValue = self.conndb.executeSQL_zoneid_one(self.cur, self.sql, zoneid, startT, endT)
  File "C:\Users\ipharmacare\newreport\common\connectDB.py", line 49, in executeSQL_zoneid_one
    cur.execute(sql, (zoneid, startT, endT))
  File "C:\Users\ipharmacare\python27\lib\site-packages\MySQLdb\cursors.py", line 205, in execute
    self.errorhandler(self, exc, value)
  File "C:\Users\ipharmacare\python27\lib\site-packages\MySQLdb\connections.py", line 36, in defaulterrorhandler
    raise errorclass, errorvalue
OperationalError: (2006, 'MySQL server has gone away')
Thu, 15 Aug 2019 09:34:29 log.py[line:17] DEBUG 执行过程中出错
Thu, 15 Aug 2019 09:34:29 log.py[line:20] ERROR (2006, 'MySQL server has gone away')
Traceback (most recent call last):
  File "C:\Users\ipharmacare\newreport\GetSQLvalue\itemZoneValue.py", line 314, in getSqlValue_zone
    sqlValue = self.getValueInZone(itemname, zoneid, startT, endT)
  File "C:\Users\ipharmacare\newreport\GetSQLvalue\itemZoneValue.py", line 43, in getValueInZone
    sqlValue = self.conndb.executeSQL_zoneid_one(self.cur, self.sql, zoneid, startT, endT)
  File "C:\Users\ipharmacare\newreport\common\connectDB.py", line 49, in executeSQL_zoneid_one
    cur.execute(sql, (zoneid, startT, endT))
  File "C:\Users\ipharmacare\python27\lib\site-packages\MySQLdb\cursors.py", line 205, in execute
    self.errorhandler(self, exc, value)
  File "C:\Users\ipharmacare\python27\lib\site-packages\MySQLdb\connections.py", line 36, in defaulterrorhandler
    raise errorclass, errorvalue
OperationalError: (2006, 'MySQL server has gone away')
Thu, 15 Aug 2019 09:34:29 log.py[line:17] DEBUG 执行过程中出错
Thu, 15 Aug 2019 09:34:29 log.py[line:20] ERROR unsupported operand type(s) for %: 'NoneType' and 'tuple'
Traceback (most recent call last):
  File "C:\Users\ipharmacare\newreport\GetSQLvalue\itemZoneValue.py", line 324, in getSqlValue_zone
    sqlValue = self.getValueInCalc(itemname, zoneid, startT, endT, self.optcalcminus)
  File "C:\Users\ipharmacare\newreport\GetSQLvalue\itemZoneValue.py", line 114, in getValueInCalc
    self.itemvalue_one = self.getCalc_Numerator_zone(self.itemnameOne, zoneid, startT, endT, optcalcminus)
  File "C:\Users\ipharmacare\newreport\GetSQLvalue\itemZoneValue.py", line 218, in getCalc_Numerator_zone
    self.itemvalue_one = self.conndb.executeSQL_zoneid_one(self.cur, self.itemOneSql, zoneid, startT, endT)
  File "C:\Users\ipharmacare\newreport\common\connectDB.py", line 49, in executeSQL_zoneid_one
    cur.execute(sql, (zoneid, startT, endT))
  File "C:\Users\ipharmacare\python27\lib\site-packages\MySQLdb\cursors.py", line 187, in execute
    query = query % tuple([db.literal(item) for item in args])
TypeError: unsupported operand type(s) for %: 'NoneType' and 'tuple'
Thu, 15 Aug 2019 09:34:29 log.py[line:17] DEBUG 该指标在指标库中不存在,门诊处方总数（排除中药饮片）
Thu, 15 Aug 2019 09:34:29 log.py[line:17] DEBUG 该指标在指标库中不存在,门诊处方人次（排除中药饮片）
Thu, 15 Aug 2019 09:34:29 log.py[line:17] DEBUG 该指标在指标库中不存在,门诊处方人次
Thu, 15 Aug 2019 09:34:29 log.py[line:17] DEBUG 执行过程中出错
Thu, 15 Aug 2019 09:34:29 log.py[line:20] ERROR (2006, 'MySQL server has gone away')
Traceback (most recent call last):
  File "C:\Users\ipharmacare\newreport\GetSQLvalue\itemZoneValue.py", line 314, in getSqlValue_zone
    sqlValue = self.getValueInZone(itemname, zoneid, startT, endT)
  File "C:\Users\ipharmacare\newreport\GetSQLvalue\itemZoneValue.py", line 43, in getValueInZone
    sqlValue = self.conndb.executeSQL_zoneid_one(self.cur, self.sql, zoneid, startT, endT)
  File "C:\Users\ipharmacare\newreport\common\connectDB.py", line 49, in executeSQL_zoneid_one
    cur.execute(sql, (zoneid, startT, endT))
  File "C:\Users\ipharmacare\python27\lib\site-packages\MySQLdb\cursors.py", line 205, in execute
    self.errorhandler(self, exc, value)
  File "C:\Users\ipharmacare\python27\lib\site-packages\MySQLdb\connections.py", line 36, in defaulterrorhandler
    raise errorclass, errorvalue
OperationalError: (2006, 'MySQL server has gone away')
Thu, 15 Aug 2019 09:34:29 log.py[line:17] DEBUG 该指标在指标库中不存在,门诊中药饮片处方人次
Thu, 15 Aug 2019 09:34:29 log.py[line:17] DEBUG 执行过程中出错
Thu, 15 Aug 2019 09:34:29 log.py[line:20] ERROR (2006, 'MySQL server has gone away')
Traceback (most recent call last):
  File "C:\Users\ipharmacare\newreport\GetSQLvalue\itemZoneValue.py", line 324, in getSqlValue_zone
    sqlValue = self.getValueInCalc(itemname, zoneid, startT, endT, self.optcalcminus)
  File "C:\Users\ipharmacare\newreport\GetSQLvalue\itemZoneValue.py", line 114, in getValueInCalc
    self.itemvalue_one = self.getCalc_Numerator_zone(self.itemnameOne, zoneid, startT, endT, optcalcminus)
  File "C:\Users\ipharmacare\newreport\GetSQLvalue\itemZoneValue.py", line 218, in getCalc_Numerator_zone
    self.itemvalue_one = self.conndb.executeSQL_zoneid_one(self.cur, self.itemOneSql, zoneid, startT, endT)
  File "C:\Users\ipharmacare\newreport\common\connectDB.py", line 49, in executeSQL_zoneid_one
    cur.execute(sql, (zoneid, startT, endT))
  File "C:\Users\ipharmacare\python27\lib\site-packages\MySQLdb\cursors.py", line 205, in execute
    self.errorhandler(self, exc, value)
  File "C:\Users\ipharmacare\python27\lib\site-packages\MySQLdb\connections.py", line 36, in defaulterrorhandler
    raise errorclass, errorvalue
OperationalError: (2006, 'MySQL server has gone away')
Thu, 15 Aug 2019 09:34:29 log.py[line:17] DEBUG 读取配置项发生了错误,zone,(门诊处方药品总金额
Thu, 15 Aug 2019 09:34:29 log.py[line:20] ERROR No option '(\xe9\x97\xa8\xe8\xaf\x8a\xe5\xa4\x84\xe6\x96\xb9\xe8\x8d\xaf\xe5\x93\x81\xe6\x80\xbb\xe9\x87\x91\xe9\xa2\x9d' in section: 'zone'
Traceback (most recent call last):
  File "C:\Users\ipharmacare\newreport\common\configReader.py", line 27, in get
    return self.conf.get(field,key)
  File "C:\Users\ipharmacare\python27\lib\ConfigParser.py", line 618, in get
    raise NoOptionError(option, section)
NoOptionError: No option '(\xe9\x97\xa8\xe8\xaf\x8a\xe5\xa4\x84\xe6\x96\xb9\xe8\x8d\xaf\xe5\x93\x81\xe6\x80\xbb\xe9\x87\x91\xe9\xa2\x9d' in section: 'zone'
Thu, 15 Aug 2019 09:34:29 log.py[line:17] DEBUG 读取配置项发生了错误,zone,门诊患者使用中药饮片总金额)/门诊处方人次（排除中药饮片）
Thu, 15 Aug 2019 09:34:29 log.py[line:20] ERROR No option '\xe9\x97\xa8\xe8\xaf\x8a\xe6\x82\xa3\xe8\x80\x85\xe4\xbd\xbf\xe7\x94\xa8\xe4\xb8\xad\xe8\x8d\xaf\xe9\xa5\xae\xe7\x89\x87\xe6\x80\xbb\xe9\x87\x91\xe9\xa2\x9d)/\xe9\x97\xa8\xe8\xaf\x8a\xe5\xa4\x84\xe6\x96\xb9\xe4\xba\xba\xe6\xac\xa1\xef\xbc\x88\xe6\x8e\x92\xe9\x99\xa4\xe4\xb8\xad\xe8\x8d\xaf\xe9\xa5\xae\xe7\x89\x87\xef\xbc\x89' in section: 'zone'
Traceback (most recent call last):
  File "C:\Users\ipharmacare\newreport\common\configReader.py", line 27, in get
    return self.conf.get(field,key)
  File "C:\Users\ipharmacare\python27\lib\ConfigParser.py", line 618, in get
    raise NoOptionError(option, section)
NoOptionError: No option '\xe9\x97\xa8\xe8\xaf\x8a\xe6\x82\xa3\xe8\x80\x85\xe4\xbd\xbf\xe7\x94\xa8\xe4\xb8\xad\xe8\x8d\xaf\xe9\xa5\xae\xe7\x89\x87\xe6\x80\xbb\xe9\x87\x91\xe9\xa2\x9d)/\xe9\x97\xa8\xe8\xaf\x8a\xe5\xa4\x84\xe6\x96\xb9\xe4\xba\xba\xe6\xac\xa1\xef\xbc\x88\xe6\x8e\x92\xe9\x99\xa4\xe4\xb8\xad\xe8\x8d\xaf\xe9\xa5\xae\xe7\x89\x87\xef\xbc\x89' in section: 'zone'
Thu, 15 Aug 2019 09:34:29 log.py[line:17] DEBUG 指标计算时出错
Thu, 15 Aug 2019 09:34:29 log.py[line:20] ERROR unsupported operand type(s) for %: 'NoneType' and 'tuple'
Traceback (most recent call last):
  File "C:\Users\ipharmacare\newreport\GetSQLvalue\itemZoneValue.py", line 93, in getValueInCalcminus
    endT)
  File "C:\Users\ipharmacare\newreport\common\connectDB.py", line 49, in executeSQL_zoneid_one
    cur.execute(sql, (zoneid, startT, endT))
  File "C:\Users\ipharmacare\python27\lib\site-packages\MySQLdb\cursors.py", line 187, in execute
    query = query % tuple([db.literal(item) for item in args])
TypeError: unsupported operand type(s) for %: 'NoneType' and 'tuple'
Thu, 15 Aug 2019 09:34:29 log.py[line:17] DEBUG 执行过程中出错
Thu, 15 Aug 2019 09:34:29 log.py[line:20] ERROR (2006, 'MySQL server has gone away')
Traceback (most recent call last):
  File "C:\Users\ipharmacare\newreport\GetSQLvalue\itemZoneValue.py", line 324, in getSqlValue_zone
    sqlValue = self.getValueInCalc(itemname, zoneid, startT, endT, self.optcalcminus)
  File "C:\Users\ipharmacare\newreport\GetSQLvalue\itemZoneValue.py", line 114, in getValueInCalc
    self.itemvalue_one = self.getCalc_Numerator_zone(self.itemnameOne, zoneid, startT, endT, optcalcminus)
  File "C:\Users\ipharmacare\newreport\GetSQLvalue\itemZoneValue.py", line 218, in getCalc_Numerator_zone
    self.itemvalue_one = self.conndb.executeSQL_zoneid_one(self.cur, self.itemOneSql, zoneid, startT, endT)
  File "C:\Users\ipharmacare\newreport\common\connectDB.py", line 49, in executeSQL_zoneid_one
    cur.execute(sql, (zoneid, startT, endT))
  File "C:\Users\ipharmacare\python27\lib\site-packages\MySQLdb\cursors.py", line 205, in execute
    self.errorhandler(self, exc, value)
  File "C:\Users\ipharmacare\python27\lib\site-packages\MySQLdb\connections.py", line 36, in defaulterrorhandler
    raise errorclass, errorvalue
OperationalError: (2006, 'MySQL server has gone away')
Thu, 15 Aug 2019 09:34:29 log.py[line:17] DEBUG 执行过程中出错
Thu, 15 Aug 2019 09:34:29 log.py[line:20] ERROR (2006, 'MySQL server has gone away')
Traceback (most recent call last):
  File "C:\Users\ipharmacare\newreport\GetSQLvalue\itemZoneValue.py", line 314, in getSqlValue_zone
    sqlValue = self.getValueInZone(itemname, zoneid, startT, endT)
  File "C:\Users\ipharmacare\newreport\GetSQLvalue\itemZoneValue.py", line 43, in getValueInZone
    sqlValue = self.conndb.executeSQL_zoneid_one(self.cur, self.sql, zoneid, startT, endT)
  File "C:\Users\ipharmacare\newreport\common\connectDB.py", line 49, in executeSQL_zoneid_one
    cur.execute(sql, (zoneid, startT, endT))
  File "C:\Users\ipharmacare\python27\lib\site-packages\MySQLdb\cursors.py", line 205, in execute
    self.errorhandler(self, exc, value)
  File "C:\Users\ipharmacare\python27\lib\site-packages\MySQLdb\connections.py", line 36, in defaulterrorhandler
    raise errorclass, errorvalue
OperationalError: (2006, 'MySQL server has gone away')
Thu, 15 Aug 2019 09:34:29 log.py[line:17] DEBUG 执行过程中出错
Thu, 15 Aug 2019 09:34:29 log.py[line:20] ERROR (2006, 'MySQL server has gone away')
Traceback (most recent call last):
  File "C:\Users\ipharmacare\newreport\GetSQLvalue\itemZoneValue.py", line 314, in getSqlValue_zone
    sqlValue = self.getValueInZone(itemname, zoneid, startT, endT)
  File "C:\Users\ipharmacare\newreport\GetSQLvalue\itemZoneValue.py", line 43, in getValueInZone
    sqlValue = self.conndb.executeSQL_zoneid_one(self.cur, self.sql, zoneid, startT, endT)
  File "C:\Users\ipharmacare\newreport\common\connectDB.py", line 49, in executeSQL_zoneid_one
    cur.execute(sql, (zoneid, startT, endT))
  File "C:\Users\ipharmacare\python27\lib\site-packages\MySQLdb\cursors.py", line 205, in execute
    self.errorhandler(self, exc, value)
  File "C:\Users\ipharmacare\python27\lib\site-packages\MySQLdb\connections.py", line 36, in defaulterrorhandler
    raise errorclass, errorvalue
OperationalError: (2006, 'MySQL server has gone away')
Thu, 15 Aug 2019 09:34:29 log.py[line:17] DEBUG 执行过程中出错
Thu, 15 Aug 2019 09:34:29 log.py[line:20] ERROR (2006, 'MySQL server has gone away')
Traceback (most recent call last):
  File "C:\Users\ipharmacare\newreport\GetSQLvalue\itemZoneValue.py", line 314, in getSqlValue_zone
    sqlValue = self.getValueInZone(itemname, zoneid, startT, endT)
  File "C:\Users\ipharmacare\newreport\GetSQLvalue\itemZoneValue.py", line 43, in getValueInZone
    sqlValue = self.conndb.executeSQL_zoneid_one(self.cur, self.sql, zoneid, startT, endT)
  File "C:\Users\ipharmacare\newreport\common\connectDB.py", line 49, in executeSQL_zoneid_one
    cur.execute(sql, (zoneid, startT, endT))
  File "C:\Users\ipharmacare\python27\lib\site-packages\MySQLdb\cursors.py", line 205, in execute
    self.errorhandler(self, exc, value)
  File "C:\Users\ipharmacare\python27\lib\site-packages\MySQLdb\connections.py", line 36, in defaulterrorhandler
    raise errorclass, errorvalue
OperationalError: (2006, 'MySQL server has gone away')
Thu, 15 Aug 2019 09:34:29 log.py[line:17] DEBUG 执行过程中出错
Thu, 15 Aug 2019 09:34:29 log.py[line:20] ERROR (2006, 'MySQL server has gone away')
Traceback (most recent call last):
  File "C:\Users\ipharmacare\newreport\GetSQLvalue\itemZoneValue.py", line 324, in getSqlValue_zone
    sqlValue = self.getValueInCalc(itemname, zoneid, startT, endT, self.optcalcminus)
  File "C:\Users\ipharmacare\newreport\GetSQLvalue\itemZoneValue.py", line 114, in getValueInCalc
    self.itemvalue_one = self.getCalc_Numerator_zone(self.itemnameOne, zoneid, startT, endT, optcalcminus)
  File "C:\Users\ipharmacare\newreport\GetSQLvalue\itemZoneValue.py", line 218, in getCalc_Numerator_zone
    self.itemvalue_one = self.conndb.executeSQL_zoneid_one(self.cur, self.itemOneSql, zoneid, startT, endT)
  File "C:\Users\ipharmacare\newreport\common\connectDB.py", line 49, in executeSQL_zoneid_one
    cur.execute(sql, (zoneid, startT, endT))
  File "C:\Users\ipharmacare\python27\lib\site-packages\MySQLdb\cursors.py", line 205, in execute
    self.errorhandler(self, exc, value)
  File "C:\Users\ipharmacare\python27\lib\site-packages\MySQLdb\connections.py", line 36, in defaulterrorhandler
    raise errorclass, errorvalue
OperationalError: (2006, 'MySQL server has gone away')
Thu, 15 Aug 2019 09:34:29 log.py[line:17] DEBUG 执行过程中出错
Thu, 15 Aug 2019 09:34:29 log.py[line:20] ERROR (2006, 'MySQL server has gone away')
Traceback (most recent call last):
  File "C:\Users\ipharmacare\newreport\GetSQLvalue\itemZoneValue.py", line 324, in getSqlValue_zone
    sqlValue = self.getValueInCalc(itemname, zoneid, startT, endT, self.optcalcminus)
  File "C:\Users\ipharmacare\newreport\GetSQLvalue\itemZoneValue.py", line 114, in getValueInCalc
    self.itemvalue_one = self.getCalc_Numerator_zone(self.itemnameOne, zoneid, startT, endT, optcalcminus)
  File "C:\Users\ipharmacare\newreport\GetSQLvalue\itemZoneValue.py", line 218, in getCalc_Numerator_zone
    self.itemvalue_one = self.conndb.executeSQL_zoneid_one(self.cur, self.itemOneSql, zoneid, startT, endT)
  File "C:\Users\ipharmacare\newreport\common\connectDB.py", line 49, in executeSQL_zoneid_one
    cur.execute(sql, (zoneid, startT, endT))
  File "C:\Users\ipharmacare\python27\lib\site-packages\MySQLdb\cursors.py", line 205, in execute
    self.errorhandler(self, exc, value)
  File "C:\Users\ipharmacare\python27\lib\site-packages\MySQLdb\connections.py", line 36, in defaulterrorhandler
    raise errorclass, errorvalue
OperationalError: (2006, 'MySQL server has gone away')
Thu, 15 Aug 2019 09:34:29 log.py[line:17] DEBUG 该指标在指标库中不存在,出院患者使用中药饮片人次数占比(%)
Thu, 15 Aug 2019 09:34:29 log.py[line:17] DEBUG 该指标在指标库中不存在,出院患者使用中药饮片总金额占比(%)
Thu, 15 Aug 2019 09:34:29 log.py[line:17] DEBUG 该指标在指标库中不存在,出院患者总人次（排除中药饮片）
Thu, 15 Aug 2019 09:34:29 log.py[line:17] DEBUG 该指标在指标库中不存在,出院患者用药总金额（排除中药饮片）
Thu, 15 Aug 2019 09:34:29 log.py[line:17] DEBUG 该指标在指标库中不存在,门急诊处方人次
Thu, 15 Aug 2019 09:34:29 log.py[line:17] DEBUG 执行过程中出错
Thu, 15 Aug 2019 09:34:29 log.py[line:20] ERROR (2006, 'MySQL server has gone away')
Traceback (most recent call last):
  File "C:\Users\ipharmacare\newreport\GetSQLvalue\itemZoneValue.py", line 314, in getSqlValue_zone
    sqlValue = self.getValueInZone(itemname, zoneid, startT, endT)
  File "C:\Users\ipharmacare\newreport\GetSQLvalue\itemZoneValue.py", line 43, in getValueInZone
    sqlValue = self.conndb.executeSQL_zoneid_one(self.cur, self.sql, zoneid, startT, endT)
  File "C:\Users\ipharmacare\newreport\common\connectDB.py", line 49, in executeSQL_zoneid_one
    cur.execute(sql, (zoneid, startT, endT))
  File "C:\Users\ipharmacare\python27\lib\site-packages\MySQLdb\cursors.py", line 205, in execute
    self.errorhandler(self, exc, value)
  File "C:\Users\ipharmacare\python27\lib\site-packages\MySQLdb\connections.py", line 36, in defaulterrorhandler
    raise errorclass, errorvalue
OperationalError: (2006, 'MySQL server has gone away')
Thu, 15 Aug 2019 09:34:29 log.py[line:17] DEBUG 执行过程中出错
Thu, 15 Aug 2019 09:34:29 log.py[line:20] ERROR (2006, 'MySQL server has gone away')
Traceback (most recent call last):
  File "C:\Users\ipharmacare\newreport\GetSQLvalue\itemZoneValue.py", line 314, in getSqlValue_zone
    sqlValue = self.getValueInZone(itemname, zoneid, startT, endT)
  File "C:\Users\ipharmacare\newreport\GetSQLvalue\itemZoneValue.py", line 43, in getValueInZone
    sqlValue = self.conndb.executeSQL_zoneid_one(self.cur, self.sql, zoneid, startT, endT)
  File "C:\Users\ipharmacare\newreport\common\connectDB.py", line 49, in executeSQL_zoneid_one
    cur.execute(sql, (zoneid, startT, endT))
  File "C:\Users\ipharmacare\python27\lib\site-packages\MySQLdb\cursors.py", line 205, in execute
    self.errorhandler(self, exc, value)
  File "C:\Users\ipharmacare\python27\lib\site-packages\MySQLdb\connections.py", line 36, in defaulterrorhandler
    raise errorclass, errorvalue
OperationalError: (2006, 'MySQL server has gone away')
Thu, 15 Aug 2019 09:34:29 log.py[line:17] DEBUG 执行过程中出错
Thu, 15 Aug 2019 09:34:29 log.py[line:20] ERROR (2006, 'MySQL server has gone away')
Traceback (most recent call last):
  File "C:\Users\ipharmacare\newreport\GetSQLvalue\itemZoneValue.py", line 314, in getSqlValue_zone
    sqlValue = self.getValueInZone(itemname, zoneid, startT, endT)
  File "C:\Users\ipharmacare\newreport\GetSQLvalue\itemZoneValue.py", line 43, in getValueInZone
    sqlValue = self.conndb.executeSQL_zoneid_one(self.cur, self.sql, zoneid, startT, endT)
  File "C:\Users\ipharmacare\newreport\common\connectDB.py", line 49, in executeSQL_zoneid_one
    cur.execute(sql, (zoneid, startT, endT))
  File "C:\Users\ipharmacare\python27\lib\site-packages\MySQLdb\cursors.py", line 205, in execute
    self.errorhandler(self, exc, value)
  File "C:\Users\ipharmacare\python27\lib\site-packages\MySQLdb\connections.py", line 36, in defaulterrorhandler
    raise errorclass, errorvalue
OperationalError: (2006, 'MySQL server has gone away')
Thu, 15 Aug 2019 09:34:29 log.py[line:17] DEBUG 执行过程中出错
Thu, 15 Aug 2019 09:34:29 log.py[line:20] ERROR (2006, 'MySQL server has gone away')
Traceback (most recent call last):
  File "C:\Users\ipharmacare\newreport\GetSQLvalue\itemZoneValue.py", line 314, in getSqlValue_zone
    sqlValue = self.getValueInZone(itemname, zoneid, startT, endT)
  File "C:\Users\ipharmacare\newreport\GetSQLvalue\itemZoneValue.py", line 43, in getValueInZone
    sqlValue = self.conndb.executeSQL_zoneid_one(self.cur, self.sql, zoneid, startT, endT)
  File "C:\Users\ipharmacare\newreport\common\connectDB.py", line 49, in executeSQL_zoneid_one
    cur.execute(sql, (zoneid, startT, endT))
  File "C:\Users\ipharmacare\python27\lib\site-packages\MySQLdb\cursors.py", line 205, in execute
    self.errorhandler(self, exc, value)
  File "C:\Users\ipharmacare\python27\lib\site-packages\MySQLdb\connections.py", line 36, in defaulterrorhandler
    raise errorclass, errorvalue
OperationalError: (2006, 'MySQL server has gone away')
Thu, 15 Aug 2019 09:34:29 log.py[line:17] DEBUG 执行过程中出错
Thu, 15 Aug 2019 09:34:29 log.py[line:20] ERROR (2006, 'MySQL server has gone away')
Traceback (most recent call last):
  File "C:\Users\ipharmacare\newreport\GetSQLvalue\itemZoneValue.py", line 314, in getSqlValue_zone
    sqlValue = self.getValueInZone(itemname, zoneid, startT, endT)
  File "C:\Users\ipharmacare\newreport\GetSQLvalue\itemZoneValue.py", line 43, in getValueInZone
    sqlValue = self.conndb.executeSQL_zoneid_one(self.cur, self.sql, zoneid, startT, endT)
  File "C:\Users\ipharmacare\newreport\common\connectDB.py", line 49, in executeSQL_zoneid_one
    cur.execute(sql, (zoneid, startT, endT))
  File "C:\Users\ipharmacare\python27\lib\site-packages\MySQLdb\cursors.py", line 205, in execute
    self.errorhandler(self, exc, value)
  File "C:\Users\ipharmacare\python27\lib\site-packages\MySQLdb\connections.py", line 36, in defaulterrorhandler
    raise errorclass, errorvalue
OperationalError: (2006, 'MySQL server has gone away')
Thu, 15 Aug 2019 09:34:29 log.py[line:17] DEBUG 该指标在指标库中不存在,门诊质子泵使用处方人次占比(%)
Thu, 15 Aug 2019 09:34:29 log.py[line:17] DEBUG 该指标在指标库中不存在,急诊质子泵使用处方人次占比(%)
Thu, 15 Aug 2019 09:34:29 log.py[line:17] DEBUG 该指标在指标库中不存在,门诊质子泵费用占比(%)
Thu, 15 Aug 2019 09:34:30 log.py[line:17] DEBUG 该指标在指标库中不存在,急诊质子泵费用占比(%)
Thu, 15 Aug 2019 09:34:30 log.py[line:17] DEBUG 执行过程中出错
Thu, 15 Aug 2019 09:34:30 log.py[line:20] ERROR (2006, 'MySQL server has gone away')
Traceback (most recent call last):
  File "C:\Users\ipharmacare\newreport\GetSQLvalue\itemZoneValue.py", line 314, in getSqlValue_zone
    sqlValue = self.getValueInZone(itemname, zoneid, startT, endT)
  File "C:\Users\ipharmacare\newreport\GetSQLvalue\itemZoneValue.py", line 43, in getValueInZone
    sqlValue = self.conndb.executeSQL_zoneid_one(self.cur, self.sql, zoneid, startT, endT)
  File "C:\Users\ipharmacare\newreport\common\connectDB.py", line 49, in executeSQL_zoneid_one
    cur.execute(sql, (zoneid, startT, endT))
  File "C:\Users\ipharmacare\python27\lib\site-packages\MySQLdb\cursors.py", line 205, in execute
    self.errorhandler(self, exc, value)
  File "C:\Users\ipharmacare\python27\lib\site-packages\MySQLdb\connections.py", line 36, in defaulterrorhandler
    raise errorclass, errorvalue
OperationalError: (2006, 'MySQL server has gone away')
Thu, 15 Aug 2019 09:34:30 log.py[line:17] DEBUG 该指标在指标库中不存在,出院患者质子泵总费用
Thu, 15 Aug 2019 09:34:30 log.py[line:17] DEBUG 该指标在指标库中不存在,出院患者质子泵总费用占比(%)
Thu, 15 Aug 2019 09:34:30 log.py[line:17] DEBUG 该指标在指标库中不存在,出院患者预防使用抗菌药物手术例次占比(%)
Thu, 15 Aug 2019 09:34:30 log.py[line:17] DEBUG 执行过程中出错
Thu, 15 Aug 2019 09:34:30 log.py[line:20] ERROR (2006, 'MySQL server has gone away')
Traceback (most recent call last):
  File "C:\Users\ipharmacare\newreport\GetSQLvalue\itemZoneValue.py", line 314, in getSqlValue_zone
    sqlValue = self.getValueInZone(itemname, zoneid, startT, endT)
  File "C:\Users\ipharmacare\newreport\GetSQLvalue\itemZoneValue.py", line 43, in getValueInZone
    sqlValue = self.conndb.executeSQL_zoneid_one(self.cur, self.sql, zoneid, startT, endT)
  File "C:\Users\ipharmacare\newreport\common\connectDB.py", line 49, in executeSQL_zoneid_one
    cur.execute(sql, (zoneid, startT, endT))
  File "C:\Users\ipharmacare\python27\lib\site-packages\MySQLdb\cursors.py", line 205, in execute
    self.errorhandler(self, exc, value)
  File "C:\Users\ipharmacare\python27\lib\site-packages\MySQLdb\connections.py", line 36, in defaulterrorhandler
    raise errorclass, errorvalue
OperationalError: (2006, 'MySQL server has gone away')
Thu, 15 Aug 2019 09:34:30 log.py[line:17] DEBUG 该指标在指标库中不存在,手术前0.5～1.0小时内给药例次占比(%)
Thu, 15 Aug 2019 09:34:29 log.py[line:20] ERROR (2006, 'MySQL server has gone away')
Traceback (most recent call last):
  File "C:\Users\ipharmacare\newreport\GetSQLvalue\itemZoneValue.py", line 314, in getSqlValue_zone
    sqlValue = self.getValueInZone(itemname, zoneid, startT, endT)
  File "C:\Users\ipharmacare\newreport\GetSQLvalue\itemZoneValue.py", line 43, in getValueInZone
    sqlValue = self.conndb.executeSQL_zoneid_one(self.cur, self.sql, zoneid, startT, endT)
  File "C:\Users\ipharmacare\newreport\common\connectDB.py", line 49, in executeSQL_zoneid_one
    cur.execute(sql, (zoneid, startT, endT))
  File "C:\Users\ipharmacare\python27\lib\site-packages\MySQLdb\cursors.py", line 205, in execute
    self.errorhandler(self, exc, value)
  File "C:\Users\ipharmacare\python27\lib\site-packages\MySQLdb\connections.py", line 36, in defaulterrorhandler
    raise errorclass, errorvalue
OperationalError: (2006, 'MySQL server has gone away')
Thu, 15 Aug 2019 09:34:30 log.py[line:17] DEBUG 执行过程中出错
Thu, 15 Aug 2019 09:34:30 log.py[line:20] ERROR (2006, 'MySQL server has gone away')
Traceback (most recent call last):
  File "C:\Users\ipharmacare\newreport\GetSQLvalue\itemZoneValue.py", line 314, in getSqlValue_zone
    sqlValue = self.getValueInZone(itemname, zoneid, startT, endT)
  File "C:\Users\ipharmacare\newreport\GetSQLvalue\itemZoneValue.py", line 43, in getValueInZone
    sqlValue = self.conndb.executeSQL_zoneid_one(self.cur, self.sql, zoneid, startT, endT)
  File "C:\Users\ipharmacare\newreport\common\connectDB.py", line 49, in executeSQL_zoneid_one
    cur.execute(sql, (zoneid, startT, endT))
  File "C:\Users\ipharmacare\python27\lib\site-packages\MySQLdb\cursors.py", line 205, in execute
    self.errorhandler(self, exc, value)
  File "C:\Users\ipharmacare\python27\lib\site-packages\MySQLdb\connections.py", line 36, in defaulterrorhandler
    raise errorclass, errorvalue
OperationalError: (2006, 'MySQL server has gone away')
Thu, 15 Aug 2019 09:34:30 log.py[line:17] DEBUG 执行过程中出错
Thu, 15 Aug 2019 09:34:30 log.py[line:20] ERROR (2006, 'MySQL server has gone away')
Traceback (most recent call last):
  File "C:\Users\ipharmacare\newreport\GetSQLvalue\itemZoneValue.py", line 314, in getSqlValue_zone
    sqlValue = self.getValueInZone(itemname, zoneid, startT, endT)
  File "C:\Users\ipharmacare\newreport\GetSQLvalue\itemZoneValue.py", line 43, in getValueInZone
    sqlValue = self.conndb.executeSQL_zoneid_one(self.cur, self.sql, zoneid, startT, endT)
  File "C:\Users\ipharmacare\newreport\common\connectDB.py", line 49, in executeSQL_zoneid_one
    cur.execute(sql, (zoneid, startT, endT))
  File "C:\Users\ipharmacare\python27\lib\site-packages\MySQLdb\cursors.py", line 205, in execute
    self.errorhandler(self, exc, value)
  File "C:\Users\ipharmacare\python27\lib\site-packages\MySQLdb\connections.py", line 36, in defaulterrorhandler
    raise errorclass, errorvalue
OperationalError: (2006, 'MySQL server has gone away')
Thu, 15 Aug 2019 09:34:30 log.py[line:17] DEBUG 该指标在指标库中不存在,门诊质子泵使用处方人次占比(%)
Thu, 15 Aug 2019 09:34:30 log.py[line:17] DEBUG 该指标在指标库中不存在,急诊质子泵使用处方人次占比(%)
Thu, 15 Aug 2019 09:34:30 log.py[line:17] DEBUG 该指标在指标库中不存在,门诊质子泵费用占比(%)
Thu, 15 Aug 2019 09:34:30 log.py[line:17] DEBUG 该指标在指标库中不存在,急诊质子泵费用占比(%)
Thu, 15 Aug 2019 09:34:30 log.py[line:17] DEBUG 执行过程中出错
Thu, 15 Aug 2019 09:34:30 log.py[line:20] ERROR (2006, 'MySQL server has gone away')
Traceback (most recent call last):
  File "C:\Users\ipharmacare\newreport\GetSQLvalue\itemZoneValue.py", line 314, in getSqlValue_zone
    sqlValue = self.getValueInZone(itemname, zoneid, startT, endT)
  File "C:\Users\ipharmacare\newreport\GetSQLvalue\itemZoneValue.py", line 43, in getValueInZone
    sqlValue = self.conndb.executeSQL_zoneid_one(self.cur, self.sql, zoneid, startT, endT)
  File "C:\Users\ipharmacare\newreport\common\connectDB.py", line 49, in executeSQL_zoneid_one
    cur.execute(sql, (zoneid, startT, endT))
  File "C:\Users\ipharmacare\python27\lib\site-packages\MySQLdb\cursors.py", line 205, in execute
    self.errorhandler(self, exc, value)
  File "C:\Users\ipharmacare\python27\lib\site-packages\MySQLdb\connections.py", line 36, in defaulterrorhandler
    raise errorclass, errorvalue
OperationalError: (2006, 'MySQL server has gone away')
Thu, 15 Aug 2019 09:34:30 log.py[line:17] DEBUG 该指标在指标库中不存在,出院患者质子泵总费用
Thu, 15 Aug 2019 09:34:30 log.py[line:17] DEBUG 该指标在指标库中不存在,出院患者质子泵总费用占比(%)
Thu, 15 Aug 2019 09:34:30 log.py[line:17] DEBUG 该指标在指标库中不存在,出院患者预防使用抗菌药物手术例次占比(%)
Thu, 15 Aug 2019 09:34:30 log.py[line:17] DEBUG 执行过程中出错
Thu, 15 Aug 2019 09:34:30 log.py[line:20] ERROR (2006, 'MySQL server has gone away')
Traceback (most recent call last):
  File "C:\Users\ipharmacare\newreport\GetSQLvalue\itemZoneValue.py", line 314, in getSqlValue_zone
    sqlValue = self.getValueInZone(itemname, zoneid, startT, endT)
  File "C:\Users\ipharmacare\newreport\GetSQLvalue\itemZoneValue.py", line 43, in getValueInZone
    sqlValue = self.conndb.executeSQL_zoneid_one(self.cur, self.sql, zoneid, startT, endT)
  File "C:\Users\ipharmacare\newreport\common\connectDB.py", line 49, in executeSQL_zoneid_one
    cur.execute(sql, (zoneid, startT, endT))
  File "C:\Users\ipharmacare\python27\lib\site-packages\MySQLdb\cursors.py", line 205, in execute
    self.errorhandler(self, exc, value)
  File "C:\Users\ipharmacare\python27\lib\site-packages\MySQLdb\connections.py", line 36, in defaulterrorhandler
    raise errorclass, errorvalue
OperationalError: (2006, 'MySQL server has gone away')
Thu, 15 Aug 2019 09:34:31 log.py[line:17] DEBUG 该指标在指标库中不存在,手术前0.5～1.0小时内给药例次占比(%)
Thu, 15 Aug 2019 09:34:31 log.py[line:17] DEBUG 执行过程中出错
Thu, 15 Aug 2019 09:34:31 log.py[line:20] ERROR (2006, 'MySQL server has gone away')
Traceback (most recent call last):
  File "C:\Users\ipharmacare\newreport\GetSQLvalue\itemZoneValue.py", line 314, in getSqlValue_zone
    sqlValue = self.getValueInZone(itemname, zoneid, startT, endT)
  File "C:\Users\ipharmacare\newreport\GetSQLvalue\itemZoneValue.py", line 43, in getValueInZone
    sqlValue = self.conndb.executeSQL_zoneid_one(self.cur, self.sql, zoneid, startT, endT)
  File "C:\Users\ipharmacare\newreport\common\connectDB.py", line 49, in executeSQL_zoneid_one
    cur.execute(sql, (zoneid, startT, endT))
  File "C:\Users\ipharmacare\python27\lib\site-packages\MySQLdb\cursors.py", line 205, in execute
    self.errorhandler(self, exc, value)
  File "C:\Users\ipharmacare\python27\lib\site-packages\MySQLdb\connections.py", line 36, in defaulterrorhandler
    raise errorclass, errorvalue
OperationalError: (2006, 'MySQL server has gone away')
Thu, 15 Aug 2019 09:34:31 log.py[line:17] DEBUG 该指标在指标库中不存在,手术预防使用抗菌药物时间≤24小时例次占比(%)
Thu, 15 Aug 2019 09:34:31 log.py[line:17] DEBUG 该指标在指标库中不存在,I类切口手术预防使用抗菌药物例次占比(%)
Thu, 15 Aug 2019 09:34:31 log.py[line:17] DEBUG 该指标在指标库中不存在,原则上不需要预防使用抗菌药物I类切口手术预防使用抗菌药物例次占比(%)
Thu, 15 Aug 2019 09:34:31 log.py[line:17] DEBUG 该指标在指标库中不存在,I类切口手术预防使用抗菌药物品种选择符合指南例次占比(%)
Thu, 15 Aug 2019 09:34:31 log.py[line:17] DEBUG 该指标在指标库中不存在,I类切口手术前0.5～1.0小时内抗菌药物给药例次
Thu, 15 Aug 2019 09:34:31 log.py[line:17] DEBUG 该指标在指标库中不存在,I类切口手术前0.5～1.0小时内抗菌药物给药例次占比(%)
Thu, 15 Aug 2019 09:34:31 log.py[line:17] DEBUG 该指标在指标库中不存在,门诊抗菌药物使用金额
Thu, 15 Aug 2019 09:34:31 log.py[line:17] DEBUG 该指标在指标库中不存在,住院抗菌药物使用金额
Thu, 15 Aug 2019 09:34:31 log.py[line:17] DEBUG 执行过程中出错
Thu, 15 Aug 2019 09:34:31 log.py[line:20] ERROR (2006, 'MySQL server has gone away')
Traceback (most recent call last):
  File "C:\Users\ipharmacare\newreport\GetSQLvalue\itemZoneValue.py", line 319, in getSqlValue_zone
    sqlValue = self.getValueInHospital(itemname, zoneid, startT, endT)
  File "C:\Users\ipharmacare\newreport\GetSQLvalue\itemZoneValue.py", line 73, in getValueInHospital
    sqlValue = self.conndb.executeSQL_zoneid_two(self.cur, self.sql, zoneid, startT, endT)
  File "C:\Users\ipharmacare\newreport\common\connectDB.py", line 54, in executeSQL_zoneid_two
    cur.execute(sql,(zoneid, startT, endT,zoneid, startT, endT))
  File "C:\Users\ipharmacare\python27\lib\site-packages\MySQLdb\cursors.py", line 205, in execute
    self.errorhandler(self, exc, value)
  File "C:\Users\ipharmacare\python27\lib\site-packages\MySQLdb\connections.py", line 36, in defaulterrorhandler
    raise errorclass, errorvalue
OperationalError: (2006, 'MySQL server has gone away')
Thu, 15 Aug 2019 09:34:31 log.py[line:17] DEBUG 执行过程中出错
Thu, 15 Aug 2019 09:34:31 log.py[line:20] ERROR (2006, 'MySQL server has gone away')
Traceback (most recent call last):
  File "C:\Users\ipharmacare\newreport\GetSQLvalue\itemZoneValue.py", line 319, in getSqlValue_zone
    sqlValue = self.getValueInHospital(itemname, zoneid, startT, endT)
  File "C:\Users\ipharmacare\newreport\GetSQLvalue\itemZoneValue.py", line 73, in getValueInHospital
    sqlValue = self.conndb.executeSQL_zoneid_two(self.cur, self.sql, zoneid, startT, endT)
  File "C:\Users\ipharmacare\newreport\common\connectDB.py", line 54, in executeSQL_zoneid_two
    cur.execute(sql,(zoneid, startT, endT,zoneid, startT, endT))
  File "C:\Users\ipharmacare\python27\lib\site-packages\MySQLdb\cursors.py", line 205, in execute
    self.errorhandler(self, exc, value)
  File "C:\Users\ipharmacare\python27\lib\site-packages\MySQLdb\connections.py", line 36, in defaulterrorhandler
    raise errorclass, errorvalue
OperationalError: (2006, 'MySQL server has gone away')
Thu, 15 Aug 2019 09:34:31 log.py[line:17] DEBUG 执行过程中出错
Thu, 15 Aug 2019 09:34:31 log.py[line:20] ERROR (2006, 'MySQL server has gone away')
Traceback (most recent call last):
  File "C:\Users\ipharmacare\newreport\GetSQLvalue\itemZoneValue.py", line 324, in getSqlValue_zone
    sqlValue = self.getValueInCalc(itemname, zoneid, startT, endT, self.optcalcminus)
  File "C:\Users\ipharmacare\newreport\GetSQLvalue\itemZoneValue.py", line 114, in getValueInCalc
    self.itemvalue_one = self.getCalc_Numerator_zone(self.itemnameOne, zoneid, startT, endT, optcalcminus)
  File "C:\Users\ipharmacare\newreport\GetSQLvalue\itemZoneValue.py", line 186, in getCalc_Numerator_zone
    self.itemvalue_one = self.conndb.executeSQL_zoneid_two(self.cur, self.itemOneSql, zoneid, startT, endT)
  File "C:\Users\ipharmacare\newreport\common\connectDB.py", line 54, in executeSQL_zoneid_two
    cur.execute(sql,(zoneid, startT, endT,zoneid, startT, endT))
  File "C:\Users\ipharmacare\python27\lib\site-packages\MySQLdb\cursors.py", line 205, in execute
    self.errorhandler(self, exc, value)
  File "C:\Users\ipharmacare\python27\lib\site-packages\MySQLdb\connections.py", line 36, in defaulterrorhandler
    raise errorclass, errorvalue
OperationalError: (2006, 'MySQL server has gone away')
Thu, 15 Aug 2019 09:34:31 log.py[line:17] DEBUG 读取配置项发生了错误,zone,门诊处方药品总金额
Thu, 15 Aug 2019 09:34:31 log.py[line:20] ERROR No option '\xe9\x97\xa8\xe8\xaf\x8a\xe5\xa4\x84\xe6\x96\xb9\xe8\x8d\xaf\xe5\x93\x81\xe6\x80\xbb\xe9\x87\x91\xe9\xa2\x9d' in section: 'zone'
Traceback (most recent call last):
  File "C:\Users\ipharmacare\newreport\common\configReader.py", line 27, in get
    return self.conf.get(field,key)
  File "C:\Users\ipharmacare\python27\lib\ConfigParser.py", line 618, in get
    raise NoOptionError(option, section)
NoOptionError: No option '\xe9\x97\xa8\xe8\xaf\x8a\xe5\xa4\x84\xe6\x96\xb9\xe8\x8d\xaf\xe5\x93\x81\xe6\x80\xbb\xe9\x87\x91\xe9\xa2\x9d' in section: 'zone'
Thu, 15 Aug 2019 09:34:31 log.py[line:17] DEBUG 执行过程中出错
Thu, 15 Aug 2019 09:34:31 log.py[line:20] ERROR unsupported operand type(s) for %: 'NoneType' and 'tuple'
Traceback (most recent call last):
  File "C:\Users\ipharmacare\newreport\GetSQLvalue\itemZoneValue.py", line 324, in getSqlValue_zone
    sqlValue = self.getValueInCalc(itemname, zoneid, startT, endT, self.optcalcminus)
  File "C:\Users\ipharmacare\newreport\GetSQLvalue\itemZoneValue.py", line 114, in getValueInCalc
    self.itemvalue_one = self.getCalc_Numerator_zone(self.itemnameOne, zoneid, startT, endT, optcalcminus)
  File "C:\Users\ipharmacare\newreport\GetSQLvalue\itemZoneValue.py", line 218, in getCalc_Numerator_zone
    self.itemvalue_one = self.conndb.executeSQL_zoneid_one(self.cur, self.itemOneSql, zoneid, startT, endT)
  File "C:\Users\ipharmacare\newreport\common\connectDB.py", line 49, in executeSQL_zoneid_one
    cur.execute(sql, (zoneid, startT, endT))
  File "C:\Users\ipharmacare\python27\lib\site-packages\MySQLdb\cursors.py", line 187, in execute
    query = query % tuple([db.literal(item) for item in args])
TypeError: unsupported operand type(s) for %: 'NoneType' and 'tuple'
Thu, 15 Aug 2019 09:34:31 connectionpool.py[line:205] DEBUG Starting new HTTP connection (1): 10.1.1.89:9999
Thu, 15 Aug 2019 09:34:31 log.py[line:20] ERROR HTTPConnectionPool(host='10.1.1.89', port=9999): Max retries exceeded with url: /syscenter/api/v1/currentUser (Caused by NewConnectionError('<urllib3.connection.HTTPConnection object at 0x00000000041B24E0>: Failed to establish a new connection: [Errno 10065] ',))
Traceback (most recent call last):
  File "C:\Users\ipharmacare\newreport\GetSQLvalue\itemZoneValue.py", line 351, in getSqlValue_zone
    sqlValue = self.getValueInddds(itemname,zoneid,startT,endT)[0]
  File "C:\Users\ipharmacare\newreport\GetSQLvalue\itemZoneValue.py", line 53, in getValueInddds
    qtyvalue=self.configValue.getvalue('qty')
  File "C:\Users\ipharmacare\newreport\configvalue\getconfigvalue.py", line 37, in getvalue
    self.login()
  File "C:\Users\ipharmacare\newreport\configvalue\getconfigvalue.py", line 31, in login
    self.loginr=self.session.post(self.addr, data=json.dumps(self.params), headers=self.headers)
  File "C:\Users\ipharmacare\python27\lib\site-packages\requests\sessions.py", line 581, in post
    return self.request('POST', url, data=data, json=json, **kwargs)
  File "C:\Users\ipharmacare\python27\lib\site-packages\requests\sessions.py", line 533, in request
    resp = self.send(prep, **send_kwargs)
  File "C:\Users\ipharmacare\python27\lib\site-packages\requests\sessions.py", line 646, in send
    r = adapter.send(request, **kwargs)
  File "C:\Users\ipharmacare\python27\lib\site-packages\requests\adapters.py", line 516, in send
    raise ConnectionError(e, request=request)
ConnectionError: HTTPConnectionPool(host='10.1.1.89', port=9999): Max retries exceeded with url: /syscenter/api/v1/currentUser (Caused by NewConnectionError('<urllib3.connection.HTTPConnection object at 0x00000000041B24E0>: Failed to establish a new connection: [Errno 10065] ',))
Thu, 15 Aug 2019 09:34:32 log.py[line:17] DEBUG 该指标在指标库中不存在,门诊抗菌药物消耗总克数
Thu, 15 Aug 2019 09:34:32 log.py[line:17] DEBUG 该指标在指标库中不存在,门诊抗菌药物处方数占比(%)
Thu, 15 Aug 2019 09:34:32 log.py[line:17] DEBUG 该指标在指标库中不存在,出院患者使用抗菌药物金额占比(%)
Thu, 15 Aug 2019 09:34:32 log.py[line:17] DEBUG 该指标在指标库中不存在,出院患者使用抗菌药物人次占比(%)
Thu, 15 Aug 2019 09:34:32 log.py[line:17] DEBUG 该指标在指标库中不存在,出院患者限制级抗菌药物使用人次数占比(%)
Thu, 15 Aug 2019 09:34:32 log.py[line:17] DEBUG 该指标在指标库中不存在,出院患者限制级抗菌药物使用量（累计DDD数）
Thu, 15 Aug 2019 09:34:33 connectionpool.py[line:205] DEBUG Starting new HTTP connection (1): 10.1.1.89:9999
Thu, 15 Aug 2019 09:34:33 log.py[line:20] ERROR HTTPConnectionPool(host='10.1.1.89', port=9999): Max retries exceeded with url: /syscenter/api/v1/currentUser (Caused by NewConnectionError('<urllib3.connection.HTTPConnection object at 0x00000000041B2400>: Failed to establish a new connection: [Errno 10065] ',))
Traceback (most recent call last):
  File "C:\Users\ipharmacare\newreport\GetSQLvalue\itemZoneValue.py", line 351, in getSqlValue_zone
    sqlValue = self.getValueInddds(itemname,zoneid,startT,endT)[0]
  File "C:\Users\ipharmacare\newreport\GetSQLvalue\itemZoneValue.py", line 53, in getValueInddds
    qtyvalue=self.configValue.getvalue('qty')
  File "C:\Users\ipharmacare\newreport\configvalue\getconfigvalue.py", line 37, in getvalue
    self.login()
  File "C:\Users\ipharmacare\newreport\configvalue\getconfigvalue.py", line 31, in login
    self.loginr=self.session.post(self.addr, data=json.dumps(self.params), headers=self.headers)
  File "C:\Users\ipharmacare\python27\lib\site-packages\requests\sessions.py", line 581, in post
    return self.request('POST', url, data=data, json=json, **kwargs)
  File "C:\Users\ipharmacare\python27\lib\site-packages\requests\sessions.py", line 533, in request
    resp = self.send(prep, **send_kwargs)
  File "C:\Users\ipharmacare\python27\lib\site-packages\requests\sessions.py", line 646, in send
    r = adapter.send(request, **kwargs)
  File "C:\Users\ipharmacare\python27\lib\site-packages\requests\adapters.py", line 516, in send
    raise ConnectionError(e, request=request)
ConnectionError: HTTPConnectionPool(host='10.1.1.89', port=9999): Max retries exceeded with url: /syscenter/api/v1/currentUser (Caused by NewConnectionError('<urllib3.connection.HTTPConnection object at 0x00000000041B2400>: Failed to establish a new connection: [Errno 10065] ',))
Thu, 15 Aug 2019 09:34:33 log.py[line:17] DEBUG 读取配置项发生了错误,zone,出院患者限制级抗菌药物使用量（累计DDD数）
Thu, 15 Aug 2019 09:34:33 log.py[line:20] ERROR No option '\xe5\x87\xba\xe9\x99\xa2\xe6\x82\xa3\xe8\x80\x85\xe9\x99\x90\xe5\x88\xb6\xe7\xba\xa7\xe6\x8a\x97\xe8\x8f\x8c\xe8\x8d\xaf\xe7\x89\xa9\xe4\xbd\xbf\xe7\x94\xa8\xe9\x87\x8f\xef\xbc\x88\xe7\xb4\xaf\xe8\xae\xa1ddd\xe6\x95\xb0\xef\xbc\x89' in section: 'zone'
Traceback (most recent call last):
  File "C:\Users\ipharmacare\newreport\common\configReader.py", line 27, in get
    return self.conf.get(field,key)
  File "C:\Users\ipharmacare\python27\lib\ConfigParser.py", line 618, in get
    raise NoOptionError(option, section)
NoOptionError: No option '\xe5\x87\xba\xe9\x99\xa2\xe6\x82\xa3\xe8\x80\x85\xe9\x99\x90\xe5\x88\xb6\xe7\xba\xa7\xe6\x8a\x97\xe8\x8f\x8c\xe8\x8d\xaf\xe7\x89\xa9\xe4\xbd\xbf\xe7\x94\xa8\xe9\x87\x8f\xef\xbc\x88\xe7\xb4\xaf\xe8\xae\xa1ddd\xe6\x95\xb0\xef\xbc\x89' in section: 'zone'
Thu, 15 Aug 2019 09:34:33 log.py[line:17] DEBUG 执行过程中出错
Thu, 15 Aug 2019 09:34:33 log.py[line:20] ERROR unsupported operand type(s) for %: 'NoneType' and 'tuple'
Traceback (most recent call last):
  File "C:\Users\ipharmacare\newreport\GetSQLvalue\itemZoneValue.py", line 334, in getSqlValue_zone
    sqlValue = self.getValueInCalc100(itemname, zoneid, startT, endT)
  File "C:\Users\ipharmacare\newreport\GetSQLvalue\itemZoneValue.py", line 144, in getValueInCalc100
    self.itemvalue_one = self.conndb.executeSQL_zoneid_one(self.cur, self.itemOneSql, zoneid, startT, endT)
  File "C:\Users\ipharmacare\newreport\common\connectDB.py", line 49, in executeSQL_zoneid_one
    cur.execute(sql, (zoneid, startT, endT))
  File "C:\Users\ipharmacare\python27\lib\site-packages\MySQLdb\cursors.py", line 187, in execute
    query = query % tuple([db.literal(item) for item in args])
TypeError: unsupported operand type(s) for %: 'NoneType' and 'tuple'
Thu, 15 Aug 2019 09:34:33 log.py[line:17] DEBUG 执行过程中出错
Thu, 15 Aug 2019 09:34:33 log.py[line:20] ERROR 'NoneType' object has no attribute '__getitem__'
Traceback (most recent call last):
  File "C:\Users\ipharmacare\newreport\GetSQLvalue\itemZoneValue.py", line 334, in getSqlValue_zone
    sqlValue = self.getValueInCalc100(itemname, zoneid, startT, endT)
  File "C:\Users\ipharmacare\newreport\GetSQLvalue\itemZoneValue.py", line 138, in getValueInCalc100
    self.itemvalue_one = self.calcddds.calcddds_1('zone_ddds', self.itemnameOne, zoneid, startT, endT)[0]
TypeError: 'NoneType' object has no attribute '__getitem__'
Thu, 15 Aug 2019 09:34:33 log.py[line:17] DEBUG 执行过程中出错
Thu, 15 Aug 2019 09:34:33 log.py[line:20] ERROR (2006, 'MySQL server has gone away')
Traceback (most recent call last):
  File "C:\Users\ipharmacare\newreport\GetSQLvalue\itemZoneValue.py", line 314, in getSqlValue_zone
    sqlValue = self.getValueInZone(itemname, zoneid, startT, endT)
  File "C:\Users\ipharmacare\newreport\GetSQLvalue\itemZoneValue.py", line 43, in getValueInZone
    sqlValue = self.conndb.executeSQL_zoneid_one(self.cur, self.sql, zoneid, startT, endT)
  File "C:\Users\ipharmacare\newreport\common\connectDB.py", line 49, in executeSQL_zoneid_one
    cur.execute(sql, (zoneid, startT, endT))
  File "C:\Users\ipharmacare\python27\lib\site-packages\MySQLdb\cursors.py", line 205, in execute
    self.errorhandler(self, exc, value)
  File "C:\Users\ipharmacare\python27\lib\site-packages\MySQLdb\connections.py", line 36, in defaulterrorhandler
    raise errorclass, errorvalue
OperationalError: (2006, 'MySQL server has gone away')
Thu, 15 Aug 2019 09:34:33 log.py[line:17] DEBUG 执行过程中出错
Thu, 15 Aug 2019 09:34:33 log.py[line:20] ERROR (2006, 'MySQL server has gone away')
Traceback (most recent call last):
  File "C:\Users\ipharmacare\newreport\GetSQLvalue\itemZoneValue.py", line 314, in getSqlValue_zone
    sqlValue = self.getValueInZone(itemname, zoneid, startT, endT)
  File "C:\Users\ipharmacare\newreport\GetSQLvalue\itemZoneValue.py", line 43, in getValueInZone
    sqlValue = self.conndb.executeSQL_zoneid_one(self.cur, self.sql, zoneid, startT, endT)
  File "C:\Users\ipharmacare\newreport\common\connectDB.py", line 49, in executeSQL_zoneid_one
    cur.execute(sql, (zoneid, startT, endT))
  File "C:\Users\ipharmacare\python27\lib\site-packages\MySQLdb\cursors.py", line 205, in execute
    self.errorhandler(self, exc, value)
  File "C:\Users\ipharmacare\python27\lib\site-packages\MySQLdb\connections.py", line 36, in defaulterrorhandler
    raise errorclass, errorvalue
OperationalError: (2006, 'MySQL server has gone away')
Thu, 15 Aug 2019 09:34:33 log.py[line:17] DEBUG 该指标在指标库中不存在,出院患者使用特殊级抗菌药物人次占比(%)
Thu, 15 Aug 2019 09:34:43 log.py[line:17] DEBUG 执行过程中出错
Thu, 15 Aug 2019 09:34:43 log.py[line:20] ERROR (2006, 'MySQL server has gone away')
Traceback (most recent call last):
  File "C:\Users\ipharmacare\newreport\GetSQLvalue\itemZoneValue.py", line 314, in getSqlValue_zone
    sqlValue = self.getValueInZone(itemname, zoneid, startT, endT)
  File "C:\Users\ipharmacare\newreport\GetSQLvalue\itemZoneValue.py", line 43, in getValueInZone
    sqlValue = self.conndb.executeSQL_zoneid_one(self.cur, self.sql, zoneid, startT, endT)
  File "C:\Users\ipharmacare\newreport\common\connectDB.py", line 49, in executeSQL_zoneid_one
    cur.execute(sql, (zoneid, startT, endT))
  File "C:\Users\ipharmacare\python27\lib\site-packages\MySQLdb\cursors.py", line 205, in execute
    self.errorhandler(self, exc, value)
  File "C:\Users\ipharmacare\python27\lib\site-packages\MySQLdb\connections.py", line 36, in defaulterrorhandler
    raise errorclass, errorvalue
OperationalError: (2006, 'MySQL server has gone away')
Thu, 15 Aug 2019 09:34:43 log.py[line:17] DEBUG 该指标在指标库中不存在,手术预防使用抗菌药物时间≤24小时例次占比(%)
Thu, 15 Aug 2019 09:34:43 log.py[line:17] DEBUG 该指标在指标库中不存在,I类切口手术预防使用抗菌药物例次占比(%)
Thu, 15 Aug 2019 09:34:43 log.py[line:17] DEBUG 该指标在指标库中不存在,原则上不需要预防使用抗菌药物I类切口手术预防使用抗菌药物例次占比(%)
Thu, 15 Aug 2019 09:34:43 log.py[line:17] DEBUG 该指标在指标库中不存在,I类切口手术预防使用抗菌药物品种选择符合指南例次占比(%)
Thu, 15 Aug 2019 09:34:43 log.py[line:17] DEBUG 该指标在指标库中不存在,I类切口手术前0.5～1.0小时内抗菌药物给药例次
Thu, 15 Aug 2019 09:34:43 log.py[line:17] DEBUG 该指标在指标库中不存在,I类切口手术前0.5～1.0小时内抗菌药物给药例次占比(%)
Thu, 15 Aug 2019 09:34:43 log.py[line:17] DEBUG 该指标在指标库中不存在,门诊抗菌药物使用金额
Thu, 15 Aug 2019 09:34:43 log.py[line:17] DEBUG 该指标在指标库中不存在,住院抗菌药物使用金额
Thu, 15 Aug 2019 09:34:43 log.py[line:17] DEBUG 执行过程中出错
Thu, 15 Aug 2019 09:34:43 log.py[line:20] ERROR (2006, 'MySQL server has gone away')
Traceback (most recent call last):
  File "C:\Users\ipharmacare\newreport\GetSQLvalue\itemZoneValue.py", line 319, in getSqlValue_zone
    sqlValue = self.getValueInHospital(itemname, zoneid, startT, endT)
  File "C:\Users\ipharmacare\newreport\GetSQLvalue\itemZoneValue.py", line 73, in getValueInHospital
    sqlValue = self.conndb.executeSQL_zoneid_two(self.cur, self.sql, zoneid, startT, endT)
  File "C:\Users\ipharmacare\newreport\common\connectDB.py", line 54, in executeSQL_zoneid_two
    cur.execute(sql,(zoneid, startT, endT,zoneid, startT, endT))
  File "C:\Users\ipharmacare\python27\lib\site-packages\MySQLdb\cursors.py", line 205, in execute
    self.errorhandler(self, exc, value)
  File "C:\Users\ipharmacare\python27\lib\site-packages\MySQLdb\connections.py", line 36, in defaulterrorhandler
    raise errorclass, errorvalue
OperationalError: (2006, 'MySQL server has gone away')
Thu, 15 Aug 2019 09:34:43 log.py[line:17] DEBUG 执行过程中出错
Thu, 15 Aug 2019 09:34:43 log.py[line:20] ERROR (2006, 'MySQL server has gone away')
Traceback (most recent call last):
  File "C:\Users\ipharmacare\newreport\GetSQLvalue\itemZoneValue.py", line 319, in getSqlValue_zone
    sqlValue = self.getValueInHospital(itemname, zoneid, startT, endT)
  File "C:\Users\ipharmacare\newreport\GetSQLvalue\itemZoneValue.py", line 73, in getValueInHospital
    sqlValue = self.conndb.executeSQL_zoneid_two(self.cur, self.sql, zoneid, startT, endT)
  File "C:\Users\ipharmacare\newreport\common\connectDB.py", line 54, in executeSQL_zoneid_two
    cur.execute(sql,(zoneid, startT, endT,zoneid, startT, endT))
  File "C:\Users\ipharmacare\python27\lib\site-packages\MySQLdb\cursors.py", line 205, in execute
    self.errorhandler(self, exc, value)
  File "C:\Users\ipharmacare\python27\lib\site-packages\MySQLdb\connections.py", line 36, in defaulterrorhandler
    raise errorclass, errorvalue
OperationalError: (2006, 'MySQL server has gone away')
Thu, 15 Aug 2019 09:34:43 log.py[line:17] DEBUG 执行过程中出错
Thu, 15 Aug 2019 09:34:43 log.py[line:20] ERROR (2006, 'MySQL server has gone away')
Traceback (most recent call last):
  File "C:\Users\ipharmacare\newreport\GetSQLvalue\itemZoneValue.py", line 324, in getSqlValue_zone
    sqlValue = self.getValueInCalc(itemname, zoneid, startT, endT, self.optcalcminus)
  File "C:\Users\ipharmacare\newreport\GetSQLvalue\itemZoneValue.py", line 114, in getValueInCalc
    self.itemvalue_one = self.getCalc_Numerator_zone(self.itemnameOne, zoneid, startT, endT, optcalcminus)
  File "C:\Users\ipharmacare\newreport\GetSQLvalue\itemZoneValue.py", line 186, in getCalc_Numerator_zone
    self.itemvalue_one = self.conndb.executeSQL_zoneid_two(self.cur, self.itemOneSql, zoneid, startT, endT)
  File "C:\Users\ipharmacare\newreport\common\connectDB.py", line 54, in executeSQL_zoneid_two
    cur.execute(sql,(zoneid, startT, endT,zoneid, startT, endT))
  File "C:\Users\ipharmacare\python27\lib\site-packages\MySQLdb\cursors.py", line 205, in execute
    self.errorhandler(self, exc, value)
  File "C:\Users\ipharmacare\python27\lib\site-packages\MySQLdb\connections.py", line 36, in defaulterrorhandler
    raise errorclass, errorvalue
OperationalError: (2006, 'MySQL server has gone away')
Thu, 15 Aug 2019 09:34:43 log.py[line:17] DEBUG 读取配置项发生了错误,zone,门诊处方药品总金额
Thu, 15 Aug 2019 09:34:43 log.py[line:20] ERROR No option '\xe9\x97\xa8\xe8\xaf\x8a\xe5\xa4\x84\xe6\x96\xb9\xe8\x8d\xaf\xe5\x93\x81\xe6\x80\xbb\xe9\x87\x91\xe9\xa2\x9d' in section: 'zone'
Traceback (most recent call last):
  File "C:\Users\ipharmacare\newreport\common\configReader.py", line 27, in get
    return self.conf.get(field,key)
  File "C:\Users\ipharmacare\python27\lib\ConfigParser.py", line 618, in get
    raise NoOptionError(option, section)
NoOptionError: No option '\xe9\x97\xa8\xe8\xaf\x8a\xe5\xa4\x84\xe6\x96\xb9\xe8\x8d\xaf\xe5\x93\x81\xe6\x80\xbb\xe9\x87\x91\xe9\xa2\x9d' in section: 'zone'
Thu, 15 Aug 2019 09:34:43 log.py[line:17] DEBUG 执行过程中出错
Thu, 15 Aug 2019 09:34:43 log.py[line:20] ERROR unsupported operand type(s) for %: 'NoneType' and 'tuple'
Traceback (most recent call last):
  File "C:\Users\ipharmacare\newreport\GetSQLvalue\itemZoneValue.py", line 324, in getSqlValue_zone
    sqlValue = self.getValueInCalc(itemname, zoneid, startT, endT, self.optcalcminus)
  File "C:\Users\ipharmacare\newreport\GetSQLvalue\itemZoneValue.py", line 114, in getValueInCalc
    self.itemvalue_one = self.getCalc_Numerator_zone(self.itemnameOne, zoneid, startT, endT, optcalcminus)
  File "C:\Users\ipharmacare\newreport\GetSQLvalue\itemZoneValue.py", line 218, in getCalc_Numerator_zone
    self.itemvalue_one = self.conndb.executeSQL_zoneid_one(self.cur, self.itemOneSql, zoneid, startT, endT)
  File "C:\Users\ipharmacare\newreport\common\connectDB.py", line 49, in executeSQL_zoneid_one
    cur.execute(sql, (zoneid, startT, endT))
  File "C:\Users\ipharmacare\python27\lib\site-packages\MySQLdb\cursors.py", line 187, in execute
    query = query % tuple([db.literal(item) for item in args])
TypeError: unsupported operand type(s) for %: 'NoneType' and 'tuple'
Thu, 15 Aug 2019 09:34:43 connectionpool.py[line:205] DEBUG Starting new HTTP connection (1): 10.1.1.89:9999
Thu, 15 Aug 2019 09:34:43 connectionpool.py[line:205] DEBUG Starting new HTTP connection (1): 10.1.1.89:9999
Thu, 15 Aug 2019 09:34:43 connectionpool.py[line:393] DEBUG http://10.1.1.89:9999 "POST /syscenter/api/v1/currentUser HTTP/1.1" 200 None
Thu, 15 Aug 2019 09:34:43 connectionpool.py[line:393] DEBUG http://10.1.1.89:9999 "POST /syscenter/api/v1/currentUser HTTP/1.1" 200 None
Thu, 15 Aug 2019 09:34:43 connectionpool.py[line:393] DEBUG http://10.1.1.89:9999 "GET /syscenter/api/v1/config/selectSysConfig?showName=qty%E8%AE%A1%E7%AE%97%E6%96%B9%E6%B3%95 HTTP/1.1" 200 None
Thu, 15 Aug 2019 09:34:43 log.py[line:17] DEBUG 配置项错误
Thu, 15 Aug 2019 09:34:43 log.py[line:20] ERROR getZoneSQLvalue instance has no attribute 'sqlValue'
Traceback (most recent call last):
  File "C:\Users\ipharmacare\newreport\GetSQLvalue\itemZoneValue.py", line 351, in getSqlValue_zone
    sqlValue = self.getValueInddds(itemname,zoneid,startT,endT)[0]
  File "C:\Users\ipharmacare\newreport\GetSQLvalue\itemZoneValue.py", line 63, in getValueInddds
    return self.sqlValue
AttributeError: getZoneSQLvalue instance has no attribute 'sqlValue'
Thu, 15 Aug 2019 09:34:43 log.py[line:17] DEBUG 该指标在指标库中不存在,门诊抗菌药物消耗总克数
Thu, 15 Aug 2019 09:34:43 log.py[line:17] DEBUG 该指标在指标库中不存在,门诊抗菌药物处方数占比(%)
Thu, 15 Aug 2019 09:34:43 log.py[line:17] DEBUG 该指标在指标库中不存在,出院患者使用抗菌药物金额占比(%)
Thu, 15 Aug 2019 09:34:43 log.py[line:17] DEBUG 该指标在指标库中不存在,出院患者使用抗菌药物人次占比(%)
Thu, 15 Aug 2019 09:34:43 log.py[line:17] DEBUG 该指标在指标库中不存在,出院患者限制级抗菌药物使用人次数占比(%)
Thu, 15 Aug 2019 09:34:43 log.py[line:17] DEBUG 该指标在指标库中不存在,出院患者限制级抗菌药物使用量（累计DDD数）
Thu, 15 Aug 2019 09:34:43 connectionpool.py[line:393] DEBUG http://10.1.1.89:9999 "GET /syscenter/api/v1/config/selectSysConfig?showName=qty%E8%AE%A1%E7%AE%97%E6%96%B9%E6%B3%95 HTTP/1.1" 200 None
Thu, 15 Aug 2019 09:34:43 connectionpool.py[line:205] DEBUG Starting new HTTP connection (1): 10.1.1.89:9999
Thu, 15 Aug 2019 09:34:43 log.py[line:17] DEBUG 配置项错误
Thu, 15 Aug 2019 09:34:43 log.py[line:20] ERROR getZoneSQLvalue instance has no attribute 'sqlValue'
Traceback (most recent call last):
  File "C:\Users\ipharmacare\newreport\GetSQLvalue\itemZoneValue.py", line 351, in getSqlValue_zone
    sqlValue = self.getValueInddds(itemname,zoneid,startT,endT)[0]
  File "C:\Users\ipharmacare\newreport\GetSQLvalue\itemZoneValue.py", line 63, in getValueInddds
    return self.sqlValue
AttributeError: getZoneSQLvalue instance has no attribute 'sqlValue'
Thu, 15 Aug 2019 09:34:43 log.py[line:17] DEBUG 读取配置项发生了错误,zone,出院患者特殊级抗菌药物使用量（累计DDD数）
Thu, 15 Aug 2019 09:34:43 log.py[line:20] ERROR No option '\xe5\x87\xba\xe9\x99\xa2\xe6\x82\xa3\xe8\x80\x85\xe7\x89\xb9\xe6\xae\x8a\xe7\xba\xa7\xe6\x8a\x97\xe8\x8f\x8c\xe8\x8d\xaf\xe7\x89\xa9\xe4\xbd\xbf\xe7\x94\xa8\xe9\x87\x8f\xef\xbc\x88\xe7\xb4\xaf\xe8\xae\xa1ddd\xe6\x95\xb0\xef\xbc\x89' in section: 'zone'
Traceback (most recent call last):
  File "C:\Users\ipharmacare\newreport\common\configReader.py", line 27, in get
    return self.conf.get(field,key)
  File "C:\Users\ipharmacare\python27\lib\ConfigParser.py", line 618, in get
    raise NoOptionError(option, section)
NoOptionError: No option '\xe5\x87\xba\xe9\x99\xa2\xe6\x82\xa3\xe8\x80\x85\xe7\x89\xb9\xe6\xae\x8a\xe7\xba\xa7\xe6\x8a\x97\xe8\x8f\x8c\xe8\x8d\xaf\xe7\x89\xa9\xe4\xbd\xbf\xe7\x94\xa8\xe9\x87\x8f\xef\xbc\x88\xe7\xb4\xaf\xe8\xae\xa1ddd\xe6\x95\xb0\xef\xbc\x89' in section: 'zone'
Thu, 15 Aug 2019 09:34:43 log.py[line:17] DEBUG 执行过程中出错
Thu, 15 Aug 2019 09:34:43 log.py[line:20] ERROR unsupported operand type(s) for %: 'NoneType' and 'tuple'
Traceback (most recent call last):
  File "C:\Users\ipharmacare\newreport\GetSQLvalue\itemZoneValue.py", line 334, in getSqlValue_zone
    sqlValue = self.getValueInCalc100(itemname, zoneid, startT, endT)
  File "C:\Users\ipharmacare\newreport\GetSQLvalue\itemZoneValue.py", line 144, in getValueInCalc100
    self.itemvalue_one = self.conndb.executeSQL_zoneid_one(self.cur, self.itemOneSql, zoneid, startT, endT)
  File "C:\Users\ipharmacare\newreport\common\connectDB.py", line 49, in executeSQL_zoneid_one
    cur.execute(sql, (zoneid, startT, endT))
  File "C:\Users\ipharmacare\python27\lib\site-packages\MySQLdb\cursors.py", line 187, in execute
    query = query % tuple([db.literal(item) for item in args])
TypeError: unsupported operand type(s) for %: 'NoneType' and 'tuple'
Thu, 15 Aug 2019 09:34:43 log.py[line:17] DEBUG 读取配置项发生了错误,zone,出院患者特殊使用级抗菌药物使用量（累计DDD数）（不含出院带药）
Thu, 15 Aug 2019 09:34:43 log.py[line:20] ERROR No option '\xe5\x87\xba\xe9\x99\xa2\xe6\x82\xa3\xe8\x80\x85\xe7\x89\xb9\xe6\xae\x8a\xe4\xbd\xbf\xe7\x94\xa8\xe7\xba\xa7\xe6\x8a\x97\xe8\x8f\x8c\xe8\x8d\xaf\xe7\x89\xa9\xe4\xbd\xbf\xe7\x94\xa8\xe9\x87\x8f\xef\xbc\x88\xe7\xb4\xaf\xe8\xae\xa1ddd\xe6\x95\xb0\xef\xbc\x89\xef\xbc\x88\xe4\xb8\x8d\xe5\x90\xab\xe5\x87\xba\xe9\x99\xa2\xe5\xb8\xa6\xe8\x8d\xaf\xef\xbc\x89' in section: 'zone'
Traceback (most recent call last):
  File "C:\Users\ipharmacare\newreport\common\configReader.py", line 27, in get
    return self.conf.get(field,key)
  File "C:\Users\ipharmacare\python27\lib\ConfigParser.py", line 618, in get
    raise NoOptionError(option, section)
NoOptionError: No option '\xe5\x87\xba\xe9\x99\xa2\xe6\x82\xa3\xe8\x80\x85\xe7\x89\xb9\xe6\xae\x8a\xe4\xbd\xbf\xe7\x94\xa8\xe7\xba\xa7\xe6\x8a\x97\xe8\x8f\x8c\xe8\x8d\xaf\xe7\x89\xa9\xe4\xbd\xbf\xe7\x94\xa8\xe9\x87\x8f\xef\xbc\x88\xe7\xb4\xaf\xe8\xae\xa1ddd\xe6\x95\xb0\xef\xbc\x89\xef\xbc\x88\xe4\xb8\x8d\xe5\x90\xab\xe5\x87\xba\xe9\x99\xa2\xe5\xb8\xa6\xe8\x8d\xaf\xef\xbc\x89' in section: 'zone'
Thu, 15 Aug 2019 09:34:43 log.py[line:17] DEBUG 执行过程中出错
Thu, 15 Aug 2019 09:34:43 log.py[line:20] ERROR unsupported operand type(s) for %: 'NoneType' and 'tuple'
Traceback (most recent call last):
  File "C:\Users\ipharmacare\newreport\GetSQLvalue\itemZoneValue.py", line 334, in getSqlValue_zone
    sqlValue = self.getValueInCalc100(itemname, zoneid, startT, endT)
  File "C:\Users\ipharmacare\newreport\GetSQLvalue\itemZoneValue.py", line 144, in getValueInCalc100
    self.itemvalue_one = self.conndb.executeSQL_zoneid_one(self.cur, self.itemOneSql, zoneid, startT, endT)
  File "C:\Users\ipharmacare\newreport\common\connectDB.py", line 49, in executeSQL_zoneid_one
    cur.execute(sql, (zoneid, startT, endT))
  File "C:\Users\ipharmacare\python27\lib\site-packages\MySQLdb\cursors.py", line 187, in execute
    query = query % tuple([db.literal(item) for item in args])
TypeError: unsupported operand type(s) for %: 'NoneType' and 'tuple'
Thu, 15 Aug 2019 09:34:43 log.py[line:17] DEBUG 执行过程中出错
Thu, 15 Aug 2019 09:34:43 log.py[line:20] ERROR (2006, 'MySQL server has gone away')
Traceback (most recent call last):
  File "C:\Users\ipharmacare\newreport\GetSQLvalue\itemZoneValue.py", line 314, in getSqlValue_zone
    sqlValue = self.getValueInZone(itemname, zoneid, startT, endT)
  File "C:\Users\ipharmacare\newreport\GetSQLvalue\itemZoneValue.py", line 43, in getValueInZone
    sqlValue = self.conndb.executeSQL_zoneid_one(self.cur, self.sql, zoneid, startT, endT)
  File "C:\Users\ipharmacare\newreport\common\connectDB.py", line 49, in executeSQL_zoneid_one
    cur.execute(sql, (zoneid, startT, endT))
  File "C:\Users\ipharmacare\python27\lib\site-packages\MySQLdb\cursors.py", line 205, in execute
    self.errorhandler(self, exc, value)
  File "C:\Users\ipharmacare\python27\lib\site-packages\MySQLdb\connections.py", line 36, in defaulterrorhandler
    raise errorclass, errorvalue
OperationalError: (2006, 'MySQL server has gone away')
Thu, 15 Aug 2019 09:34:43 log.py[line:17] DEBUG 该指标在指标库中不存在,出院患者使用非限制级抗菌药物人次占比(%)
Thu, 15 Aug 2019 09:34:43 connectionpool.py[line:393] DEBUG http://10.1.1.89:9999 "POST /syscenter/api/v1/currentUser HTTP/1.1" 200 None
Thu, 15 Aug 2019 09:34:43 connectionpool.py[line:393] DEBUG http://10.1.1.89:9999 "GET /syscenter/api/v1/config/selectSysConfig?showName=qty%E8%AE%A1%E7%AE%97%E6%96%B9%E6%B3%95 HTTP/1.1" 200 None
Thu, 15 Aug 2019 09:34:43 log.py[line:17] DEBUG 配置项错误
Thu, 15 Aug 2019 09:34:43 log.py[line:20] ERROR getZoneSQLvalue instance has no attribute 'sqlValue'
Traceback (most recent call last):
  File "C:\Users\ipharmacare\newreport\GetSQLvalue\itemZoneValue.py", line 351, in getSqlValue_zone
    sqlValue = self.getValueInddds(itemname,zoneid,startT,endT)[0]
  File "C:\Users\ipharmacare\newreport\GetSQLvalue\itemZoneValue.py", line 63, in getValueInddds
    return self.sqlValue
AttributeError: getZoneSQLvalue instance has no attribute 'sqlValue'
Thu, 15 Aug 2019 09:34:43 log.py[line:17] DEBUG 读取配置项发生了错误,zone,出院患者限制级抗菌药物使用量（累计DDD数）
Thu, 15 Aug 2019 09:34:43 connectionpool.py[line:205] DEBUG Starting new HTTP connection (1): 10.1.1.89:9999
Thu, 15 Aug 2019 09:34:43 log.py[line:20] ERROR No option '\xe5\x87\xba\xe9\x99\xa2\xe6\x82\xa3\xe8\x80\x85\xe9\x99\x90\xe5\x88\xb6\xe7\xba\xa7\xe6\x8a\x97\xe8\x8f\x8c\xe8\x8d\xaf\xe7\x89\xa9\xe4\xbd\xbf\xe7\x94\xa8\xe9\x87\x8f\xef\xbc\x88\xe7\xb4\xaf\xe8\xae\xa1ddd\xe6\x95\xb0\xef\xbc\x89' in section: 'zone'
Traceback (most recent call last):
  File "C:\Users\ipharmacare\newreport\common\configReader.py", line 27, in get
    return self.conf.get(field,key)
  File "C:\Users\ipharmacare\python27\lib\ConfigParser.py", line 618, in get
    raise NoOptionError(option, section)
NoOptionError: No option '\xe5\x87\xba\xe9\x99\xa2\xe6\x82\xa3\xe8\x80\x85\xe9\x99\x90\xe5\x88\xb6\xe7\xba\xa7\xe6\x8a\x97\xe8\x8f\x8c\xe8\x8d\xaf\xe7\x89\xa9\xe4\xbd\xbf\xe7\x94\xa8\xe9\x87\x8f\xef\xbc\x88\xe7\xb4\xaf\xe8\xae\xa1ddd\xe6\x95\xb0\xef\xbc\x89' in section: 'zone'
Thu, 15 Aug 2019 09:34:43 log.py[line:17] DEBUG 执行过程中出错
Thu, 15 Aug 2019 09:34:43 log.py[line:20] ERROR unsupported operand type(s) for %: 'NoneType' and 'tuple'
Traceback (most recent call last):
  File "C:\Users\ipharmacare\newreport\GetSQLvalue\itemZoneValue.py", line 334, in getSqlValue_zone
    sqlValue = self.getValueInCalc100(itemname, zoneid, startT, endT)
  File "C:\Users\ipharmacare\newreport\GetSQLvalue\itemZoneValue.py", line 144, in getValueInCalc100
    self.itemvalue_one = self.conndb.executeSQL_zoneid_one(self.cur, self.itemOneSql, zoneid, startT, endT)
  File "C:\Users\ipharmacare\newreport\common\connectDB.py", line 49, in executeSQL_zoneid_one
    cur.execute(sql, (zoneid, startT, endT))
  File "C:\Users\ipharmacare\python27\lib\site-packages\MySQLdb\cursors.py", line 187, in execute
    query = query % tuple([db.literal(item) for item in args])
TypeError: unsupported operand type(s) for %: 'NoneType' and 'tuple'
Thu, 15 Aug 2019 09:34:43 log.py[line:17] DEBUG 执行过程中出错
Thu, 15 Aug 2019 09:34:43 log.py[line:20] ERROR 'NoneType' object has no attribute '__getitem__'
Traceback (most recent call last):
  File "C:\Users\ipharmacare\newreport\GetSQLvalue\itemZoneValue.py", line 334, in getSqlValue_zone
    sqlValue = self.getValueInCalc100(itemname, zoneid, startT, endT)
  File "C:\Users\ipharmacare\newreport\GetSQLvalue\itemZoneValue.py", line 138, in getValueInCalc100
    self.itemvalue_one = self.calcddds.calcddds_1('zone_ddds', self.itemnameOne, zoneid, startT, endT)[0]
TypeError: 'NoneType' object has no attribute '__getitem__'
Thu, 15 Aug 2019 09:34:43 log.py[line:17] DEBUG 执行过程中出错
Thu, 15 Aug 2019 09:34:43 log.py[line:20] ERROR (2006, 'MySQL server has gone away')
Traceback (most recent call last):
  File "C:\Users\ipharmacare\newreport\GetSQLvalue\itemZoneValue.py", line 314, in getSqlValue_zone
    sqlValue = self.getValueInZone(itemname, zoneid, startT, endT)
  File "C:\Users\ipharmacare\newreport\GetSQLvalue\itemZoneValue.py", line 43, in getValueInZone
    sqlValue = self.conndb.executeSQL_zoneid_one(self.cur, self.sql, zoneid, startT, endT)
  File "C:\Users\ipharmacare\newreport\common\connectDB.py", line 49, in executeSQL_zoneid_one
    cur.execute(sql, (zoneid, startT, endT))
  File "C:\Users\ipharmacare\python27\lib\site-packages\MySQLdb\cursors.py", line 205, in execute
    self.errorhandler(self, exc, value)
  File "C:\Users\ipharmacare\python27\lib\site-packages\MySQLdb\connections.py", line 36, in defaulterrorhandler
    raise errorclass, errorvalue
OperationalError: (2006, 'MySQL server has gone away')
Thu, 15 Aug 2019 09:34:43 log.py[line:17] DEBUG 执行过程中出错
Thu, 15 Aug 2019 09:34:43 log.py[line:20] ERROR (2006, 'MySQL server has gone away')
Traceback (most recent call last):
  File "C:\Users\ipharmacare\newreport\GetSQLvalue\itemZoneValue.py", line 314, in getSqlValue_zone
    sqlValue = self.getValueInZone(itemname, zoneid, startT, endT)
  File "C:\Users\ipharmacare\newreport\GetSQLvalue\itemZoneValue.py", line 43, in getValueInZone
    sqlValue = self.conndb.executeSQL_zoneid_one(self.cur, self.sql, zoneid, startT, endT)
  File "C:\Users\ipharmacare\newreport\common\connectDB.py", line 49, in executeSQL_zoneid_one
    cur.execute(sql, (zoneid, startT, endT))
  File "C:\Users\ipharmacare\python27\lib\site-packages\MySQLdb\cursors.py", line 205, in execute
    self.errorhandler(self, exc, value)
  File "C:\Users\ipharmacare\python27\lib\site-packages\MySQLdb\connections.py", line 36, in defaulterrorhandler
    raise errorclass, errorvalue
OperationalError: (2006, 'MySQL server has gone away')
Thu, 15 Aug 2019 09:34:43 log.py[line:17] DEBUG 该指标在指标库中不存在,出院患者使用特殊级抗菌药物人次占比(%)
Thu, 15 Aug 2019 09:34:43 connectionpool.py[line:205] DEBUG Starting new HTTP connection (1): 10.1.1.89:9999
Thu, 15 Aug 2019 09:34:43 connectionpool.py[line:393] DEBUG http://10.1.1.89:9999 "POST /syscenter/api/v1/currentUser HTTP/1.1" 200 None
Thu, 15 Aug 2019 09:34:43 connectionpool.py[line:393] DEBUG http://10.1.1.89:9999 "POST /syscenter/api/v1/currentUser HTTP/1.1" 200 None
Thu, 15 Aug 2019 09:34:43 connectionpool.py[line:393] DEBUG http://10.1.1.89:9999 "GET /syscenter/api/v1/config/selectSysConfig?showName=qty%E8%AE%A1%E7%AE%97%E6%96%B9%E6%B3%95 HTTP/1.1" 200 None
Thu, 15 Aug 2019 09:34:43 log.py[line:17] DEBUG 配置项错误
Thu, 15 Aug 2019 09:34:43 log.py[line:20] ERROR getZoneSQLvalue instance has no attribute 'sqlValue'
Traceback (most recent call last):
  File "C:\Users\ipharmacare\newreport\GetSQLvalue\itemZoneValue.py", line 351, in getSqlValue_zone
    sqlValue = self.getValueInddds(itemname,zoneid,startT,endT)[0]
  File "C:\Users\ipharmacare\newreport\GetSQLvalue\itemZoneValue.py", line 63, in getValueInddds
    return self.sqlValue
AttributeError: getZoneSQLvalue instance has no attribute 'sqlValue'
Thu, 15 Aug 2019 09:34:43 connectionpool.py[line:393] DEBUG http://10.1.1.89:9999 "GET /syscenter/api/v1/config/selectSysConfig?showName=qty%E8%AE%A1%E7%AE%97%E6%96%B9%E6%B3%95 HTTP/1.1" 200 None
Thu, 15 Aug 2019 09:34:43 log.py[line:17] DEBUG 配置项错误
Thu, 15 Aug 2019 09:34:43 connectionpool.py[line:205] DEBUG Starting new HTTP connection (1): 10.1.1.89:9999
Thu, 15 Aug 2019 09:34:43 log.py[line:20] ERROR getZoneSQLvalue instance has no attribute 'sqlValue'
Traceback (most recent call last):
  File "C:\Users\ipharmacare\newreport\GetSQLvalue\itemZoneValue.py", line 351, in getSqlValue_zone
    sqlValue = self.getValueInddds(itemname,zoneid,startT,endT)[0]
  File "C:\Users\ipharmacare\newreport\GetSQLvalue\itemZoneValue.py", line 63, in getValueInddds
    return self.sqlValue
AttributeError: getZoneSQLvalue instance has no attribute 'sqlValue'
Thu, 15 Aug 2019 09:34:43 log.py[line:17] DEBUG 读取配置项发生了错误,zone,出院患者特殊级抗菌药物使用量（累计DDD数）
Thu, 15 Aug 2019 09:34:43 log.py[line:20] ERROR No option '\xe5\x87\xba\xe9\x99\xa2\xe6\x82\xa3\xe8\x80\x85\xe7\x89\xb9\xe6\xae\x8a\xe7\xba\xa7\xe6\x8a\x97\xe8\x8f\x8c\xe8\x8d\xaf\xe7\x89\xa9\xe4\xbd\xbf\xe7\x94\xa8\xe9\x87\x8f\xef\xbc\x88\xe7\xb4\xaf\xe8\xae\xa1ddd\xe6\x95\xb0\xef\xbc\x89' in section: 'zone'
Traceback (most recent call last):
  File "C:\Users\ipharmacare\newreport\common\configReader.py", line 27, in get
    return self.conf.get(field,key)
  File "C:\Users\ipharmacare\python27\lib\ConfigParser.py", line 618, in get
    raise NoOptionError(option, section)
NoOptionError: No option '\xe5\x87\xba\xe9\x99\xa2\xe6\x82\xa3\xe8\x80\x85\xe7\x89\xb9\xe6\xae\x8a\xe7\xba\xa7\xe6\x8a\x97\xe8\x8f\x8c\xe8\x8d\xaf\xe7\x89\xa9\xe4\xbd\xbf\xe7\x94\xa8\xe9\x87\x8f\xef\xbc\x88\xe7\xb4\xaf\xe8\xae\xa1ddd\xe6\x95\xb0\xef\xbc\x89' in section: 'zone'
Thu, 15 Aug 2019 09:34:43 log.py[line:17] DEBUG 执行过程中出错
Thu, 15 Aug 2019 09:34:43 log.py[line:20] ERROR unsupported operand type(s) for %: 'NoneType' and 'tuple'
Traceback (most recent call last):
  File "C:\Users\ipharmacare\newreport\GetSQLvalue\itemZoneValue.py", line 334, in getSqlValue_zone
    sqlValue = self.getValueInCalc100(itemname, zoneid, startT, endT)
  File "C:\Users\ipharmacare\newreport\GetSQLvalue\itemZoneValue.py", line 144, in getValueInCalc100
    self.itemvalue_one = self.conndb.executeSQL_zoneid_one(self.cur, self.itemOneSql, zoneid, startT, endT)
  File "C:\Users\ipharmacare\newreport\common\connectDB.py", line 49, in executeSQL_zoneid_one
    cur.execute(sql, (zoneid, startT, endT))
  File "C:\Users\ipharmacare\python27\lib\site-packages\MySQLdb\cursors.py", line 187, in execute
    query = query % tuple([db.literal(item) for item in args])
TypeError: unsupported operand type(s) for %: 'NoneType' and 'tuple'
Thu, 15 Aug 2019 09:34:43 log.py[line:17] DEBUG 读取配置项发生了错误,zone,出院患者特殊使用级抗菌药物使用量（累计DDD数）（不含出院带药）
Thu, 15 Aug 2019 09:34:43 log.py[line:20] ERROR No option '\xe5\x87\xba\xe9\x99\xa2\xe6\x82\xa3\xe8\x80\x85\xe7\x89\xb9\xe6\xae\x8a\xe4\xbd\xbf\xe7\x94\xa8\xe7\xba\xa7\xe6\x8a\x97\xe8\x8f\x8c\xe8\x8d\xaf\xe7\x89\xa9\xe4\xbd\xbf\xe7\x94\xa8\xe9\x87\x8f\xef\xbc\x88\xe7\xb4\xaf\xe8\xae\xa1ddd\xe6\x95\xb0\xef\xbc\x89\xef\xbc\x88\xe4\xb8\x8d\xe5\x90\xab\xe5\x87\xba\xe9\x99\xa2\xe5\xb8\xa6\xe8\x8d\xaf\xef\xbc\x89' in section: 'zone'
Traceback (most recent call last):
  File "C:\Users\ipharmacare\newreport\common\configReader.py", line 27, in get
    return self.conf.get(field,key)
  File "C:\Users\ipharmacare\python27\lib\ConfigParser.py", line 618, in get
    raise NoOptionError(option, section)
NoOptionError: No option '\xe5\x87\xba\xe9\x99\xa2\xe6\x82\xa3\xe8\x80\x85\xe7\x89\xb9\xe6\xae\x8a\xe4\xbd\xbf\xe7\x94\xa8\xe7\xba\xa7\xe6\x8a\x97\xe8\x8f\x8c\xe8\x8d\xaf\xe7\x89\xa9\xe4\xbd\xbf\xe7\x94\xa8\xe9\x87\x8f\xef\xbc\x88\xe7\xb4\xaf\xe8\xae\xa1ddd\xe6\x95\xb0\xef\xbc\x89\xef\xbc\x88\xe4\xb8\x8d\xe5\x90\xab\xe5\x87\xba\xe9\x99\xa2\xe5\xb8\xa6\xe8\x8d\xaf\xef\xbc\x89' in section: 'zone'
Thu, 15 Aug 2019 09:34:43 log.py[line:17] DEBUG 执行过程中出错
Thu, 15 Aug 2019 09:34:43 log.py[line:20] ERROR unsupported operand type(s) for %: 'NoneType' and 'tuple'
Traceback (most recent call last):
  File "C:\Users\ipharmacare\newreport\GetSQLvalue\itemZoneValue.py", line 334, in getSqlValue_zone
    sqlValue = self.getValueInCalc100(itemname, zoneid, startT, endT)
  File "C:\Users\ipharmacare\newreport\GetSQLvalue\itemZoneValue.py", line 144, in getValueInCalc100
    self.itemvalue_one = self.conndb.executeSQL_zoneid_one(self.cur, self.itemOneSql, zoneid, startT, endT)
  File "C:\Users\ipharmacare\newreport\common\connectDB.py", line 49, in executeSQL_zoneid_one
    cur.execute(sql, (zoneid, startT, endT))
  File "C:\Users\ipharmacare\python27\lib\site-packages\MySQLdb\cursors.py", line 187, in execute
    query = query % tuple([db.literal(item) for item in args])
TypeError: unsupported operand type(s) for %: 'NoneType' and 'tuple'
Thu, 15 Aug 2019 09:34:43 log.py[line:17] DEBUG 执行过程中出错
Thu, 15 Aug 2019 09:34:43 log.py[line:20] ERROR (2006, 'MySQL server has gone away')
Traceback (most recent call last):
  File "C:\Users\ipharmacare\newreport\GetSQLvalue\itemZoneValue.py", line 314, in getSqlValue_zone
    sqlValue = self.getValueInZone(itemname, zoneid, startT, endT)
  File "C:\Users\ipharmacare\newreport\GetSQLvalue\itemZoneValue.py", line 43, in getValueInZone
    sqlValue = self.conndb.executeSQL_zoneid_one(self.cur, self.sql, zoneid, startT, endT)
  File "C:\Users\ipharmacare\newreport\common\connectDB.py", line 49, in executeSQL_zoneid_one
    cur.execute(sql, (zoneid, startT, endT))
  File "C:\Users\ipharmacare\python27\lib\site-packages\MySQLdb\cursors.py", line 205, in execute
    self.errorhandler(self, exc, value)
  File "C:\Users\ipharmacare\python27\lib\site-packages\MySQLdb\connections.py", line 36, in defaulterrorhandler
    raise errorclass, errorvalue
OperationalError: (2006, 'MySQL server has gone away')
Thu, 15 Aug 2019 09:34:43 log.py[line:17] DEBUG 该指标在指标库中不存在,出院患者使用非限制级抗菌药物人次占比(%)
Thu, 15 Aug 2019 09:34:43 connectionpool.py[line:205] DEBUG Starting new HTTP connection (1): 10.1.1.89:9999
Thu, 15 Aug 2019 09:34:43 connectionpool.py[line:393] DEBUG http://10.1.1.89:9999 "POST /syscenter/api/v1/currentUser HTTP/1.1" 200 None
Thu, 15 Aug 2019 09:34:43 connectionpool.py[line:393] DEBUG http://10.1.1.89:9999 "POST /syscenter/api/v1/currentUser HTTP/1.1" 200 None
Thu, 15 Aug 2019 09:34:43 connectionpool.py[line:393] DEBUG http://10.1.1.89:9999 "GET /syscenter/api/v1/config/selectSysConfig?showName=qty%E8%AE%A1%E7%AE%97%E6%96%B9%E6%B3%95 HTTP/1.1" 200 None
Thu, 15 Aug 2019 09:34:43 log.py[line:17] DEBUG 配置项错误
Thu, 15 Aug 2019 09:34:43 log.py[line:20] ERROR getZoneSQLvalue instance has no attribute 'sqlValue'
Traceback (most recent call last):
  File "C:\Users\ipharmacare\newreport\GetSQLvalue\itemZoneValue.py", line 351, in getSqlValue_zone
    sqlValue = self.getValueInddds(itemname,zoneid,startT,endT)[0]
  File "C:\Users\ipharmacare\newreport\GetSQLvalue\itemZoneValue.py", line 63, in getValueInddds
    return self.sqlValue
AttributeError: getZoneSQLvalue instance has no attribute 'sqlValue'
Thu, 15 Aug 2019 09:34:43 log.py[line:17] DEBUG 执行过程中出错
Thu, 15 Aug 2019 09:34:43 connectionpool.py[line:393] DEBUG http://10.1.1.89:9999 "GET /syscenter/api/v1/config/selectSysConfig?showName=qty%E8%AE%A1%E7%AE%97%E6%96%B9%E6%B3%95 HTTP/1.1" 200 None
Thu, 15 Aug 2019 09:34:43 log.py[line:20] ERROR 'NoneType' object has no attribute '__getitem__'
Traceback (most recent call last):
  File "C:\Users\ipharmacare\newreport\GetSQLvalue\itemZoneValue.py", line 334, in getSqlValue_zone
    sqlValue = self.getValueInCalc100(itemname, zoneid, startT, endT)
  File "C:\Users\ipharmacare\newreport\GetSQLvalue\itemZoneValue.py", line 138, in getValueInCalc100
    self.itemvalue_one = self.calcddds.calcddds_1('zone_ddds', self.itemnameOne, zoneid, startT, endT)[0]
TypeError: 'NoneType' object has no attribute '__getitem__'
Thu, 15 Aug 2019 09:34:43 log.py[line:17] DEBUG 执行过程中出错
Thu, 15 Aug 2019 09:34:43 log.py[line:17] DEBUG 配置项错误
Thu, 15 Aug 2019 09:34:43 log.py[line:20] ERROR 'NoneType' object has no attribute '__getitem__'
Traceback (most recent call last):
  File "C:\Users\ipharmacare\newreport\GetSQLvalue\itemZoneValue.py", line 334, in getSqlValue_zone
    sqlValue = self.getValueInCalc100(itemname, zoneid, startT, endT)
  File "C:\Users\ipharmacare\newreport\GetSQLvalue\itemZoneValue.py", line 138, in getValueInCalc100
    self.itemvalue_one = self.calcddds.calcddds_1('zone_ddds', self.itemnameOne, zoneid, startT, endT)[0]
TypeError: 'NoneType' object has no attribute '__getitem__'
Thu, 15 Aug 2019 09:34:43 log.py[line:17] DEBUG 该指标在指标库中不存在,出院患者抗菌药物预防使用率(%)
Thu, 15 Aug 2019 09:34:43 log.py[line:20] ERROR getZoneSQLvalue instance has no attribute 'sqlValue'
Traceback (most recent call last):
  File "C:\Users\ipharmacare\newreport\GetSQLvalue\itemZoneValue.py", line 351, in getSqlValue_zone
    sqlValue = self.getValueInddds(itemname,zoneid,startT,endT)[0]
  File "C:\Users\ipharmacare\newreport\GetSQLvalue\itemZoneValue.py", line 63, in getValueInddds
    return self.sqlValue
AttributeError: getZoneSQLvalue instance has no attribute 'sqlValue'
Thu, 15 Aug 2019 09:34:43 log.py[line:17] DEBUG 该指标在指标库中不存在,出院患者抗菌药物治疗使用率(%)
Thu, 15 Aug 2019 09:34:43 log.py[line:17] DEBUG 该指标在指标库中不存在,出院患者抗菌药物联合用药率(%)
Thu, 15 Aug 2019 09:34:43 log.py[line:17] DEBUG 执行过程中出错
Thu, 15 Aug 2019 09:34:43 log.py[line:20] ERROR (2006, 'MySQL server has gone away')
Traceback (most recent call last):
  File "C:\Users\ipharmacare\newreport\GetSQLvalue\itemZoneValue.py", line 314, in getSqlValue_zone
    sqlValue = self.getValueInZone(itemname, zoneid, startT, endT)
  File "C:\Users\ipharmacare\newreport\GetSQLvalue\itemZoneValue.py", line 43, in getValueInZone
    sqlValue = self.conndb.executeSQL_zoneid_one(self.cur, self.sql, zoneid, startT, endT)
  File "C:\Users\ipharmacare\newreport\common\connectDB.py", line 49, in executeSQL_zoneid_one
    cur.execute(sql, (zoneid, startT, endT))
  File "C:\Users\ipharmacare\python27\lib\site-packages\MySQLdb\cursors.py", line 205, in execute
    self.errorhandler(self, exc, value)
  File "C:\Users\ipharmacare\python27\lib\site-packages\MySQLdb\connections.py", line 36, in defaulterrorhandler
    raise errorclass, errorvalue
OperationalError: (2006, 'MySQL server has gone away')
Thu, 15 Aug 2019 09:34:43 log.py[line:17] DEBUG 执行过程中出错
Thu, 15 Aug 2019 09:34:43 log.py[line:20] ERROR (2006, 'MySQL server has gone away')
Traceback (most recent call last):
  File "C:\Users\ipharmacare\newreport\GetSQLvalue\itemZoneValue.py", line 314, in getSqlValue_zone
    sqlValue = self.getValueInZone(itemname, zoneid, startT, endT)
  File "C:\Users\ipharmacare\newreport\GetSQLvalue\itemZoneValue.py", line 43, in getValueInZone
    sqlValue = self.conndb.executeSQL_zoneid_one(self.cur, self.sql, zoneid, startT, endT)
  File "C:\Users\ipharmacare\newreport\common\connectDB.py", line 49, in executeSQL_zoneid_one
    cur.execute(sql, (zoneid, startT, endT))
  File "C:\Users\ipharmacare\python27\lib\site-packages\MySQLdb\cursors.py", line 205, in execute
    self.errorhandler(self, exc, value)
  File "C:\Users\ipharmacare\python27\lib\site-packages\MySQLdb\connections.py", line 36, in defaulterrorhandler
    raise errorclass, errorvalue
OperationalError: (2006, 'MySQL server has gone away')
Thu, 15 Aug 2019 09:34:43 log.py[line:17] DEBUG 执行过程中出错
Thu, 15 Aug 2019 09:34:43 log.py[line:20] ERROR (2006, 'MySQL server has gone away')
Traceback (most recent call last):
  File "C:\Users\ipharmacare\newreport\GetSQLvalue\itemZoneValue.py", line 324, in getSqlValue_zone
    sqlValue = self.getValueInCalc(itemname, zoneid, startT, endT, self.optcalcminus)
  File "C:\Users\ipharmacare\newreport\GetSQLvalue\itemZoneValue.py", line 114, in getValueInCalc
    self.itemvalue_one = self.getCalc_Numerator_zone(self.itemnameOne, zoneid, startT, endT, optcalcminus)
  File "C:\Users\ipharmacare\newreport\GetSQLvalue\itemZoneValue.py", line 218, in getCalc_Numerator_zone
    self.itemvalue_one = self.conndb.executeSQL_zoneid_one(self.cur, self.itemOneSql, zoneid, startT, endT)
  File "C:\Users\ipharmacare\newreport\common\connectDB.py", line 49, in executeSQL_zoneid_one
    cur.execute(sql, (zoneid, startT, endT))
  File "C:\Users\ipharmacare\python27\lib\site-packages\MySQLdb\cursors.py", line 205, in execute
    self.errorhandler(self, exc, value)
  File "C:\Users\ipharmacare\python27\lib\site-packages\MySQLdb\connections.py", line 36, in defaulterrorhandler
    raise errorclass, errorvalue
OperationalError: (2006, 'MySQL server has gone away')
Thu, 15 Aug 2019 09:34:43 log.py[line:17] DEBUG 该指标在指标库中不存在,门诊抗菌药物人次数占比(%)
Thu, 15 Aug 2019 09:34:43 connectionpool.py[line:205] DEBUG Starting new HTTP connection (1): 10.1.1.89:9999
Thu, 15 Aug 2019 09:34:44 connectionpool.py[line:205] DEBUG Starting new HTTP connection (1): 10.1.1.89:9999
Thu, 15 Aug 2019 09:34:44 connectionpool.py[line:393] DEBUG http://10.1.1.89:9999 "POST /syscenter/api/v1/currentUser HTTP/1.1" 200 None
Thu, 15 Aug 2019 09:34:44 connectionpool.py[line:393] DEBUG http://10.1.1.89:9999 "POST /syscenter/api/v1/currentUser HTTP/1.1" 200 None
Thu, 15 Aug 2019 09:34:44 connectionpool.py[line:393] DEBUG http://10.1.1.89:9999 "GET /syscenter/api/v1/config/selectSysConfig?showName=qty%E8%AE%A1%E7%AE%97%E6%96%B9%E6%B3%95 HTTP/1.1" 200 None
Thu, 15 Aug 2019 09:34:44 log.py[line:17] DEBUG 配置项错误
Thu, 15 Aug 2019 09:34:44 log.py[line:20] ERROR getZoneSQLvalue instance has no attribute 'sqlValue'
Traceback (most recent call last):
  File "C:\Users\ipharmacare\newreport\GetSQLvalue\itemZoneValue.py", line 351, in getSqlValue_zone
    sqlValue = self.getValueInddds(itemname,zoneid,startT,endT)[0]
  File "C:\Users\ipharmacare\newreport\GetSQLvalue\itemZoneValue.py", line 63, in getValueInddds
    return self.sqlValue
AttributeError: getZoneSQLvalue instance has no attribute 'sqlValue'
Thu, 15 Aug 2019 09:34:44 log.py[line:17] DEBUG 执行过程中出错
Thu, 15 Aug 2019 09:34:44 log.py[line:20] ERROR 'NoneType' object has no attribute '__getitem__'
Traceback (most recent call last):
  File "C:\Users\ipharmacare\newreport\GetSQLvalue\itemZoneValue.py", line 334, in getSqlValue_zone
    sqlValue = self.getValueInCalc100(itemname, zoneid, startT, endT)
  File "C:\Users\ipharmacare\newreport\GetSQLvalue\itemZoneValue.py", line 138, in getValueInCalc100
    self.itemvalue_one = self.calcddds.calcddds_1('zone_ddds', self.itemnameOne, zoneid, startT, endT)[0]
TypeError: 'NoneType' object has no attribute '__getitem__'
Thu, 15 Aug 2019 09:34:44 log.py[line:17] DEBUG 执行过程中出错
Thu, 15 Aug 2019 09:34:44 log.py[line:20] ERROR 'NoneType' object has no attribute '__getitem__'
Traceback (most recent call last):
  File "C:\Users\ipharmacare\newreport\GetSQLvalue\itemZoneValue.py", line 334, in getSqlValue_zone
    sqlValue = self.getValueInCalc100(itemname, zoneid, startT, endT)
  File "C:\Users\ipharmacare\newreport\GetSQLvalue\itemZoneValue.py", line 138, in getValueInCalc100
    self.itemvalue_one = self.calcddds.calcddds_1('zone_ddds', self.itemnameOne, zoneid, startT, endT)[0]
TypeError: 'NoneType' object has no attribute '__getitem__'
Thu, 15 Aug 2019 09:34:44 log.py[line:17] DEBUG 该指标在指标库中不存在,出院患者抗菌药物预防使用率(%)
Thu, 15 Aug 2019 09:34:44 log.py[line:17] DEBUG 该指标在指标库中不存在,出院患者抗菌药物治疗使用率(%)
Thu, 15 Aug 2019 09:34:44 log.py[line:17] DEBUG 该指标在指标库中不存在,出院患者抗菌药物联合用药率(%)
Thu, 15 Aug 2019 09:34:44 log.py[line:17] DEBUG 执行过程中出错
Thu, 15 Aug 2019 09:34:44 log.py[line:20] ERROR (2006, 'MySQL server has gone away')
Traceback (most recent call last):
  File "C:\Users\ipharmacare\newreport\GetSQLvalue\itemZoneValue.py", line 314, in getSqlValue_zone
    sqlValue = self.getValueInZone(itemname, zoneid, startT, endT)
  File "C:\Users\ipharmacare\newreport\GetSQLvalue\itemZoneValue.py", line 43, in getValueInZone
    sqlValue = self.conndb.executeSQL_zoneid_one(self.cur, self.sql, zoneid, startT, endT)
  File "C:\Users\ipharmacare\newreport\common\connectDB.py", line 49, in executeSQL_zoneid_one
    cur.execute(sql, (zoneid, startT, endT))
  File "C:\Users\ipharmacare\python27\lib\site-packages\MySQLdb\cursors.py", line 205, in execute
    self.errorhandler(self, exc, value)
  File "C:\Users\ipharmacare\python27\lib\site-packages\MySQLdb\connections.py", line 36, in defaulterrorhandler
    raise errorclass, errorvalue
OperationalError: (2006, 'MySQL server has gone away')
Thu, 15 Aug 2019 09:34:44 log.py[line:17] DEBUG 执行过程中出错
Thu, 15 Aug 2019 09:34:44 log.py[line:20] ERROR (2006, 'MySQL server has gone away')
Traceback (most recent call last):
  File "C:\Users\ipharmacare\newreport\GetSQLvalue\itemZoneValue.py", line 314, in getSqlValue_zone
    sqlValue = self.getValueInZone(itemname, zoneid, startT, endT)
  File "C:\Users\ipharmacare\newreport\GetSQLvalue\itemZoneValue.py", line 43, in getValueInZone
    sqlValue = self.conndb.executeSQL_zoneid_one(self.cur, self.sql, zoneid, startT, endT)
  File "C:\Users\ipharmacare\newreport\common\connectDB.py", line 49, in executeSQL_zoneid_one
    cur.execute(sql, (zoneid, startT, endT))
  File "C:\Users\ipharmacare\python27\lib\site-packages\MySQLdb\cursors.py", line 205, in execute
    self.errorhandler(self, exc, value)
  File "C:\Users\ipharmacare\python27\lib\site-packages\MySQLdb\connections.py", line 36, in defaulterrorhandler
    raise errorclass, errorvalue
OperationalError: (2006, 'MySQL server has gone away')
Thu, 15 Aug 2019 09:34:44 log.py[line:17] DEBUG 执行过程中出错
Thu, 15 Aug 2019 09:34:44 log.py[line:20] ERROR (2006, 'MySQL server has gone away')
Traceback (most recent call last):
  File "C:\Users\ipharmacare\newreport\GetSQLvalue\itemZoneValue.py", line 324, in getSqlValue_zone
    sqlValue = self.getValueInCalc(itemname, zoneid, startT, endT, self.optcalcminus)
  File "C:\Users\ipharmacare\newreport\GetSQLvalue\itemZoneValue.py", line 114, in getValueInCalc
    self.itemvalue_one = self.getCalc_Numerator_zone(self.itemnameOne, zoneid, startT, endT, optcalcminus)
  File "C:\Users\ipharmacare\newreport\GetSQLvalue\itemZoneValue.py", line 218, in getCalc_Numerator_zone
    self.itemvalue_one = self.conndb.executeSQL_zoneid_one(self.cur, self.itemOneSql, zoneid, startT, endT)
  File "C:\Users\ipharmacare\newreport\common\connectDB.py", line 49, in executeSQL_zoneid_one
    cur.execute(sql, (zoneid, startT, endT))
  File "C:\Users\ipharmacare\python27\lib\site-packages\MySQLdb\cursors.py", line 205, in execute
    self.errorhandler(self, exc, value)
  File "C:\Users\ipharmacare\python27\lib\site-packages\MySQLdb\connections.py", line 36, in defaulterrorhandler
    raise errorclass, errorvalue
OperationalError: (2006, 'MySQL server has gone away')
Thu, 15 Aug 2019 09:34:44 log.py[line:17] DEBUG 该指标在指标库中不存在,门诊抗菌药物人次数占比(%)
Thu, 15 Aug 2019 09:34:44 connectionpool.py[line:393] DEBUG http://10.1.1.89:9999 "GET /syscenter/api/v1/config/selectSysConfig?showName=qty%E8%AE%A1%E7%AE%97%E6%96%B9%E6%B3%95 HTTP/1.1" 200 None
Thu, 15 Aug 2019 09:34:44 log.py[line:17] DEBUG 配置项错误
Thu, 15 Aug 2019 09:34:44 log.py[line:20] ERROR getZoneSQLvalue instance has no attribute 'sqlValue'
Traceback (most recent call last):
  File "C:\Users\ipharmacare\newreport\GetSQLvalue\itemZoneValue.py", line 351, in getSqlValue_zone
    sqlValue = self.getValueInddds(itemname,zoneid,startT,endT)[0]
  File "C:\Users\ipharmacare\newreport\GetSQLvalue\itemZoneValue.py", line 63, in getValueInddds
    return self.sqlValue
AttributeError: getZoneSQLvalue instance has no attribute 'sqlValue'
Thu, 15 Aug 2019 09:34:44 log.py[line:17] DEBUG 读取配置项发生了错误,zone,出院患者抗菌药物使用量（累计DDD数）(非出院带药)
Thu, 15 Aug 2019 09:34:44 log.py[line:20] ERROR No option '\xe5\x87\xba\xe9\x99\xa2\xe6\x82\xa3\xe8\x80\x85\xe6\x8a\x97\xe8\x8f\x8c\xe8\x8d\xaf\xe7\x89\xa9\xe4\xbd\xbf\xe7\x94\xa8\xe9\x87\x8f\xef\xbc\x88\xe7\xb4\xaf\xe8\xae\xa1ddd\xe6\x95\xb0\xef\xbc\x89(\xe9\x9d\x9e\xe5\x87\xba\xe9\x99\xa2\xe5\xb8\xa6\xe8\x8d\xaf)' in section: 'zone'
Traceback (most recent call last):
  File "C:\Users\ipharmacare\newreport\common\configReader.py", line 27, in get
    return self.conf.get(field,key)
  File "C:\Users\ipharmacare\python27\lib\ConfigParser.py", line 618, in get
    raise NoOptionError(option, section)
NoOptionError: No option '\xe5\x87\xba\xe9\x99\xa2\xe6\x82\xa3\xe8\x80\x85\xe6\x8a\x97\xe8\x8f\x8c\xe8\x8d\xaf\xe7\x89\xa9\xe4\xbd\xbf\xe7\x94\xa8\xe9\x87\x8f\xef\xbc\x88\xe7\xb4\xaf\xe8\xae\xa1ddd\xe6\x95\xb0\xef\xbc\x89(\xe9\x9d\x9e\xe5\x87\xba\xe9\x99\xa2\xe5\xb8\xa6\xe8\x8d\xaf)' in section: 'zone'
Thu, 15 Aug 2019 09:34:44 log.py[line:17] DEBUG 执行过程中出错
Thu, 15 Aug 2019 09:34:44 log.py[line:20] ERROR unsupported operand type(s) for %: 'NoneType' and 'tuple'
Traceback (most recent call last):
  File "C:\Users\ipharmacare\newreport\GetSQLvalue\itemZoneValue.py", line 334, in getSqlValue_zone
    sqlValue = self.getValueInCalc100(itemname, zoneid, startT, endT)
  File "C:\Users\ipharmacare\newreport\GetSQLvalue\itemZoneValue.py", line 144, in getValueInCalc100
    self.itemvalue_one = self.conndb.executeSQL_zoneid_one(self.cur, self.itemOneSql, zoneid, startT, endT)
  File "C:\Users\ipharmacare\newreport\common\connectDB.py", line 49, in executeSQL_zoneid_one
    cur.execute(sql, (zoneid, startT, endT))
  File "C:\Users\ipharmacare\python27\lib\site-packages\MySQLdb\cursors.py", line 187, in execute
    query = query % tuple([db.literal(item) for item in args])
TypeError: unsupported operand type(s) for %: 'NoneType' and 'tuple'
Thu, 15 Aug 2019 09:34:44 log.py[line:17] DEBUG 该指标在指标库中不存在,特殊使用级品规数
Thu, 15 Aug 2019 09:34:44 log.py[line:17] DEBUG 该指标在指标库中不存在,抗菌药物品规数
Thu, 15 Aug 2019 09:34:44 log.py[line:17] DEBUG 执行过程中出错
Thu, 15 Aug 2019 09:34:44 log.py[line:20] ERROR (2006, 'MySQL server has gone away')
Traceback (most recent call last):
  File "C:\Users\ipharmacare\newreport\GetSQLvalue\itemZoneValue.py", line 324, in getSqlValue_zone
    sqlValue = self.getValueInCalc(itemname, zoneid, startT, endT, self.optcalcminus)
  File "C:\Users\ipharmacare\newreport\GetSQLvalue\itemZoneValue.py", line 114, in getValueInCalc
    self.itemvalue_one = self.getCalc_Numerator_zone(self.itemnameOne, zoneid, startT, endT, optcalcminus)
  File "C:\Users\ipharmacare\newreport\GetSQLvalue\itemZoneValue.py", line 218, in getCalc_Numerator_zone
    self.itemvalue_one = self.conndb.executeSQL_zoneid_one(self.cur, self.itemOneSql, zoneid, startT, endT)
  File "C:\Users\ipharmacare\newreport\common\connectDB.py", line 49, in executeSQL_zoneid_one
    cur.execute(sql, (zoneid, startT, endT))
  File "C:\Users\ipharmacare\python27\lib\site-packages\MySQLdb\cursors.py", line 205, in execute
    self.errorhandler(self, exc, value)
  File "C:\Users\ipharmacare\python27\lib\site-packages\MySQLdb\connections.py", line 36, in defaulterrorhandler
    raise errorclass, errorvalue
OperationalError: (2006, 'MySQL server has gone away')
Thu, 15 Aug 2019 09:34:44 log.py[line:17] DEBUG 该指标在指标库中不存在,住院手术患者预防使用抗菌药物用药时机合理率切皮前0.5-1h比例
Thu, 15 Aug 2019 09:34:44 log.py[line:17] DEBUG 该指标在指标库中不存在,去年同期出院患者总人次
Thu, 15 Aug 2019 09:34:44 log.py[line:17] DEBUG 该指标在指标库中不存在,门诊去年同期就诊人次数
Thu, 15 Aug 2019 09:34:44 log.py[line:17] DEBUG 该指标在指标库中不存在,出院患者去年同期住院天数
Thu, 15 Aug 2019 09:34:44 log.py[line:17] DEBUG 该指标在指标库中不存在,出院患者去年同期药品金额
Thu, 15 Aug 2019 09:34:44 log.py[line:17] DEBUG 该指标在指标库中不存在,门诊就诊人次数同比增长(%)
Thu, 15 Aug 2019 09:34:44 log.py[line:17] DEBUG 读取配置项发生了错误,zone,门诊处方药品总金额
Thu, 15 Aug 2019 09:34:44 log.py[line:20] ERROR No option '\xe9\x97\xa8\xe8\xaf\x8a\xe5\xa4\x84\xe6\x96\xb9\xe8\x8d\xaf\xe5\x93\x81\xe6\x80\xbb\xe9\x87\x91\xe9\xa2\x9d' in section: 'zone'
Traceback (most recent call last):
  File "C:\Users\ipharmacare\newreport\common\configReader.py", line 27, in get
    return self.conf.get(field,key)
  File "C:\Users\ipharmacare\python27\lib\ConfigParser.py", line 618, in get
    raise NoOptionError(option, section)
NoOptionError: No option '\xe9\x97\xa8\xe8\xaf\x8a\xe5\xa4\x84\xe6\x96\xb9\xe8\x8d\xaf\xe5\x93\x81\xe6\x80\xbb\xe9\x87\x91\xe9\xa2\x9d' in section: 'zone'
Thu, 15 Aug 2019 09:34:44 log.py[line:17] DEBUG 执行过程中出错
Thu, 15 Aug 2019 09:34:44 log.py[line:20] ERROR unsupported operand type(s) for %: 'NoneType' and 'tuple'
Traceback (most recent call last):
  File "C:\Users\ipharmacare\newreport\GetSQLvalue\itemZoneValue.py", line 324, in getSqlValue_zone
    sqlValue = self.getValueInCalc(itemname, zoneid, startT, endT, self.optcalcminus)
  File "C:\Users\ipharmacare\newreport\GetSQLvalue\itemZoneValue.py", line 114, in getValueInCalc
    self.itemvalue_one = self.getCalc_Numerator_zone(self.itemnameOne, zoneid, startT, endT, optcalcminus)
  File "C:\Users\ipharmacare\newreport\GetSQLvalue\itemZoneValue.py", line 218, in getCalc_Numerator_zone
    self.itemvalue_one = self.conndb.executeSQL_zoneid_one(self.cur, self.itemOneSql, zoneid, startT, endT)
  File "C:\Users\ipharmacare\newreport\common\connectDB.py", line 49, in executeSQL_zoneid_one
    cur.execute(sql, (zoneid, startT, endT))
  File "C:\Users\ipharmacare\python27\lib\site-packages\MySQLdb\cursors.py", line 187, in execute
    query = query % tuple([db.literal(item) for item in args])
TypeError: unsupported operand type(s) for %: 'NoneType' and 'tuple'
Thu, 15 Aug 2019 09:34:44 log.py[line:17] DEBUG 该指标在指标库中不存在,门诊次均药费同比增长比率（%）
Thu, 15 Aug 2019 09:34:44 connectionpool.py[line:205] DEBUG Starting new HTTP connection (1): 10.1.1.89:9999
Thu, 15 Aug 2019 09:34:44 log.py[line:17] DEBUG 该指标在指标库中不存在,门诊次均药费同比增长金额
Thu, 15 Aug 2019 09:34:44 log.py[line:17] DEBUG 读取配置项发生了错误,zone,出院患者去年同期住院天数
Thu, 15 Aug 2019 09:34:44 log.py[line:20] ERROR No option '\xe5\x87\xba\xe9\x99\xa2\xe6\x82\xa3\xe8\x80\x85\xe5\x8e\xbb\xe5\xb9\xb4\xe5\x90\x8c\xe6\x9c\x9f\xe4\xbd\x8f\xe9\x99\xa2\xe5\xa4\xa9\xe6\x95\xb0' in section: 'zone'
Traceback (most recent call last):
  File "C:\Users\ipharmacare\newreport\common\configReader.py", line 27, in get
    return self.conf.get(field,key)
  File "C:\Users\ipharmacare\python27\lib\ConfigParser.py", line 618, in get
    raise NoOptionError(option, section)
NoOptionError: No option '\xe5\x87\xba\xe9\x99\xa2\xe6\x82\xa3\xe8\x80\x85\xe5\x8e\xbb\xe5\xb9\xb4\xe5\x90\x8c\xe6\x9c\x9f\xe4\xbd\x8f\xe9\x99\xa2\xe5\xa4\xa9\xe6\x95\xb0' in section: 'zone'
Thu, 15 Aug 2019 09:34:44 log.py[line:17] DEBUG 执行过程中出错
Thu, 15 Aug 2019 09:34:44 log.py[line:20] ERROR unsupported operand type(s) for %: 'NoneType' and 'tuple'
Traceback (most recent call last):
  File "C:\Users\ipharmacare\newreport\GetSQLvalue\itemZoneValue.py", line 324, in getSqlValue_zone
    sqlValue = self.getValueInCalc(itemname, zoneid, startT, endT, self.optcalcminus)
  File "C:\Users\ipharmacare\newreport\GetSQLvalue\itemZoneValue.py", line 114, in getValueInCalc
    self.itemvalue_one = self.getCalc_Numerator_zone(self.itemnameOne, zoneid, startT, endT, optcalcminus)
  File "C:\Users\ipharmacare\newreport\GetSQLvalue\itemZoneValue.py", line 218, in getCalc_Numerator_zone
    self.itemvalue_one = self.conndb.executeSQL_zoneid_one(self.cur, self.itemOneSql, zoneid, startT, endT)
  File "C:\Users\ipharmacare\newreport\common\connectDB.py", line 49, in executeSQL_zoneid_one
    cur.execute(sql, (zoneid, startT, endT))
  File "C:\Users\ipharmacare\python27\lib\site-packages\MySQLdb\cursors.py", line 187, in execute
    query = query % tuple([db.literal(item) for item in args])
TypeError: unsupported operand type(s) for %: 'NoneType' and 'tuple'
Thu, 15 Aug 2019 09:34:44 log.py[line:17] DEBUG 该指标在指标库中不存在,平均住院天数同比增长
Thu, 15 Aug 2019 09:34:44 log.py[line:17] DEBUG 执行过程中出错
Thu, 15 Aug 2019 09:34:44 log.py[line:20] ERROR (2006, 'MySQL server has gone away')
Traceback (most recent call last):
  File "C:\Users\ipharmacare\newreport\GetSQLvalue\itemZoneValue.py", line 324, in getSqlValue_zone
    sqlValue = self.getValueInCalc(itemname, zoneid, startT, endT, self.optcalcminus)
  File "C:\Users\ipharmacare\newreport\GetSQLvalue\itemZoneValue.py", line 114, in getValueInCalc
    self.itemvalue_one = self.getCalc_Numerator_zone(self.itemnameOne, zoneid, startT, endT, optcalcminus)
  File "C:\Users\ipharmacare\newreport\GetSQLvalue\itemZoneValue.py", line 218, in getCalc_Numerator_zone
    self.itemvalue_one = self.conndb.executeSQL_zoneid_one(self.cur, self.itemOneSql, zoneid, startT, endT)
  File "C:\Users\ipharmacare\newreport\common\connectDB.py", line 49, in executeSQL_zoneid_one
    cur.execute(sql, (zoneid, startT, endT))
  File "C:\Users\ipharmacare\python27\lib\site-packages\MySQLdb\cursors.py", line 205, in execute
    self.errorhandler(self, exc, value)
  File "C:\Users\ipharmacare\python27\lib\site-packages\MySQLdb\connections.py", line 36, in defaulterrorhandler
    raise errorclass, errorvalue
OperationalError: (2006, 'MySQL server has gone away')
Thu, 15 Aug 2019 09:34:44 log.py[line:17] DEBUG 该指标在指标库中不存在,出院患者次均药费同比增长比率（%）
Thu, 15 Aug 2019 09:34:44 log.py[line:17] DEBUG 该指标在指标库中不存在,出院患者次均药费同比增长金额
Thu, 15 Aug 2019 09:34:44 log.py[line:17] DEBUG 该指标在指标库中不存在,抗菌药物使用数量
Thu, 15 Aug 2019 09:34:44 log.py[line:17] DEBUG 该指标在指标库中不存在,门诊抗菌药物使用数量
Thu, 15 Aug 2019 09:34:44 log.py[line:17] DEBUG 该指标在指标库中不存在,使用数量
Thu, 15 Aug 2019 09:34:44 log.py[line:17] DEBUG 该指标在指标库中不存在,全院抗菌药物使用数量
Thu, 15 Aug 2019 09:34:44 log.py[line:17] DEBUG 该指标在指标库中不存在,出院患者使用特殊级抗菌药物输液金额2
Thu, 15 Aug 2019 09:34:44 log.py[line:17] DEBUG 执行过程中出错
Thu, 15 Aug 2019 09:34:44 log.py[line:20] ERROR (2006, 'MySQL server has gone away')
Traceback (most recent call last):
  File "C:\Users\ipharmacare\newreport\GetSQLvalue\itemZoneValue.py", line 314, in getSqlValue_zone
    sqlValue = self.getValueInZone(itemname, zoneid, startT, endT)
  File "C:\Users\ipharmacare\newreport\GetSQLvalue\itemZoneValue.py", line 43, in getValueInZone
    sqlValue = self.conndb.executeSQL_zoneid_one(self.cur, self.sql, zoneid, startT, endT)
  File "C:\Users\ipharmacare\newreport\common\connectDB.py", line 49, in executeSQL_zoneid_one
    cur.execute(sql, (zoneid, startT, endT))
  File "C:\Users\ipharmacare\python27\lib\site-packages\MySQLdb\cursors.py", line 205, in execute
    self.errorhandler(self, exc, value)
  File "C:\Users\ipharmacare\python27\lib\site-packages\MySQLdb\connections.py", line 36, in defaulterrorhandler
    raise errorclass, errorvalue
OperationalError: (2006, 'MySQL server has gone away')
Thu, 15 Aug 2019 09:34:44 log.py[line:17] DEBUG 该指标在指标库中不存在,出院药品总品规数
Thu, 15 Aug 2019 09:34:44 log.py[line:17] DEBUG 该指标在指标库中不存在,住院手术患者预防使用抗菌药物用药时机合理率切皮前0.5-1h例次
Thu, 15 Aug 2019 09:34:44 connectionpool.py[line:393] DEBUG http://10.1.1.89:9999 "POST /syscenter/api/v1/currentUser HTTP/1.1" 200 None
Thu, 15 Aug 2019 09:34:44 connectionpool.py[line:393] DEBUG http://10.1.1.89:9999 "GET /syscenter/api/v1/config/selectSysConfig?showName=qty%E8%AE%A1%E7%AE%97%E6%96%B9%E6%B3%95 HTTP/1.1" 200 None
Thu, 15 Aug 2019 09:34:44 log.py[line:17] DEBUG 配置项错误
Thu, 15 Aug 2019 09:34:44 log.py[line:20] ERROR getZoneSQLvalue instance has no attribute 'sqlValue'
Traceback (most recent call last):
  File "C:\Users\ipharmacare\newreport\GetSQLvalue\itemZoneValue.py", line 351, in getSqlValue_zone
    sqlValue = self.getValueInddds(itemname,zoneid,startT,endT)[0]
  File "C:\Users\ipharmacare\newreport\GetSQLvalue\itemZoneValue.py", line 63, in getValueInddds
    return self.sqlValue
AttributeError: getZoneSQLvalue instance has no attribute 'sqlValue'
Thu, 15 Aug 2019 09:34:44 log.py[line:17] DEBUG 读取配置项发生了错误,zone,出院患者抗菌药物使用量（累计DDD数）(非出院带药)
Thu, 15 Aug 2019 09:34:44 log.py[line:20] ERROR No option '\xe5\x87\xba\xe9\x99\xa2\xe6\x82\xa3\xe8\x80\x85\xe6\x8a\x97\xe8\x8f\x8c\xe8\x8d\xaf\xe7\x89\xa9\xe4\xbd\xbf\xe7\x94\xa8\xe9\x87\x8f\xef\xbc\x88\xe7\xb4\xaf\xe8\xae\xa1ddd\xe6\x95\xb0\xef\xbc\x89(\xe9\x9d\x9e\xe5\x87\xba\xe9\x99\xa2\xe5\xb8\xa6\xe8\x8d\xaf)' in section: 'zone'
Traceback (most recent call last):
  File "C:\Users\ipharmacare\newreport\common\configReader.py", line 27, in get
    return self.conf.get(field,key)
  File "C:\Users\ipharmacare\python27\lib\ConfigParser.py", line 618, in get
    raise NoOptionError(option, section)
NoOptionError: No option '\xe5\x87\xba\xe9\x99\xa2\xe6\x82\xa3\xe8\x80\x85\xe6\x8a\x97\xe8\x8f\x8c\xe8\x8d\xaf\xe7\x89\xa9\xe4\xbd\xbf\xe7\x94\xa8\xe9\x87\x8f\xef\xbc\x88\xe7\xb4\xaf\xe8\xae\xa1ddd\xe6\x95\xb0\xef\xbc\x89(\xe9\x9d\x9e\xe5\x87\xba\xe9\x99\xa2\xe5\xb8\xa6\xe8\x8d\xaf)' in section: 'zone'
Thu, 15 Aug 2019 09:34:44 log.py[line:17] DEBUG 执行过程中出错
Thu, 15 Aug 2019 09:34:44 log.py[line:20] ERROR unsupported operand type(s) for %: 'NoneType' and 'tuple'
Traceback (most recent call last):
  File "C:\Users\ipharmacare\newreport\GetSQLvalue\itemZoneValue.py", line 334, in getSqlValue_zone
    sqlValue = self.getValueInCalc100(itemname, zoneid, startT, endT)
  File "C:\Users\ipharmacare\newreport\GetSQLvalue\itemZoneValue.py", line 144, in getValueInCalc100
    self.itemvalue_one = self.conndb.executeSQL_zoneid_one(self.cur, self.itemOneSql, zoneid, startT, endT)
  File "C:\Users\ipharmacare\newreport\common\connectDB.py", line 49, in executeSQL_zoneid_one
    cur.execute(sql, (zoneid, startT, endT))
  File "C:\Users\ipharmacare\python27\lib\site-packages\MySQLdb\cursors.py", line 187, in execute
    query = query % tuple([db.literal(item) for item in args])
TypeError: unsupported operand type(s) for %: 'NoneType' and 'tuple'
Thu, 15 Aug 2019 09:34:44 log.py[line:17] DEBUG 该指标在指标库中不存在,特殊使用级品规数
Thu, 15 Aug 2019 09:34:44 log.py[line:17] DEBUG 该指标在指标库中不存在,抗菌药物品规数
Thu, 15 Aug 2019 09:34:44 log.py[line:17] DEBUG 执行过程中出错
Thu, 15 Aug 2019 09:34:44 log.py[line:20] ERROR (2006, 'MySQL server has gone away')
Traceback (most recent call last):
  File "C:\Users\ipharmacare\newreport\GetSQLvalue\itemZoneValue.py", line 324, in getSqlValue_zone
    sqlValue = self.getValueInCalc(itemname, zoneid, startT, endT, self.optcalcminus)
  File "C:\Users\ipharmacare\newreport\GetSQLvalue\itemZoneValue.py", line 114, in getValueInCalc
    self.itemvalue_one = self.getCalc_Numerator_zone(self.itemnameOne, zoneid, startT, endT, optcalcminus)
  File "C:\Users\ipharmacare\newreport\GetSQLvalue\itemZoneValue.py", line 218, in getCalc_Numerator_zone
    self.itemvalue_one = self.conndb.executeSQL_zoneid_one(self.cur, self.itemOneSql, zoneid, startT, endT)
  File "C:\Users\ipharmacare\newreport\common\connectDB.py", line 49, in executeSQL_zoneid_one
    cur.execute(sql, (zoneid, startT, endT))
  File "C:\Users\ipharmacare\python27\lib\site-packages\MySQLdb\cursors.py", line 205, in execute
    self.errorhandler(self, exc, value)
  File "C:\Users\ipharmacare\python27\lib\site-packages\MySQLdb\connections.py", line 36, in defaulterrorhandler
    raise errorclass, errorvalue
OperationalError: (2006, 'MySQL server has gone away')
Thu, 15 Aug 2019 09:34:44 log.py[line:17] DEBUG 该指标在指标库中不存在,住院手术患者预防使用抗菌药物用药时机合理率切皮前0.5-1h比例
Thu, 15 Aug 2019 09:34:44 log.py[line:17] DEBUG 该指标在指标库中不存在,去年同期出院患者总人次
Thu, 15 Aug 2019 09:34:44 log.py[line:17] DEBUG 该指标在指标库中不存在,门诊去年同期就诊人次数
Thu, 15 Aug 2019 09:34:44 log.py[line:17] DEBUG 该指标在指标库中不存在,出院患者去年同期住院天数
Thu, 15 Aug 2019 09:34:44 log.py[line:17] DEBUG 该指标在指标库中不存在,出院患者去年同期药品金额
Thu, 15 Aug 2019 09:34:44 log.py[line:17] DEBUG 该指标在指标库中不存在,门诊就诊人次数同比增长(%)
Thu, 15 Aug 2019 09:34:44 log.py[line:17] DEBUG 读取配置项发生了错误,zone,门诊处方药品总金额
Thu, 15 Aug 2019 09:34:44 log.py[line:20] ERROR No option '\xe9\x97\xa8\xe8\xaf\x8a\xe5\xa4\x84\xe6\x96\xb9\xe8\x8d\xaf\xe5\x93\x81\xe6\x80\xbb\xe9\x87\x91\xe9\xa2\x9d' in section: 'zone'
Traceback (most recent call last):
  File "C:\Users\ipharmacare\newreport\common\configReader.py", line 27, in get
    return self.conf.get(field,key)
  File "C:\Users\ipharmacare\python27\lib\ConfigParser.py", line 618, in get
    raise NoOptionError(option, section)
NoOptionError: No option '\xe9\x97\xa8\xe8\xaf\x8a\xe5\xa4\x84\xe6\x96\xb9\xe8\x8d\xaf\xe5\x93\x81\xe6\x80\xbb\xe9\x87\x91\xe9\xa2\x9d' in section: 'zone'
Thu, 15 Aug 2019 09:34:44 log.py[line:17] DEBUG 执行过程中出错
Thu, 15 Aug 2019 09:34:44 log.py[line:20] ERROR unsupported operand type(s) for %: 'NoneType' and 'tuple'
Traceback (most recent call last):
  File "C:\Users\ipharmacare\newreport\GetSQLvalue\itemZoneValue.py", line 324, in getSqlValue_zone
    sqlValue = self.getValueInCalc(itemname, zoneid, startT, endT, self.optcalcminus)
  File "C:\Users\ipharmacare\newreport\GetSQLvalue\itemZoneValue.py", line 114, in getValueInCalc
    self.itemvalue_one = self.getCalc_Numerator_zone(self.itemnameOne, zoneid, startT, endT, optcalcminus)
  File "C:\Users\ipharmacare\newreport\GetSQLvalue\itemZoneValue.py", line 218, in getCalc_Numerator_zone
    self.itemvalue_one = self.conndb.executeSQL_zoneid_one(self.cur, self.itemOneSql, zoneid, startT, endT)
  File "C:\Users\ipharmacare\newreport\common\connectDB.py", line 49, in executeSQL_zoneid_one
    cur.execute(sql, (zoneid, startT, endT))
  File "C:\Users\ipharmacare\python27\lib\site-packages\MySQLdb\cursors.py", line 187, in execute
    query = query % tuple([db.literal(item) for item in args])
TypeError: unsupported operand type(s) for %: 'NoneType' and 'tuple'
Thu, 15 Aug 2019 09:34:44 log.py[line:17] DEBUG 该指标在指标库中不存在,门诊次均药费同比增长比率（%）
Thu, 15 Aug 2019 09:34:44 log.py[line:17] DEBUG 该指标在指标库中不存在,门诊次均药费同比增长金额
Thu, 15 Aug 2019 09:34:44 log.py[line:17] DEBUG 读取配置项发生了错误,zone,出院患者去年同期住院天数
Thu, 15 Aug 2019 09:34:44 log.py[line:20] ERROR No option '\xe5\x87\xba\xe9\x99\xa2\xe6\x82\xa3\xe8\x80\x85\xe5\x8e\xbb\xe5\xb9\xb4\xe5\x90\x8c\xe6\x9c\x9f\xe4\xbd\x8f\xe9\x99\xa2\xe5\xa4\xa9\xe6\x95\xb0' in section: 'zone'
Traceback (most recent call last):
  File "C:\Users\ipharmacare\newreport\common\configReader.py", line 27, in get
    return self.conf.get(field,key)
  File "C:\Users\ipharmacare\python27\lib\ConfigParser.py", line 618, in get
    raise NoOptionError(option, section)
NoOptionError: No option '\xe5\x87\xba\xe9\x99\xa2\xe6\x82\xa3\xe8\x80\x85\xe5\x8e\xbb\xe5\xb9\xb4\xe5\x90\x8c\xe6\x9c\x9f\xe4\xbd\x8f\xe9\x99\xa2\xe5\xa4\xa9\xe6\x95\xb0' in section: 'zone'
Thu, 15 Aug 2019 09:34:44 log.py[line:17] DEBUG 执行过程中出错
Thu, 15 Aug 2019 09:34:44 log.py[line:20] ERROR unsupported operand type(s) for %: 'NoneType' and 'tuple'
Traceback (most recent call last):
  File "C:\Users\ipharmacare\newreport\GetSQLvalue\itemZoneValue.py", line 324, in getSqlValue_zone
    sqlValue = self.getValueInCalc(itemname, zoneid, startT, endT, self.optcalcminus)
  File "C:\Users\ipharmacare\newreport\GetSQLvalue\itemZoneValue.py", line 114, in getValueInCalc
    self.itemvalue_one = self.getCalc_Numerator_zone(self.itemnameOne, zoneid, startT, endT, optcalcminus)
  File "C:\Users\ipharmacare\newreport\GetSQLvalue\itemZoneValue.py", line 218, in getCalc_Numerator_zone
    self.itemvalue_one = self.conndb.executeSQL_zoneid_one(self.cur, self.itemOneSql, zoneid, startT, endT)
  File "C:\Users\ipharmacare\newreport\common\connectDB.py", line 49, in executeSQL_zoneid_one
    cur.execute(sql, (zoneid, startT, endT))
  File "C:\Users\ipharmacare\python27\lib\site-packages\MySQLdb\cursors.py", line 187, in execute
    query = query % tuple([db.literal(item) for item in args])
TypeError: unsupported operand type(s) for %: 'NoneType' and 'tuple'
Thu, 15 Aug 2019 09:34:44 log.py[line:17] DEBUG 该指标在指标库中不存在,平均住院天数同比增长
Thu, 15 Aug 2019 09:34:44 log.py[line:17] DEBUG 执行过程中出错
Thu, 15 Aug 2019 09:34:44 log.py[line:20] ERROR (2006, 'MySQL server has gone away')
Traceback (most recent call last):
  File "C:\Users\ipharmacare\newreport\GetSQLvalue\itemZoneValue.py", line 324, in getSqlValue_zone
    sqlValue = self.getValueInCalc(itemname, zoneid, startT, endT, self.optcalcminus)
  File "C:\Users\ipharmacare\newreport\GetSQLvalue\itemZoneValue.py", line 114, in getValueInCalc
    self.itemvalue_one = self.getCalc_Numerator_zone(self.itemnameOne, zoneid, startT, endT, optcalcminus)
  File "C:\Users\ipharmacare\newreport\GetSQLvalue\itemZoneValue.py", line 218, in getCalc_Numerator_zone
    self.itemvalue_one = self.conndb.executeSQL_zoneid_one(self.cur, self.itemOneSql, zoneid, startT, endT)
  File "C:\Users\ipharmacare\newreport\common\connectDB.py", line 49, in executeSQL_zoneid_one
    cur.execute(sql, (zoneid, startT, endT))
  File "C:\Users\ipharmacare\python27\lib\site-packages\MySQLdb\cursors.py", line 205, in execute
    self.errorhandler(self, exc, value)
  File "C:\Users\ipharmacare\python27\lib\site-packages\MySQLdb\connections.py", line 36, in defaulterrorhandler
    raise errorclass, errorvalue
OperationalError: (2006, 'MySQL server has gone away')
Thu, 15 Aug 2019 09:34:44 log.py[line:17] DEBUG 该指标在指标库中不存在,出院患者次均药费同比增长比率（%）
Thu, 15 Aug 2019 09:34:44 log.py[line:17] DEBUG 该指标在指标库中不存在,出院患者次均药费同比增长金额
Thu, 15 Aug 2019 09:34:44 log.py[line:17] DEBUG 该指标在指标库中不存在,抗菌药物使用数量
Thu, 15 Aug 2019 09:34:44 log.py[line:17] DEBUG 该指标在指标库中不存在,门诊抗菌药物使用数量
Thu, 15 Aug 2019 09:34:44 log.py[line:17] DEBUG 该指标在指标库中不存在,使用数量
Thu, 15 Aug 2019 09:34:44 log.py[line:17] DEBUG 该指标在指标库中不存在,全院抗菌药物使用数量
Thu, 15 Aug 2019 09:34:44 log.py[line:17] DEBUG 该指标在指标库中不存在,出院患者使用特殊级抗菌药物输液金额2
Thu, 15 Aug 2019 09:34:44 log.py[line:17] DEBUG 执行过程中出错
Thu, 15 Aug 2019 09:34:44 log.py[line:20] ERROR (2006, 'MySQL server has gone away')
Traceback (most recent call last):
  File "C:\Users\ipharmacare\newreport\GetSQLvalue\itemZoneValue.py", line 314, in getSqlValue_zone
    sqlValue = self.getValueInZone(itemname, zoneid, startT, endT)
  File "C:\Users\ipharmacare\newreport\GetSQLvalue\itemZoneValue.py", line 43, in getValueInZone
    sqlValue = self.conndb.executeSQL_zoneid_one(self.cur, self.sql, zoneid, startT, endT)
  File "C:\Users\ipharmacare\newreport\common\connectDB.py", line 49, in executeSQL_zoneid_one
    cur.execute(sql, (zoneid, startT, endT))
  File "C:\Users\ipharmacare\python27\lib\site-packages\MySQLdb\cursors.py", line 205, in execute
    self.errorhandler(self, exc, value)
  File "C:\Users\ipharmacare\python27\lib\site-packages\MySQLdb\connections.py", line 36, in defaulterrorhandler
    raise errorclass, errorvalue
OperationalError: (2006, 'MySQL server has gone away')
Thu, 15 Aug 2019 09:34:44 log.py[line:17] DEBUG 该指标在指标库中不存在,出院药品总品规数
Thu, 15 Aug 2019 09:34:44 log.py[line:17] DEBUG 该指标在指标库中不存在,住院手术患者预防使用抗菌药物用药时机合理率切皮前0.5-1h例次
Thu, 15 Aug 2019 09:34:44 log.py[line:17] DEBUG 执行过程中出错
Thu, 15 Aug 2019 09:34:44 log.py[line:20] ERROR (2006, 'MySQL server has gone away')
Traceback (most recent call last):
  File "C:\Users\ipharmacare\newreport\GetSQLvalue\itemZoneValue.py", line 314, in getSqlValue_zone
    sqlValue = self.getValueInZone(itemname, zoneid, startT, endT)
  File "C:\Users\ipharmacare\newreport\GetSQLvalue\itemZoneValue.py", line 43, in getValueInZone
    sqlValue = self.conndb.executeSQL_zoneid_one(self.cur, self.sql, zoneid, startT, endT)
  File "C:\Users\ipharmacare\newreport\common\connectDB.py", line 49, in executeSQL_zoneid_one
    cur.execute(sql, (zoneid, startT, endT))
  File "C:\Users\ipharmacare\python27\lib\site-packages\MySQLdb\cursors.py", line 205, in execute
    self.errorhandler(self, exc, value)
  File "C:\Users\ipharmacare\python27\lib\site-packages\MySQLdb\connections.py", line 36, in defaulterrorhandler
    raise errorclass, errorvalue
OperationalError: (2006, 'MySQL server has gone away')
Fri, 16 Aug 2019 17:55:55 log.py[line:17] DEBUG 执行过程中出错
Fri, 16 Aug 2019 17:55:55 log.py[line:20] ERROR (2006, 'MySQL server has gone away')
Traceback (most recent call last):
  File "C:/Users/ipharmacare/newreport\GetSQLvalue\itemZoneValue.py", line 314, in getSqlValue_zone
    sqlValue = self.getValueInZone(itemname, zoneid, startT, endT)
  File "C:/Users/ipharmacare/newreport\GetSQLvalue\itemZoneValue.py", line 43, in getValueInZone
    sqlValue = self.conndb.executeSQL_zoneid_one(self.cur, self.sql, zoneid, startT, endT)
  File "C:/Users/ipharmacare/newreport\common\connectDB.py", line 49, in executeSQL_zoneid_one
    cur.execute(sql, (zoneid, startT, endT))
  File "C:\Users\ipharmacare\python27\lib\site-packages\MySQLdb\cursors.py", line 205, in execute
    self.errorhandler(self, exc, value)
  File "C:\Users\ipharmacare\python27\lib\site-packages\MySQLdb\connections.py", line 36, in defaulterrorhandler
    raise errorclass, errorvalue
OperationalError: (2006, 'MySQL server has gone away')
Fri, 16 Aug 2019 17:55:55 connectionpool.py[line:205] DEBUG Starting new HTTP connection (1): 10.1.1.89:9999
Fri, 16 Aug 2019 17:55:55 connectionpool.py[line:393] DEBUG http://10.1.1.89:9999 "POST /syscenter/api/v1/currentUser HTTP/1.1" 200 None
Fri, 16 Aug 2019 17:55:55 connectionpool.py[line:393] DEBUG http://10.1.1.89:9999 "GET /syscenter/api/v1/config/selectSysConfig?showName=%E6%8A%97%E8%8F%8C%E8%8D%AF%E7%89%A9%E9%80%81%E6%A3%80%E6%A0%87%E8%AF%86 HTTP/1.1" 200 None
Fri, 16 Aug 2019 17:55:55 log.py[line:17] DEBUG 执行过程中出错
Fri, 16 Aug 2019 17:55:55 log.py[line:20] ERROR (2006, 'MySQL server has gone away')
Traceback (most recent call last):
  File "C:/Users/ipharmacare/newreport\GetSQLvalue\itemZoneValue.py", line 314, in getSqlValue_zone
    sqlValue = self.getValueInZone(itemname, zoneid, startT, endT)
  File "C:/Users/ipharmacare/newreport\GetSQLvalue\itemZoneValue.py", line 43, in getValueInZone
    sqlValue = self.conndb.executeSQL_zoneid_one(self.cur, self.sql, zoneid, startT, endT)
  File "C:/Users/ipharmacare/newreport\common\connectDB.py", line 49, in executeSQL_zoneid_one
    cur.execute(sql, (zoneid, startT, endT))
  File "C:\Users\ipharmacare\python27\lib\site-packages\MySQLdb\cursors.py", line 205, in execute
    self.errorhandler(self, exc, value)
  File "C:\Users\ipharmacare\python27\lib\site-packages\MySQLdb\connections.py", line 36, in defaulterrorhandler
    raise errorclass, errorvalue
OperationalError: (2006, 'MySQL server has gone away')
Fri, 16 Aug 2019 17:55:55 log.py[line:17] DEBUG 执行过程中出错
Fri, 16 Aug 2019 17:55:55 log.py[line:20] ERROR (2006, 'MySQL server has gone away')
Traceback (most recent call last):
  File "C:/Users/ipharmacare/newreport\GetSQLvalue\itemZoneValue.py", line 314, in getSqlValue_zone
    sqlValue = self.getValueInZone(itemname, zoneid, startT, endT)
  File "C:/Users/ipharmacare/newreport\GetSQLvalue\itemZoneValue.py", line 43, in getValueInZone
    sqlValue = self.conndb.executeSQL_zoneid_one(self.cur, self.sql, zoneid, startT, endT)
  File "C:/Users/ipharmacare/newreport\common\connectDB.py", line 49, in executeSQL_zoneid_one
    cur.execute(sql, (zoneid, startT, endT))
  File "C:\Users\ipharmacare\python27\lib\site-packages\MySQLdb\cursors.py", line 205, in execute
    self.errorhandler(self, exc, value)
  File "C:\Users\ipharmacare\python27\lib\site-packages\MySQLdb\connections.py", line 36, in defaulterrorhandler
    raise errorclass, errorvalue
OperationalError: (2006, 'MySQL server has gone away')
Fri, 16 Aug 2019 17:55:55 log.py[line:17] DEBUG 执行过程中出错
Fri, 16 Aug 2019 17:55:55 log.py[line:20] ERROR (2006, 'MySQL server has gone away')
Traceback (most recent call last):
  File "C:/Users/ipharmacare/newreport\GetSQLvalue\itemZoneValue.py", line 314, in getSqlValue_zone
    sqlValue = self.getValueInZone(itemname, zoneid, startT, endT)
  File "C:/Users/ipharmacare/newreport\GetSQLvalue\itemZoneValue.py", line 43, in getValueInZone
    sqlValue = self.conndb.executeSQL_zoneid_one(self.cur, self.sql, zoneid, startT, endT)
  File "C:/Users/ipharmacare/newreport\common\connectDB.py", line 49, in executeSQL_zoneid_one
    cur.execute(sql, (zoneid, startT, endT))
  File "C:\Users\ipharmacare\python27\lib\site-packages\MySQLdb\cursors.py", line 205, in execute
    self.errorhandler(self, exc, value)
  File "C:\Users\ipharmacare\python27\lib\site-packages\MySQLdb\connections.py", line 36, in defaulterrorhandler
    raise errorclass, errorvalue
OperationalError: (2006, 'MySQL server has gone away')
Fri, 16 Aug 2019 17:55:55 log.py[line:17] DEBUG 执行过程中出错
Fri, 16 Aug 2019 17:55:55 log.py[line:20] ERROR (2006, 'MySQL server has gone away')
Traceback (most recent call last):
  File "C:/Users/ipharmacare/newreport\GetSQLvalue\itemZoneValue.py", line 314, in getSqlValue_zone
    sqlValue = self.getValueInZone(itemname, zoneid, startT, endT)
  File "C:/Users/ipharmacare/newreport\GetSQLvalue\itemZoneValue.py", line 43, in getValueInZone
    sqlValue = self.conndb.executeSQL_zoneid_one(self.cur, self.sql, zoneid, startT, endT)
  File "C:/Users/ipharmacare/newreport\common\connectDB.py", line 49, in executeSQL_zoneid_one
    cur.execute(sql, (zoneid, startT, endT))
  File "C:\Users\ipharmacare\python27\lib\site-packages\MySQLdb\cursors.py", line 205, in execute
    self.errorhandler(self, exc, value)
  File "C:\Users\ipharmacare\python27\lib\site-packages\MySQLdb\connections.py", line 36, in defaulterrorhandler
    raise errorclass, errorvalue
OperationalError: (2006, 'MySQL server has gone away')
Fri, 16 Aug 2019 17:55:55 log.py[line:17] DEBUG 执行过程中出错
Fri, 16 Aug 2019 17:55:55 log.py[line:20] ERROR (2006, 'MySQL server has gone away')
Traceback (most recent call last):
  File "C:/Users/ipharmacare/newreport\GetSQLvalue\itemZoneValue.py", line 314, in getSqlValue_zone
    sqlValue = self.getValueInZone(itemname, zoneid, startT, endT)
  File "C:/Users/ipharmacare/newreport\GetSQLvalue\itemZoneValue.py", line 43, in getValueInZone
    sqlValue = self.conndb.executeSQL_zoneid_one(self.cur, self.sql, zoneid, startT, endT)
  File "C:/Users/ipharmacare/newreport\common\connectDB.py", line 49, in executeSQL_zoneid_one
    cur.execute(sql, (zoneid, startT, endT))
  File "C:\Users\ipharmacare\python27\lib\site-packages\MySQLdb\cursors.py", line 205, in execute
    self.errorhandler(self, exc, value)
  File "C:\Users\ipharmacare\python27\lib\site-packages\MySQLdb\connections.py", line 36, in defaulterrorhandler
    raise errorclass, errorvalue
OperationalError: (2006, 'MySQL server has gone away')
Fri, 16 Aug 2019 17:55:55 log.py[line:17] DEBUG 执行过程中出错
Fri, 16 Aug 2019 17:55:55 log.py[line:20] ERROR (2006, 'MySQL server has gone away')
Traceback (most recent call last):
  File "C:/Users/ipharmacare/newreport\GetSQLvalue\itemZoneValue.py", line 314, in getSqlValue_zone
    sqlValue = self.getValueInZone(itemname, zoneid, startT, endT)
  File "C:/Users/ipharmacare/newreport\GetSQLvalue\itemZoneValue.py", line 43, in getValueInZone
    sqlValue = self.conndb.executeSQL_zoneid_one(self.cur, self.sql, zoneid, startT, endT)
  File "C:/Users/ipharmacare/newreport\common\connectDB.py", line 49, in executeSQL_zoneid_one
    cur.execute(sql, (zoneid, startT, endT))
  File "C:\Users\ipharmacare\python27\lib\site-packages\MySQLdb\cursors.py", line 205, in execute
    self.errorhandler(self, exc, value)
  File "C:\Users\ipharmacare\python27\lib\site-packages\MySQLdb\connections.py", line 36, in defaulterrorhandler
    raise errorclass, errorvalue
OperationalError: (2006, 'MySQL server has gone away')
Fri, 16 Aug 2019 17:55:55 log.py[line:17] DEBUG 执行过程中出错
Fri, 16 Aug 2019 17:55:55 log.py[line:20] ERROR (2006, 'MySQL server has gone away')
Traceback (most recent call last):
  File "C:/Users/ipharmacare/newreport\GetSQLvalue\itemZoneValue.py", line 314, in getSqlValue_zone
    sqlValue = self.getValueInZone(itemname, zoneid, startT, endT)
  File "C:/Users/ipharmacare/newreport\GetSQLvalue\itemZoneValue.py", line 43, in getValueInZone
    sqlValue = self.conndb.executeSQL_zoneid_one(self.cur, self.sql, zoneid, startT, endT)
  File "C:/Users/ipharmacare/newreport\common\connectDB.py", line 49, in executeSQL_zoneid_one
    cur.execute(sql, (zoneid, startT, endT))
  File "C:\Users\ipharmacare\python27\lib\site-packages\MySQLdb\cursors.py", line 205, in execute
    self.errorhandler(self, exc, value)
  File "C:\Users\ipharmacare\python27\lib\site-packages\MySQLdb\connections.py", line 36, in defaulterrorhandler
    raise errorclass, errorvalue
OperationalError: (2006, 'MySQL server has gone away')
Fri, 16 Aug 2019 17:55:55 log.py[line:17] DEBUG 执行过程中出错
Fri, 16 Aug 2019 17:55:55 log.py[line:20] ERROR (2006, 'MySQL server has gone away')
Traceback (most recent call last):
  File "C:/Users/ipharmacare/newreport\GetSQLvalue\itemZoneValue.py", line 314, in getSqlValue_zone
    sqlValue = self.getValueInZone(itemname, zoneid, startT, endT)
  File "C:/Users/ipharmacare/newreport\GetSQLvalue\itemZoneValue.py", line 43, in getValueInZone
    sqlValue = self.conndb.executeSQL_zoneid_one(self.cur, self.sql, zoneid, startT, endT)
  File "C:/Users/ipharmacare/newreport\common\connectDB.py", line 49, in executeSQL_zoneid_one
    cur.execute(sql, (zoneid, startT, endT))
  File "C:\Users\ipharmacare\python27\lib\site-packages\MySQLdb\cursors.py", line 205, in execute
    self.errorhandler(self, exc, value)
  File "C:\Users\ipharmacare\python27\lib\site-packages\MySQLdb\connections.py", line 36, in defaulterrorhandler
    raise errorclass, errorvalue
OperationalError: (2006, 'MySQL server has gone away')
Fri, 16 Aug 2019 17:55:55 log.py[line:17] DEBUG 执行过程中出错
Fri, 16 Aug 2019 17:55:55 log.py[line:20] ERROR (2006, 'MySQL server has gone away')
Traceback (most recent call last):
  File "C:/Users/ipharmacare/newreport\GetSQLvalue\itemZoneValue.py", line 314, in getSqlValue_zone
    sqlValue = self.getValueInZone(itemname, zoneid, startT, endT)
  File "C:/Users/ipharmacare/newreport\GetSQLvalue\itemZoneValue.py", line 43, in getValueInZone
    sqlValue = self.conndb.executeSQL_zoneid_one(self.cur, self.sql, zoneid, startT, endT)
  File "C:/Users/ipharmacare/newreport\common\connectDB.py", line 49, in executeSQL_zoneid_one
    cur.execute(sql, (zoneid, startT, endT))
  File "C:\Users\ipharmacare\python27\lib\site-packages\MySQLdb\cursors.py", line 205, in execute
    self.errorhandler(self, exc, value)
  File "C:\Users\ipharmacare\python27\lib\site-packages\MySQLdb\connections.py", line 36, in defaulterrorhandler
    raise errorclass, errorvalue
OperationalError: (2006, 'MySQL server has gone away')
Fri, 16 Aug 2019 17:55:55 log.py[line:17] DEBUG 执行过程中出错
Fri, 16 Aug 2019 17:55:55 log.py[line:20] ERROR (2006, 'MySQL server has gone away')
Traceback (most recent call last):
  File "C:/Users/ipharmacare/newreport\GetSQLvalue\itemZoneValue.py", line 314, in getSqlValue_zone
    sqlValue = self.getValueInZone(itemname, zoneid, startT, endT)
  File "C:/Users/ipharmacare/newreport\GetSQLvalue\itemZoneValue.py", line 43, in getValueInZone
    sqlValue = self.conndb.executeSQL_zoneid_one(self.cur, self.sql, zoneid, startT, endT)
  File "C:/Users/ipharmacare/newreport\common\connectDB.py", line 49, in executeSQL_zoneid_one
    cur.execute(sql, (zoneid, startT, endT))
  File "C:\Users\ipharmacare\python27\lib\site-packages\MySQLdb\cursors.py", line 205, in execute
    self.errorhandler(self, exc, value)
  File "C:\Users\ipharmacare\python27\lib\site-packages\MySQLdb\connections.py", line 36, in defaulterrorhandler
    raise errorclass, errorvalue
OperationalError: (2006, 'MySQL server has gone away')
Fri, 16 Aug 2019 17:55:55 log.py[line:17] DEBUG 执行过程中出错
Fri, 16 Aug 2019 17:55:55 log.py[line:20] ERROR (2006, 'MySQL server has gone away')
Traceback (most recent call last):
  File "C:/Users/ipharmacare/newreport\GetSQLvalue\itemZoneValue.py", line 314, in getSqlValue_zone
    sqlValue = self.getValueInZone(itemname, zoneid, startT, endT)
  File "C:/Users/ipharmacare/newreport\GetSQLvalue\itemZoneValue.py", line 43, in getValueInZone
    sqlValue = self.conndb.executeSQL_zoneid_one(self.cur, self.sql, zoneid, startT, endT)
  File "C:/Users/ipharmacare/newreport\common\connectDB.py", line 49, in executeSQL_zoneid_one
    cur.execute(sql, (zoneid, startT, endT))
  File "C:\Users\ipharmacare\python27\lib\site-packages\MySQLdb\cursors.py", line 205, in execute
    self.errorhandler(self, exc, value)
  File "C:\Users\ipharmacare\python27\lib\site-packages\MySQLdb\connections.py", line 36, in defaulterrorhandler
    raise errorclass, errorvalue
OperationalError: (2006, 'MySQL server has gone away')
Fri, 16 Aug 2019 17:55:55 log.py[line:17] DEBUG 执行过程中出错
Fri, 16 Aug 2019 17:55:55 log.py[line:20] ERROR (2006, 'MySQL server has gone away')
Traceback (most recent call last):
  File "C:/Users/ipharmacare/newreport\GetSQLvalue\itemZoneValue.py", line 314, in getSqlValue_zone
    sqlValue = self.getValueInZone(itemname, zoneid, startT, endT)
  File "C:/Users/ipharmacare/newreport\GetSQLvalue\itemZoneValue.py", line 43, in getValueInZone
    sqlValue = self.conndb.executeSQL_zoneid_one(self.cur, self.sql, zoneid, startT, endT)
  File "C:/Users/ipharmacare/newreport\common\connectDB.py", line 49, in executeSQL_zoneid_one
    cur.execute(sql, (zoneid, startT, endT))
  File "C:\Users\ipharmacare\python27\lib\site-packages\MySQLdb\cursors.py", line 205, in execute
    self.errorhandler(self, exc, value)
  File "C:\Users\ipharmacare\python27\lib\site-packages\MySQLdb\connections.py", line 36, in defaulterrorhandler
    raise errorclass, errorvalue
OperationalError: (2006, 'MySQL server has gone away')
Fri, 16 Aug 2019 17:55:56 connectionpool.py[line:205] DEBUG Starting new HTTP connection (1): 10.1.1.89:9999
Fri, 16 Aug 2019 17:55:56 connectionpool.py[line:393] DEBUG http://10.1.1.89:9999 "POST /syscenter/api/v1/currentUser HTTP/1.1" 200 None
Fri, 16 Aug 2019 17:55:56 connectionpool.py[line:393] DEBUG http://10.1.1.89:9999 "GET /syscenter/api/v1/config/selectSysConfig?showName=%E6%8A%97%E8%8F%8C%E8%8D%AF%E7%89%A9%E9%80%81%E6%A3%80%E6%A0%87%E8%AF%86 HTTP/1.1" 200 None
Fri, 16 Aug 2019 17:55:56 log.py[line:17] DEBUG 该指标在指标库中不存在,去年同期出院患者总人次
Fri, 16 Aug 2019 17:55:56 log.py[line:17] DEBUG 执行过程中出错
Fri, 16 Aug 2019 17:55:56 log.py[line:20] ERROR (2006, 'MySQL server has gone away')
Traceback (most recent call last):
  File "C:/Users/ipharmacare/newreport\GetSQLvalue\itemZoneValue.py", line 314, in getSqlValue_zone
    sqlValue = self.getValueInZone(itemname, zoneid, startT, endT)
  File "C:/Users/ipharmacare/newreport\GetSQLvalue\itemZoneValue.py", line 43, in getValueInZone
    sqlValue = self.conndb.executeSQL_zoneid_one(self.cur, self.sql, zoneid, startT, endT)
  File "C:/Users/ipharmacare/newreport\common\connectDB.py", line 49, in executeSQL_zoneid_one
    cur.execute(sql, (zoneid, startT, endT))
  File "C:\Users\ipharmacare\python27\lib\site-packages\MySQLdb\cursors.py", line 205, in execute
    self.errorhandler(self, exc, value)
  File "C:\Users\ipharmacare\python27\lib\site-packages\MySQLdb\connections.py", line 36, in defaulterrorhandler
    raise errorclass, errorvalue
OperationalError: (2006, 'MySQL server has gone away')
Fri, 16 Aug 2019 17:55:56 log.py[line:17] DEBUG 该指标在指标库中不存在,使用非限制级抗菌药物出院患者中病原学检查送检人次
Fri, 16 Aug 2019 17:55:56 log.py[line:17] DEBUG 该指标在指标库中不存在,使用限制级抗菌药物出院患者中病原学检查送检人次
Fri, 16 Aug 2019 17:55:56 log.py[line:17] DEBUG 该指标在指标库中不存在,使用特殊级抗菌药物出院患者中病原学检查送检人次
Fri, 16 Aug 2019 17:55:56 log.py[line:17] DEBUG 执行过程中出错
Fri, 16 Aug 2019 17:55:56 log.py[line:20] ERROR (2006, 'MySQL server has gone away')
Traceback (most recent call last):
  File "C:/Users/ipharmacare/newreport\GetSQLvalue\itemZoneValue.py", line 314, in getSqlValue_zone
    sqlValue = self.getValueInZone(itemname, zoneid, startT, endT)
  File "C:/Users/ipharmacare/newreport\GetSQLvalue\itemZoneValue.py", line 43, in getValueInZone
    sqlValue = self.conndb.executeSQL_zoneid_one(self.cur, self.sql, zoneid, startT, endT)
  File "C:/Users/ipharmacare/newreport\common\connectDB.py", line 49, in executeSQL_zoneid_one
    cur.execute(sql, (zoneid, startT, endT))
  File "C:\Users\ipharmacare\python27\lib\site-packages\MySQLdb\cursors.py", line 205, in execute
    self.errorhandler(self, exc, value)
  File "C:\Users\ipharmacare\python27\lib\site-packages\MySQLdb\connections.py", line 36, in defaulterrorhandler
    raise errorclass, errorvalue
OperationalError: (2006, 'MySQL server has gone away')
Fri, 16 Aug 2019 17:55:56 log.py[line:17] DEBUG 执行过程中出错
Fri, 16 Aug 2019 17:55:56 log.py[line:20] ERROR (2006, 'MySQL server has gone away')
Traceback (most recent call last):
  File "C:/Users/ipharmacare/newreport\GetSQLvalue\itemZoneValue.py", line 314, in getSqlValue_zone
    sqlValue = self.getValueInZone(itemname, zoneid, startT, endT)
  File "C:/Users/ipharmacare/newreport\GetSQLvalue\itemZoneValue.py", line 43, in getValueInZone
    sqlValue = self.conndb.executeSQL_zoneid_one(self.cur, self.sql, zoneid, startT, endT)
  File "C:/Users/ipharmacare/newreport\common\connectDB.py", line 49, in executeSQL_zoneid_one
    cur.execute(sql, (zoneid, startT, endT))
  File "C:\Users\ipharmacare\python27\lib\site-packages\MySQLdb\cursors.py", line 205, in execute
    self.errorhandler(self, exc, value)
  File "C:\Users\ipharmacare\python27\lib\site-packages\MySQLdb\connections.py", line 36, in defaulterrorhandler
    raise errorclass, errorvalue
OperationalError: (2006, 'MySQL server has gone away')
Fri, 16 Aug 2019 17:55:56 log.py[line:17] DEBUG 该指标在指标库中不存在,出院患者静脉输液总人次
Fri, 16 Aug 2019 17:55:56 log.py[line:17] DEBUG 执行过程中出错
Fri, 16 Aug 2019 17:55:56 log.py[line:20] ERROR (2006, 'MySQL server has gone away')
Traceback (most recent call last):
  File "C:/Users/ipharmacare/newreport\GetSQLvalue\itemZoneValue.py", line 314, in getSqlValue_zone
    sqlValue = self.getValueInZone(itemname, zoneid, startT, endT)
  File "C:/Users/ipharmacare/newreport\GetSQLvalue\itemZoneValue.py", line 43, in getValueInZone
    sqlValue = self.conndb.executeSQL_zoneid_one(self.cur, self.sql, zoneid, startT, endT)
  File "C:/Users/ipharmacare/newreport\common\connectDB.py", line 49, in executeSQL_zoneid_one
    cur.execute(sql, (zoneid, startT, endT))
  File "C:\Users\ipharmacare\python27\lib\site-packages\MySQLdb\cursors.py", line 205, in execute
    self.errorhandler(self, exc, value)
  File "C:\Users\ipharmacare\python27\lib\site-packages\MySQLdb\connections.py", line 36, in defaulterrorhandler
    raise errorclass, errorvalue
OperationalError: (2006, 'MySQL server has gone away')
Fri, 16 Aug 2019 17:55:56 log.py[line:17] DEBUG 该指标在指标库中不存在,出院患者总人次（排除中药饮片）
Fri, 16 Aug 2019 17:55:56 log.py[line:17] DEBUG 执行过程中出错
Fri, 16 Aug 2019 17:55:56 log.py[line:20] ERROR (2006, 'MySQL server has gone away')
Traceback (most recent call last):
  File "C:/Users/ipharmacare/newreport\GetSQLvalue\itemZoneValue.py", line 314, in getSqlValue_zone
    sqlValue = self.getValueInZone(itemname, zoneid, startT, endT)
  File "C:/Users/ipharmacare/newreport\GetSQLvalue\itemZoneValue.py", line 43, in getValueInZone
    sqlValue = self.conndb.executeSQL_zoneid_one(self.cur, self.sql, zoneid, startT, endT)
  File "C:/Users/ipharmacare/newreport\common\connectDB.py", line 49, in executeSQL_zoneid_one
    cur.execute(sql, (zoneid, startT, endT))
  File "C:\Users\ipharmacare\python27\lib\site-packages\MySQLdb\cursors.py", line 205, in execute
    self.errorhandler(self, exc, value)
  File "C:\Users\ipharmacare\python27\lib\site-packages\MySQLdb\connections.py", line 36, in defaulterrorhandler
    raise errorclass, errorvalue
OperationalError: (2006, 'MySQL server has gone away')
Fri, 16 Aug 2019 17:55:56 log.py[line:17] DEBUG 执行过程中出错
Fri, 16 Aug 2019 17:55:56 log.py[line:20] ERROR (2006, 'MySQL server has gone away')
Traceback (most recent call last):
  File "C:/Users/ipharmacare/newreport\GetSQLvalue\itemZoneValue.py", line 314, in getSqlValue_zone
    sqlValue = self.getValueInZone(itemname, zoneid, startT, endT)
  File "C:/Users/ipharmacare/newreport\GetSQLvalue\itemZoneValue.py", line 43, in getValueInZone
    sqlValue = self.conndb.executeSQL_zoneid_one(self.cur, self.sql, zoneid, startT, endT)
  File "C:/Users/ipharmacare/newreport\common\connectDB.py", line 49, in executeSQL_zoneid_one
    cur.execute(sql, (zoneid, startT, endT))
  File "C:\Users\ipharmacare\python27\lib\site-packages\MySQLdb\cursors.py", line 205, in execute
    self.errorhandler(self, exc, value)
  File "C:\Users\ipharmacare\python27\lib\site-packages\MySQLdb\connections.py", line 36, in defaulterrorhandler
    raise errorclass, errorvalue
OperationalError: (2006, 'MySQL server has gone away')
Fri, 16 Aug 2019 17:55:56 log.py[line:17] DEBUG 执行过程中出错
Fri, 16 Aug 2019 17:55:56 log.py[line:20] ERROR (2006, 'MySQL server has gone away')
Traceback (most recent call last):
  File "C:/Users/ipharmacare/newreport\GetSQLvalue\itemZoneValue.py", line 319, in getSqlValue_zone
    sqlValue = self.getValueInHospital(itemname, zoneid, startT, endT)
  File "C:/Users/ipharmacare/newreport\GetSQLvalue\itemZoneValue.py", line 73, in getValueInHospital
    sqlValue = self.conndb.executeSQL_zoneid_two(self.cur, self.sql, zoneid, startT, endT)
  File "C:/Users/ipharmacare/newreport\common\connectDB.py", line 54, in executeSQL_zoneid_two
    cur.execute(sql,(zoneid, startT, endT,zoneid, startT, endT))
  File "C:\Users\ipharmacare\python27\lib\site-packages\MySQLdb\cursors.py", line 205, in execute
    self.errorhandler(self, exc, value)
  File "C:\Users\ipharmacare\python27\lib\site-packages\MySQLdb\connections.py", line 36, in defaulterrorhandler
    raise errorclass, errorvalue
OperationalError: (2006, 'MySQL server has gone away')
Fri, 16 Aug 2019 17:55:56 log.py[line:17] DEBUG 该指标在指标库中不存在,住院省基药使用金额
Fri, 16 Aug 2019 17:55:56 log.py[line:17] DEBUG 该指标在指标库中不存在,门诊省基药使用金额
Fri, 16 Aug 2019 17:55:56 log.py[line:17] DEBUG 该指标在指标库中不存在,急诊省基药使用金额
