Tue, 23 Jul 2019 11:42:21 log.py[line:17] DEBUG 读取配置项发生了错误,mysql,host
Tue, 23 Jul 2019 11:42:21 log.py[line:20] ERROR No section: 'mysql'
Traceback (most recent call last):
  File "C:\Users\ipharmacare\newreport\common\configReader.py", line 27, in get
    return self.conf.get(field,key)
  File "C:\Users\ipharmacare\python27\lib\ConfigParser.py", line 607, in get
    raise NoSectionError(section)
NoSectionError: No section: 'mysql'
Tue, 23 Jul 2019 11:42:21 log.py[line:17] DEBUG 读取配置项发生了错误,mysql,port
Tue, 23 Jul 2019 11:42:21 log.py[line:20] ERROR No section: 'mysql'
Traceback (most recent call last):
  File "C:\Users\ipharmacare\newreport\common\configReader.py", line 37, in getint
    return self.conf.getint(field,key)
  File "C:\Users\ipharmacare\python27\lib\ConfigParser.py", line 359, in getint
    return self._get(section, int, option)
  File "C:\Users\ipharmacare\python27\lib\ConfigParser.py", line 356, in _get
    return conv(self.get(section, option))
  File "C:\Users\ipharmacare\python27\lib\ConfigParser.py", line 607, in get
    raise NoSectionError(section)
NoSectionError: No section: 'mysql'
Tue, 23 Jul 2019 11:42:21 log.py[line:17] DEBUG 读取配置项发生了错误,mysql,username
Tue, 23 Jul 2019 11:42:21 log.py[line:20] ERROR No section: 'mysql'
Traceback (most recent call last):
  File "C:\Users\ipharmacare\newreport\common\configReader.py", line 27, in get
    return self.conf.get(field,key)
  File "C:\Users\ipharmacare\python27\lib\ConfigParser.py", line 607, in get
    raise NoSectionError(section)
NoSectionError: No section: 'mysql'
Tue, 23 Jul 2019 11:42:21 log.py[line:17] DEBUG 读取配置项发生了错误,mysql,passwd
Tue, 23 Jul 2019 11:42:21 log.py[line:20] ERROR No section: 'mysql'
Traceback (most recent call last):
  File "C:\Users\ipharmacare\newreport\common\configReader.py", line 27, in get
    return self.conf.get(field,key)
  File "C:\Users\ipharmacare\python27\lib\ConfigParser.py", line 607, in get
    raise NoSectionError(section)
NoSectionError: No section: 'mysql'
Tue, 23 Jul 2019 11:42:21 log.py[line:17] DEBUG 读取配置项发生了错误,mysql,dbname_dp
Tue, 23 Jul 2019 11:42:21 log.py[line:20] ERROR No section: 'mysql'
Traceback (most recent call last):
  File "C:\Users\ipharmacare\newreport\common\configReader.py", line 27, in get
    return self.conf.get(field,key)
  File "C:\Users\ipharmacare\python27\lib\ConfigParser.py", line 607, in get
    raise NoSectionError(section)
NoSectionError: No section: 'mysql'
Tue, 23 Jul 2019 11:42:21 log.py[line:17] DEBUG 读取配置项发生了错误,mysql,dbname_sys
Tue, 23 Jul 2019 11:42:21 log.py[line:20] ERROR No section: 'mysql'
Traceback (most recent call last):
  File "C:\Users\ipharmacare\newreport\common\configReader.py", line 27, in get
    return self.conf.get(field,key)
  File "C:\Users\ipharmacare\python27\lib\ConfigParser.py", line 607, in get
    raise NoSectionError(section)
NoSectionError: No section: 'mysql'
Tue, 23 Jul 2019 11:42:21 log.py[line:17] DEBUG 读取配置项发生了错误,mysql,dbname_report
Tue, 23 Jul 2019 11:42:21 log.py[line:20] ERROR No section: 'mysql'
Traceback (most recent call last):
  File "C:\Users\ipharmacare\newreport\common\configReader.py", line 27, in get
    return self.conf.get(field,key)
  File "C:\Users\ipharmacare\python27\lib\ConfigParser.py", line 607, in get
    raise NoSectionError(section)
NoSectionError: No section: 'mysql'
Tue, 23 Jul 2019 11:42:21 log.py[line:17] DEBUG 读取配置项发生了错误,mysql,charset
Tue, 23 Jul 2019 11:42:21 log.py[line:20] ERROR No section: 'mysql'
Traceback (most recent call last):
  File "C:\Users\ipharmacare\newreport\common\configReader.py", line 27, in get
    return self.conf.get(field,key)
  File "C:\Users\ipharmacare\python27\lib\ConfigParser.py", line 607, in get
    raise NoSectionError(section)
NoSectionError: No section: 'mysql'
Tue, 23 Jul 2019 11:42:21 log.py[line:17] DEBUG 数据库连接出错
Tue, 23 Jul 2019 11:42:21 log.py[line:20] ERROR connect() argument 1 must be string, not None
Traceback (most recent call last):
  File "C:\Users\ipharmacare\newreport\common\connectDB.py", line 28, in connect
    return MySQLdb.Connect(host=self.host,port=self.port,user=self.username,passwd=self.passwd,db=dbname,charset=self.charset)
  File "C:\Users\ipharmacare\python27\lib\site-packages\MySQLdb\__init__.py", line 81, in Connect
    return Connection(*args, **kwargs)
  File "C:\Users\ipharmacare\python27\lib\site-packages\MySQLdb\connections.py", line 193, in __init__
    super(Connection, self).__init__(*args, **kwargs2)
TypeError: connect() argument 1 must be string, not None
Tue, 23 Jul 2019 11:42:21 log.py[line:17] DEBUG 读取配置项发生了错误,mysql,host
Tue, 23 Jul 2019 11:42:21 log.py[line:20] ERROR No section: 'mysql'
Traceback (most recent call last):
  File "C:\Users\ipharmacare\newreport\common\configReader.py", line 27, in get
    return self.conf.get(field,key)
  File "C:\Users\ipharmacare\python27\lib\ConfigParser.py", line 607, in get
    raise NoSectionError(section)
NoSectionError: No section: 'mysql'
Tue, 23 Jul 2019 11:42:21 log.py[line:17] DEBUG 读取配置项发生了错误,mysql,port
Tue, 23 Jul 2019 11:42:21 log.py[line:20] ERROR No section: 'mysql'
Traceback (most recent call last):
  File "C:\Users\ipharmacare\newreport\common\configReader.py", line 37, in getint
    return self.conf.getint(field,key)
  File "C:\Users\ipharmacare\python27\lib\ConfigParser.py", line 359, in getint
    return self._get(section, int, option)
  File "C:\Users\ipharmacare\python27\lib\ConfigParser.py", line 356, in _get
    return conv(self.get(section, option))
  File "C:\Users\ipharmacare\python27\lib\ConfigParser.py", line 607, in get
    raise NoSectionError(section)
NoSectionError: No section: 'mysql'
Tue, 23 Jul 2019 11:42:21 log.py[line:17] DEBUG 读取配置项发生了错误,mysql,username
Tue, 23 Jul 2019 11:42:21 log.py[line:20] ERROR No section: 'mysql'
Traceback (most recent call last):
  File "C:\Users\ipharmacare\newreport\common\configReader.py", line 27, in get
    return self.conf.get(field,key)
  File "C:\Users\ipharmacare\python27\lib\ConfigParser.py", line 607, in get
    raise NoSectionError(section)
NoSectionError: No section: 'mysql'
Tue, 23 Jul 2019 11:42:21 log.py[line:17] DEBUG 读取配置项发生了错误,mysql,passwd
Tue, 23 Jul 2019 11:42:21 log.py[line:20] ERROR No section: 'mysql'
Traceback (most recent call last):
  File "C:\Users\ipharmacare\newreport\common\configReader.py", line 27, in get
    return self.conf.get(field,key)
  File "C:\Users\ipharmacare\python27\lib\ConfigParser.py", line 607, in get
    raise NoSectionError(section)
NoSectionError: No section: 'mysql'
Tue, 23 Jul 2019 11:42:21 log.py[line:17] DEBUG 读取配置项发生了错误,mysql,dbname_dp
Tue, 23 Jul 2019 11:42:21 log.py[line:20] ERROR No section: 'mysql'
Traceback (most recent call last):
  File "C:\Users\ipharmacare\newreport\common\configReader.py", line 27, in get
    return self.conf.get(field,key)
  File "C:\Users\ipharmacare\python27\lib\ConfigParser.py", line 607, in get
    raise NoSectionError(section)
NoSectionError: No section: 'mysql'
Tue, 23 Jul 2019 11:42:21 log.py[line:17] DEBUG 读取配置项发生了错误,mysql,dbname_sys
Tue, 23 Jul 2019 11:42:21 log.py[line:20] ERROR No section: 'mysql'
Traceback (most recent call last):
  File "C:\Users\ipharmacare\newreport\common\configReader.py", line 27, in get
    return self.conf.get(field,key)
  File "C:\Users\ipharmacare\python27\lib\ConfigParser.py", line 607, in get
    raise NoSectionError(section)
NoSectionError: No section: 'mysql'
Tue, 23 Jul 2019 11:42:21 log.py[line:17] DEBUG 读取配置项发生了错误,mysql,dbname_report
Tue, 23 Jul 2019 11:42:21 log.py[line:20] ERROR No section: 'mysql'
Traceback (most recent call last):
  File "C:\Users\ipharmacare\newreport\common\configReader.py", line 27, in get
    return self.conf.get(field,key)
  File "C:\Users\ipharmacare\python27\lib\ConfigParser.py", line 607, in get
    raise NoSectionError(section)
NoSectionError: No section: 'mysql'
Tue, 23 Jul 2019 11:42:21 log.py[line:17] DEBUG 读取配置项发生了错误,mysql,charset
Tue, 23 Jul 2019 11:42:21 log.py[line:20] ERROR No section: 'mysql'
Traceback (most recent call last):
  File "C:\Users\ipharmacare\newreport\common\configReader.py", line 27, in get
    return self.conf.get(field,key)
  File "C:\Users\ipharmacare\python27\lib\ConfigParser.py", line 607, in get
    raise NoSectionError(section)
NoSectionError: No section: 'mysql'
Tue, 23 Jul 2019 11:42:21 log.py[line:17] DEBUG 数据库连接出错
Tue, 23 Jul 2019 11:42:21 log.py[line:20] ERROR connect() argument 1 must be string, not None
Traceback (most recent call last):
  File "C:\Users\ipharmacare\newreport\common\connectDB.py", line 28, in connect
    return MySQLdb.Connect(host=self.host,port=self.port,user=self.username,passwd=self.passwd,db=dbname,charset=self.charset)
  File "C:\Users\ipharmacare\python27\lib\site-packages\MySQLdb\__init__.py", line 81, in Connect
    return Connection(*args, **kwargs)
  File "C:\Users\ipharmacare\python27\lib\site-packages\MySQLdb\connections.py", line 193, in __init__
    super(Connection, self).__init__(*args, **kwargs2)
TypeError: connect() argument 1 must be string, not None
Tue, 23 Jul 2019 11:42:51 log.py[line:17] DEBUG 读取配置项发生了错误,hospital_doc
Tue, 23 Jul 2019 11:42:51 log.py[line:20] ERROR No section: 'hospital_doc'
Traceback (most recent call last):
  File "C:\Users\ipharmacare\newreport\common\configReader.py", line 50, in getitems
    result=self.conf.items(field)
  File "C:\Users\ipharmacare\python27\lib\ConfigParser.py", line 642, in items
    raise NoSectionError(section)
NoSectionError: No section: 'hospital_doc'
Tue, 23 Jul 2019 11:42:51 log.py[line:17] DEBUG 读取配置项发生了错误,default_doc
Tue, 23 Jul 2019 11:42:51 log.py[line:20] ERROR No section: 'default_doc'
Traceback (most recent call last):
  File "C:\Users\ipharmacare\newreport\common\configReader.py", line 50, in getitems
    result=self.conf.items(field)
  File "C:\Users\ipharmacare\python27\lib\ConfigParser.py", line 642, in items
    raise NoSectionError(section)
NoSectionError: No section: 'default_doc'
Tue, 23 Jul 2019 11:42:51 log.py[line:17] DEBUG 读取配置项发生了错误,ConfigurationItem_doc
Tue, 23 Jul 2019 11:42:51 log.py[line:20] ERROR No section: 'ConfigurationItem_doc'
Traceback (most recent call last):
  File "C:\Users\ipharmacare\newreport\common\configReader.py", line 50, in getitems
    result=self.conf.items(field)
  File "C:\Users\ipharmacare\python27\lib\ConfigParser.py", line 642, in items
    raise NoSectionError(section)
NoSectionError: No section: 'ConfigurationItem_doc'
Tue, 23 Jul 2019 11:42:51 log.py[line:17] DEBUG 读取配置项发生了错误,doc_ddds
Tue, 23 Jul 2019 11:42:51 log.py[line:20] ERROR No section: 'doc_ddds'
Traceback (most recent call last):
  File "C:\Users\ipharmacare\newreport\common\configReader.py", line 50, in getitems
    result=self.conf.items(field)
  File "C:\Users\ipharmacare\python27\lib\ConfigParser.py", line 642, in items
    raise NoSectionError(section)
NoSectionError: No section: 'doc_ddds'
Tue, 23 Jul 2019 11:42:51 log.py[line:17] DEBUG 读取配置项发生了错误,hospitalDoc_ddds
Tue, 23 Jul 2019 11:42:51 log.py[line:20] ERROR No section: 'hospitalDoc_ddds'
Traceback (most recent call last):
  File "C:\Users\ipharmacare\newreport\common\configReader.py", line 50, in getitems
    result=self.conf.items(field)
  File "C:\Users\ipharmacare\python27\lib\ConfigParser.py", line 642, in items
    raise NoSectionError(section)
NoSectionError: No section: 'hospitalDoc_ddds'
Tue, 23 Jul 2019 11:42:51 log.py[line:17] DEBUG 读取配置项发生了错误,hospital_dept
Tue, 23 Jul 2019 11:42:51 log.py[line:20] ERROR No section: 'hospital_dept'
Traceback (most recent call last):
  File "C:\Users\ipharmacare\newreport\common\configReader.py", line 50, in getitems
    result=self.conf.items(field)
  File "C:\Users\ipharmacare\python27\lib\ConfigParser.py", line 642, in items
    raise NoSectionError(section)
NoSectionError: No section: 'hospital_dept'
Tue, 23 Jul 2019 11:42:51 log.py[line:17] DEBUG 读取配置项发生了错误,default_dept
Tue, 23 Jul 2019 11:42:51 log.py[line:20] ERROR No section: 'default_dept'
Traceback (most recent call last):
  File "C:\Users\ipharmacare\newreport\common\configReader.py", line 50, in getitems
    result=self.conf.items(field)
  File "C:\Users\ipharmacare\python27\lib\ConfigParser.py", line 642, in items
    raise NoSectionError(section)
NoSectionError: No section: 'default_dept'
Tue, 23 Jul 2019 11:42:51 log.py[line:17] DEBUG 读取配置项发生了错误,ConfigurationItem_dept
Tue, 23 Jul 2019 11:42:51 log.py[line:20] ERROR No section: 'ConfigurationItem_dept'
Traceback (most recent call last):
  File "C:\Users\ipharmacare\newreport\common\configReader.py", line 50, in getitems
    result=self.conf.items(field)
  File "C:\Users\ipharmacare\python27\lib\ConfigParser.py", line 642, in items
    raise NoSectionError(section)
NoSectionError: No section: 'ConfigurationItem_dept'
Tue, 23 Jul 2019 11:42:51 log.py[line:17] DEBUG 读取配置项发生了错误,dept_ddds
Tue, 23 Jul 2019 11:42:51 log.py[line:20] ERROR No section: 'dept_ddds'
Traceback (most recent call last):
  File "C:\Users\ipharmacare\newreport\common\configReader.py", line 50, in getitems
    result=self.conf.items(field)
  File "C:\Users\ipharmacare\python27\lib\ConfigParser.py", line 642, in items
    raise NoSectionError(section)
NoSectionError: No section: 'dept_ddds'
Tue, 23 Jul 2019 11:42:51 log.py[line:17] DEBUG 读取配置项发生了错误,hospitalDept_ddds
Tue, 23 Jul 2019 11:42:51 log.py[line:20] ERROR No section: 'hospitalDept_ddds'
Traceback (most recent call last):
  File "C:\Users\ipharmacare\newreport\common\configReader.py", line 50, in getitems
    result=self.conf.items(field)
  File "C:\Users\ipharmacare\python27\lib\ConfigParser.py", line 642, in items
    raise NoSectionError(section)
NoSectionError: No section: 'hospitalDept_ddds'
Tue, 23 Jul 2019 11:42:51 log.py[line:17] DEBUG 读取配置项发生了错误,default_group
Tue, 23 Jul 2019 11:42:51 log.py[line:20] ERROR No section: 'default_group'
Traceback (most recent call last):
  File "C:\Users\ipharmacare\newreport\common\configReader.py", line 50, in getitems
    result=self.conf.items(field)
  File "C:\Users\ipharmacare\python27\lib\ConfigParser.py", line 642, in items
    raise NoSectionError(section)
NoSectionError: No section: 'default_group'
Tue, 23 Jul 2019 11:42:51 log.py[line:17] DEBUG 执行过程中出错
Tue, 23 Jul 2019 11:42:51 log.py[line:20] ERROR (1054, "Unknown column 'key_time' in 'field list'")
Traceback (most recent call last):
  File "C:\Users\ipharmacare\newreport\GetSQLvalue\itemZoneValue.py", line 314, in getSqlValue_zone
    sqlValue = self.getValueInZone(itemname, zoneid, startT, endT)
  File "C:\Users\ipharmacare\newreport\GetSQLvalue\itemZoneValue.py", line 43, in getValueInZone
    sqlValue = self.conndb.executeSQL_zoneid_one(self.cur, self.sql, zoneid, startT, endT)
  File "C:\Users\ipharmacare\newreport\common\connectDB.py", line 49, in executeSQL_zoneid_one
    cur.execute(sql, (zoneid, startT, endT))
  File "C:\Users\ipharmacare\python27\lib\site-packages\MySQLdb\cursors.py", line 205, in execute
    self.errorhandler(self, exc, value)
  File "C:\Users\ipharmacare\python27\lib\site-packages\MySQLdb\connections.py", line 36, in defaulterrorhandler
    raise errorclass, errorvalue
OperationalError: (1054, "Unknown column 'key_time' in 'field list'")
Tue, 23 Jul 2019 11:42:51 log.py[line:17] DEBUG 该指标在指标库中不存在,出院患者静脉输液总人次
Tue, 23 Jul 2019 11:42:51 log.py[line:17] DEBUG 该指标在指标库中不存在,出院患者抗菌药物预防使用人次
Tue, 23 Jul 2019 11:42:51 log.py[line:17] DEBUG 该指标在指标库中不存在,去年同期出院患者总人次
Tue, 23 Jul 2019 11:42:51 log.py[line:17] DEBUG 该指标在指标库中不存在,出院患者特殊级抗菌药物使用人次数
Tue, 23 Jul 2019 11:42:51 log.py[line:17] DEBUG 执行过程中出错
Tue, 23 Jul 2019 11:42:51 log.py[line:20] ERROR (1054, "Unknown column 'key_time' in 'field list'")
Traceback (most recent call last):
  File "C:\Users\ipharmacare\newreport\GetSQLvalue\itemZoneValue.py", line 314, in getSqlValue_zone
    sqlValue = self.getValueInZone(itemname, zoneid, startT, endT)
  File "C:\Users\ipharmacare\newreport\GetSQLvalue\itemZoneValue.py", line 43, in getValueInZone
    sqlValue = self.conndb.executeSQL_zoneid_one(self.cur, self.sql, zoneid, startT, endT)
  File "C:\Users\ipharmacare\newreport\common\connectDB.py", line 49, in executeSQL_zoneid_one
    cur.execute(sql, (zoneid, startT, endT))
  File "C:\Users\ipharmacare\python27\lib\site-packages\MySQLdb\cursors.py", line 205, in execute
    self.errorhandler(self, exc, value)
  File "C:\Users\ipharmacare\python27\lib\site-packages\MySQLdb\connections.py", line 36, in defaulterrorhandler
    raise errorclass, errorvalue
OperationalError: (1054, "Unknown column 'key_time' in 'field list'")
Tue, 23 Jul 2019 11:42:51 log.py[line:17] DEBUG 执行过程中出错
Tue, 23 Jul 2019 11:42:51 log.py[line:20] ERROR (1054, "Unknown column 'key_time' in 'field list'")
Traceback (most recent call last):
  File "C:\Users\ipharmacare\newreport\GetSQLvalue\itemZoneValue.py", line 314, in getSqlValue_zone
    sqlValue = self.getValueInZone(itemname, zoneid, startT, endT)
  File "C:\Users\ipharmacare\newreport\GetSQLvalue\itemZoneValue.py", line 43, in getValueInZone
    sqlValue = self.conndb.executeSQL_zoneid_one(self.cur, self.sql, zoneid, startT, endT)
  File "C:\Users\ipharmacare\newreport\common\connectDB.py", line 49, in executeSQL_zoneid_one
    cur.execute(sql, (zoneid, startT, endT))
  File "C:\Users\ipharmacare\python27\lib\site-packages\MySQLdb\cursors.py", line 205, in execute
    self.errorhandler(self, exc, value)
  File "C:\Users\ipharmacare\python27\lib\site-packages\MySQLdb\connections.py", line 36, in defaulterrorhandler
    raise errorclass, errorvalue
OperationalError: (1054, "Unknown column 'key_time' in 'field list'")
Tue, 23 Jul 2019 11:42:51 log.py[line:17] DEBUG 该指标在指标库中不存在,使用非限制级抗菌药物出院患者中病原学检查送检人次
Tue, 23 Jul 2019 11:42:51 log.py[line:17] DEBUG 该指标在指标库中不存在,使用限制级抗菌药物出院患者中病原学检查送检人次
Tue, 23 Jul 2019 11:42:51 log.py[line:17] DEBUG 该指标在指标库中不存在,使用特殊级抗菌药物出院患者中病原学检查送检人次
Tue, 23 Jul 2019 11:42:51 log.py[line:17] DEBUG 执行过程中出错
Tue, 23 Jul 2019 11:42:51 log.py[line:20] ERROR (1054, "Unknown column 'key_time' in 'field list'")
Traceback (most recent call last):
  File "C:\Users\ipharmacare\newreport\GetSQLvalue\itemZoneValue.py", line 314, in getSqlValue_zone
    sqlValue = self.getValueInZone(itemname, zoneid, startT, endT)
  File "C:\Users\ipharmacare\newreport\GetSQLvalue\itemZoneValue.py", line 43, in getValueInZone
    sqlValue = self.conndb.executeSQL_zoneid_one(self.cur, self.sql, zoneid, startT, endT)
  File "C:\Users\ipharmacare\newreport\common\connectDB.py", line 49, in executeSQL_zoneid_one
    cur.execute(sql, (zoneid, startT, endT))
  File "C:\Users\ipharmacare\python27\lib\site-packages\MySQLdb\cursors.py", line 205, in execute
    self.errorhandler(self, exc, value)
  File "C:\Users\ipharmacare\python27\lib\site-packages\MySQLdb\connections.py", line 36, in defaulterrorhandler
    raise errorclass, errorvalue
OperationalError: (1054, "Unknown column 'key_time' in 'field list'")
Tue, 23 Jul 2019 11:42:51 log.py[line:17] DEBUG 该指标在指标库中不存在,出院患者静脉输液总人次
Tue, 23 Jul 2019 11:42:51 log.py[line:17] DEBUG 执行过程中出错
Tue, 23 Jul 2019 11:42:51 log.py[line:20] ERROR (1054, "Unknown column 'key_time' in 'field list'")
Traceback (most recent call last):
  File "C:\Users\ipharmacare\newreport\GetSQLvalue\itemZoneValue.py", line 314, in getSqlValue_zone
    sqlValue = self.getValueInZone(itemname, zoneid, startT, endT)
  File "C:\Users\ipharmacare\newreport\GetSQLvalue\itemZoneValue.py", line 43, in getValueInZone
    sqlValue = self.conndb.executeSQL_zoneid_one(self.cur, self.sql, zoneid, startT, endT)
  File "C:\Users\ipharmacare\newreport\common\connectDB.py", line 49, in executeSQL_zoneid_one
    cur.execute(sql, (zoneid, startT, endT))
  File "C:\Users\ipharmacare\python27\lib\site-packages\MySQLdb\cursors.py", line 205, in execute
    self.errorhandler(self, exc, value)
  File "C:\Users\ipharmacare\python27\lib\site-packages\MySQLdb\connections.py", line 36, in defaulterrorhandler
    raise errorclass, errorvalue
OperationalError: (1054, "Unknown column 'key_time' in 'field list'")
Tue, 23 Jul 2019 11:42:51 log.py[line:17] DEBUG 该指标在指标库中不存在,出院患者总人次（排除中药饮片）
Tue, 23 Jul 2019 11:42:51 log.py[line:17] DEBUG 执行过程中出错
Tue, 23 Jul 2019 11:42:51 log.py[line:20] ERROR (1054, "Unknown column 'key_time' in 'field list'")
Traceback (most recent call last):
  File "C:\Users\ipharmacare\newreport\GetSQLvalue\itemZoneValue.py", line 314, in getSqlValue_zone
    sqlValue = self.getValueInZone(itemname, zoneid, startT, endT)
  File "C:\Users\ipharmacare\newreport\GetSQLvalue\itemZoneValue.py", line 43, in getValueInZone
    sqlValue = self.conndb.executeSQL_zoneid_one(self.cur, self.sql, zoneid, startT, endT)
  File "C:\Users\ipharmacare\newreport\common\connectDB.py", line 49, in executeSQL_zoneid_one
    cur.execute(sql, (zoneid, startT, endT))
  File "C:\Users\ipharmacare\python27\lib\site-packages\MySQLdb\cursors.py", line 205, in execute
    self.errorhandler(self, exc, value)
  File "C:\Users\ipharmacare\python27\lib\site-packages\MySQLdb\connections.py", line 36, in defaulterrorhandler
    raise errorclass, errorvalue
OperationalError: (1054, "Unknown column 'key_time' in 'field list'")
Tue, 23 Jul 2019 11:42:51 connectionpool.py[line:205] DEBUG Starting new HTTP connection (1): 10.1.1.89:9999
Tue, 23 Jul 2019 11:42:51 connectionpool.py[line:393] DEBUG http://10.1.1.89:9999 "POST /syscenter/api/v1/currentUser HTTP/1.1" 200 None
Tue, 23 Jul 2019 11:42:51 connectionpool.py[line:393] DEBUG http://10.1.1.89:9999 "GET /syscenter/api/v1/config/selectSysConfig?showName=%E6%8A%97%E8%8F%8C%E8%8D%AF%E7%89%A9%E9%80%81%E6%A3%80%E6%A0%87%E8%AF%86 HTTP/1.1" 200 None
Tue, 23 Jul 2019 11:42:57 log.py[line:17] DEBUG 执行过程中出错
Tue, 23 Jul 2019 11:42:57 log.py[line:20] ERROR (1054, "Unknown column 'key_time' in 'field list'")
Traceback (most recent call last):
  File "C:\Users\ipharmacare\newreport\GetSQLvalue\itemZoneValue.py", line 314, in getSqlValue_zone
    sqlValue = self.getValueInZone(itemname, zoneid, startT, endT)
  File "C:\Users\ipharmacare\newreport\GetSQLvalue\itemZoneValue.py", line 43, in getValueInZone
    sqlValue = self.conndb.executeSQL_zoneid_one(self.cur, self.sql, zoneid, startT, endT)
  File "C:\Users\ipharmacare\newreport\common\connectDB.py", line 49, in executeSQL_zoneid_one
    cur.execute(sql, (zoneid, startT, endT))
  File "C:\Users\ipharmacare\python27\lib\site-packages\MySQLdb\cursors.py", line 205, in execute
    self.errorhandler(self, exc, value)
  File "C:\Users\ipharmacare\python27\lib\site-packages\MySQLdb\connections.py", line 36, in defaulterrorhandler
    raise errorclass, errorvalue
OperationalError: (1054, "Unknown column 'key_time' in 'field list'")
Tue, 23 Jul 2019 11:42:57 log.py[line:17] DEBUG 执行过程中出错
Tue, 23 Jul 2019 11:42:57 log.py[line:20] ERROR (1054, "Unknown column 'key_time' in 'field list'")
Traceback (most recent call last):
  File "C:\Users\ipharmacare\newreport\GetSQLvalue\itemZoneValue.py", line 314, in getSqlValue_zone
    sqlValue = self.getValueInZone(itemname, zoneid, startT, endT)
  File "C:\Users\ipharmacare\newreport\GetSQLvalue\itemZoneValue.py", line 43, in getValueInZone
    sqlValue = self.conndb.executeSQL_zoneid_one(self.cur, self.sql, zoneid, startT, endT)
  File "C:\Users\ipharmacare\newreport\common\connectDB.py", line 49, in executeSQL_zoneid_one
    cur.execute(sql, (zoneid, startT, endT))
  File "C:\Users\ipharmacare\python27\lib\site-packages\MySQLdb\cursors.py", line 205, in execute
    self.errorhandler(self, exc, value)
  File "C:\Users\ipharmacare\python27\lib\site-packages\MySQLdb\connections.py", line 36, in defaulterrorhandler
    raise errorclass, errorvalue
OperationalError: (1054, "Unknown column 'key_time' in 'field list'")
Tue, 23 Jul 2019 11:42:57 log.py[line:17] DEBUG 执行过程中出错
Tue, 23 Jul 2019 11:42:57 log.py[line:20] ERROR (1054, "Unknown column 'key_time' in 'field list'")
Traceback (most recent call last):
  File "C:\Users\ipharmacare\newreport\GetSQLvalue\itemZoneValue.py", line 314, in getSqlValue_zone
    sqlValue = self.getValueInZone(itemname, zoneid, startT, endT)
  File "C:\Users\ipharmacare\newreport\GetSQLvalue\itemZoneValue.py", line 43, in getValueInZone
    sqlValue = self.conndb.executeSQL_zoneid_one(self.cur, self.sql, zoneid, startT, endT)
  File "C:\Users\ipharmacare\newreport\common\connectDB.py", line 49, in executeSQL_zoneid_one
    cur.execute(sql, (zoneid, startT, endT))
  File "C:\Users\ipharmacare\python27\lib\site-packages\MySQLdb\cursors.py", line 205, in execute
    self.errorhandler(self, exc, value)
  File "C:\Users\ipharmacare\python27\lib\site-packages\MySQLdb\connections.py", line 36, in defaulterrorhandler
    raise errorclass, errorvalue
OperationalError: (1054, "Unknown column 'key_time' in 'field list'")
Tue, 23 Jul 2019 11:42:57 log.py[line:17] DEBUG 执行过程中出错
Tue, 23 Jul 2019 11:42:57 log.py[line:20] ERROR (1054, "Unknown column 'key_time' in 'field list'")
Traceback (most recent call last):
  File "C:\Users\ipharmacare\newreport\GetSQLvalue\itemZoneValue.py", line 314, in getSqlValue_zone
    sqlValue = self.getValueInZone(itemname, zoneid, startT, endT)
  File "C:\Users\ipharmacare\newreport\GetSQLvalue\itemZoneValue.py", line 43, in getValueInZone
    sqlValue = self.conndb.executeSQL_zoneid_one(self.cur, self.sql, zoneid, startT, endT)
  File "C:\Users\ipharmacare\newreport\common\connectDB.py", line 49, in executeSQL_zoneid_one
    cur.execute(sql, (zoneid, startT, endT))
  File "C:\Users\ipharmacare\python27\lib\site-packages\MySQLdb\cursors.py", line 205, in execute
    self.errorhandler(self, exc, value)
  File "C:\Users\ipharmacare\python27\lib\site-packages\MySQLdb\connections.py", line 36, in defaulterrorhandler
    raise errorclass, errorvalue
OperationalError: (1054, "Unknown column 'key_time' in 'field list'")
Tue, 23 Jul 2019 11:42:57 log.py[line:17] DEBUG 执行过程中出错
Tue, 23 Jul 2019 11:42:57 log.py[line:20] ERROR (1054, "Unknown column 'key_time' in 'field list'")
Traceback (most recent call last):
  File "C:\Users\ipharmacare\newreport\GetSQLvalue\itemZoneValue.py", line 314, in getSqlValue_zone
    sqlValue = self.getValueInZone(itemname, zoneid, startT, endT)
  File "C:\Users\ipharmacare\newreport\GetSQLvalue\itemZoneValue.py", line 43, in getValueInZone
    sqlValue = self.conndb.executeSQL_zoneid_one(self.cur, self.sql, zoneid, startT, endT)
  File "C:\Users\ipharmacare\newreport\common\connectDB.py", line 49, in executeSQL_zoneid_one
    cur.execute(sql, (zoneid, startT, endT))
  File "C:\Users\ipharmacare\python27\lib\site-packages\MySQLdb\cursors.py", line 205, in execute
    self.errorhandler(self, exc, value)
  File "C:\Users\ipharmacare\python27\lib\site-packages\MySQLdb\connections.py", line 36, in defaulterrorhandler
    raise errorclass, errorvalue
OperationalError: (1054, "Unknown column 'key_time' in 'field list'")
Tue, 23 Jul 2019 11:42:57 log.py[line:17] DEBUG 执行过程中出错
Tue, 23 Jul 2019 11:42:57 log.py[line:20] ERROR (1054, "Unknown column 'key_time' in 'field list'")
Traceback (most recent call last):
  File "C:\Users\ipharmacare\newreport\GetSQLvalue\itemZoneValue.py", line 314, in getSqlValue_zone
    sqlValue = self.getValueInZone(itemname, zoneid, startT, endT)
  File "C:\Users\ipharmacare\newreport\GetSQLvalue\itemZoneValue.py", line 43, in getValueInZone
    sqlValue = self.conndb.executeSQL_zoneid_one(self.cur, self.sql, zoneid, startT, endT)
  File "C:\Users\ipharmacare\newreport\common\connectDB.py", line 49, in executeSQL_zoneid_one
    cur.execute(sql, (zoneid, startT, endT))
  File "C:\Users\ipharmacare\python27\lib\site-packages\MySQLdb\cursors.py", line 205, in execute
    self.errorhandler(self, exc, value)
  File "C:\Users\ipharmacare\python27\lib\site-packages\MySQLdb\connections.py", line 36, in defaulterrorhandler
    raise errorclass, errorvalue
OperationalError: (1054, "Unknown column 'key_time' in 'field list'")
Tue, 23 Jul 2019 11:42:57 log.py[line:17] DEBUG 执行过程中出错
Tue, 23 Jul 2019 11:42:57 log.py[line:20] ERROR (1054, "Unknown column 'key_time' in 'field list'")
Traceback (most recent call last):
  File "C:\Users\ipharmacare\newreport\GetSQLvalue\itemZoneValue.py", line 314, in getSqlValue_zone
    sqlValue = self.getValueInZone(itemname, zoneid, startT, endT)
  File "C:\Users\ipharmacare\newreport\GetSQLvalue\itemZoneValue.py", line 43, in getValueInZone
    sqlValue = self.conndb.executeSQL_zoneid_one(self.cur, self.sql, zoneid, startT, endT)
  File "C:\Users\ipharmacare\newreport\common\connectDB.py", line 49, in executeSQL_zoneid_one
    cur.execute(sql, (zoneid, startT, endT))
  File "C:\Users\ipharmacare\python27\lib\site-packages\MySQLdb\cursors.py", line 205, in execute
    self.errorhandler(self, exc, value)
  File "C:\Users\ipharmacare\python27\lib\site-packages\MySQLdb\connections.py", line 36, in defaulterrorhandler
    raise errorclass, errorvalue
OperationalError: (1054, "Unknown column 'key_time' in 'field list'")
Tue, 23 Jul 2019 11:42:57 log.py[line:17] DEBUG 执行过程中出错
Tue, 23 Jul 2019 11:42:57 log.py[line:20] ERROR (1054, "Unknown column 'key_time' in 'field list'")
Traceback (most recent call last):
  File "C:\Users\ipharmacare\newreport\GetSQLvalue\itemZoneValue.py", line 314, in getSqlValue_zone
    sqlValue = self.getValueInZone(itemname, zoneid, startT, endT)
  File "C:\Users\ipharmacare\newreport\GetSQLvalue\itemZoneValue.py", line 43, in getValueInZone
    sqlValue = self.conndb.executeSQL_zoneid_one(self.cur, self.sql, zoneid, startT, endT)
  File "C:\Users\ipharmacare\newreport\common\connectDB.py", line 49, in executeSQL_zoneid_one
    cur.execute(sql, (zoneid, startT, endT))
  File "C:\Users\ipharmacare\python27\lib\site-packages\MySQLdb\cursors.py", line 205, in execute
    self.errorhandler(self, exc, value)
  File "C:\Users\ipharmacare\python27\lib\site-packages\MySQLdb\connections.py", line 36, in defaulterrorhandler
    raise errorclass, errorvalue
OperationalError: (1054, "Unknown column 'key_time' in 'field list'")
Tue, 23 Jul 2019 11:42:57 connectionpool.py[line:205] DEBUG Starting new HTTP connection (1): 10.1.1.89:9999
Tue, 23 Jul 2019 11:42:57 connectionpool.py[line:393] DEBUG http://10.1.1.89:9999 "POST /syscenter/api/v1/currentUser HTTP/1.1" 200 None
Tue, 23 Jul 2019 11:42:57 connectionpool.py[line:393] DEBUG http://10.1.1.89:9999 "GET /syscenter/api/v1/config/selectSysConfig?showName=%E6%8A%97%E8%8F%8C%E8%8D%AF%E7%89%A9%E9%80%81%E6%A3%80%E6%A0%87%E8%AF%86 HTTP/1.1" 200 None
Tue, 23 Jul 2019 11:44:42 log.py[line:17] DEBUG 读取配置项发生了错误,hospital_doc
Tue, 23 Jul 2019 11:44:42 log.py[line:20] ERROR No section: 'hospital_doc'
Traceback (most recent call last):
  File "C:\Users\ipharmacare\newreport\common\configReader.py", line 50, in getitems
    result=self.conf.items(field)
  File "C:\Users\ipharmacare\python27\lib\ConfigParser.py", line 642, in items
    raise NoSectionError(section)
NoSectionError: No section: 'hospital_doc'
Tue, 23 Jul 2019 11:44:42 log.py[line:17] DEBUG 读取配置项发生了错误,default_doc
Tue, 23 Jul 2019 11:44:42 log.py[line:20] ERROR No section: 'default_doc'
Traceback (most recent call last):
  File "C:\Users\ipharmacare\newreport\common\configReader.py", line 50, in getitems
    result=self.conf.items(field)
  File "C:\Users\ipharmacare\python27\lib\ConfigParser.py", line 642, in items
    raise NoSectionError(section)
NoSectionError: No section: 'default_doc'
Tue, 23 Jul 2019 11:44:42 log.py[line:17] DEBUG 读取配置项发生了错误,ConfigurationItem_doc
Tue, 23 Jul 2019 11:44:42 log.py[line:20] ERROR No section: 'ConfigurationItem_doc'
Traceback (most recent call last):
  File "C:\Users\ipharmacare\newreport\common\configReader.py", line 50, in getitems
    result=self.conf.items(field)
  File "C:\Users\ipharmacare\python27\lib\ConfigParser.py", line 642, in items
    raise NoSectionError(section)
NoSectionError: No section: 'ConfigurationItem_doc'
Tue, 23 Jul 2019 11:44:42 log.py[line:17] DEBUG 读取配置项发生了错误,doc_ddds
Tue, 23 Jul 2019 11:44:42 log.py[line:20] ERROR No section: 'doc_ddds'
Traceback (most recent call last):
  File "C:\Users\ipharmacare\newreport\common\configReader.py", line 50, in getitems
    result=self.conf.items(field)
  File "C:\Users\ipharmacare\python27\lib\ConfigParser.py", line 642, in items
    raise NoSectionError(section)
NoSectionError: No section: 'doc_ddds'
Tue, 23 Jul 2019 11:44:42 log.py[line:17] DEBUG 读取配置项发生了错误,hospitalDoc_ddds
Tue, 23 Jul 2019 11:44:42 log.py[line:20] ERROR No section: 'hospitalDoc_ddds'
Traceback (most recent call last):
  File "C:\Users\ipharmacare\newreport\common\configReader.py", line 50, in getitems
    result=self.conf.items(field)
  File "C:\Users\ipharmacare\python27\lib\ConfigParser.py", line 642, in items
    raise NoSectionError(section)
NoSectionError: No section: 'hospitalDoc_ddds'
Tue, 23 Jul 2019 11:44:42 log.py[line:17] DEBUG 读取配置项发生了错误,hospital_dept
Tue, 23 Jul 2019 11:44:42 log.py[line:20] ERROR No section: 'hospital_dept'
Traceback (most recent call last):
  File "C:\Users\ipharmacare\newreport\common\configReader.py", line 50, in getitems
    result=self.conf.items(field)
  File "C:\Users\ipharmacare\python27\lib\ConfigParser.py", line 642, in items
    raise NoSectionError(section)
NoSectionError: No section: 'hospital_dept'
Tue, 23 Jul 2019 11:44:42 log.py[line:17] DEBUG 读取配置项发生了错误,default_dept
Tue, 23 Jul 2019 11:44:42 log.py[line:20] ERROR No section: 'default_dept'
Traceback (most recent call last):
  File "C:\Users\ipharmacare\newreport\common\configReader.py", line 50, in getitems
    result=self.conf.items(field)
  File "C:\Users\ipharmacare\python27\lib\ConfigParser.py", line 642, in items
    raise NoSectionError(section)
NoSectionError: No section: 'default_dept'
Tue, 23 Jul 2019 11:44:42 log.py[line:17] DEBUG 读取配置项发生了错误,ConfigurationItem_dept
Tue, 23 Jul 2019 11:44:42 log.py[line:20] ERROR No section: 'ConfigurationItem_dept'
Traceback (most recent call last):
  File "C:\Users\ipharmacare\newreport\common\configReader.py", line 50, in getitems
    result=self.conf.items(field)
  File "C:\Users\ipharmacare\python27\lib\ConfigParser.py", line 642, in items
    raise NoSectionError(section)
NoSectionError: No section: 'ConfigurationItem_dept'
Tue, 23 Jul 2019 11:44:42 log.py[line:17] DEBUG 读取配置项发生了错误,dept_ddds
Tue, 23 Jul 2019 11:44:42 log.py[line:20] ERROR No section: 'dept_ddds'
Traceback (most recent call last):
  File "C:\Users\ipharmacare\newreport\common\configReader.py", line 50, in getitems
    result=self.conf.items(field)
  File "C:\Users\ipharmacare\python27\lib\ConfigParser.py", line 642, in items
    raise NoSectionError(section)
NoSectionError: No section: 'dept_ddds'
Tue, 23 Jul 2019 11:44:42 log.py[line:17] DEBUG 读取配置项发生了错误,hospitalDept_ddds
Tue, 23 Jul 2019 11:44:42 log.py[line:20] ERROR No section: 'hospitalDept_ddds'
Traceback (most recent call last):
  File "C:\Users\ipharmacare\newreport\common\configReader.py", line 50, in getitems
    result=self.conf.items(field)
  File "C:\Users\ipharmacare\python27\lib\ConfigParser.py", line 642, in items
    raise NoSectionError(section)
NoSectionError: No section: 'hospitalDept_ddds'
Tue, 23 Jul 2019 11:44:42 log.py[line:17] DEBUG 读取配置项发生了错误,default_group
Tue, 23 Jul 2019 11:44:42 log.py[line:20] ERROR No section: 'default_group'
Traceback (most recent call last):
  File "C:\Users\ipharmacare\newreport\common\configReader.py", line 50, in getitems
    result=self.conf.items(field)
  File "C:\Users\ipharmacare\python27\lib\ConfigParser.py", line 642, in items
    raise NoSectionError(section)
NoSectionError: No section: 'default_group'
Tue, 23 Jul 2019 11:44:42 log.py[line:17] DEBUG 该指标在指标库中不存在,出院患者静脉输液总人次
Tue, 23 Jul 2019 11:44:42 log.py[line:17] DEBUG 该指标在指标库中不存在,出院患者抗菌药物预防使用人次
Tue, 23 Jul 2019 11:44:42 log.py[line:17] DEBUG 该指标在指标库中不存在,去年同期出院患者总人次
Tue, 23 Jul 2019 11:44:42 log.py[line:17] DEBUG 该指标在指标库中不存在,出院患者特殊级抗菌药物使用人次数
Tue, 23 Jul 2019 11:44:42 log.py[line:17] DEBUG 执行过程中出错
Tue, 23 Jul 2019 11:44:42 log.py[line:20] ERROR (1054, "Unknown column 'key_time' in 'field list'")
Traceback (most recent call last):
  File "C:\Users\ipharmacare\newreport\GetSQLvalue\itemZoneValue.py", line 314, in getSqlValue_zone
    sqlValue = self.getValueInZone(itemname, zoneid, startT, endT)
  File "C:\Users\ipharmacare\newreport\GetSQLvalue\itemZoneValue.py", line 43, in getValueInZone
    sqlValue = self.conndb.executeSQL_zoneid_one(self.cur, self.sql, zoneid, startT, endT)
  File "C:\Users\ipharmacare\newreport\common\connectDB.py", line 49, in executeSQL_zoneid_one
    cur.execute(sql, (zoneid, startT, endT))
  File "C:\Users\ipharmacare\python27\lib\site-packages\MySQLdb\cursors.py", line 205, in execute
    self.errorhandler(self, exc, value)
  File "C:\Users\ipharmacare\python27\lib\site-packages\MySQLdb\connections.py", line 36, in defaulterrorhandler
    raise errorclass, errorvalue
OperationalError: (1054, "Unknown column 'key_time' in 'field list'")
Tue, 23 Jul 2019 11:44:42 log.py[line:17] DEBUG 执行过程中出错
Tue, 23 Jul 2019 11:44:42 log.py[line:20] ERROR (1054, "Unknown column 'key_time' in 'field list'")
Traceback (most recent call last):
  File "C:\Users\ipharmacare\newreport\GetSQLvalue\itemZoneValue.py", line 314, in getSqlValue_zone
    sqlValue = self.getValueInZone(itemname, zoneid, startT, endT)
  File "C:\Users\ipharmacare\newreport\GetSQLvalue\itemZoneValue.py", line 43, in getValueInZone
    sqlValue = self.conndb.executeSQL_zoneid_one(self.cur, self.sql, zoneid, startT, endT)
  File "C:\Users\ipharmacare\newreport\common\connectDB.py", line 49, in executeSQL_zoneid_one
    cur.execute(sql, (zoneid, startT, endT))
  File "C:\Users\ipharmacare\python27\lib\site-packages\MySQLdb\cursors.py", line 205, in execute
    self.errorhandler(self, exc, value)
  File "C:\Users\ipharmacare\python27\lib\site-packages\MySQLdb\connections.py", line 36, in defaulterrorhandler
    raise errorclass, errorvalue
OperationalError: (1054, "Unknown column 'key_time' in 'field list'")
Tue, 23 Jul 2019 11:44:42 log.py[line:17] DEBUG 该指标在指标库中不存在,使用非限制级抗菌药物出院患者中病原学检查送检人次
Tue, 23 Jul 2019 11:44:42 log.py[line:17] DEBUG 该指标在指标库中不存在,使用限制级抗菌药物出院患者中病原学检查送检人次
Tue, 23 Jul 2019 11:44:42 log.py[line:17] DEBUG 该指标在指标库中不存在,使用特殊级抗菌药物出院患者中病原学检查送检人次
Tue, 23 Jul 2019 11:44:42 log.py[line:17] DEBUG 执行过程中出错
Tue, 23 Jul 2019 11:44:42 log.py[line:20] ERROR (1054, "Unknown column 'key_time' in 'field list'")
Traceback (most recent call last):
  File "C:\Users\ipharmacare\newreport\GetSQLvalue\itemZoneValue.py", line 314, in getSqlValue_zone
    sqlValue = self.getValueInZone(itemname, zoneid, startT, endT)
  File "C:\Users\ipharmacare\newreport\GetSQLvalue\itemZoneValue.py", line 43, in getValueInZone
    sqlValue = self.conndb.executeSQL_zoneid_one(self.cur, self.sql, zoneid, startT, endT)
  File "C:\Users\ipharmacare\newreport\common\connectDB.py", line 49, in executeSQL_zoneid_one
    cur.execute(sql, (zoneid, startT, endT))
  File "C:\Users\ipharmacare\python27\lib\site-packages\MySQLdb\cursors.py", line 205, in execute
    self.errorhandler(self, exc, value)
  File "C:\Users\ipharmacare\python27\lib\site-packages\MySQLdb\connections.py", line 36, in defaulterrorhandler
    raise errorclass, errorvalue
OperationalError: (1054, "Unknown column 'key_time' in 'field list'")
Tue, 23 Jul 2019 11:44:42 log.py[line:17] DEBUG 该指标在指标库中不存在,出院患者静脉输液总人次
Tue, 23 Jul 2019 11:44:43 log.py[line:17] DEBUG 该指标在指标库中不存在,出院患者总人次（排除中药饮片）
Tue, 23 Jul 2019 11:44:43 log.py[line:17] DEBUG 执行过程中出错
Tue, 23 Jul 2019 11:44:43 log.py[line:20] ERROR (1054, "Unknown column 'key_time' in 'field list'")
Traceback (most recent call last):
  File "C:\Users\ipharmacare\newreport\GetSQLvalue\itemZoneValue.py", line 314, in getSqlValue_zone
    sqlValue = self.getValueInZone(itemname, zoneid, startT, endT)
  File "C:\Users\ipharmacare\newreport\GetSQLvalue\itemZoneValue.py", line 43, in getValueInZone
    sqlValue = self.conndb.executeSQL_zoneid_one(self.cur, self.sql, zoneid, startT, endT)
  File "C:\Users\ipharmacare\newreport\common\connectDB.py", line 49, in executeSQL_zoneid_one
    cur.execute(sql, (zoneid, startT, endT))
  File "C:\Users\ipharmacare\python27\lib\site-packages\MySQLdb\cursors.py", line 205, in execute
    self.errorhandler(self, exc, value)
  File "C:\Users\ipharmacare\python27\lib\site-packages\MySQLdb\connections.py", line 36, in defaulterrorhandler
    raise errorclass, errorvalue
OperationalError: (1054, "Unknown column 'key_time' in 'field list'")
Tue, 23 Jul 2019 11:44:43 connectionpool.py[line:205] DEBUG Starting new HTTP connection (1): 10.1.1.89:9999
Tue, 23 Jul 2019 11:44:43 connectionpool.py[line:393] DEBUG http://10.1.1.89:9999 "POST /syscenter/api/v1/currentUser HTTP/1.1" 200 None
Tue, 23 Jul 2019 11:44:43 connectionpool.py[line:393] DEBUG http://10.1.1.89:9999 "GET /syscenter/api/v1/config/selectSysConfig?showName=%E6%8A%97%E8%8F%8C%E8%8D%AF%E7%89%A9%E9%80%81%E6%A3%80%E6%A0%87%E8%AF%86 HTTP/1.1" 200 None
Tue, 23 Jul 2019 11:44:45 log.py[line:17] DEBUG 执行过程中出错
Tue, 23 Jul 2019 11:44:45 log.py[line:20] ERROR (1054, "Unknown column 'key_time' in 'field list'")
Traceback (most recent call last):
  File "C:\Users\ipharmacare\newreport\GetSQLvalue\itemZoneValue.py", line 314, in getSqlValue_zone
    sqlValue = self.getValueInZone(itemname, zoneid, startT, endT)
  File "C:\Users\ipharmacare\newreport\GetSQLvalue\itemZoneValue.py", line 43, in getValueInZone
    sqlValue = self.conndb.executeSQL_zoneid_one(self.cur, self.sql, zoneid, startT, endT)
  File "C:\Users\ipharmacare\newreport\common\connectDB.py", line 49, in executeSQL_zoneid_one
    cur.execute(sql, (zoneid, startT, endT))
  File "C:\Users\ipharmacare\python27\lib\site-packages\MySQLdb\cursors.py", line 205, in execute
    self.errorhandler(self, exc, value)
  File "C:\Users\ipharmacare\python27\lib\site-packages\MySQLdb\connections.py", line 36, in defaulterrorhandler
    raise errorclass, errorvalue
OperationalError: (1054, "Unknown column 'key_time' in 'field list'")
Tue, 23 Jul 2019 11:44:45 log.py[line:17] DEBUG 执行过程中出错
Tue, 23 Jul 2019 11:44:45 log.py[line:20] ERROR (1054, "Unknown column 'key_time' in 'field list'")
Traceback (most recent call last):
  File "C:\Users\ipharmacare\newreport\GetSQLvalue\itemZoneValue.py", line 314, in getSqlValue_zone
    sqlValue = self.getValueInZone(itemname, zoneid, startT, endT)
  File "C:\Users\ipharmacare\newreport\GetSQLvalue\itemZoneValue.py", line 43, in getValueInZone
    sqlValue = self.conndb.executeSQL_zoneid_one(self.cur, self.sql, zoneid, startT, endT)
  File "C:\Users\ipharmacare\newreport\common\connectDB.py", line 49, in executeSQL_zoneid_one
    cur.execute(sql, (zoneid, startT, endT))
  File "C:\Users\ipharmacare\python27\lib\site-packages\MySQLdb\cursors.py", line 205, in execute
    self.errorhandler(self, exc, value)
  File "C:\Users\ipharmacare\python27\lib\site-packages\MySQLdb\connections.py", line 36, in defaulterrorhandler
    raise errorclass, errorvalue
OperationalError: (1054, "Unknown column 'key_time' in 'field list'")
Tue, 23 Jul 2019 11:44:45 log.py[line:17] DEBUG 执行过程中出错
Tue, 23 Jul 2019 11:44:45 log.py[line:20] ERROR (1054, "Unknown column 'key_time' in 'field list'")
Traceback (most recent call last):
  File "C:\Users\ipharmacare\newreport\GetSQLvalue\itemZoneValue.py", line 314, in getSqlValue_zone
    sqlValue = self.getValueInZone(itemname, zoneid, startT, endT)
  File "C:\Users\ipharmacare\newreport\GetSQLvalue\itemZoneValue.py", line 43, in getValueInZone
    sqlValue = self.conndb.executeSQL_zoneid_one(self.cur, self.sql, zoneid, startT, endT)
  File "C:\Users\ipharmacare\newreport\common\connectDB.py", line 49, in executeSQL_zoneid_one
    cur.execute(sql, (zoneid, startT, endT))
  File "C:\Users\ipharmacare\python27\lib\site-packages\MySQLdb\cursors.py", line 205, in execute
    self.errorhandler(self, exc, value)
  File "C:\Users\ipharmacare\python27\lib\site-packages\MySQLdb\connections.py", line 36, in defaulterrorhandler
    raise errorclass, errorvalue
OperationalError: (1054, "Unknown column 'key_time' in 'field list'")
Tue, 23 Jul 2019 11:44:45 log.py[line:17] DEBUG 执行过程中出错
Tue, 23 Jul 2019 11:44:45 log.py[line:20] ERROR (1054, "Unknown column 'key_time' in 'field list'")
Traceback (most recent call last):
  File "C:\Users\ipharmacare\newreport\GetSQLvalue\itemZoneValue.py", line 314, in getSqlValue_zone
    sqlValue = self.getValueInZone(itemname, zoneid, startT, endT)
  File "C:\Users\ipharmacare\newreport\GetSQLvalue\itemZoneValue.py", line 43, in getValueInZone
    sqlValue = self.conndb.executeSQL_zoneid_one(self.cur, self.sql, zoneid, startT, endT)
  File "C:\Users\ipharmacare\newreport\common\connectDB.py", line 49, in executeSQL_zoneid_one
    cur.execute(sql, (zoneid, startT, endT))
  File "C:\Users\ipharmacare\python27\lib\site-packages\MySQLdb\cursors.py", line 205, in execute
    self.errorhandler(self, exc, value)
  File "C:\Users\ipharmacare\python27\lib\site-packages\MySQLdb\connections.py", line 36, in defaulterrorhandler
    raise errorclass, errorvalue
OperationalError: (1054, "Unknown column 'key_time' in 'field list'")
Tue, 23 Jul 2019 11:44:45 log.py[line:17] DEBUG 执行过程中出错
Tue, 23 Jul 2019 11:44:45 log.py[line:20] ERROR (1054, "Unknown column 'key_time' in 'field list'")
Traceback (most recent call last):
  File "C:\Users\ipharmacare\newreport\GetSQLvalue\itemZoneValue.py", line 314, in getSqlValue_zone
    sqlValue = self.getValueInZone(itemname, zoneid, startT, endT)
  File "C:\Users\ipharmacare\newreport\GetSQLvalue\itemZoneValue.py", line 43, in getValueInZone
    sqlValue = self.conndb.executeSQL_zoneid_one(self.cur, self.sql, zoneid, startT, endT)
  File "C:\Users\ipharmacare\newreport\common\connectDB.py", line 49, in executeSQL_zoneid_one
    cur.execute(sql, (zoneid, startT, endT))
  File "C:\Users\ipharmacare\python27\lib\site-packages\MySQLdb\cursors.py", line 205, in execute
    self.errorhandler(self, exc, value)
  File "C:\Users\ipharmacare\python27\lib\site-packages\MySQLdb\connections.py", line 36, in defaulterrorhandler
    raise errorclass, errorvalue
OperationalError: (1054, "Unknown column 'key_time' in 'field list'")
Tue, 23 Jul 2019 11:44:45 log.py[line:17] DEBUG 执行过程中出错
Tue, 23 Jul 2019 11:44:45 log.py[line:20] ERROR (1054, "Unknown column 'key_time' in 'field list'")
Traceback (most recent call last):
  File "C:\Users\ipharmacare\newreport\GetSQLvalue\itemZoneValue.py", line 314, in getSqlValue_zone
    sqlValue = self.getValueInZone(itemname, zoneid, startT, endT)
  File "C:\Users\ipharmacare\newreport\GetSQLvalue\itemZoneValue.py", line 43, in getValueInZone
    sqlValue = self.conndb.executeSQL_zoneid_one(self.cur, self.sql, zoneid, startT, endT)
  File "C:\Users\ipharmacare\newreport\common\connectDB.py", line 49, in executeSQL_zoneid_one
    cur.execute(sql, (zoneid, startT, endT))
  File "C:\Users\ipharmacare\python27\lib\site-packages\MySQLdb\cursors.py", line 205, in execute
    self.errorhandler(self, exc, value)
  File "C:\Users\ipharmacare\python27\lib\site-packages\MySQLdb\connections.py", line 36, in defaulterrorhandler
    raise errorclass, errorvalue
OperationalError: (1054, "Unknown column 'key_time' in 'field list'")
Tue, 23 Jul 2019 11:44:45 log.py[line:17] DEBUG 执行过程中出错
Tue, 23 Jul 2019 11:44:45 log.py[line:20] ERROR (1054, "Unknown column 'key_time' in 'field list'")
Traceback (most recent call last):
  File "C:\Users\ipharmacare\newreport\GetSQLvalue\itemZoneValue.py", line 314, in getSqlValue_zone
    sqlValue = self.getValueInZone(itemname, zoneid, startT, endT)
  File "C:\Users\ipharmacare\newreport\GetSQLvalue\itemZoneValue.py", line 43, in getValueInZone
    sqlValue = self.conndb.executeSQL_zoneid_one(self.cur, self.sql, zoneid, startT, endT)
  File "C:\Users\ipharmacare\newreport\common\connectDB.py", line 49, in executeSQL_zoneid_one
    cur.execute(sql, (zoneid, startT, endT))
  File "C:\Users\ipharmacare\python27\lib\site-packages\MySQLdb\cursors.py", line 205, in execute
    self.errorhandler(self, exc, value)
  File "C:\Users\ipharmacare\python27\lib\site-packages\MySQLdb\connections.py", line 36, in defaulterrorhandler
    raise errorclass, errorvalue
OperationalError: (1054, "Unknown column 'key_time' in 'field list'")
Tue, 23 Jul 2019 11:44:45 log.py[line:17] DEBUG 执行过程中出错
Tue, 23 Jul 2019 11:44:45 log.py[line:20] ERROR (1054, "Unknown column 'key_time' in 'field list'")
Traceback (most recent call last):
  File "C:\Users\ipharmacare\newreport\GetSQLvalue\itemZoneValue.py", line 314, in getSqlValue_zone
    sqlValue = self.getValueInZone(itemname, zoneid, startT, endT)
  File "C:\Users\ipharmacare\newreport\GetSQLvalue\itemZoneValue.py", line 43, in getValueInZone
    sqlValue = self.conndb.executeSQL_zoneid_one(self.cur, self.sql, zoneid, startT, endT)
  File "C:\Users\ipharmacare\newreport\common\connectDB.py", line 49, in executeSQL_zoneid_one
    cur.execute(sql, (zoneid, startT, endT))
  File "C:\Users\ipharmacare\python27\lib\site-packages\MySQLdb\cursors.py", line 205, in execute
    self.errorhandler(self, exc, value)
  File "C:\Users\ipharmacare\python27\lib\site-packages\MySQLdb\connections.py", line 36, in defaulterrorhandler
    raise errorclass, errorvalue
OperationalError: (1054, "Unknown column 'key_time' in 'field list'")
Tue, 23 Jul 2019 11:44:45 connectionpool.py[line:205] DEBUG Starting new HTTP connection (1): 10.1.1.89:9999
Tue, 23 Jul 2019 11:44:45 connectionpool.py[line:393] DEBUG http://10.1.1.89:9999 "POST /syscenter/api/v1/currentUser HTTP/1.1" 200 None
Tue, 23 Jul 2019 11:44:45 connectionpool.py[line:393] DEBUG http://10.1.1.89:9999 "GET /syscenter/api/v1/config/selectSysConfig?showName=%E6%8A%97%E8%8F%8C%E8%8D%AF%E7%89%A9%E9%80%81%E6%A3%80%E6%A0%87%E8%AF%86 HTTP/1.1" 200 None
Tue, 23 Jul 2019 11:47:52 log.py[line:17] DEBUG 读取配置项发生了错误,hospital_doc
Tue, 23 Jul 2019 11:47:52 log.py[line:20] ERROR No section: 'hospital_doc'
Traceback (most recent call last):
  File "C:\Users\ipharmacare\newreport\common\configReader.py", line 50, in getitems
    result=self.conf.items(field)
  File "C:\Users\ipharmacare\python27\lib\ConfigParser.py", line 642, in items
    raise NoSectionError(section)
NoSectionError: No section: 'hospital_doc'
Tue, 23 Jul 2019 11:47:52 log.py[line:17] DEBUG 读取配置项发生了错误,default_doc
Tue, 23 Jul 2019 11:47:52 log.py[line:20] ERROR No section: 'default_doc'
Traceback (most recent call last):
  File "C:\Users\ipharmacare\newreport\common\configReader.py", line 50, in getitems
    result=self.conf.items(field)
  File "C:\Users\ipharmacare\python27\lib\ConfigParser.py", line 642, in items
    raise NoSectionError(section)
NoSectionError: No section: 'default_doc'
Tue, 23 Jul 2019 11:47:52 log.py[line:17] DEBUG 读取配置项发生了错误,ConfigurationItem_doc
Tue, 23 Jul 2019 11:47:52 log.py[line:20] ERROR No section: 'ConfigurationItem_doc'
Traceback (most recent call last):
  File "C:\Users\ipharmacare\newreport\common\configReader.py", line 50, in getitems
    result=self.conf.items(field)
  File "C:\Users\ipharmacare\python27\lib\ConfigParser.py", line 642, in items
    raise NoSectionError(section)
NoSectionError: No section: 'ConfigurationItem_doc'
Tue, 23 Jul 2019 11:47:52 log.py[line:17] DEBUG 读取配置项发生了错误,doc_ddds
Tue, 23 Jul 2019 11:47:52 log.py[line:20] ERROR No section: 'doc_ddds'
Traceback (most recent call last):
  File "C:\Users\ipharmacare\newreport\common\configReader.py", line 50, in getitems
    result=self.conf.items(field)
  File "C:\Users\ipharmacare\python27\lib\ConfigParser.py", line 642, in items
    raise NoSectionError(section)
NoSectionError: No section: 'doc_ddds'
Tue, 23 Jul 2019 11:47:52 log.py[line:17] DEBUG 读取配置项发生了错误,hospitalDoc_ddds
Tue, 23 Jul 2019 11:47:52 log.py[line:20] ERROR No section: 'hospitalDoc_ddds'
Traceback (most recent call last):
  File "C:\Users\ipharmacare\newreport\common\configReader.py", line 50, in getitems
    result=self.conf.items(field)
  File "C:\Users\ipharmacare\python27\lib\ConfigParser.py", line 642, in items
    raise NoSectionError(section)
NoSectionError: No section: 'hospitalDoc_ddds'
Tue, 23 Jul 2019 11:47:52 log.py[line:17] DEBUG 读取配置项发生了错误,hospital_dept
Tue, 23 Jul 2019 11:47:52 log.py[line:20] ERROR No section: 'hospital_dept'
Traceback (most recent call last):
  File "C:\Users\ipharmacare\newreport\common\configReader.py", line 50, in getitems
    result=self.conf.items(field)
  File "C:\Users\ipharmacare\python27\lib\ConfigParser.py", line 642, in items
    raise NoSectionError(section)
NoSectionError: No section: 'hospital_dept'
Tue, 23 Jul 2019 11:47:52 log.py[line:17] DEBUG 读取配置项发生了错误,default_dept
Tue, 23 Jul 2019 11:47:52 log.py[line:20] ERROR No section: 'default_dept'
Traceback (most recent call last):
  File "C:\Users\ipharmacare\newreport\common\configReader.py", line 50, in getitems
    result=self.conf.items(field)
  File "C:\Users\ipharmacare\python27\lib\ConfigParser.py", line 642, in items
    raise NoSectionError(section)
NoSectionError: No section: 'default_dept'
Tue, 23 Jul 2019 11:47:52 log.py[line:17] DEBUG 读取配置项发生了错误,ConfigurationItem_dept
Tue, 23 Jul 2019 11:47:52 log.py[line:20] ERROR No section: 'ConfigurationItem_dept'
Traceback (most recent call last):
  File "C:\Users\ipharmacare\newreport\common\configReader.py", line 50, in getitems
    result=self.conf.items(field)
  File "C:\Users\ipharmacare\python27\lib\ConfigParser.py", line 642, in items
    raise NoSectionError(section)
NoSectionError: No section: 'ConfigurationItem_dept'
Tue, 23 Jul 2019 11:47:52 log.py[line:17] DEBUG 读取配置项发生了错误,dept_ddds
Tue, 23 Jul 2019 11:47:52 log.py[line:20] ERROR No section: 'dept_ddds'
Traceback (most recent call last):
  File "C:\Users\ipharmacare\newreport\common\configReader.py", line 50, in getitems
    result=self.conf.items(field)
  File "C:\Users\ipharmacare\python27\lib\ConfigParser.py", line 642, in items
    raise NoSectionError(section)
NoSectionError: No section: 'dept_ddds'
Tue, 23 Jul 2019 11:47:52 log.py[line:17] DEBUG 读取配置项发生了错误,hospitalDept_ddds
Tue, 23 Jul 2019 11:47:52 log.py[line:20] ERROR No section: 'hospitalDept_ddds'
Traceback (most recent call last):
  File "C:\Users\ipharmacare\newreport\common\configReader.py", line 50, in getitems
    result=self.conf.items(field)
  File "C:\Users\ipharmacare\python27\lib\ConfigParser.py", line 642, in items
    raise NoSectionError(section)
NoSectionError: No section: 'hospitalDept_ddds'
Tue, 23 Jul 2019 11:47:52 log.py[line:17] DEBUG 读取配置项发生了错误,default_group
Tue, 23 Jul 2019 11:47:52 log.py[line:20] ERROR No section: 'default_group'
Traceback (most recent call last):
  File "C:\Users\ipharmacare\newreport\common\configReader.py", line 50, in getitems
    result=self.conf.items(field)
  File "C:\Users\ipharmacare\python27\lib\ConfigParser.py", line 642, in items
    raise NoSectionError(section)
NoSectionError: No section: 'default_group'
Tue, 23 Jul 2019 11:47:52 log.py[line:17] DEBUG 该指标在指标库中不存在,出院患者静脉输液总人次
Tue, 23 Jul 2019 11:47:52 log.py[line:17] DEBUG 该指标在指标库中不存在,出院患者抗菌药物预防使用人次
Tue, 23 Jul 2019 11:47:52 log.py[line:17] DEBUG 该指标在指标库中不存在,去年同期出院患者总人次
Tue, 23 Jul 2019 11:47:52 log.py[line:17] DEBUG 该指标在指标库中不存在,出院患者特殊级抗菌药物使用人次数
Tue, 23 Jul 2019 11:47:52 log.py[line:17] DEBUG 该指标在指标库中不存在,使用非限制级抗菌药物出院患者中病原学检查送检人次
Tue, 23 Jul 2019 11:47:52 log.py[line:17] DEBUG 该指标在指标库中不存在,使用限制级抗菌药物出院患者中病原学检查送检人次
Tue, 23 Jul 2019 11:47:52 log.py[line:17] DEBUG 该指标在指标库中不存在,使用特殊级抗菌药物出院患者中病原学检查送检人次
Tue, 23 Jul 2019 11:47:53 log.py[line:17] DEBUG 执行过程中出错
Tue, 23 Jul 2019 11:47:53 log.py[line:20] ERROR (1054, "Unknown column 'key_time' in 'field list'")
Traceback (most recent call last):
  File "C:\Users\ipharmacare\newreport\GetSQLvalue\itemZoneValue.py", line 314, in getSqlValue_zone
    sqlValue = self.getValueInZone(itemname, zoneid, startT, endT)
  File "C:\Users\ipharmacare\newreport\GetSQLvalue\itemZoneValue.py", line 43, in getValueInZone
    sqlValue = self.conndb.executeSQL_zoneid_one(self.cur, self.sql, zoneid, startT, endT)
  File "C:\Users\ipharmacare\newreport\common\connectDB.py", line 49, in executeSQL_zoneid_one
    cur.execute(sql, (zoneid, startT, endT))
  File "C:\Users\ipharmacare\python27\lib\site-packages\MySQLdb\cursors.py", line 205, in execute
    self.errorhandler(self, exc, value)
  File "C:\Users\ipharmacare\python27\lib\site-packages\MySQLdb\connections.py", line 36, in defaulterrorhandler
    raise errorclass, errorvalue
OperationalError: (1054, "Unknown column 'key_time' in 'field list'")
Tue, 23 Jul 2019 11:47:53 log.py[line:17] DEBUG 该指标在指标库中不存在,出院患者静脉输液总人次
Tue, 23 Jul 2019 11:47:53 log.py[line:17] DEBUG 该指标在指标库中不存在,出院患者总人次（排除中药饮片）
Tue, 23 Jul 2019 11:47:53 log.py[line:17] DEBUG 执行过程中出错
Tue, 23 Jul 2019 11:47:53 log.py[line:20] ERROR (1054, "Unknown column 'key_time' in 'field list'")
Traceback (most recent call last):
  File "C:\Users\ipharmacare\newreport\GetSQLvalue\itemZoneValue.py", line 314, in getSqlValue_zone
    sqlValue = self.getValueInZone(itemname, zoneid, startT, endT)
  File "C:\Users\ipharmacare\newreport\GetSQLvalue\itemZoneValue.py", line 43, in getValueInZone
    sqlValue = self.conndb.executeSQL_zoneid_one(self.cur, self.sql, zoneid, startT, endT)
  File "C:\Users\ipharmacare\newreport\common\connectDB.py", line 49, in executeSQL_zoneid_one
    cur.execute(sql, (zoneid, startT, endT))
  File "C:\Users\ipharmacare\python27\lib\site-packages\MySQLdb\cursors.py", line 205, in execute
    self.errorhandler(self, exc, value)
  File "C:\Users\ipharmacare\python27\lib\site-packages\MySQLdb\connections.py", line 36, in defaulterrorhandler
    raise errorclass, errorvalue
OperationalError: (1054, "Unknown column 'key_time' in 'field list'")
Tue, 23 Jul 2019 11:47:53 connectionpool.py[line:205] DEBUG Starting new HTTP connection (1): 10.1.1.89:9999
Tue, 23 Jul 2019 11:47:53 connectionpool.py[line:393] DEBUG http://10.1.1.89:9999 "POST /syscenter/api/v1/currentUser HTTP/1.1" 200 None
Tue, 23 Jul 2019 11:47:53 connectionpool.py[line:393] DEBUG http://10.1.1.89:9999 "GET /syscenter/api/v1/config/selectSysConfig?showName=%E6%8A%97%E8%8F%8C%E8%8D%AF%E7%89%A9%E9%80%81%E6%A3%80%E6%A0%87%E8%AF%86 HTTP/1.1" 200 None
Tue, 23 Jul 2019 11:47:55 log.py[line:17] DEBUG 执行过程中出错
Tue, 23 Jul 2019 11:47:55 log.py[line:20] ERROR (1054, "Unknown column 'key_time' in 'field list'")
Traceback (most recent call last):
  File "C:\Users\ipharmacare\newreport\GetSQLvalue\itemZoneValue.py", line 314, in getSqlValue_zone
    sqlValue = self.getValueInZone(itemname, zoneid, startT, endT)
  File "C:\Users\ipharmacare\newreport\GetSQLvalue\itemZoneValue.py", line 43, in getValueInZone
    sqlValue = self.conndb.executeSQL_zoneid_one(self.cur, self.sql, zoneid, startT, endT)
  File "C:\Users\ipharmacare\newreport\common\connectDB.py", line 49, in executeSQL_zoneid_one
    cur.execute(sql, (zoneid, startT, endT))
  File "C:\Users\ipharmacare\python27\lib\site-packages\MySQLdb\cursors.py", line 205, in execute
    self.errorhandler(self, exc, value)
  File "C:\Users\ipharmacare\python27\lib\site-packages\MySQLdb\connections.py", line 36, in defaulterrorhandler
    raise errorclass, errorvalue
OperationalError: (1054, "Unknown column 'key_time' in 'field list'")
Tue, 23 Jul 2019 11:47:55 log.py[line:17] DEBUG 执行过程中出错
Tue, 23 Jul 2019 11:47:55 log.py[line:20] ERROR (1054, "Unknown column 'key_time' in 'field list'")
Traceback (most recent call last):
  File "C:\Users\ipharmacare\newreport\GetSQLvalue\itemZoneValue.py", line 314, in getSqlValue_zone
    sqlValue = self.getValueInZone(itemname, zoneid, startT, endT)
  File "C:\Users\ipharmacare\newreport\GetSQLvalue\itemZoneValue.py", line 43, in getValueInZone
    sqlValue = self.conndb.executeSQL_zoneid_one(self.cur, self.sql, zoneid, startT, endT)
  File "C:\Users\ipharmacare\newreport\common\connectDB.py", line 49, in executeSQL_zoneid_one
    cur.execute(sql, (zoneid, startT, endT))
  File "C:\Users\ipharmacare\python27\lib\site-packages\MySQLdb\cursors.py", line 205, in execute
    self.errorhandler(self, exc, value)
  File "C:\Users\ipharmacare\python27\lib\site-packages\MySQLdb\connections.py", line 36, in defaulterrorhandler
    raise errorclass, errorvalue
OperationalError: (1054, "Unknown column 'key_time' in 'field list'")
Tue, 23 Jul 2019 11:48:08 log.py[line:17] DEBUG 执行过程中出错
Tue, 23 Jul 2019 11:48:08 log.py[line:20] ERROR (1054, "Unknown column 'key_time' in 'field list'")
Traceback (most recent call last):
  File "C:\Users\ipharmacare\newreport\GetSQLvalue\itemZoneValue.py", line 314, in getSqlValue_zone
    sqlValue = self.getValueInZone(itemname, zoneid, startT, endT)
  File "C:\Users\ipharmacare\newreport\GetSQLvalue\itemZoneValue.py", line 43, in getValueInZone
    sqlValue = self.conndb.executeSQL_zoneid_one(self.cur, self.sql, zoneid, startT, endT)
  File "C:\Users\ipharmacare\newreport\common\connectDB.py", line 49, in executeSQL_zoneid_one
    cur.execute(sql, (zoneid, startT, endT))
  File "C:\Users\ipharmacare\python27\lib\site-packages\MySQLdb\cursors.py", line 205, in execute
    self.errorhandler(self, exc, value)
  File "C:\Users\ipharmacare\python27\lib\site-packages\MySQLdb\connections.py", line 36, in defaulterrorhandler
    raise errorclass, errorvalue
OperationalError: (1054, "Unknown column 'key_time' in 'field list'")
Tue, 23 Jul 2019 11:48:09 connectionpool.py[line:205] DEBUG Starting new HTTP connection (1): 10.1.1.89:9999
Tue, 23 Jul 2019 11:48:09 connectionpool.py[line:393] DEBUG http://10.1.1.89:9999 "POST /syscenter/api/v1/currentUser HTTP/1.1" 200 None
Tue, 23 Jul 2019 11:48:09 connectionpool.py[line:393] DEBUG http://10.1.1.89:9999 "GET /syscenter/api/v1/config/selectSysConfig?showName=%E6%8A%97%E8%8F%8C%E8%8D%AF%E7%89%A9%E9%80%81%E6%A3%80%E6%A0%87%E8%AF%86 HTTP/1.1" 200 None
Tue, 23 Jul 2019 11:50:15 log.py[line:17] DEBUG 读取配置项发生了错误,hospital_doc
Tue, 23 Jul 2019 11:50:15 log.py[line:20] ERROR No section: 'hospital_doc'
Traceback (most recent call last):
  File "C:\Users\ipharmacare\newreport\common\configReader.py", line 50, in getitems
    result=self.conf.items(field)
  File "C:\Users\ipharmacare\python27\lib\ConfigParser.py", line 642, in items
    raise NoSectionError(section)
NoSectionError: No section: 'hospital_doc'
Tue, 23 Jul 2019 11:50:15 log.py[line:17] DEBUG 读取配置项发生了错误,default_doc
Tue, 23 Jul 2019 11:50:15 log.py[line:20] ERROR No section: 'default_doc'
Traceback (most recent call last):
  File "C:\Users\ipharmacare\newreport\common\configReader.py", line 50, in getitems
    result=self.conf.items(field)
  File "C:\Users\ipharmacare\python27\lib\ConfigParser.py", line 642, in items
    raise NoSectionError(section)
NoSectionError: No section: 'default_doc'
Tue, 23 Jul 2019 11:50:15 log.py[line:17] DEBUG 读取配置项发生了错误,ConfigurationItem_doc
Tue, 23 Jul 2019 11:50:15 log.py[line:20] ERROR No section: 'ConfigurationItem_doc'
Traceback (most recent call last):
  File "C:\Users\ipharmacare\newreport\common\configReader.py", line 50, in getitems
    result=self.conf.items(field)
  File "C:\Users\ipharmacare\python27\lib\ConfigParser.py", line 642, in items
    raise NoSectionError(section)
NoSectionError: No section: 'ConfigurationItem_doc'
Tue, 23 Jul 2019 11:50:15 log.py[line:17] DEBUG 读取配置项发生了错误,doc_ddds
Tue, 23 Jul 2019 11:50:15 log.py[line:20] ERROR No section: 'doc_ddds'
Traceback (most recent call last):
  File "C:\Users\ipharmacare\newreport\common\configReader.py", line 50, in getitems
    result=self.conf.items(field)
  File "C:\Users\ipharmacare\python27\lib\ConfigParser.py", line 642, in items
    raise NoSectionError(section)
NoSectionError: No section: 'doc_ddds'
Tue, 23 Jul 2019 11:50:15 log.py[line:17] DEBUG 读取配置项发生了错误,hospitalDoc_ddds
Tue, 23 Jul 2019 11:50:15 log.py[line:20] ERROR No section: 'hospitalDoc_ddds'
Traceback (most recent call last):
  File "C:\Users\ipharmacare\newreport\common\configReader.py", line 50, in getitems
    result=self.conf.items(field)
  File "C:\Users\ipharmacare\python27\lib\ConfigParser.py", line 642, in items
    raise NoSectionError(section)
NoSectionError: No section: 'hospitalDoc_ddds'
Tue, 23 Jul 2019 11:50:15 log.py[line:17] DEBUG 读取配置项发生了错误,hospital_dept
Tue, 23 Jul 2019 11:50:15 log.py[line:20] ERROR No section: 'hospital_dept'
Traceback (most recent call last):
  File "C:\Users\ipharmacare\newreport\common\configReader.py", line 50, in getitems
    result=self.conf.items(field)
  File "C:\Users\ipharmacare\python27\lib\ConfigParser.py", line 642, in items
    raise NoSectionError(section)
NoSectionError: No section: 'hospital_dept'
Tue, 23 Jul 2019 11:50:15 log.py[line:17] DEBUG 读取配置项发生了错误,default_dept
Tue, 23 Jul 2019 11:50:15 log.py[line:20] ERROR No section: 'default_dept'
Traceback (most recent call last):
  File "C:\Users\ipharmacare\newreport\common\configReader.py", line 50, in getitems
    result=self.conf.items(field)
  File "C:\Users\ipharmacare\python27\lib\ConfigParser.py", line 642, in items
    raise NoSectionError(section)
NoSectionError: No section: 'default_dept'
Tue, 23 Jul 2019 11:50:15 log.py[line:17] DEBUG 读取配置项发生了错误,ConfigurationItem_dept
Tue, 23 Jul 2019 11:50:15 log.py[line:20] ERROR No section: 'ConfigurationItem_dept'
Traceback (most recent call last):
  File "C:\Users\ipharmacare\newreport\common\configReader.py", line 50, in getitems
    result=self.conf.items(field)
  File "C:\Users\ipharmacare\python27\lib\ConfigParser.py", line 642, in items
    raise NoSectionError(section)
NoSectionError: No section: 'ConfigurationItem_dept'
Tue, 23 Jul 2019 11:50:15 log.py[line:17] DEBUG 读取配置项发生了错误,dept_ddds
Tue, 23 Jul 2019 11:50:15 log.py[line:20] ERROR No section: 'dept_ddds'
Traceback (most recent call last):
  File "C:\Users\ipharmacare\newreport\common\configReader.py", line 50, in getitems
    result=self.conf.items(field)
  File "C:\Users\ipharmacare\python27\lib\ConfigParser.py", line 642, in items
    raise NoSectionError(section)
NoSectionError: No section: 'dept_ddds'
Tue, 23 Jul 2019 11:50:15 log.py[line:17] DEBUG 读取配置项发生了错误,hospitalDept_ddds
Tue, 23 Jul 2019 11:50:15 log.py[line:20] ERROR No section: 'hospitalDept_ddds'
Traceback (most recent call last):
  File "C:\Users\ipharmacare\newreport\common\configReader.py", line 50, in getitems
    result=self.conf.items(field)
  File "C:\Users\ipharmacare\python27\lib\ConfigParser.py", line 642, in items
    raise NoSectionError(section)
NoSectionError: No section: 'hospitalDept_ddds'
Tue, 23 Jul 2019 11:50:15 log.py[line:17] DEBUG 读取配置项发生了错误,default_group
Tue, 23 Jul 2019 11:50:15 log.py[line:20] ERROR No section: 'default_group'
Traceback (most recent call last):
  File "C:\Users\ipharmacare\newreport\common\configReader.py", line 50, in getitems
    result=self.conf.items(field)
  File "C:\Users\ipharmacare\python27\lib\ConfigParser.py", line 642, in items
    raise NoSectionError(section)
NoSectionError: No section: 'default_group'
Tue, 23 Jul 2019 11:50:15 log.py[line:17] DEBUG 该指标在指标库中不存在,出院患者静脉输液总人次
Tue, 23 Jul 2019 11:50:15 log.py[line:17] DEBUG 该指标在指标库中不存在,出院患者抗菌药物预防使用人次
Tue, 23 Jul 2019 11:50:15 log.py[line:17] DEBUG 该指标在指标库中不存在,去年同期出院患者总人次
Tue, 23 Jul 2019 11:50:15 log.py[line:17] DEBUG 该指标在指标库中不存在,出院患者特殊级抗菌药物使用人次数
Tue, 23 Jul 2019 11:50:16 log.py[line:17] DEBUG 该指标在指标库中不存在,使用非限制级抗菌药物出院患者中病原学检查送检人次
Tue, 23 Jul 2019 11:50:16 log.py[line:17] DEBUG 该指标在指标库中不存在,使用限制级抗菌药物出院患者中病原学检查送检人次
Tue, 23 Jul 2019 11:50:16 log.py[line:17] DEBUG 该指标在指标库中不存在,使用特殊级抗菌药物出院患者中病原学检查送检人次
Tue, 23 Jul 2019 11:50:16 log.py[line:17] DEBUG 执行过程中出错
Tue, 23 Jul 2019 11:50:16 log.py[line:20] ERROR (1054, "Unknown column 'key_time' in 'field list'")
Traceback (most recent call last):
  File "C:\Users\ipharmacare\newreport\GetSQLvalue\itemZoneValue.py", line 314, in getSqlValue_zone
    sqlValue = self.getValueInZone(itemname, zoneid, startT, endT)
  File "C:\Users\ipharmacare\newreport\GetSQLvalue\itemZoneValue.py", line 43, in getValueInZone
    sqlValue = self.conndb.executeSQL_zoneid_one(self.cur, self.sql, zoneid, startT, endT)
  File "C:\Users\ipharmacare\newreport\common\connectDB.py", line 49, in executeSQL_zoneid_one
    cur.execute(sql, (zoneid, startT, endT))
  File "C:\Users\ipharmacare\python27\lib\site-packages\MySQLdb\cursors.py", line 205, in execute
    self.errorhandler(self, exc, value)
  File "C:\Users\ipharmacare\python27\lib\site-packages\MySQLdb\connections.py", line 36, in defaulterrorhandler
    raise errorclass, errorvalue
OperationalError: (1054, "Unknown column 'key_time' in 'field list'")
Tue, 23 Jul 2019 11:50:16 log.py[line:17] DEBUG 该指标在指标库中不存在,出院患者静脉输液总人次
Tue, 23 Jul 2019 11:50:16 log.py[line:17] DEBUG 该指标在指标库中不存在,出院患者总人次（排除中药饮片）
Tue, 23 Jul 2019 11:50:16 connectionpool.py[line:205] DEBUG Starting new HTTP connection (1): 10.1.1.89:9999
Tue, 23 Jul 2019 11:50:16 connectionpool.py[line:393] DEBUG http://10.1.1.89:9999 "POST /syscenter/api/v1/currentUser HTTP/1.1" 200 None
Tue, 23 Jul 2019 11:50:16 connectionpool.py[line:393] DEBUG http://10.1.1.89:9999 "GET /syscenter/api/v1/config/selectSysConfig?showName=%E6%8A%97%E8%8F%8C%E8%8D%AF%E7%89%A9%E9%80%81%E6%A3%80%E6%A0%87%E8%AF%86 HTTP/1.1" 200 None
Tue, 23 Jul 2019 11:50:19 connectionpool.py[line:205] DEBUG Starting new HTTP connection (1): 10.1.1.89:9999
Tue, 23 Jul 2019 11:50:19 connectionpool.py[line:393] DEBUG http://10.1.1.89:9999 "POST /syscenter/api/v1/currentUser HTTP/1.1" 200 None
Tue, 23 Jul 2019 11:50:19 connectionpool.py[line:393] DEBUG http://10.1.1.89:9999 "GET /syscenter/api/v1/config/selectSysConfig?showName=%E6%8A%97%E8%8F%8C%E8%8D%AF%E7%89%A9%E9%80%81%E6%A3%80%E6%A0%87%E8%AF%86 HTTP/1.1" 200 None
Tue, 23 Jul 2019 14:01:49 log.py[line:17] DEBUG SQL执行错误
Tue, 23 Jul 2019 14:01:49 log.py[line:20] ERROR (1146, "Table 'ipharmacare_reportcenter.report_338284375160389632_data' doesn't exist")
Traceback (most recent call last):
  File "C:\Users\ipharmacare\newreport\common\getReportContent.py", line 80, in getESvalue
    self.cur.execute(self.sql.format(reportDataName))
  File "C:\Users\ipharmacare\python27\lib\site-packages\MySQLdb\cursors.py", line 205, in execute
    self.errorhandler(self, exc, value)
  File "C:\Users\ipharmacare\python27\lib\site-packages\MySQLdb\connections.py", line 36, in defaulterrorhandler
    raise errorclass, errorvalue
ProgrammingError: (1146, "Table 'ipharmacare_reportcenter.report_338284375160389632_data' doesn't exist")
Tue, 23 Jul 2019 14:17:03 log.py[line:17] DEBUG 读取配置项发生了错误,hospital_doc
Tue, 23 Jul 2019 14:17:03 log.py[line:20] ERROR No section: 'hospital_doc'
Traceback (most recent call last):
  File "C:\Users\ipharmacare\newreport\common\configReader.py", line 50, in getitems
    result=self.conf.items(field)
  File "C:\Users\ipharmacare\python27\lib\ConfigParser.py", line 642, in items
    raise NoSectionError(section)
NoSectionError: No section: 'hospital_doc'
Tue, 23 Jul 2019 14:17:03 log.py[line:17] DEBUG 读取配置项发生了错误,default_doc
Tue, 23 Jul 2019 14:17:03 log.py[line:20] ERROR No section: 'default_doc'
Traceback (most recent call last):
  File "C:\Users\ipharmacare\newreport\common\configReader.py", line 50, in getitems
    result=self.conf.items(field)
  File "C:\Users\ipharmacare\python27\lib\ConfigParser.py", line 642, in items
    raise NoSectionError(section)
NoSectionError: No section: 'default_doc'
Tue, 23 Jul 2019 14:17:03 log.py[line:17] DEBUG 读取配置项发生了错误,ConfigurationItem_doc
Tue, 23 Jul 2019 14:17:03 log.py[line:20] ERROR No section: 'ConfigurationItem_doc'
Traceback (most recent call last):
  File "C:\Users\ipharmacare\newreport\common\configReader.py", line 50, in getitems
    result=self.conf.items(field)
  File "C:\Users\ipharmacare\python27\lib\ConfigParser.py", line 642, in items
    raise NoSectionError(section)
NoSectionError: No section: 'ConfigurationItem_doc'
Tue, 23 Jul 2019 14:17:03 log.py[line:17] DEBUG 读取配置项发生了错误,doc_ddds
Tue, 23 Jul 2019 14:17:03 log.py[line:20] ERROR No section: 'doc_ddds'
Traceback (most recent call last):
  File "C:\Users\ipharmacare\newreport\common\configReader.py", line 50, in getitems
    result=self.conf.items(field)
  File "C:\Users\ipharmacare\python27\lib\ConfigParser.py", line 642, in items
    raise NoSectionError(section)
NoSectionError: No section: 'doc_ddds'
Tue, 23 Jul 2019 14:17:03 log.py[line:17] DEBUG 读取配置项发生了错误,hospitalDoc_ddds
Tue, 23 Jul 2019 14:17:03 log.py[line:20] ERROR No section: 'hospitalDoc_ddds'
Traceback (most recent call last):
  File "C:\Users\ipharmacare\newreport\common\configReader.py", line 50, in getitems
    result=self.conf.items(field)
  File "C:\Users\ipharmacare\python27\lib\ConfigParser.py", line 642, in items
    raise NoSectionError(section)
NoSectionError: No section: 'hospitalDoc_ddds'
Tue, 23 Jul 2019 14:17:03 log.py[line:17] DEBUG 读取配置项发生了错误,hospital_dept
Tue, 23 Jul 2019 14:17:03 log.py[line:20] ERROR No section: 'hospital_dept'
Traceback (most recent call last):
  File "C:\Users\ipharmacare\newreport\common\configReader.py", line 50, in getitems
    result=self.conf.items(field)
  File "C:\Users\ipharmacare\python27\lib\ConfigParser.py", line 642, in items
    raise NoSectionError(section)
NoSectionError: No section: 'hospital_dept'
Tue, 23 Jul 2019 14:17:03 log.py[line:17] DEBUG 读取配置项发生了错误,default_dept
Tue, 23 Jul 2019 14:17:03 log.py[line:20] ERROR No section: 'default_dept'
Traceback (most recent call last):
  File "C:\Users\ipharmacare\newreport\common\configReader.py", line 50, in getitems
    result=self.conf.items(field)
  File "C:\Users\ipharmacare\python27\lib\ConfigParser.py", line 642, in items
    raise NoSectionError(section)
NoSectionError: No section: 'default_dept'
Tue, 23 Jul 2019 14:17:03 log.py[line:17] DEBUG 读取配置项发生了错误,ConfigurationItem_dept
Tue, 23 Jul 2019 14:17:03 log.py[line:20] ERROR No section: 'ConfigurationItem_dept'
Traceback (most recent call last):
  File "C:\Users\ipharmacare\newreport\common\configReader.py", line 50, in getitems
    result=self.conf.items(field)
  File "C:\Users\ipharmacare\python27\lib\ConfigParser.py", line 642, in items
    raise NoSectionError(section)
NoSectionError: No section: 'ConfigurationItem_dept'
Tue, 23 Jul 2019 14:17:03 log.py[line:17] DEBUG 读取配置项发生了错误,dept_ddds
Tue, 23 Jul 2019 14:17:03 log.py[line:20] ERROR No section: 'dept_ddds'
Traceback (most recent call last):
  File "C:\Users\ipharmacare\newreport\common\configReader.py", line 50, in getitems
    result=self.conf.items(field)
  File "C:\Users\ipharmacare\python27\lib\ConfigParser.py", line 642, in items
    raise NoSectionError(section)
NoSectionError: No section: 'dept_ddds'
Tue, 23 Jul 2019 14:17:03 log.py[line:17] DEBUG 读取配置项发生了错误,hospitalDept_ddds
Tue, 23 Jul 2019 14:17:03 log.py[line:20] ERROR No section: 'hospitalDept_ddds'
Traceback (most recent call last):
  File "C:\Users\ipharmacare\newreport\common\configReader.py", line 50, in getitems
    result=self.conf.items(field)
  File "C:\Users\ipharmacare\python27\lib\ConfigParser.py", line 642, in items
    raise NoSectionError(section)
NoSectionError: No section: 'hospitalDept_ddds'
Tue, 23 Jul 2019 14:17:03 log.py[line:17] DEBUG 读取配置项发生了错误,default_group
Tue, 23 Jul 2019 14:17:03 log.py[line:20] ERROR No section: 'default_group'
Traceback (most recent call last):
  File "C:\Users\ipharmacare\newreport\common\configReader.py", line 50, in getitems
    result=self.conf.items(field)
  File "C:\Users\ipharmacare\python27\lib\ConfigParser.py", line 642, in items
    raise NoSectionError(section)
NoSectionError: No section: 'default_group'
Tue, 23 Jul 2019 14:17:03 log.py[line:17] DEBUG 该指标在指标库中不存在,去年同期出院患者总人次
Tue, 23 Jul 2019 14:17:03 log.py[line:17] DEBUG 该指标在指标库中不存在,出院患者特殊级抗菌药物使用人次数
Tue, 23 Jul 2019 14:17:04 log.py[line:17] DEBUG 该指标在指标库中不存在,使用非限制级抗菌药物出院患者中病原学检查送检人次
Tue, 23 Jul 2019 14:17:04 log.py[line:17] DEBUG 该指标在指标库中不存在,使用限制级抗菌药物出院患者中病原学检查送检人次
Tue, 23 Jul 2019 14:17:04 log.py[line:17] DEBUG 该指标在指标库中不存在,使用特殊级抗菌药物出院患者中病原学检查送检人次
Tue, 23 Jul 2019 14:17:04 log.py[line:17] DEBUG 该指标在指标库中不存在,出院患者静脉输液总人次
Tue, 23 Jul 2019 14:17:04 log.py[line:17] DEBUG 该指标在指标库中不存在,出院患者总人次（排除中药饮片）
Tue, 23 Jul 2019 14:17:04 connectionpool.py[line:205] DEBUG Starting new HTTP connection (1): 10.1.1.89:9999
Tue, 23 Jul 2019 14:17:04 connectionpool.py[line:393] DEBUG http://10.1.1.89:9999 "POST /syscenter/api/v1/currentUser HTTP/1.1" 200 None
Tue, 23 Jul 2019 14:17:05 connectionpool.py[line:393] DEBUG http://10.1.1.89:9999 "GET /syscenter/api/v1/config/selectSysConfig?showName=%E6%8A%97%E8%8F%8C%E8%8D%AF%E7%89%A9%E9%80%81%E6%A3%80%E6%A0%87%E8%AF%86 HTTP/1.1" 200 None
Tue, 23 Jul 2019 14:17:07 connectionpool.py[line:205] DEBUG Starting new HTTP connection (1): 10.1.1.89:9999
Tue, 23 Jul 2019 14:17:07 connectionpool.py[line:393] DEBUG http://10.1.1.89:9999 "POST /syscenter/api/v1/currentUser HTTP/1.1" 200 None
Tue, 23 Jul 2019 14:17:07 connectionpool.py[line:393] DEBUG http://10.1.1.89:9999 "GET /syscenter/api/v1/config/selectSysConfig?showName=%E6%8A%97%E8%8F%8C%E8%8D%AF%E7%89%A9%E9%80%81%E6%A3%80%E6%A0%87%E8%AF%86 HTTP/1.1" 200 None
Tue, 23 Jul 2019 19:38:50 log.py[line:17] DEBUG 读取配置项发生了错误,zone,省增补基本药物使用金额
Tue, 23 Jul 2019 19:38:50 log.py[line:20] ERROR No option '\xe7\x9c\x81\xe5\xa2\x9e\xe8\xa1\xa5\xe5\x9f\xba\xe6\x9c\xac\xe8\x8d\xaf\xe7\x89\xa9\xe4\xbd\xbf\xe7\x94\xa8\xe9\x87\x91\xe9\xa2\x9d' in section: 'zone'
Traceback (most recent call last):
  File "C:\Users\ipharmacare\newreport\common\configReader.py", line 27, in get
    return self.conf.get(field,key)
  File "C:\Users\ipharmacare\python27\lib\ConfigParser.py", line 618, in get
    raise NoOptionError(option, section)
NoOptionError: No option '\xe7\x9c\x81\xe5\xa2\x9e\xe8\xa1\xa5\xe5\x9f\xba\xe6\x9c\xac\xe8\x8d\xaf\xe7\x89\xa9\xe4\xbd\xbf\xe7\x94\xa8\xe9\x87\x91\xe9\xa2\x9d' in section: 'zone'
Tue, 23 Jul 2019 19:39:58 log.py[line:17] DEBUG 读取配置项发生了错误,zone,省增补基本药物使用金额
Tue, 23 Jul 2019 19:39:58 log.py[line:20] ERROR No option '\xe7\x9c\x81\xe5\xa2\x9e\xe8\xa1\xa5\xe5\x9f\xba\xe6\x9c\xac\xe8\x8d\xaf\xe7\x89\xa9\xe4\xbd\xbf\xe7\x94\xa8\xe9\x87\x91\xe9\xa2\x9d' in section: 'zone'
Traceback (most recent call last):
  File "C:\Users\ipharmacare\newreport\common\configReader.py", line 27, in get
    return self.conf.get(field,key)
  File "C:\Users\ipharmacare\python27\lib\ConfigParser.py", line 618, in get
    raise NoOptionError(option, section)
NoOptionError: No option '\xe7\x9c\x81\xe5\xa2\x9e\xe8\xa1\xa5\xe5\x9f\xba\xe6\x9c\xac\xe8\x8d\xaf\xe7\x89\xa9\xe4\xbd\xbf\xe7\x94\xa8\xe9\x87\x91\xe9\xa2\x9d' in section: 'zone'
